[2025-06-27T07:41:03.220+0000] {local_task_job_runner.py:120} INFO - ::group::Pre task execution logs
[2025-06-27T07:41:03.270+0000] {taskinstance.py:2076} INFO - Dependencies all met for dep_context=non-requeueable deps ti=<TaskInstance: WF_MAIN.run_hop_pipeline scheduled__2025-06-27T06:41:00+00:00 [queued]>
[2025-06-27T07:41:03.282+0000] {taskinstance.py:2076} INFO - Dependencies all met for dep_context=requeueable deps ti=<TaskInstance: WF_MAIN.run_hop_pipeline scheduled__2025-06-27T06:41:00+00:00 [queued]>
[2025-06-27T07:41:03.282+0000] {taskinstance.py:2306} INFO - Starting attempt 1 of 2
[2025-06-27T07:41:03.301+0000] {taskinstance.py:2330} INFO - Executing <Task(DockerOperator): run_hop_pipeline> on 2025-06-27 06:41:00+00:00
[2025-06-27T07:41:03.308+0000] {warnings.py:110} WARNING - /home/***/.local/lib/python3.12/site-packages/***/task/task_runner/standard_task_runner.py:61: DeprecationWarning: This process (pid=119) is multi-threaded, use of fork() may lead to deadlocks in the child.
  pid = os.fork()

[2025-06-27T07:41:03.310+0000] {standard_task_runner.py:90} INFO - Running: ['***', 'tasks', 'run', 'WF_MAIN', 'run_hop_pipeline', 'scheduled__2025-06-27T06:41:00+00:00', '--job-id', '8', '--raw', '--subdir', 'DAGS_FOLDER/apache-hop-dag-wf-main.py', '--cfg-path', '/tmp/tmpv0ns82cr']
[2025-06-27T07:41:03.313+0000] {standard_task_runner.py:63} INFO - Started process 126 to run task
[2025-06-27T07:41:03.313+0000] {standard_task_runner.py:91} INFO - Job 8: Subtask run_hop_pipeline
[2025-06-27T07:41:03.401+0000] {task_command.py:426} INFO - Running <TaskInstance: WF_MAIN.run_hop_pipeline scheduled__2025-06-27T06:41:00+00:00 [running]> on host ec14a5b8088e
[2025-06-27T07:41:03.524+0000] {taskinstance.py:2648} INFO - Exporting env vars: AIRFLOW_CTX_DAG_OWNER='***' AIRFLOW_CTX_DAG_ID='WF_MAIN' AIRFLOW_CTX_TASK_ID='run_hop_pipeline' AIRFLOW_CTX_EXECUTION_DATE='2025-06-27T06:41:00+00:00' AIRFLOW_CTX_TRY_NUMBER='1' AIRFLOW_CTX_DAG_RUN_ID='scheduled__2025-06-27T06:41:00+00:00'
[2025-06-27T07:41:03.525+0000] {taskinstance.py:430} INFO - ::endgroup::
[2025-06-27T07:41:03.644+0000] {docker.py:366} INFO - Starting docker container from image apache/hop:latest
[2025-06-27T07:41:03.670+0000] {docker.py:374} WARNING - Using remote engine or docker-in-docker and mounting temporary volume from host is not supported. Falling back to `mount_tmp_dir=False` mode. You can set `mount_tmp_dir` parameter to False to disable mounting and remove the warning
[2025-06-27T07:41:04.158+0000] {docker.py:436} INFO - 2025/06/27 07:41:04 - Running the entrypoint script with PID 7
[2025-06-27T07:41:04.160+0000] {docker.py:436} INFO - 2025/06/27 07:41:04 - The project folder for ProyectoSmartMed is set to: /files
[2025-06-27T07:41:04.165+0000] {docker.py:436} INFO - 2025/06/27 07:41:04 - The specified project folder exists
[2025-06-27T07:41:04.166+0000] {docker.py:436} INFO - 2025/06/27 07:41:04 - Registering project ProyectoSmartMed in the Hop container configuration
[2025-06-27T07:41:04.169+0000] {docker.py:436} INFO - 2025/06/27 07:41:04 - /opt/hop/hop-conf.sh --project=ProyectoSmartMed --project-create --project-home='/files' --project-config-file='project-config.json'
[2025-06-27T07:41:24.567+0000] {docker.py:436} INFO - Creating project 'ProyectoSmartMed'
[2025-06-27T07:41:25.088+0000] {docker.py:436} INFO - Project 'ProyectoSmartMed' was created for home folder : /files
[2025-06-27T07:41:25.174+0000] {docker.py:436} INFO - Configuration file for project 'ProyectoSmartMed' was saved to : file:/files/project-config.json
[2025-06-27T07:41:25.274+0000] {docker.py:436} INFO - 2025/06/27 07:41:25 - Not creating an environment in the container
[2025-06-27T07:41:25.278+0000] {docker.py:436} INFO - 2025/06/27 07:41:25 - Running a single hop workflow / pipeline (${PROJECT_HOME}/workflows/WF_MAIN.hwf)
[2025-06-27T07:41:35.455+0000] {docker.py:436} INFO - 2025/06/27 07:41:35 - HopRun - Enabling project 'ProyectoSmartMed'
[2025-06-27T07:41:35.675+0000] {docker.py:436} INFO - 2025/06/27 07:41:35 - HopRun - Starting workflow: /files/workflows/WF_MAIN.hwf
[2025-06-27T07:41:37.880+0000] {docker.py:436} INFO - 2025/06/27 07:41:37 - WF_MAIN - Start of workflow execution
[2025-06-27T07:41:38.119+0000] {docker.py:436} INFO - 2025/06/27 07:41:38 - WF_MAIN - Starting action [filename.hwf]
[2025-06-27T07:41:39.093+0000] {docker.py:436} INFO - 2025/06/27 07:41:39 - filename - Start of workflow execution
[2025-06-27T07:41:39.116+0000] {docker.py:436} INFO - 2025/06/27 07:41:39 - filename - Starting action [prueba.hpl]
[2025-06-27T07:41:39.209+0000] {docker.py:436} INFO - 2025/06/27 07:41:39 - prueba.hpl - Using run configuration [local]
[2025-06-27T07:41:39.244+0000] {docker.py:436} INFO - 2025/06/27 07:41:39 - prueba - Executing this pipeline using the Local Pipeline Engine with run configuration 'local'
[2025-06-27T07:41:39.255+0000] {docker.py:436} INFO - 2025/06/27 07:41:39 - prueba - Execution started for pipeline [prueba]
[2025-06-27T07:41:42.636+0000] {docker.py:436} INFO - 2025/06/27 07:41:42 - Table input.0 - Finished reading query, closing connection.
[2025-06-27T07:41:42.638+0000] {docker.py:436} INFO - 2025/06/27 07:41:42 - Set variables.0 - Setting project variables...
[2025-06-27T07:41:42.639+0000] {docker.py:436} INFO - 2025/06/27 07:41:42 - Set variables.0 - Set variable lastDate to value [2025-06-27 01:20:57]
[2025-06-27T07:41:42.645+0000] {docker.py:436} INFO - 2025/06/27 07:41:42 - Set variables.0 - Finished after 1 rows.
[2025-06-27T07:41:42.646+0000] {docker.py:436} INFO - 2025/06/27 07:41:42 - Set variables.0 - Finished processing (I=0, O=0, R=1, W=1, U=0, E=0)
[2025-06-27T07:41:42.749+0000] {docker.py:436} INFO - 2025/06/27 07:41:42 - Table input.0 - Finished processing (I=1, O=0, R=0, W=1, U=0, E=0)
[2025-06-27T07:41:53.852+0000] {docker.py:436} INFO - 2025/06/27 07:41:53 - REST client.0 - ERROR: Because of an error, this transform can't continue:
2025/06/27 07:41:53 - REST client.0 - Can not read result from [http://20.0.1.136:8000/api/v1/dags/dagruns]
2025/06/27 07:41:53 - REST client.0 - 
2025/06/27 07:41:53 - REST client.0 - Request could not be processed
2025/06/27 07:41:53 - REST client.0 - org.apache.http.conn.ConnectTimeoutException: Connect to 20.0.1.136:8000 [/20.0.1.136] failed: Connect timed out
[2025-06-27T07:41:53.854+0000] {docker.py:436} INFO - 2025/06/27 07:41:53 - REST client.0 - ERROR: org.apache.hop.core.exception.HopException: 
2025/06/27 07:41:53 - REST client.0 - Can not read result from [http://20.0.1.136:8000/api/v1/dags/dagruns]
2025/06/27 07:41:53 - REST client.0 - 
2025/06/27 07:41:53 - REST client.0 - Request could not be processed
2025/06/27 07:41:53 - REST client.0 - org.apache.http.conn.ConnectTimeoutException: Connect to 20.0.1.136:8000 [/20.0.1.136] failed: Connect timed out
2025/06/27 07:41:53 - REST client.0 - 
2025/06/27 07:41:53 - REST client.0 - 
2025/06/27 07:41:53 - REST client.0 - 	at org.apache.hop.pipeline.transforms.rest.Rest.callRest(Rest.java:321)
2025/06/27 07:41:53 - REST client.0 - 	at org.apache.hop.pipeline.transforms.rest.Rest.processRow(Rest.java:538)
2025/06/27 07:41:53 - REST client.0 - 	at org.apache.hop.pipeline.transform.RunThread.run(RunThread.java:54)
2025/06/27 07:41:53 - REST client.0 - 	at java.base/java.lang.Thread.run(Thread.java:840)
2025/06/27 07:41:53 - REST client.0 - Caused by: org.apache.hop.core.exception.HopException: 
2025/06/27 07:41:53 - REST client.0 - Request could not be processed
2025/06/27 07:41:53 - REST client.0 - org.apache.http.conn.ConnectTimeoutException: Connect to 20.0.1.136:8000 [/20.0.1.136] failed: Connect timed out
2025/06/27 07:41:53 - REST client.0 - 
2025/06/27 07:41:53 - REST client.0 - 	at org.apache.hop.pipeline.transforms.rest.Rest.callRest(Rest.java:258)
2025/06/27 07:41:53 - REST client.0 - 	... 3 more
2025/06/27 07:41:53 - REST client.0 - Caused by: javax.ws.rs.ProcessingException: org.apache.http.conn.ConnectTimeoutException: Connect to 20.0.1.136:8000 [/20.0.1.136] failed: Connect timed out
2025/06/27 07:41:53 - REST client.0 - 	at org.glassfish.jersey.apache.connector.ApacheConnector.apply(ApacheConnector.java:533)
2025/06/27 07:41:53 - REST client.0 - 	at org.glassfish.jersey.client.ClientRuntime.invoke(ClientRuntime.java:300)
2025/06/27 07:41:53 - REST client.0 - 	at org.glassfish.jersey.client.JerseyInvocation.lambda$invoke$1(JerseyInvocation.java:687)
2025/06/27 07:41:53 - REST client.0 - 	at org.glassfish.jersey.client.JerseyInvocation.call(JerseyInvocation.java:709)
2025/06/27 07:41:53 - REST client.0 - 	at org.glassfish.jersey.client.JerseyInvocation.lambda$runInScope$3(JerseyInvocation.java:703)
2025/06/27 07:41:53 - REST client.0 - 	at org.glassfish.jersey.internal.Errors.process(Errors.java:292)
2025/06/27 07:41:53 - REST client.0 - 	at org.glassfish.jersey.internal.Errors.process(Errors.java:274)
2025/06/27 07:41:53 - REST client.0 - 	at org.glassfish.jersey.internal.Errors.process(Errors.java:205)
2025/06/27 07:41:53 - REST client.0 - 	at org.glassfish.jersey.process.internal.RequestScope.runInScope(RequestScope.java:390)
2025/06/27 07:41:53 - REST client.0 - 	at org.glassfish.jersey.client.JerseyInvocation.runInScope(JerseyInvocation.java:703)
2025/06/27 07:41:53 - REST client.0 - 	at org.glassfish.jersey.client.JerseyInvocation.invoke(JerseyInvocation.java:686)
2025/06/27 07:41:53 - REST client.0 - 	at org.glassfish.jersey.client.JerseyInvocation$Builder.method(JerseyInvocation.java:422)
2025/06/27 07:41:53 - REST client.0 - 	at org.glassfish.jersey.client.JerseyInvocation$Builder.get(JerseyInvocation.java:318)
2025/06/27 07:41:53 - REST client.0 - 	at org.apache.hop.pipeline.transforms.rest.Rest.callRest(Rest.java:224)
2025/06/27 07:41:53 - REST client.0 - 	... 3 more
2025/06/27 07:41:53 - REST client.0 - Caused by: org.apache.http.conn.ConnectTimeoutException: Connect to 20.0.1.136:8000 [/20.0.1.136] failed: Connect timed out
2025/06/27 07:41:53 - REST client.0 - 	at org.apache.http.impl.conn.DefaultHttpClientConnectionOperator.connect(DefaultHttpClientConnectionOperator.java:151)
2025/06/27 07:41:53 - REST client.0 - 	at org.apache.http.impl.conn.PoolingHttpClientConnectionManager.connect(PoolingHttpClientConnectionManager.java:376)
2025/06/27 07:41:53 - REST client.0 - 	at org.apache.http.impl.execchain.MainClientExec.establishRoute(MainClientExec.java:393)
2025/06/27 07:41:53 - REST client.0 - 	at org.apache.http.impl.execchain.MainClientExec.execute(MainClientExec.java:236)
2025/06/27 07:41:53 - REST client.0 - 	at org.apache.http.impl.execchain.ProtocolExec.execute(ProtocolExec.java:186)
2025/06/27 07:41:53 - REST client.0 - 	at org.apache.http.impl.execchain.RetryExec.execute(RetryExec.java:89)
2025/06/27 07:41:53 - REST client.0 - 	at org.apache.http.impl.execchain.RedirectExec.execute(RedirectExec.java:110)
2025/06/27 07:41:53 - REST client.0 - 	at org.apache.http.impl.client.InternalHttpClient.doExecute(InternalHttpClient.java:185)
2025/06/27 07:41:53 - REST client.0 - 	at org.apache.http.impl.client.CloseableHttpClient.execute(CloseableHttpClient.java:72)
2025/06/27 07:41:53 - REST client.0 - 	at org.glassfish.jersey.apache.connector.ApacheConnector.apply(ApacheConnector.java:485)
2025/06/27 07:41:53 - REST client.0 - 	... 16 more
2025/06/27 07:41:53 - REST client.0 - Caused by: java.net.SocketTimeoutException: Connect timed out
2025/06/27 07:41:53 - REST client.0 - 	at java.base/sun.nio.ch.NioSocketImpl.timedFinishConnect(NioSocketImpl.java:551)
2025/06/27 07:41:53 - REST client.0 - 	at java.base/sun.nio.ch.NioSocketImpl.connect(NioSocketImpl.java:602)
2025/06/27 07:41:53 - REST client.0 - 	at java.base/java.net.SocksSocketImpl.connect(SocksSocketImpl.java:327)
2025/06/27 07:41:53 - REST client.0 - 	at java.base/java.net.Socket.connect(Socket.java:633)
2025/06/27 07:41:53 - REST client.0 - 	at org.apache.http.conn.socket.PlainConnectionSocketFactory.connectSocket(PlainConnectionSocketFactory.java:75)
2025/06/27 07:41:53 - REST client.0 - 	at org.apache.http.impl.conn.DefaultHttpClientConnectionOperator.connect(DefaultHttpClientConnectionOperator.java:142)
2025/06/27 07:41:53 - REST client.0 - 	... 25 more
[2025-06-27T07:41:53.855+0000] {docker.py:436} INFO - 2025/06/27 07:41:53 - REST client.0 - Finished processing (I=0, O=0, R=1, W=0, U=0, E=1)
[2025-06-27T07:41:53.855+0000] {docker.py:436} INFO - 2025/06/27 07:41:53 - prueba - Pipeline detected one or more transforms with errors.
[2025-06-27T07:41:53.856+0000] {docker.py:436} INFO - 2025/06/27 07:41:53 - prueba - Pipeline is killing the other transforms!
[2025-06-27T07:41:53.873+0000] {docker.py:436} INFO - 2025/06/27 07:41:53 - Set variables 2.0 - We didn't receive a row while setting the default values.
[2025-06-27T07:41:53.873+0000] {docker.py:436} INFO - 2025/06/27 07:41:53 - Set variables 2.0 - Finished after 0 rows.
[2025-06-27T07:41:53.878+0000] {docker.py:436} INFO - 2025/06/27 07:41:53 - prueba - Pipeline duration : 14.631 seconds [ 14.631" ]
[2025-06-27T07:41:53.913+0000] {docker.py:436} INFO - 2025/06/27 07:41:53 - prueba - Execution finished on a local pipeline engine with run configuration 'local'
[2025-06-27T07:41:53.918+0000] {docker.py:436} INFO - 2025/06/27 07:41:53 - filename - Finished action [prueba.hpl] (result=[false])
[2025-06-27T07:41:53.919+0000] {docker.py:436} INFO - 2025/06/27 07:41:53 - filename - Workflow execution finished
[2025-06-27T07:41:53.933+0000] {docker.py:436} INFO - 2025/06/27 07:41:53 - filename - Workflow duration : 15.544 seconds [ 15.544" ]
[2025-06-27T07:41:53.937+0000] {docker.py:436} INFO - 2025/06/27 07:41:53 - WF_MAIN - Finished action [filename.hwf] (result=[false])
[2025-06-27T07:41:53.937+0000] {docker.py:436} INFO - 2025/06/27 07:41:53 - WF_MAIN - Workflow execution finished
[2025-06-27T07:41:53.950+0000] {docker.py:436} INFO - 2025/06/27 07:41:53 - WF_MAIN - Workflow duration : 18.248 seconds [ 18.248" ]
[2025-06-27T07:41:53.952+0000] {docker.py:436} INFO - HopRun exit.
[2025-06-27T07:41:54.320+0000] {taskinstance.py:441} INFO - ::group::Post task execution logs
[2025-06-27T07:41:54.340+0000] {taskinstance.py:2905} ERROR - Task failed with exception
Traceback (most recent call last):
  File "/home/airflow/.local/lib/python3.12/site-packages/docker/api/client.py", line 265, in _raise_for_status
    response.raise_for_status()
  File "/home/airflow/.local/lib/python3.12/site-packages/requests/models.py", line 1021, in raise_for_status
    raise HTTPError(http_error_msg, response=self)
requests.exceptions.HTTPError: 400 Client Error: Bad Request for url: http+docker://localhost/v1.50/containers/create

The above exception was the direct cause of the following exception:

Traceback (most recent call last):
  File "/home/airflow/.local/lib/python3.12/site-packages/airflow/providers/docker/operators/docker.py", line 371, in _run_image
    return self._run_image_with_mounts([*self.mounts, tmp_mount], add_tmp_variable=True)
           ^^^^^^^^^^^^^^^^^^^^^^^^^^^^^^^^^^^^^^^^^^^^^^^^^^^^^^^^^^^^^^^^^^^^^^^^^^^^^
  File "/home/airflow/.local/lib/python3.12/site-packages/airflow/providers/docker/operators/docker.py", line 398, in _run_image_with_mounts
    self.container = self.cli.create_container(
                     ^^^^^^^^^^^^^^^^^^^^^^^^^^
  File "/home/airflow/.local/lib/python3.12/site-packages/docker/api/container.py", line 439, in create_container
    return self.create_container_from_config(config, name, platform)
           ^^^^^^^^^^^^^^^^^^^^^^^^^^^^^^^^^^^^^^^^^^^^^^^^^^^^^^^^^
  File "/home/airflow/.local/lib/python3.12/site-packages/docker/api/container.py", line 456, in create_container_from_config
    return self._result(res, True)
           ^^^^^^^^^^^^^^^^^^^^^^^
  File "/home/airflow/.local/lib/python3.12/site-packages/docker/api/client.py", line 271, in _result
    self._raise_for_status(response)
  File "/home/airflow/.local/lib/python3.12/site-packages/docker/api/client.py", line 267, in _raise_for_status
    raise create_api_error_from_http_exception(e) from e
          ^^^^^^^^^^^^^^^^^^^^^^^^^^^^^^^^^^^^^^^
  File "/home/airflow/.local/lib/python3.12/site-packages/docker/errors.py", line 39, in create_api_error_from_http_exception
    raise cls(e, response=response, explanation=explanation) from e
docker.errors.APIError: 400 Client Error for http+docker://localhost/v1.50/containers/create: Bad Request ("invalid mount config for type "bind": bind source path does not exist: /tmp/airflowtmpo_ao1776")

During handling of the above exception, another exception occurred:

Traceback (most recent call last):
  File "/home/airflow/.local/lib/python3.12/site-packages/airflow/models/taskinstance.py", line 465, in _execute_task
    result = _execute_callable(context=context, **execute_callable_kwargs)
             ^^^^^^^^^^^^^^^^^^^^^^^^^^^^^^^^^^^^^^^^^^^^^^^^^^^^^^^^^^^^^
  File "/home/airflow/.local/lib/python3.12/site-packages/airflow/models/taskinstance.py", line 432, in _execute_callable
    return execute_callable(context=context, **execute_callable_kwargs)
           ^^^^^^^^^^^^^^^^^^^^^^^^^^^^^^^^^^^^^^^^^^^^^^^^^^^^^^^^^^^^
  File "/home/airflow/.local/lib/python3.12/site-packages/airflow/models/baseoperator.py", line 400, in wrapper
    return func(self, *args, **kwargs)
           ^^^^^^^^^^^^^^^^^^^^^^^^^^^
  File "/home/airflow/.local/lib/python3.12/site-packages/airflow/providers/docker/operators/docker.py", line 509, in execute
    return self._run_image()
           ^^^^^^^^^^^^^^^^^
  File "/home/airflow/.local/lib/python3.12/site-packages/airflow/providers/docker/operators/docker.py", line 380, in _run_image
    return self._run_image_with_mounts(self.mounts, add_tmp_variable=False)
           ^^^^^^^^^^^^^^^^^^^^^^^^^^^^^^^^^^^^^^^^^^^^^^^^^^^^^^^^^^^^^^^^
  File "/home/airflow/.local/lib/python3.12/site-packages/airflow/providers/docker/operators/docker.py", line 444, in _run_image_with_mounts
    raise DockerContainerFailedException(f"Docker container failed: {result!r}", logs=log_lines)
airflow.providers.docker.exceptions.DockerContainerFailedException: Docker container failed: {'StatusCode': 1}
[2025-06-27T07:41:54.354+0000] {taskinstance.py:1206} INFO - Marking task as UP_FOR_RETRY. dag_id=WF_MAIN, task_id=run_hop_pipeline, run_id=scheduled__2025-06-27T06:41:00+00:00, execution_date=20250627T064100, start_date=20250627T074103, end_date=20250627T074154
[2025-06-27T07:41:54.391+0000] {standard_task_runner.py:110} ERROR - Failed to execute job 8 for task run_hop_pipeline (Docker container failed: {'StatusCode': 1}; 126)
[2025-06-27T07:41:54.442+0000] {local_task_job_runner.py:240} INFO - Task exited with return code 1
[2025-06-27T07:41:54.482+0000] {taskinstance.py:3498} INFO - 0 downstream tasks scheduled from follow-on schedule check
[2025-06-27T07:41:54.484+0000] {local_task_job_runner.py:222} INFO - ::endgroup::
