[2025-06-27T07:21:05.075+0000] {local_task_job_runner.py:120} INFO - ::group::Pre task execution logs
[2025-06-27T07:21:05.141+0000] {taskinstance.py:2076} INFO - Dependencies all met for dep_context=non-requeueable deps ti=<TaskInstance: STG4_MEDIDORES.run_hop_pipeline scheduled__2025-06-27T06:21:00+00:00 [queued]>
[2025-06-27T07:21:05.168+0000] {taskinstance.py:2076} INFO - Dependencies all met for dep_context=requeueable deps ti=<TaskInstance: STG4_MEDIDORES.run_hop_pipeline scheduled__2025-06-27T06:21:00+00:00 [queued]>
[2025-06-27T07:21:05.177+0000] {taskinstance.py:2306} INFO - Starting attempt 1 of 2
[2025-06-27T07:21:05.231+0000] {taskinstance.py:2330} INFO - Executing <Task(DockerOperator): run_hop_pipeline> on 2025-06-27 06:21:00+00:00
[2025-06-27T07:21:05.248+0000] {warnings.py:110} WARNING - /home/***/.local/lib/python3.12/site-packages/***/task/task_runner/standard_task_runner.py:61: DeprecationWarning: This process (pid=74) is multi-threaded, use of fork() may lead to deadlocks in the child.
  pid = os.fork()

[2025-06-27T07:21:05.261+0000] {standard_task_runner.py:63} INFO - Started process 76 to run task
[2025-06-27T07:21:05.264+0000] {standard_task_runner.py:90} INFO - Running: ['***', 'tasks', 'run', 'STG4_MEDIDORES', 'run_hop_pipeline', 'scheduled__2025-06-27T06:21:00+00:00', '--job-id', '8', '--raw', '--subdir', 'DAGS_FOLDER/apache-hop-dag-simple.py', '--cfg-path', '/tmp/tmp37s3xz8n']
[2025-06-27T07:21:05.276+0000] {standard_task_runner.py:91} INFO - Job 8: Subtask run_hop_pipeline
[2025-06-27T07:21:05.490+0000] {task_command.py:426} INFO - Running <TaskInstance: STG4_MEDIDORES.run_hop_pipeline scheduled__2025-06-27T06:21:00+00:00 [running]> on host 5e15c4a8eeb7
[2025-06-27T07:21:05.761+0000] {taskinstance.py:2648} INFO - Exporting env vars: AIRFLOW_CTX_DAG_OWNER='***' AIRFLOW_CTX_DAG_ID='STG4_MEDIDORES' AIRFLOW_CTX_TASK_ID='run_hop_pipeline' AIRFLOW_CTX_EXECUTION_DATE='2025-06-27T06:21:00+00:00' AIRFLOW_CTX_TRY_NUMBER='1' AIRFLOW_CTX_DAG_RUN_ID='scheduled__2025-06-27T06:21:00+00:00'
[2025-06-27T07:21:05.769+0000] {taskinstance.py:430} INFO - ::endgroup::
[2025-06-27T07:21:06.029+0000] {docker.py:366} INFO - Starting docker container from image apache/hop:latest
[2025-06-27T07:21:06.075+0000] {docker.py:374} WARNING - Using remote engine or docker-in-docker and mounting temporary volume from host is not supported. Falling back to `mount_tmp_dir=False` mode. You can set `mount_tmp_dir` parameter to False to disable mounting and remove the warning
[2025-06-27T07:21:08.072+0000] {docker.py:436} INFO - 2025/06/27 07:21:08 - Running the entrypoint script with PID 8
[2025-06-27T07:21:08.099+0000] {docker.py:436} INFO - 2025/06/27 07:21:08 - The project folder for ProyectoSmartMed is set to: /files
[2025-06-27T07:21:08.116+0000] {docker.py:436} INFO - 2025/06/27 07:21:08 - The specified project folder exists
[2025-06-27T07:21:08.200+0000] {docker.py:436} INFO - 2025/06/27 07:21:08 - Registering project ProyectoSmartMed in the Hop container configuration
[2025-06-27T07:21:08.260+0000] {docker.py:436} INFO - 2025/06/27 07:21:08 - /opt/hop/hop-conf.sh --project=ProyectoSmartMed --project-create --project-home='/files' --project-config-file='project-config.json'
[2025-06-27T07:22:37.440+0000] {docker.py:436} INFO - Creating project 'ProyectoSmartMed'
[2025-06-27T07:22:38.531+0000] {docker.py:436} INFO - Project 'ProyectoSmartMed' was created for home folder : /files
[2025-06-27T07:22:38.763+0000] {docker.py:436} INFO - Configuration file for project 'ProyectoSmartMed' was saved to : file:/files/project-config.json
[2025-06-27T07:22:39.039+0000] {docker.py:436} INFO - 2025/06/27 07:22:39 - Not creating an environment in the container
[2025-06-27T07:22:39.050+0000] {docker.py:436} INFO - 2025/06/27 07:22:39 - Running a single hop workflow / pipeline (${PROJECT_HOME}/Pipelines/STG4_MEDIDORES.hpl)
[2025-06-27T07:23:07.383+0000] {docker.py:436} INFO - 2025/06/27 07:23:07 - HopRun - Enabling project 'ProyectoSmartMed'
[2025-06-27T07:23:07.857+0000] {docker.py:436} INFO - 2025/06/27 07:23:07 - HopRun - Starting pipeline: /files/Pipelines/STG4_MEDIDORES.hpl
[2025-06-27T07:23:07.882+0000] {docker.py:436} INFO - 2025/06/27 07:23:07 - STG4_MEDIDORES - Executing this pipeline using the Local Pipeline Engine with run configuration 'local'
[2025-06-27T07:23:07.958+0000] {docker.py:436} INFO - 2025/06/27 07:23:07 - STG4_MEDIDORES - Execution started for pipeline [STG4_MEDIDORES]
[2025-06-27T07:23:22.247+0000] {docker.py:436} INFO - 2025/06/27 07:23:22 - STG3_MEDIDORES.0 - ERROR: An error occurred, processing will be stopped: 
2025/06/27 07:23:22 - STG3_MEDIDORES.0 - Error occurred while trying to connect to the database
2025/06/27 07:23:22 - STG3_MEDIDORES.0 - 
2025/06/27 07:23:22 - STG3_MEDIDORES.0 - Error connecting to database: (using class org.postgresql.Driver)
2025/06/27 07:23:22 - STG3_MEDIDORES.0 - The connection attempt failed.
2025/06/27 07:23:22 - STG4_MEDIDORES.0 - ERROR: An error occurred initializing this transform: 
2025/06/27 07:23:22 - STG4_MEDIDORES.0 - Error occurred while trying to connect to the database
2025/06/27 07:23:22 - STG4_MEDIDORES.0 - 
2025/06/27 07:23:22 - STG4_MEDIDORES.0 - Error connecting to database: (using class org.postgresql.Driver)
2025/06/27 07:23:22 - STG4_MEDIDORES.0 - The connection attempt failed.
[2025-06-27T07:23:22.249+0000] {docker.py:436} INFO - 2025/06/27 07:23:22 - STG4_MEDIDORES.0 - ERROR: Error initializing transform [STG4_MEDIDORES]
[2025-06-27T07:23:22.250+0000] {docker.py:436} INFO - 2025/06/27 07:23:22 - STG3_MEDIDORES.0 - ERROR: Error initializing transform [STG3_MEDIDORES]
[2025-06-27T07:23:22.251+0000] {docker.py:436} INFO - 2025/06/27 07:23:22 - STG4_MEDIDORES - ERROR: Transform [STG3_MEDIDORES.0] failed to initialize!
[2025-06-27T07:23:22.252+0000] {docker.py:436} INFO - 2025/06/27 07:23:22 - STG4_MEDIDORES - ERROR: Transform [STG4_MEDIDORES.0] failed to initialize!
[2025-06-27T07:23:22.253+0000] {docker.py:436} INFO - 2025/06/27 07:23:22 - STG3_MEDIDORES.0 - Finished reading query, closing connection.
[2025-06-27T07:23:22.254+0000] {docker.py:436} INFO - 2025/06/27 07:23:22 - STG4_MEDIDORES.0 - ERROR: Unexpected error rolling back the database connection.
[2025-06-27T07:23:22.254+0000] {docker.py:436} INFO - 2025/06/27 07:23:22 - STG4_MEDIDORES.0 - ERROR: org.apache.hop.core.exception.HopDatabaseException: 
2025/06/27 07:23:22 - STG4_MEDIDORES.0 - Unable to get database metadata from this database connection
2025/06/27 07:23:22 - STG4_MEDIDORES.0 - 
2025/06/27 07:23:22 - STG4_MEDIDORES.0 - Error connecting to database [***]
2025/06/27 07:23:22 - STG4_MEDIDORES.0 - 
2025/06/27 07:23:22 - STG4_MEDIDORES.0 - 
2025/06/27 07:23:22 - STG4_MEDIDORES.0 - 	at org.apache.hop.core.database.Database.getDatabaseMetaData(Database.java:2897)
2025/06/27 07:23:22 - STG4_MEDIDORES.0 - 	at org.apache.hop.core.database.Database.rollback(Database.java:737)
2025/06/27 07:23:22 - STG4_MEDIDORES.0 - 	at org.apache.hop.core.database.Database.rollback(Database.java:729)
2025/06/27 07:23:22 - STG4_MEDIDORES.0 - 	at org.apache.hop.pipeline.transforms.tableoutput.TableOutput.emptyAndCommitBatchBuffers(TableOutput.java:648)
2025/06/27 07:23:22 - STG4_MEDIDORES.0 - 	at org.apache.hop.pipeline.transforms.tableoutput.TableOutput.dispose(TableOutput.java:568)
2025/06/27 07:23:22 - STG4_MEDIDORES.0 - 	at org.apache.hop.pipeline.Pipeline.prepareExecution(Pipeline.java:1056)
2025/06/27 07:23:22 - STG4_MEDIDORES.0 - 	at org.apache.hop.pipeline.engines.local.LocalPipelineEngine.prepareExecution(LocalPipelineEngine.java:232)
2025/06/27 07:23:22 - STG4_MEDIDORES.0 - 	at org.apache.hop.run.HopRun.runPipeline(HopRun.java:335)
2025/06/27 07:23:22 - STG4_MEDIDORES.0 - 	at org.apache.hop.run.HopRun.runPipeline(HopRun.java:292)
2025/06/27 07:23:22 - STG4_MEDIDORES.0 - 	at org.apache.hop.run.HopRun.run(HopRun.java:203)
2025/06/27 07:23:22 - STG4_MEDIDORES.0 - 	at org.apache.hop.run.HopRun.main(HopRun.java:931)
2025/06/27 07:23:22 - STG4_MEDIDORES.0 - Caused by: org.apache.hop.core.exception.HopDatabaseException: 
2025/06/27 07:23:22 - STG4_MEDIDORES.0 - Error connecting to database [***]
2025/06/27 07:23:22 - STG4_MEDIDORES.0 - 
2025/06/27 07:23:22 - STG4_MEDIDORES.0 - 	at org.apache.hop.core.database.Database.getDatabaseMetaData(Database.java:2890)
2025/06/27 07:23:22 - STG4_MEDIDORES.0 - 	... 10 more
[2025-06-27T07:23:22.255+0000] {docker.py:436} INFO - Error found during execution!
[2025-06-27T07:23:22.256+0000] {docker.py:436} INFO - picocli.CommandLine$ExecutionException: There was an error during execution of file '${PROJECT_HOME}/Pipelines/STG4_MEDIDORES.hpl'
	at org.apache.hop.run.HopRun.run(HopRun.java:212)
	at org.apache.hop.run.HopRun.main(HopRun.java:931)
Caused by: picocli.CommandLine$ExecutionException: There was an error during execution of pipeline '${PROJECT_HOME}/Pipelines/STG4_MEDIDORES.hpl'
	at org.apache.hop.run.HopRun.runPipeline(HopRun.java:294)
	at org.apache.hop.run.HopRun.run(HopRun.java:203)
	... 1 more
Caused by: picocli.CommandLine$ExecutionException: Error running pipeline locally
	at org.apache.hop.run.HopRun.runPipeline(HopRun.java:340)
	at org.apache.hop.run.HopRun.runPipeline(HopRun.java:292)
	... 2 more
Caused by: org.apache.hop.core.exception.HopException: 
We failed to initialize at least one transform.  Execution can not begin!


	at org.apache.hop.pipeline.Pipeline.prepareExecution(Pipeline.java:1088)
	at org.apache.hop.pipeline.engines.local.LocalPipelineEngine.prepareExecution(LocalPipelineEngine.java:232)
	at org.apache.hop.run.HopRun.runPipeline(HopRun.java:335)
	... 3 more
[2025-06-27T07:23:22.694+0000] {taskinstance.py:441} INFO - ::group::Post task execution logs
[2025-06-27T07:23:22.715+0000] {taskinstance.py:2905} ERROR - Task failed with exception
Traceback (most recent call last):
  File "/home/airflow/.local/lib/python3.12/site-packages/docker/api/client.py", line 265, in _raise_for_status
    response.raise_for_status()
  File "/home/airflow/.local/lib/python3.12/site-packages/requests/models.py", line 1021, in raise_for_status
    raise HTTPError(http_error_msg, response=self)
requests.exceptions.HTTPError: 400 Client Error: Bad Request for url: http+docker://localhost/v1.50/containers/create

The above exception was the direct cause of the following exception:

Traceback (most recent call last):
  File "/home/airflow/.local/lib/python3.12/site-packages/airflow/providers/docker/operators/docker.py", line 371, in _run_image
    return self._run_image_with_mounts([*self.mounts, tmp_mount], add_tmp_variable=True)
           ^^^^^^^^^^^^^^^^^^^^^^^^^^^^^^^^^^^^^^^^^^^^^^^^^^^^^^^^^^^^^^^^^^^^^^^^^^^^^
  File "/home/airflow/.local/lib/python3.12/site-packages/airflow/providers/docker/operators/docker.py", line 398, in _run_image_with_mounts
    self.container = self.cli.create_container(
                     ^^^^^^^^^^^^^^^^^^^^^^^^^^
  File "/home/airflow/.local/lib/python3.12/site-packages/docker/api/container.py", line 439, in create_container
    return self.create_container_from_config(config, name, platform)
           ^^^^^^^^^^^^^^^^^^^^^^^^^^^^^^^^^^^^^^^^^^^^^^^^^^^^^^^^^
  File "/home/airflow/.local/lib/python3.12/site-packages/docker/api/container.py", line 456, in create_container_from_config
    return self._result(res, True)
           ^^^^^^^^^^^^^^^^^^^^^^^
  File "/home/airflow/.local/lib/python3.12/site-packages/docker/api/client.py", line 271, in _result
    self._raise_for_status(response)
  File "/home/airflow/.local/lib/python3.12/site-packages/docker/api/client.py", line 267, in _raise_for_status
    raise create_api_error_from_http_exception(e) from e
          ^^^^^^^^^^^^^^^^^^^^^^^^^^^^^^^^^^^^^^^
  File "/home/airflow/.local/lib/python3.12/site-packages/docker/errors.py", line 39, in create_api_error_from_http_exception
    raise cls(e, response=response, explanation=explanation) from e
docker.errors.APIError: 400 Client Error for http+docker://localhost/v1.50/containers/create: Bad Request ("invalid mount config for type "bind": bind source path does not exist: /tmp/airflowtmp2x0yr5ub")

During handling of the above exception, another exception occurred:

Traceback (most recent call last):
  File "/home/airflow/.local/lib/python3.12/site-packages/airflow/models/taskinstance.py", line 465, in _execute_task
    result = _execute_callable(context=context, **execute_callable_kwargs)
             ^^^^^^^^^^^^^^^^^^^^^^^^^^^^^^^^^^^^^^^^^^^^^^^^^^^^^^^^^^^^^
  File "/home/airflow/.local/lib/python3.12/site-packages/airflow/models/taskinstance.py", line 432, in _execute_callable
    return execute_callable(context=context, **execute_callable_kwargs)
           ^^^^^^^^^^^^^^^^^^^^^^^^^^^^^^^^^^^^^^^^^^^^^^^^^^^^^^^^^^^^
  File "/home/airflow/.local/lib/python3.12/site-packages/airflow/models/baseoperator.py", line 400, in wrapper
    return func(self, *args, **kwargs)
           ^^^^^^^^^^^^^^^^^^^^^^^^^^^
  File "/home/airflow/.local/lib/python3.12/site-packages/airflow/providers/docker/operators/docker.py", line 509, in execute
    return self._run_image()
           ^^^^^^^^^^^^^^^^^
  File "/home/airflow/.local/lib/python3.12/site-packages/airflow/providers/docker/operators/docker.py", line 380, in _run_image
    return self._run_image_with_mounts(self.mounts, add_tmp_variable=False)
           ^^^^^^^^^^^^^^^^^^^^^^^^^^^^^^^^^^^^^^^^^^^^^^^^^^^^^^^^^^^^^^^^
  File "/home/airflow/.local/lib/python3.12/site-packages/airflow/providers/docker/operators/docker.py", line 444, in _run_image_with_mounts
    raise DockerContainerFailedException(f"Docker container failed: {result!r}", logs=log_lines)
airflow.providers.docker.exceptions.DockerContainerFailedException: Docker container failed: {'StatusCode': 1}
[2025-06-27T07:23:22.738+0000] {taskinstance.py:1206} INFO - Marking task as UP_FOR_RETRY. dag_id=STG4_MEDIDORES, task_id=run_hop_pipeline, run_id=scheduled__2025-06-27T06:21:00+00:00, execution_date=20250627T062100, start_date=20250627T072105, end_date=20250627T072322
[2025-06-27T07:23:22.765+0000] {standard_task_runner.py:110} ERROR - Failed to execute job 8 for task run_hop_pipeline (Docker container failed: {'StatusCode': 1}; 76)
[2025-06-27T07:23:22.812+0000] {local_task_job_runner.py:240} INFO - Task exited with return code 1
[2025-06-27T07:23:22.841+0000] {taskinstance.py:3498} INFO - 0 downstream tasks scheduled from follow-on schedule check
[2025-06-27T07:23:22.843+0000] {local_task_job_runner.py:222} INFO - ::endgroup::
[2025-06-27T07:37:09.176+0000] {local_task_job_runner.py:120} INFO - ::group::Pre task execution logs
[2025-06-27T07:37:09.227+0000] {taskinstance.py:2076} INFO - Dependencies all met for dep_context=non-requeueable deps ti=<TaskInstance: STG4_MEDIDORES.run_hop_pipeline scheduled__2025-06-27T06:21:00+00:00 [queued]>
[2025-06-27T07:37:09.243+0000] {taskinstance.py:2076} INFO - Dependencies all met for dep_context=requeueable deps ti=<TaskInstance: STG4_MEDIDORES.run_hop_pipeline scheduled__2025-06-27T06:21:00+00:00 [queued]>
[2025-06-27T07:37:09.244+0000] {taskinstance.py:2306} INFO - Starting attempt 1 of 2
[2025-06-27T07:37:09.269+0000] {taskinstance.py:2330} INFO - Executing <Task(DockerOperator): run_hop_pipeline> on 2025-06-27 06:21:00+00:00
[2025-06-27T07:37:09.281+0000] {warnings.py:110} WARNING - /home/***/.local/lib/python3.12/site-packages/***/task/task_runner/standard_task_runner.py:61: DeprecationWarning: This process (pid=67) is multi-threaded, use of fork() may lead to deadlocks in the child.
  pid = os.fork()

[2025-06-27T07:37:09.288+0000] {standard_task_runner.py:63} INFO - Started process 72 to run task
[2025-06-27T07:37:09.289+0000] {standard_task_runner.py:90} INFO - Running: ['***', 'tasks', 'run', 'STG4_MEDIDORES', 'run_hop_pipeline', 'scheduled__2025-06-27T06:21:00+00:00', '--job-id', '5', '--raw', '--subdir', 'DAGS_FOLDER/apache-hop-dag-simple.py', '--cfg-path', '/tmp/tmp9pgiq6op']
[2025-06-27T07:37:09.292+0000] {standard_task_runner.py:91} INFO - Job 5: Subtask run_hop_pipeline
[2025-06-27T07:37:09.434+0000] {task_command.py:426} INFO - Running <TaskInstance: STG4_MEDIDORES.run_hop_pipeline scheduled__2025-06-27T06:21:00+00:00 [running]> on host ec14a5b8088e
[2025-06-27T07:37:09.605+0000] {taskinstance.py:2648} INFO - Exporting env vars: AIRFLOW_CTX_DAG_OWNER='***' AIRFLOW_CTX_DAG_ID='STG4_MEDIDORES' AIRFLOW_CTX_TASK_ID='run_hop_pipeline' AIRFLOW_CTX_EXECUTION_DATE='2025-06-27T06:21:00+00:00' AIRFLOW_CTX_TRY_NUMBER='1' AIRFLOW_CTX_DAG_RUN_ID='scheduled__2025-06-27T06:21:00+00:00'
[2025-06-27T07:37:09.610+0000] {taskinstance.py:430} INFO - ::endgroup::
[2025-06-27T07:37:09.828+0000] {docker.py:366} INFO - Starting docker container from image apache/hop:latest
[2025-06-27T07:37:09.855+0000] {docker.py:374} WARNING - Using remote engine or docker-in-docker and mounting temporary volume from host is not supported. Falling back to `mount_tmp_dir=False` mode. You can set `mount_tmp_dir` parameter to False to disable mounting and remove the warning
[2025-06-27T07:37:10.711+0000] {docker.py:436} INFO - 2025/06/27 07:37:10 - Running the entrypoint script with PID 7
[2025-06-27T07:37:10.715+0000] {docker.py:436} INFO - 2025/06/27 07:37:10 - The project folder for ProyectoSmartMed is set to: /files
[2025-06-27T07:37:10.720+0000] {docker.py:436} INFO - 2025/06/27 07:37:10 - The specified project folder exists
[2025-06-27T07:37:10.723+0000] {docker.py:436} INFO - 2025/06/27 07:37:10 - Registering project ProyectoSmartMed in the Hop container configuration
[2025-06-27T07:37:10.724+0000] {docker.py:436} INFO - 2025/06/27 07:37:10 - /opt/hop/hop-conf.sh --project=ProyectoSmartMed --project-create --project-home='/files' --project-config-file='project-config.json'
[2025-06-27T07:38:02.433+0000] {docker.py:436} INFO - Creating project 'ProyectoSmartMed'
[2025-06-27T07:38:02.870+0000] {docker.py:436} INFO - Project 'ProyectoSmartMed' was created for home folder : /files
[2025-06-27T07:38:03.092+0000] {docker.py:436} INFO - Configuration file for project 'ProyectoSmartMed' was saved to : file:/files/project-config.json
[2025-06-27T07:38:03.304+0000] {docker.py:436} INFO - 2025/06/27 07:38:03 - Not creating an environment in the container
[2025-06-27T07:38:03.310+0000] {docker.py:436} INFO - 2025/06/27 07:38:03 - Running a single hop workflow / pipeline (${PROJECT_HOME}/Pipelines/STG4_MEDIDORES.hpl)
[2025-06-27T07:38:30.674+0000] {docker.py:436} INFO - 2025/06/27 07:38:30 - HopRun - Enabling project 'ProyectoSmartMed'
[2025-06-27T07:38:31.447+0000] {docker.py:436} INFO - 2025/06/27 07:38:31 - HopRun - Starting pipeline: /files/Pipelines/STG4_MEDIDORES.hpl
[2025-06-27T07:38:31.451+0000] {docker.py:436} INFO - 2025/06/27 07:38:31 - STG4_MEDIDORES - Executing this pipeline using the Local Pipeline Engine with run configuration 'local'
[2025-06-27T07:38:31.513+0000] {docker.py:436} INFO - 2025/06/27 07:38:31 - STG4_MEDIDORES - Execution started for pipeline [STG4_MEDIDORES]
[2025-06-27T07:38:35.086+0000] {docker.py:436} INFO - 2025/06/27 07:38:35 - STG4_MEDIDORES.0 - Connected to database [POSTGRES_SMART] (commit=1000)
[2025-06-27T07:38:43.241+0000] {docker.py:436} INFO - 2025/06/27 07:38:43 - STG3_MEDIDORES.0 - Finished reading query, closing connection.
[2025-06-27T07:38:43.340+0000] {docker.py:436} INFO - 2025/06/27 07:38:43 - STG3_MEDIDORES.0 - Finished processing (I=16398, O=0, R=0, W=16398, U=0, E=0)
[2025-06-27T07:38:49.029+0000] {docker.py:436} INFO - 2025/06/27 07:38:49 - STG4_MEDIDORES.0 - Finished processing (I=0, O=16398, R=16398, W=16398, U=0, E=0)
[2025-06-27T07:38:49.034+0000] {docker.py:436} INFO - 2025/06/27 07:38:49 - STG4_MEDIDORES - Pipeline duration : 17.587 seconds [ 17.586" ]
[2025-06-27T07:38:49.066+0000] {docker.py:436} INFO - HopRun exit.
[2025-06-27T07:38:49.067+0000] {docker.py:436} INFO - 2025/06/27 07:38:49 - STG4_MEDIDORES - Execution finished on a local pipeline engine with run configuration 'local'
[2025-06-27T07:38:49.558+0000] {taskinstance.py:441} INFO - ::group::Post task execution logs
[2025-06-27T07:38:49.653+0000] {taskinstance.py:1206} INFO - Marking task as SUCCESS. dag_id=STG4_MEDIDORES, task_id=run_hop_pipeline, run_id=scheduled__2025-06-27T06:21:00+00:00, execution_date=20250627T062100, start_date=20250627T073709, end_date=20250627T073849
[2025-06-27T07:38:49.764+0000] {local_task_job_runner.py:240} INFO - Task exited with return code 0
[2025-06-27T07:38:49.818+0000] {taskinstance.py:3498} INFO - 0 downstream tasks scheduled from follow-on schedule check
[2025-06-27T07:38:49.823+0000] {local_task_job_runner.py:222} INFO - ::endgroup::
