[2025-06-27T03:49:08.603+0000] {local_task_job_runner.py:120} INFO - ::group::Pre task execution logs
[2025-06-27T03:49:08.672+0000] {taskinstance.py:2076} INFO - Dependencies all met for dep_context=non-requeueable deps ti=<TaskInstance: WF_MAIN.run_hop_pipeline scheduled__2025-06-27T02:41:00+00:00 [queued]>
[2025-06-27T03:49:08.697+0000] {taskinstance.py:2076} INFO - Dependencies all met for dep_context=requeueable deps ti=<TaskInstance: WF_MAIN.run_hop_pipeline scheduled__2025-06-27T02:41:00+00:00 [queued]>
[2025-06-27T03:49:08.698+0000] {taskinstance.py:2306} INFO - Starting attempt 1 of 2
[2025-06-27T03:49:08.817+0000] {taskinstance.py:2330} INFO - Executing <Task(DockerOperator): run_hop_pipeline> on 2025-06-27 02:41:00+00:00
[2025-06-27T03:49:08.835+0000] {warnings.py:110} WARNING - /home/***/.local/lib/python3.12/site-packages/***/task/task_runner/standard_task_runner.py:61: DeprecationWarning: This process (pid=66) is multi-threaded, use of fork() may lead to deadlocks in the child.
  pid = os.fork()

[2025-06-27T03:49:08.840+0000] {standard_task_runner.py:63} INFO - Started process 72 to run task
[2025-06-27T03:49:08.840+0000] {standard_task_runner.py:90} INFO - Running: ['***', 'tasks', 'run', 'WF_MAIN', 'run_hop_pipeline', 'scheduled__2025-06-27T02:41:00+00:00', '--job-id', '5', '--raw', '--subdir', 'DAGS_FOLDER/apache-hop-dag-wf-main.py', '--cfg-path', '/tmp/tmps3orfial']
[2025-06-27T03:49:08.842+0000] {standard_task_runner.py:91} INFO - Job 5: Subtask run_hop_pipeline
[2025-06-27T03:49:09.704+0000] {task_command.py:426} INFO - Running <TaskInstance: WF_MAIN.run_hop_pipeline scheduled__2025-06-27T02:41:00+00:00 [running]> on host 24f72b4a1d8f
[2025-06-27T03:49:10.144+0000] {taskinstance.py:2648} INFO - Exporting env vars: AIRFLOW_CTX_DAG_OWNER='***' AIRFLOW_CTX_DAG_ID='WF_MAIN' AIRFLOW_CTX_TASK_ID='run_hop_pipeline' AIRFLOW_CTX_EXECUTION_DATE='2025-06-27T02:41:00+00:00' AIRFLOW_CTX_TRY_NUMBER='1' AIRFLOW_CTX_DAG_RUN_ID='scheduled__2025-06-27T02:41:00+00:00'
[2025-06-27T03:49:10.148+0000] {taskinstance.py:430} INFO - ::endgroup::
[2025-06-27T03:49:10.362+0000] {docker.py:366} INFO - Starting docker container from image apache/hop:latest
[2025-06-27T03:49:10.410+0000] {taskinstance.py:441} INFO - ::group::Post task execution logs
[2025-06-27T03:49:10.412+0000] {taskinstance.py:2905} ERROR - Task failed with exception
Traceback (most recent call last):
  File "/home/airflow/.local/lib/python3.12/site-packages/docker/api/client.py", line 265, in _raise_for_status
    response.raise_for_status()
  File "/home/airflow/.local/lib/python3.12/site-packages/requests/models.py", line 1021, in raise_for_status
    raise HTTPError(http_error_msg, response=self)
requests.exceptions.HTTPError: 400 Client Error: Bad Request for url: http+docker://localhost/v1.50/containers/create

The above exception was the direct cause of the following exception:

Traceback (most recent call last):
  File "/home/airflow/.local/lib/python3.12/site-packages/airflow/models/taskinstance.py", line 465, in _execute_task
    result = _execute_callable(context=context, **execute_callable_kwargs)
             ^^^^^^^^^^^^^^^^^^^^^^^^^^^^^^^^^^^^^^^^^^^^^^^^^^^^^^^^^^^^^
  File "/home/airflow/.local/lib/python3.12/site-packages/airflow/models/taskinstance.py", line 432, in _execute_callable
    return execute_callable(context=context, **execute_callable_kwargs)
           ^^^^^^^^^^^^^^^^^^^^^^^^^^^^^^^^^^^^^^^^^^^^^^^^^^^^^^^^^^^^
  File "/home/airflow/.local/lib/python3.12/site-packages/airflow/models/baseoperator.py", line 400, in wrapper
    return func(self, *args, **kwargs)
           ^^^^^^^^^^^^^^^^^^^^^^^^^^^
  File "/home/airflow/.local/lib/python3.12/site-packages/airflow/providers/docker/operators/docker.py", line 509, in execute
    return self._run_image()
           ^^^^^^^^^^^^^^^^^
  File "/home/airflow/.local/lib/python3.12/site-packages/airflow/providers/docker/operators/docker.py", line 371, in _run_image
    return self._run_image_with_mounts([*self.mounts, tmp_mount], add_tmp_variable=True)
           ^^^^^^^^^^^^^^^^^^^^^^^^^^^^^^^^^^^^^^^^^^^^^^^^^^^^^^^^^^^^^^^^^^^^^^^^^^^^^
  File "/home/airflow/.local/lib/python3.12/site-packages/airflow/providers/docker/operators/docker.py", line 398, in _run_image_with_mounts
    self.container = self.cli.create_container(
                     ^^^^^^^^^^^^^^^^^^^^^^^^^^
  File "/home/airflow/.local/lib/python3.12/site-packages/docker/api/container.py", line 439, in create_container
    return self.create_container_from_config(config, name, platform)
           ^^^^^^^^^^^^^^^^^^^^^^^^^^^^^^^^^^^^^^^^^^^^^^^^^^^^^^^^^
  File "/home/airflow/.local/lib/python3.12/site-packages/docker/api/container.py", line 456, in create_container_from_config
    return self._result(res, True)
           ^^^^^^^^^^^^^^^^^^^^^^^
  File "/home/airflow/.local/lib/python3.12/site-packages/docker/api/client.py", line 271, in _result
    self._raise_for_status(response)
  File "/home/airflow/.local/lib/python3.12/site-packages/docker/api/client.py", line 267, in _raise_for_status
    raise create_api_error_from_http_exception(e) from e
          ^^^^^^^^^^^^^^^^^^^^^^^^^^^^^^^^^^^^^^^
  File "/home/airflow/.local/lib/python3.12/site-packages/docker/errors.py", line 39, in create_api_error_from_http_exception
    raise cls(e, response=response, explanation=explanation) from e
docker.errors.APIError: 400 Client Error for http+docker://localhost/v1.50/containers/create: Bad Request ("invalid mount config for type "bind": bind source path does not exist: /mnt/data/ProyectoSmart/ProyectoSmartMed")
[2025-06-27T03:49:10.438+0000] {taskinstance.py:1206} INFO - Marking task as UP_FOR_RETRY. dag_id=WF_MAIN, task_id=run_hop_pipeline, run_id=scheduled__2025-06-27T02:41:00+00:00, execution_date=20250627T024100, start_date=20250627T034908, end_date=20250627T034910
[2025-06-27T03:49:10.471+0000] {standard_task_runner.py:110} ERROR - Failed to execute job 5 for task run_hop_pipeline (400 Client Error for http+docker://localhost/v1.50/containers/create: Bad Request ("invalid mount config for type "bind": bind source path does not exist: /mnt/data/ProyectoSmart/ProyectoSmartMed"); 72)
[2025-06-27T03:49:10.524+0000] {local_task_job_runner.py:240} INFO - Task exited with return code 1
[2025-06-27T03:49:10.593+0000] {taskinstance.py:3498} INFO - 0 downstream tasks scheduled from follow-on schedule check
[2025-06-27T03:49:10.596+0000] {local_task_job_runner.py:222} INFO - ::endgroup::
[2025-06-27T04:12:46.981+0000] {local_task_job_runner.py:123} INFO - ::group::Pre task execution logs
[2025-06-27T04:12:47.016+0000] {taskinstance.py:2612} INFO - Dependencies all met for dep_context=non-requeueable deps ti=<TaskInstance: WF_MAIN.run_hop_pipeline scheduled__2025-06-27T02:41:00+00:00 [queued]>
[2025-06-27T04:12:47.029+0000] {taskinstance.py:2612} INFO - Dependencies all met for dep_context=requeueable deps ti=<TaskInstance: WF_MAIN.run_hop_pipeline scheduled__2025-06-27T02:41:00+00:00 [queued]>
[2025-06-27T04:12:47.086+0000] {taskinstance.py:2865} INFO - Starting attempt 1 of 2
[2025-06-27T04:12:47.118+0000] {taskinstance.py:2888} INFO - Executing <Task(DockerOperator): run_hop_pipeline> on 2025-06-27 02:41:00+00:00
[2025-06-27T04:12:47.129+0000] {warnings.py:112} WARNING - /home/***/.local/lib/python3.12/site-packages/***/task/task_runner/standard_task_runner.py:70: DeprecationWarning: This process (pid=67) is multi-threaded, use of fork() may lead to deadlocks in the child.
  pid = os.fork()

[2025-06-27T04:12:47.132+0000] {standard_task_runner.py:72} INFO - Started process 76 to run task
[2025-06-27T04:12:47.134+0000] {standard_task_runner.py:104} INFO - Running: ['***', 'tasks', 'run', 'WF_MAIN', 'run_hop_pipeline', 'scheduled__2025-06-27T02:41:00+00:00', '--job-id', '7', '--raw', '--subdir', 'DAGS_FOLDER/apache-hop-dag-wf-main.py', '--cfg-path', '/tmp/tmpx2uufozx']
[2025-06-27T04:12:47.136+0000] {standard_task_runner.py:105} INFO - Job 7: Subtask run_hop_pipeline
[2025-06-27T04:12:47.707+0000] {task_command.py:467} INFO - Running <TaskInstance: WF_MAIN.run_hop_pipeline scheduled__2025-06-27T02:41:00+00:00 [running]> on host 9f6303ed7827
[2025-06-27T04:12:48.311+0000] {taskinstance.py:3131} INFO - Exporting env vars: AIRFLOW_CTX_DAG_OWNER='***' AIRFLOW_CTX_DAG_ID='WF_MAIN' AIRFLOW_CTX_TASK_ID='run_hop_pipeline' AIRFLOW_CTX_EXECUTION_DATE='2025-06-27T02:41:00+00:00' AIRFLOW_CTX_TRY_NUMBER='1' AIRFLOW_CTX_DAG_RUN_ID='scheduled__2025-06-27T02:41:00+00:00'
[2025-06-27T04:12:48.312+0000] {taskinstance.py:731} INFO - ::endgroup::
[2025-06-27T04:12:48.432+0000] {docker.py:496} INFO - ::group::Pulling docker image apache/hop:latest
[2025-06-27T04:12:51.946+0000] {docker.py:510} INFO - latest: Pulling from apache/hop
[2025-06-27T04:12:58.100+0000] {docker.py:510} INFO - 4f4fb700ef54: Pulling fs layer
[2025-06-27T04:12:58.101+0000] {docker.py:510} INFO - bf26d906d0f5: Pulling fs layer
[2025-06-27T04:12:58.102+0000] {docker.py:510} INFO - 9b6bc2cf1037: Pulling fs layer
[2025-06-27T04:12:58.103+0000] {docker.py:510} INFO - f18232174bc9: Pulling fs layer
[2025-06-27T04:12:58.105+0000] {docker.py:510} INFO - 19f1029c3f10: Pulling fs layer
[2025-06-27T04:12:58.108+0000] {docker.py:510} INFO - eb2b48b7cabe: Pulling fs layer
[2025-06-27T04:12:58.110+0000] {docker.py:510} INFO - f488a4dddc73: Pulling fs layer
[2025-06-27T04:12:58.111+0000] {docker.py:510} INFO - d4d2578e96cd: Pulling fs layer
[2025-06-27T04:12:58.201+0000] {docker.py:510} INFO - 4f4fb700ef54: Already exists
[2025-06-27T04:12:58.203+0000] {docker.py:510} INFO - 4f4fb700ef54: Pull complete
[2025-06-27T04:12:58.801+0000] {docker.py:510} INFO - f18232174bc9: Downloading
[2025-06-27T04:12:58.920+0000] {docker.py:510} INFO - eb2b48b7cabe: Downloading
[2025-06-27T04:12:59.011+0000] {docker.py:510} INFO - 9b6bc2cf1037: Downloading
[2025-06-27T04:12:59.032+0000] {docker.py:510} INFO - d4d2578e96cd: Downloading
[2025-06-27T04:12:59.223+0000] {docker.py:510} INFO - bf26d906d0f5: Downloading
[2025-06-27T04:12:59.457+0000] {docker.py:510} INFO - 19f1029c3f10: Downloading
[2025-06-27T04:12:59.538+0000] {docker.py:510} INFO - f488a4dddc73: Downloading
[2025-06-27T04:13:15.928+0000] {job.py:229} INFO - Heartbeat recovered after 13.55 seconds
[2025-06-27T04:13:20.212+0000] {docker.py:510} INFO - eb2b48b7cabe: Download complete
[2025-06-27T04:13:20.303+0000] {docker.py:510} INFO - f18232174bc9: Download complete
[2025-06-27T04:13:20.330+0000] {docker.py:510} INFO - f18232174bc9: Extracting
[2025-06-27T04:13:21.273+0000] {docker.py:510} INFO - 9b6bc2cf1037: Download complete
[2025-06-27T04:13:21.446+0000] {job.py:229} INFO - Heartbeat recovered after 12.70 seconds
[2025-06-27T04:13:21.518+0000] {docker.py:510} INFO - d4d2578e96cd: Download complete
[2025-06-27T04:13:21.711+0000] {docker.py:510} INFO - bf26d906d0f5: Download complete
[2025-06-27T04:13:25.393+0000] {docker.py:510} INFO - 19f1029c3f10: Download complete
[2025-06-27T04:13:28.981+0000] {docker.py:510} INFO - f18232174bc9: Pull complete
[2025-06-27T04:13:34.566+0000] {docker.py:510} INFO - d4d2578e96cd: Extracting
[2025-06-27T04:13:36.814+0000] {docker.py:510} INFO - d4d2578e96cd: Pull complete
[2025-06-27T04:13:41.430+0000] {docker.py:510} INFO - 19f1029c3f10: Extracting
[2025-06-27T04:14:13.202+0000] {docker.py:510} INFO - 19f1029c3f10: Pull complete
[2025-06-27T04:14:25.520+0000] {job.py:229} INFO - Heartbeat recovered after 11.31 seconds
[2025-06-27T04:14:30.718+0000] {job.py:229} INFO - Heartbeat recovered after 11.27 seconds
[2025-06-27T04:14:31.864+0000] {docker.py:510} INFO - bf26d906d0f5: Extracting
[2025-06-27T04:14:33.383+0000] {docker.py:510} INFO - bf26d906d0f5: Pull complete
[2025-06-27T04:14:41.787+0000] {docker.py:510} INFO - f488a4dddc73: Download complete
[2025-06-27T04:14:41.789+0000] {docker.py:510} INFO - f488a4dddc73: Extracting
[2025-06-27T04:16:07.211+0000] {docker.py:510} INFO - f488a4dddc73: Pull complete
[2025-06-27T04:16:07.312+0000] {docker.py:510} INFO - 9b6bc2cf1037: Extracting
[2025-06-27T04:16:07.409+0000] {docker.py:510} INFO - 9b6bc2cf1037: Pull complete
[2025-06-27T04:16:07.506+0000] {docker.py:510} INFO - eb2b48b7cabe: Pull complete
[2025-06-27T04:16:07.745+0000] {docker.py:505} INFO - Digest: sha256:950a95da3332a2782706665b58adeed820689d87e0ca5b54df59bc995b2d955e
[2025-06-27T04:16:07.749+0000] {docker.py:505} INFO - Status: Downloaded newer image for apache/hop:latest
[2025-06-27T04:16:07.761+0000] {docker.py:512} INFO - ::endgroup::
[2025-06-27T04:16:07.763+0000] {docker.py:367} INFO - Starting docker container from image apache/hop:latest
[2025-06-27T04:16:07.911+0000] {taskinstance.py:3310} ERROR - Task failed with exception
Traceback (most recent call last):
  File "/home/airflow/.local/lib/python3.12/site-packages/docker/api/client.py", line 275, in _raise_for_status
    response.raise_for_status()
  File "/home/airflow/.local/lib/python3.12/site-packages/requests/models.py", line 1024, in raise_for_status
    raise HTTPError(http_error_msg, response=self)
requests.exceptions.HTTPError: 400 Client Error: Bad Request for url: http+docker://localhost/v1.50/containers/create

The above exception was the direct cause of the following exception:

Traceback (most recent call last):
  File "/home/airflow/.local/lib/python3.12/site-packages/airflow/models/taskinstance.py", line 767, in _execute_task
    result = _execute_callable(context=context, **execute_callable_kwargs)
             ^^^^^^^^^^^^^^^^^^^^^^^^^^^^^^^^^^^^^^^^^^^^^^^^^^^^^^^^^^^^^
  File "/home/airflow/.local/lib/python3.12/site-packages/airflow/models/taskinstance.py", line 733, in _execute_callable
    return ExecutionCallableRunner(
           ^^^^^^^^^^^^^^^^^^^^^^^^
  File "/home/airflow/.local/lib/python3.12/site-packages/airflow/utils/operator_helpers.py", line 252, in run
    return self.func(*args, **kwargs)
           ^^^^^^^^^^^^^^^^^^^^^^^^^^
  File "/home/airflow/.local/lib/python3.12/site-packages/airflow/models/baseoperator.py", line 406, in wrapper
    return func(self, *args, **kwargs)
           ^^^^^^^^^^^^^^^^^^^^^^^^^^^
  File "/home/airflow/.local/lib/python3.12/site-packages/airflow/providers/docker/operators/docker.py", line 513, in execute
    return self._run_image()
           ^^^^^^^^^^^^^^^^^
  File "/home/airflow/.local/lib/python3.12/site-packages/airflow/providers/docker/operators/docker.py", line 372, in _run_image
    return self._run_image_with_mounts([*self.mounts, tmp_mount], add_tmp_variable=True)
           ^^^^^^^^^^^^^^^^^^^^^^^^^^^^^^^^^^^^^^^^^^^^^^^^^^^^^^^^^^^^^^^^^^^^^^^^^^^^^
  File "/home/airflow/.local/lib/python3.12/site-packages/airflow/providers/docker/operators/docker.py", line 399, in _run_image_with_mounts
    self.container = self.cli.create_container(
                     ^^^^^^^^^^^^^^^^^^^^^^^^^^
  File "/home/airflow/.local/lib/python3.12/site-packages/docker/api/container.py", line 440, in create_container
    return self.create_container_from_config(config, name, platform)
           ^^^^^^^^^^^^^^^^^^^^^^^^^^^^^^^^^^^^^^^^^^^^^^^^^^^^^^^^^
  File "/home/airflow/.local/lib/python3.12/site-packages/docker/api/container.py", line 457, in create_container_from_config
    return self._result(res, True)
           ^^^^^^^^^^^^^^^^^^^^^^^
  File "/home/airflow/.local/lib/python3.12/site-packages/docker/api/client.py", line 281, in _result
    self._raise_for_status(response)
  File "/home/airflow/.local/lib/python3.12/site-packages/docker/api/client.py", line 277, in _raise_for_status
    raise create_api_error_from_http_exception(e) from e
          ^^^^^^^^^^^^^^^^^^^^^^^^^^^^^^^^^^^^^^^
  File "/home/airflow/.local/lib/python3.12/site-packages/docker/errors.py", line 39, in create_api_error_from_http_exception
    raise cls(e, response=response, explanation=explanation) from e
docker.errors.APIError: 400 Client Error for http+docker://localhost/v1.50/containers/create: Bad Request ("invalid mount config for type "bind": bind source path does not exist: /mnt/data/ProyectoSmart/ProyectoSmartMed")
[2025-06-27T04:16:07.977+0000] {taskinstance.py:1225} INFO - Marking task as UP_FOR_RETRY. dag_id=WF_MAIN, task_id=run_hop_pipeline, run_id=scheduled__2025-06-27T02:41:00+00:00, execution_date=20250627T024100, start_date=20250627T041247, end_date=20250627T041607
[2025-06-27T04:16:08.054+0000] {taskinstance.py:340} INFO - ::group::Post task execution logs
[2025-06-27T04:16:08.055+0000] {standard_task_runner.py:124} ERROR - Failed to execute job 7 for task run_hop_pipeline (400 Client Error for http+docker://localhost/v1.50/containers/create: Bad Request ("invalid mount config for type "bind": bind source path does not exist: /mnt/data/ProyectoSmart/ProyectoSmartMed"); 76)
Traceback (most recent call last):
  File "/home/airflow/.local/lib/python3.12/site-packages/docker/api/client.py", line 275, in _raise_for_status
    response.raise_for_status()
  File "/home/airflow/.local/lib/python3.12/site-packages/requests/models.py", line 1024, in raise_for_status
    raise HTTPError(http_error_msg, response=self)
requests.exceptions.HTTPError: 400 Client Error: Bad Request for url: http+docker://localhost/v1.50/containers/create

The above exception was the direct cause of the following exception:

Traceback (most recent call last):
  File "/home/airflow/.local/lib/python3.12/site-packages/airflow/task/task_runner/standard_task_runner.py", line 117, in _start_by_fork
    ret = args.func(args, dag=self.dag)
          ^^^^^^^^^^^^^^^^^^^^^^^^^^^^^
  File "/home/airflow/.local/lib/python3.12/site-packages/airflow/cli/cli_config.py", line 49, in command
    return func(*args, **kwargs)
           ^^^^^^^^^^^^^^^^^^^^^
  File "/home/airflow/.local/lib/python3.12/site-packages/airflow/utils/cli.py", line 115, in wrapper
    return f(*args, **kwargs)
           ^^^^^^^^^^^^^^^^^^
  File "/home/airflow/.local/lib/python3.12/site-packages/airflow/cli/commands/task_command.py", line 483, in task_run
    task_return_code = _run_task_by_selected_method(args, _dag, ti)
                       ^^^^^^^^^^^^^^^^^^^^^^^^^^^^^^^^^^^^^^^^^^^^
  File "/home/airflow/.local/lib/python3.12/site-packages/airflow/cli/commands/task_command.py", line 256, in _run_task_by_selected_method
    return _run_raw_task(args, ti)
           ^^^^^^^^^^^^^^^^^^^^^^^
  File "/home/airflow/.local/lib/python3.12/site-packages/airflow/cli/commands/task_command.py", line 341, in _run_raw_task
    return ti._run_raw_task(
           ^^^^^^^^^^^^^^^^^
  File "/home/airflow/.local/lib/python3.12/site-packages/airflow/utils/session.py", line 97, in wrapper
    return func(*args, session=session, **kwargs)
           ^^^^^^^^^^^^^^^^^^^^^^^^^^^^^^^^^^^^^^
  File "/home/airflow/.local/lib/python3.12/site-packages/airflow/models/taskinstance.py", line 3004, in _run_raw_task
    return _run_raw_task(
           ^^^^^^^^^^^^^^
  File "/home/airflow/.local/lib/python3.12/site-packages/airflow/models/taskinstance.py", line 273, in _run_raw_task
    TaskInstance._execute_task_with_callbacks(
  File "/home/airflow/.local/lib/python3.12/site-packages/airflow/models/taskinstance.py", line 3158, in _execute_task_with_callbacks
    result = self._execute_task(context, task_orig)
             ^^^^^^^^^^^^^^^^^^^^^^^^^^^^^^^^^^^^^^
  File "/home/airflow/.local/lib/python3.12/site-packages/airflow/models/taskinstance.py", line 3182, in _execute_task
    return _execute_task(self, context, task_orig)
           ^^^^^^^^^^^^^^^^^^^^^^^^^^^^^^^^^^^^^^^
  File "/home/airflow/.local/lib/python3.12/site-packages/airflow/models/taskinstance.py", line 767, in _execute_task
    result = _execute_callable(context=context, **execute_callable_kwargs)
             ^^^^^^^^^^^^^^^^^^^^^^^^^^^^^^^^^^^^^^^^^^^^^^^^^^^^^^^^^^^^^
  File "/home/airflow/.local/lib/python3.12/site-packages/airflow/models/taskinstance.py", line 733, in _execute_callable
    return ExecutionCallableRunner(
           ^^^^^^^^^^^^^^^^^^^^^^^^
  File "/home/airflow/.local/lib/python3.12/site-packages/airflow/utils/operator_helpers.py", line 252, in run
    return self.func(*args, **kwargs)
           ^^^^^^^^^^^^^^^^^^^^^^^^^^
  File "/home/airflow/.local/lib/python3.12/site-packages/airflow/models/baseoperator.py", line 406, in wrapper
    return func(self, *args, **kwargs)
           ^^^^^^^^^^^^^^^^^^^^^^^^^^^
  File "/home/airflow/.local/lib/python3.12/site-packages/airflow/providers/docker/operators/docker.py", line 513, in execute
    return self._run_image()
           ^^^^^^^^^^^^^^^^^
  File "/home/airflow/.local/lib/python3.12/site-packages/airflow/providers/docker/operators/docker.py", line 372, in _run_image
    return self._run_image_with_mounts([*self.mounts, tmp_mount], add_tmp_variable=True)
           ^^^^^^^^^^^^^^^^^^^^^^^^^^^^^^^^^^^^^^^^^^^^^^^^^^^^^^^^^^^^^^^^^^^^^^^^^^^^^
  File "/home/airflow/.local/lib/python3.12/site-packages/airflow/providers/docker/operators/docker.py", line 399, in _run_image_with_mounts
    self.container = self.cli.create_container(
                     ^^^^^^^^^^^^^^^^^^^^^^^^^^
  File "/home/airflow/.local/lib/python3.12/site-packages/docker/api/container.py", line 440, in create_container
    return self.create_container_from_config(config, name, platform)
           ^^^^^^^^^^^^^^^^^^^^^^^^^^^^^^^^^^^^^^^^^^^^^^^^^^^^^^^^^
  File "/home/airflow/.local/lib/python3.12/site-packages/docker/api/container.py", line 457, in create_container_from_config
    return self._result(res, True)
           ^^^^^^^^^^^^^^^^^^^^^^^
  File "/home/airflow/.local/lib/python3.12/site-packages/docker/api/client.py", line 281, in _result
    self._raise_for_status(response)
  File "/home/airflow/.local/lib/python3.12/site-packages/docker/api/client.py", line 277, in _raise_for_status
    raise create_api_error_from_http_exception(e) from e
          ^^^^^^^^^^^^^^^^^^^^^^^^^^^^^^^^^^^^^^^
  File "/home/airflow/.local/lib/python3.12/site-packages/docker/errors.py", line 39, in create_api_error_from_http_exception
    raise cls(e, response=response, explanation=explanation) from e
docker.errors.APIError: 400 Client Error for http+docker://localhost/v1.50/containers/create: Bad Request ("invalid mount config for type "bind": bind source path does not exist: /mnt/data/ProyectoSmart/ProyectoSmartMed")
[2025-06-27T04:16:08.120+0000] {local_task_job_runner.py:266} INFO - Task exited with return code 1
[2025-06-27T04:16:08.204+0000] {taskinstance.py:3900} INFO - 0 downstream tasks scheduled from follow-on schedule check
[2025-06-27T04:16:08.215+0000] {local_task_job_runner.py:245} INFO - ::endgroup::
