[2025-06-27T01:29:15.171+0000] {local_task_job_runner.py:120} INFO - ::group::Pre task execution logs
[2025-06-27T01:29:15.205+0000] {taskinstance.py:2076} INFO - Dependencies all met for dep_context=non-requeueable deps ti=<TaskInstance: WF_MAIN_END_MONTH.run_hop_pipeline scheduled__2025-05-01T14:00:00+00:00 [queued]>
[2025-06-27T01:29:15.216+0000] {taskinstance.py:2076} INFO - Dependencies all met for dep_context=requeueable deps ti=<TaskInstance: WF_MAIN_END_MONTH.run_hop_pipeline scheduled__2025-05-01T14:00:00+00:00 [queued]>
[2025-06-27T01:29:15.216+0000] {taskinstance.py:2306} INFO - Starting attempt 2 of 2
[2025-06-27T01:29:15.625+0000] {taskinstance.py:2330} INFO - Executing <Task(DockerOperator): run_hop_pipeline> on 2025-05-01 14:00:00+00:00
[2025-06-27T01:29:16.206+0000] {warnings.py:110} WARNING - /home/***/.local/lib/python3.12/site-packages/***/task/task_runner/standard_task_runner.py:61: DeprecationWarning: This process (pid=126) is multi-threaded, use of fork() may lead to deadlocks in the child.
  pid = os.fork()

[2025-06-27T01:29:17.273+0000] {standard_task_runner.py:63} INFO - Started process 133 to run task
[2025-06-27T01:29:17.519+0000] {standard_task_runner.py:90} INFO - Running: ['***', 'tasks', 'run', 'WF_MAIN_END_MONTH', 'run_hop_pipeline', 'scheduled__2025-05-01T14:00:00+00:00', '--job-id', '13', '--raw', '--subdir', 'DAGS_FOLDER/apache-hop-dag-wf-main-end-month.py', '--cfg-path', '/tmp/tmp335fc8xw']
[2025-06-27T01:29:17.564+0000] {standard_task_runner.py:91} INFO - Job 13: Subtask run_hop_pipeline
[2025-06-27T01:29:31.826+0000] {task_command.py:426} INFO - Running <TaskInstance: WF_MAIN_END_MONTH.run_hop_pipeline scheduled__2025-05-01T14:00:00+00:00 [running]> on host ca79c413dce4
[2025-06-27T01:29:41.495+0000] {taskinstance.py:2648} INFO - Exporting env vars: AIRFLOW_CTX_DAG_OWNER='***' AIRFLOW_CTX_DAG_ID='WF_MAIN_END_MONTH' AIRFLOW_CTX_TASK_ID='run_hop_pipeline' AIRFLOW_CTX_EXECUTION_DATE='2025-05-01T14:00:00+00:00' AIRFLOW_CTX_TRY_NUMBER='2' AIRFLOW_CTX_DAG_RUN_ID='scheduled__2025-05-01T14:00:00+00:00'
[2025-06-27T01:29:41.496+0000] {taskinstance.py:430} INFO - ::endgroup::
[2025-06-27T01:29:48.103+0000] {docker.py:493} INFO - Pulling docker image apache/hop:latest
[2025-06-27T01:30:08.591+0000] {docker.py:507} INFO - latest: Pulling from apache/hop
[2025-06-27T01:30:14.261+0000] {docker.py:507} INFO - 4f4fb700ef54: Pulling fs layer
[2025-06-27T01:30:14.262+0000] {docker.py:507} INFO - bf26d906d0f5: Pulling fs layer
[2025-06-27T01:30:14.267+0000] {docker.py:507} INFO - 9b6bc2cf1037: Pulling fs layer
[2025-06-27T01:30:14.267+0000] {docker.py:507} INFO - f18232174bc9: Pulling fs layer
[2025-06-27T01:30:14.268+0000] {docker.py:507} INFO - f488a4dddc73: Pulling fs layer
[2025-06-27T01:30:14.269+0000] {docker.py:507} INFO - d4d2578e96cd: Pulling fs layer
[2025-06-27T01:30:14.270+0000] {docker.py:507} INFO - eb2b48b7cabe: Pulling fs layer
[2025-06-27T01:30:14.270+0000] {docker.py:507} INFO - 19f1029c3f10: Pulling fs layer
[2025-06-27T01:30:14.271+0000] {docker.py:507} INFO - 4f4fb700ef54: Already exists
[2025-06-27T01:30:14.275+0000] {docker.py:507} INFO - 4f4fb700ef54: Pull complete
[2025-06-27T01:30:16.655+0000] {docker.py:507} INFO - d4d2578e96cd: Downloading
[2025-06-27T01:30:16.660+0000] {docker.py:507} INFO - 9b6bc2cf1037: Downloading
[2025-06-27T01:30:16.807+0000] {docker.py:507} INFO - f488a4dddc73: Downloading
[2025-06-27T01:30:17.273+0000] {docker.py:507} INFO - 19f1029c3f10: Downloading
[2025-06-27T01:30:18.608+0000] {docker.py:507} INFO - eb2b48b7cabe: Downloading
[2025-06-27T01:30:18.816+0000] {docker.py:507} INFO - f18232174bc9: Downloading
[2025-06-27T01:30:19.095+0000] {docker.py:507} INFO - bf26d906d0f5: Downloading
[2025-06-27T01:30:47.670+0000] {docker.py:507} INFO - 9b6bc2cf1037: Download complete
[2025-06-27T01:30:47.785+0000] {docker.py:507} INFO - d4d2578e96cd: Download complete
[2025-06-27T01:30:53.032+0000] {docker.py:507} INFO - eb2b48b7cabe: Download complete
[2025-06-27T01:30:53.057+0000] {docker.py:507} INFO - bf26d906d0f5: Download complete
[2025-06-27T01:30:53.272+0000] {docker.py:507} INFO - f18232174bc9: Download complete
[2025-06-27T01:30:53.300+0000] {docker.py:507} INFO - f18232174bc9: Extracting
[2025-06-27T01:30:59.011+0000] {docker.py:507} INFO - 19f1029c3f10: Download complete
[2025-06-27T01:31:42.763+0000] {docker.py:507} INFO - f18232174bc9: Pull complete
[2025-06-27T01:31:56.886+0000] {docker.py:507} INFO - d4d2578e96cd: Extracting
[2025-06-27T01:32:03.975+0000] {docker.py:507} INFO - d4d2578e96cd: Pull complete
[2025-06-27T01:32:08.030+0000] {docker.py:507} INFO - 19f1029c3f10: Extracting
[2025-06-27T01:34:40.258+0000] {docker.py:507} INFO - f488a4dddc73: Download complete
[2025-06-27T01:34:45.237+0000] {docker.py:507} INFO - 19f1029c3f10: Pull complete
[2025-06-27T01:34:45.749+0000] {docker.py:507} INFO - bf26d906d0f5: Extracting
[2025-06-27T01:34:46.714+0000] {docker.py:507} INFO - bf26d906d0f5: Pull complete
[2025-06-27T01:34:46.932+0000] {docker.py:507} INFO - f488a4dddc73: Extracting
[2025-06-27T01:36:50.931+0000] {docker.py:507} INFO - f488a4dddc73: Pull complete
[2025-06-27T01:36:51.214+0000] {docker.py:507} INFO - 9b6bc2cf1037: Extracting
[2025-06-27T01:36:51.315+0000] {docker.py:507} INFO - 9b6bc2cf1037: Pull complete
[2025-06-27T01:36:51.418+0000] {docker.py:507} INFO - eb2b48b7cabe: Extracting
[2025-06-27T01:36:51.514+0000] {docker.py:507} INFO - eb2b48b7cabe: Pull complete
[2025-06-27T01:36:51.947+0000] {docker.py:502} INFO - Digest: sha256:950a95da3332a2782706665b58adeed820689d87e0ca5b54df59bc995b2d955e
[2025-06-27T01:36:51.954+0000] {docker.py:502} INFO - Status: Downloaded newer image for apache/hop:latest
[2025-06-27T01:36:52.119+0000] {docker.py:366} INFO - Starting docker container from image apache/hop:latest
[2025-06-27T01:36:52.250+0000] {taskinstance.py:441} INFO - ::group::Post task execution logs
[2025-06-27T01:36:52.253+0000] {taskinstance.py:2905} ERROR - Task failed with exception
Traceback (most recent call last):
  File "/home/airflow/.local/lib/python3.12/site-packages/docker/api/client.py", line 265, in _raise_for_status
    response.raise_for_status()
  File "/home/airflow/.local/lib/python3.12/site-packages/requests/models.py", line 1021, in raise_for_status
    raise HTTPError(http_error_msg, response=self)
requests.exceptions.HTTPError: 500 Server Error: Internal Server Error for url: http+docker://localhost/v1.50/containers/create

The above exception was the direct cause of the following exception:

Traceback (most recent call last):
  File "/home/airflow/.local/lib/python3.12/site-packages/airflow/models/taskinstance.py", line 465, in _execute_task
    result = _execute_callable(context=context, **execute_callable_kwargs)
             ^^^^^^^^^^^^^^^^^^^^^^^^^^^^^^^^^^^^^^^^^^^^^^^^^^^^^^^^^^^^^
  File "/home/airflow/.local/lib/python3.12/site-packages/airflow/models/taskinstance.py", line 432, in _execute_callable
    return execute_callable(context=context, **execute_callable_kwargs)
           ^^^^^^^^^^^^^^^^^^^^^^^^^^^^^^^^^^^^^^^^^^^^^^^^^^^^^^^^^^^^
  File "/home/airflow/.local/lib/python3.12/site-packages/airflow/models/baseoperator.py", line 400, in wrapper
    return func(self, *args, **kwargs)
           ^^^^^^^^^^^^^^^^^^^^^^^^^^^
  File "/home/airflow/.local/lib/python3.12/site-packages/airflow/providers/docker/operators/docker.py", line 509, in execute
    return self._run_image()
           ^^^^^^^^^^^^^^^^^
  File "/home/airflow/.local/lib/python3.12/site-packages/airflow/providers/docker/operators/docker.py", line 371, in _run_image
    return self._run_image_with_mounts([*self.mounts, tmp_mount], add_tmp_variable=True)
           ^^^^^^^^^^^^^^^^^^^^^^^^^^^^^^^^^^^^^^^^^^^^^^^^^^^^^^^^^^^^^^^^^^^^^^^^^^^^^
  File "/home/airflow/.local/lib/python3.12/site-packages/airflow/providers/docker/operators/docker.py", line 398, in _run_image_with_mounts
    self.container = self.cli.create_container(
                     ^^^^^^^^^^^^^^^^^^^^^^^^^^
  File "/home/airflow/.local/lib/python3.12/site-packages/docker/api/container.py", line 439, in create_container
    return self.create_container_from_config(config, name, platform)
           ^^^^^^^^^^^^^^^^^^^^^^^^^^^^^^^^^^^^^^^^^^^^^^^^^^^^^^^^^
  File "/home/airflow/.local/lib/python3.12/site-packages/docker/api/container.py", line 456, in create_container_from_config
    return self._result(res, True)
           ^^^^^^^^^^^^^^^^^^^^^^^
  File "/home/airflow/.local/lib/python3.12/site-packages/docker/api/client.py", line 271, in _result
    self._raise_for_status(response)
  File "/home/airflow/.local/lib/python3.12/site-packages/docker/api/client.py", line 267, in _raise_for_status
    raise create_api_error_from_http_exception(e) from e
          ^^^^^^^^^^^^^^^^^^^^^^^^^^^^^^^^^^^^^^^
  File "/home/airflow/.local/lib/python3.12/site-packages/docker/errors.py", line 39, in create_api_error_from_http_exception
    raise cls(e, response=response, explanation=explanation) from e
docker.errors.APIError: 500 Server Error for http+docker://localhost/v1.50/containers/create: Internal Server Error ("mkdir C:\Users\danie: Access is denied.")
[2025-06-27T01:36:52.429+0000] {taskinstance.py:1206} INFO - Marking task as FAILED. dag_id=WF_MAIN_END_MONTH, task_id=run_hop_pipeline, run_id=scheduled__2025-05-01T14:00:00+00:00, execution_date=20250501T140000, start_date=20250627T012915, end_date=20250627T013652
[2025-06-27T01:36:52.490+0000] {standard_task_runner.py:110} ERROR - Failed to execute job 13 for task run_hop_pipeline (500 Server Error for http+docker://localhost/v1.50/containers/create: Internal Server Error ("mkdir C:\Users\danie: Access is denied."); 133)
[2025-06-27T01:36:52.573+0000] {local_task_job_runner.py:240} INFO - Task exited with return code 1
[2025-06-27T01:36:52.700+0000] {taskinstance.py:3498} INFO - 0 downstream tasks scheduled from follow-on schedule check
[2025-06-27T01:36:52.718+0000] {local_task_job_runner.py:222} INFO - ::endgroup::
[2025-06-27T03:13:24.210+0000] {local_task_job_runner.py:120} INFO - ::group::Pre task execution logs
[2025-06-27T03:13:24.413+0000] {taskinstance.py:2076} INFO - Dependencies all met for dep_context=non-requeueable deps ti=<TaskInstance: WF_MAIN_END_MONTH.run_hop_pipeline scheduled__2025-05-01T14:00:00+00:00 [queued]>
[2025-06-27T03:13:24.450+0000] {taskinstance.py:2076} INFO - Dependencies all met for dep_context=requeueable deps ti=<TaskInstance: WF_MAIN_END_MONTH.run_hop_pipeline scheduled__2025-05-01T14:00:00+00:00 [queued]>
[2025-06-27T03:13:24.464+0000] {taskinstance.py:2306} INFO - Starting attempt 2 of 2
[2025-06-27T03:13:24.517+0000] {taskinstance.py:2330} INFO - Executing <Task(DockerOperator): run_hop_pipeline> on 2025-05-01 14:00:00+00:00
[2025-06-27T03:13:24.639+0000] {warnings.py:110} WARNING - /home/***/.local/lib/python3.12/site-packages/***/task/task_runner/standard_task_runner.py:61: DeprecationWarning: This process (pid=62) is multi-threaded, use of fork() may lead to deadlocks in the child.
  pid = os.fork()

[2025-06-27T03:13:24.642+0000] {standard_task_runner.py:90} INFO - Running: ['***', 'tasks', 'run', 'WF_MAIN_END_MONTH', 'run_hop_pipeline', 'scheduled__2025-05-01T14:00:00+00:00', '--job-id', '12', '--raw', '--subdir', 'DAGS_FOLDER/apache-hop-dag-wf-main-end-month.py', '--cfg-path', '/tmp/tmp8czn4xci']
[2025-06-27T03:13:24.682+0000] {standard_task_runner.py:91} INFO - Job 12: Subtask run_hop_pipeline
[2025-06-27T03:13:24.681+0000] {standard_task_runner.py:63} INFO - Started process 69 to run task
[2025-06-27T03:13:26.638+0000] {task_command.py:426} INFO - Running <TaskInstance: WF_MAIN_END_MONTH.run_hop_pipeline scheduled__2025-05-01T14:00:00+00:00 [running]> on host 887ee52390c5
[2025-06-27T03:13:26.846+0000] {taskinstance.py:2648} INFO - Exporting env vars: AIRFLOW_CTX_DAG_OWNER='***' AIRFLOW_CTX_DAG_ID='WF_MAIN_END_MONTH' AIRFLOW_CTX_TASK_ID='run_hop_pipeline' AIRFLOW_CTX_EXECUTION_DATE='2025-05-01T14:00:00+00:00' AIRFLOW_CTX_TRY_NUMBER='2' AIRFLOW_CTX_DAG_RUN_ID='scheduled__2025-05-01T14:00:00+00:00'
[2025-06-27T03:13:26.848+0000] {taskinstance.py:430} INFO - ::endgroup::
[2025-06-27T03:13:27.063+0000] {docker.py:366} INFO - Starting docker container from image apache/hop:latest
[2025-06-27T03:13:27.085+0000] {taskinstance.py:441} INFO - ::group::Post task execution logs
[2025-06-27T03:13:27.086+0000] {taskinstance.py:2905} ERROR - Task failed with exception
Traceback (most recent call last):
  File "/home/airflow/.local/lib/python3.12/site-packages/docker/api/client.py", line 265, in _raise_for_status
    response.raise_for_status()
  File "/home/airflow/.local/lib/python3.12/site-packages/requests/models.py", line 1021, in raise_for_status
    raise HTTPError(http_error_msg, response=self)
requests.exceptions.HTTPError: 400 Client Error: Bad Request for url: http+docker://localhost/v1.50/containers/create

The above exception was the direct cause of the following exception:

Traceback (most recent call last):
  File "/home/airflow/.local/lib/python3.12/site-packages/airflow/models/taskinstance.py", line 465, in _execute_task
    result = _execute_callable(context=context, **execute_callable_kwargs)
             ^^^^^^^^^^^^^^^^^^^^^^^^^^^^^^^^^^^^^^^^^^^^^^^^^^^^^^^^^^^^^
  File "/home/airflow/.local/lib/python3.12/site-packages/airflow/models/taskinstance.py", line 432, in _execute_callable
    return execute_callable(context=context, **execute_callable_kwargs)
           ^^^^^^^^^^^^^^^^^^^^^^^^^^^^^^^^^^^^^^^^^^^^^^^^^^^^^^^^^^^^
  File "/home/airflow/.local/lib/python3.12/site-packages/airflow/models/baseoperator.py", line 400, in wrapper
    return func(self, *args, **kwargs)
           ^^^^^^^^^^^^^^^^^^^^^^^^^^^
  File "/home/airflow/.local/lib/python3.12/site-packages/airflow/providers/docker/operators/docker.py", line 509, in execute
    return self._run_image()
           ^^^^^^^^^^^^^^^^^
  File "/home/airflow/.local/lib/python3.12/site-packages/airflow/providers/docker/operators/docker.py", line 371, in _run_image
    return self._run_image_with_mounts([*self.mounts, tmp_mount], add_tmp_variable=True)
           ^^^^^^^^^^^^^^^^^^^^^^^^^^^^^^^^^^^^^^^^^^^^^^^^^^^^^^^^^^^^^^^^^^^^^^^^^^^^^
  File "/home/airflow/.local/lib/python3.12/site-packages/airflow/providers/docker/operators/docker.py", line 398, in _run_image_with_mounts
    self.container = self.cli.create_container(
                     ^^^^^^^^^^^^^^^^^^^^^^^^^^
  File "/home/airflow/.local/lib/python3.12/site-packages/docker/api/container.py", line 439, in create_container
    return self.create_container_from_config(config, name, platform)
           ^^^^^^^^^^^^^^^^^^^^^^^^^^^^^^^^^^^^^^^^^^^^^^^^^^^^^^^^^
  File "/home/airflow/.local/lib/python3.12/site-packages/docker/api/container.py", line 456, in create_container_from_config
    return self._result(res, True)
           ^^^^^^^^^^^^^^^^^^^^^^^
  File "/home/airflow/.local/lib/python3.12/site-packages/docker/api/client.py", line 271, in _result
    self._raise_for_status(response)
  File "/home/airflow/.local/lib/python3.12/site-packages/docker/api/client.py", line 267, in _raise_for_status
    raise create_api_error_from_http_exception(e) from e
          ^^^^^^^^^^^^^^^^^^^^^^^^^^^^^^^^^^^^^^^
  File "/home/airflow/.local/lib/python3.12/site-packages/docker/errors.py", line 39, in create_api_error_from_http_exception
    raise cls(e, response=response, explanation=explanation) from e
docker.errors.APIError: 400 Client Error for http+docker://localhost/v1.50/containers/create: Bad Request ("invalid mount config for type "bind": bind source path does not exist: /mnt/data/ProyectoSmart/ProyectoSmartMed")
[2025-06-27T03:13:27.108+0000] {taskinstance.py:1206} INFO - Marking task as FAILED. dag_id=WF_MAIN_END_MONTH, task_id=run_hop_pipeline, run_id=scheduled__2025-05-01T14:00:00+00:00, execution_date=20250501T140000, start_date=20250627T031324, end_date=20250627T031327
[2025-06-27T03:13:27.128+0000] {standard_task_runner.py:110} ERROR - Failed to execute job 12 for task run_hop_pipeline (400 Client Error for http+docker://localhost/v1.50/containers/create: Bad Request ("invalid mount config for type "bind": bind source path does not exist: /mnt/data/ProyectoSmart/ProyectoSmartMed"); 69)
[2025-06-27T03:13:27.171+0000] {local_task_job_runner.py:240} INFO - Task exited with return code 1
[2025-06-27T03:13:27.195+0000] {local_task_job_runner.py:222} INFO - ::endgroup::
[2025-06-27T04:21:10.804+0000] {local_task_job_runner.py:123} INFO - ::group::Pre task execution logs
[2025-06-27T04:21:10.869+0000] {taskinstance.py:2612} INFO - Dependencies all met for dep_context=non-requeueable deps ti=<TaskInstance: WF_MAIN_END_MONTH.run_hop_pipeline scheduled__2025-05-01T14:00:00+00:00 [queued]>
[2025-06-27T04:21:10.913+0000] {taskinstance.py:2612} INFO - Dependencies all met for dep_context=requeueable deps ti=<TaskInstance: WF_MAIN_END_MONTH.run_hop_pipeline scheduled__2025-05-01T14:00:00+00:00 [queued]>
[2025-06-27T04:21:10.914+0000] {taskinstance.py:2865} INFO - Starting attempt 2 of 2
[2025-06-27T04:21:10.941+0000] {taskinstance.py:2888} INFO - Executing <Task(DockerOperator): run_hop_pipeline> on 2025-05-01 14:00:00+00:00
[2025-06-27T04:21:10.955+0000] {warnings.py:112} WARNING - /home/***/.local/lib/python3.12/site-packages/***/task/task_runner/standard_task_runner.py:70: DeprecationWarning: This process (pid=186) is multi-threaded, use of fork() may lead to deadlocks in the child.
  pid = os.fork()

[2025-06-27T04:21:10.959+0000] {standard_task_runner.py:72} INFO - Started process 194 to run task
[2025-06-27T04:21:10.959+0000] {standard_task_runner.py:104} INFO - Running: ['***', 'tasks', 'run', 'WF_MAIN_END_MONTH', 'run_hop_pipeline', 'scheduled__2025-05-01T14:00:00+00:00', '--job-id', '13', '--raw', '--subdir', 'DAGS_FOLDER/apache-hop-dag-wf-main-end-month.py', '--cfg-path', '/tmp/tmpvvl1bhbp']
[2025-06-27T04:21:10.962+0000] {standard_task_runner.py:105} INFO - Job 13: Subtask run_hop_pipeline
[2025-06-27T04:21:11.149+0000] {task_command.py:467} INFO - Running <TaskInstance: WF_MAIN_END_MONTH.run_hop_pipeline scheduled__2025-05-01T14:00:00+00:00 [running]> on host 9f6303ed7827
[2025-06-27T04:21:11.271+0000] {taskinstance.py:3131} INFO - Exporting env vars: AIRFLOW_CTX_DAG_OWNER='***' AIRFLOW_CTX_DAG_ID='WF_MAIN_END_MONTH' AIRFLOW_CTX_TASK_ID='run_hop_pipeline' AIRFLOW_CTX_EXECUTION_DATE='2025-05-01T14:00:00+00:00' AIRFLOW_CTX_TRY_NUMBER='2' AIRFLOW_CTX_DAG_RUN_ID='scheduled__2025-05-01T14:00:00+00:00'
[2025-06-27T04:21:11.273+0000] {taskinstance.py:731} INFO - ::endgroup::
[2025-06-27T04:21:11.422+0000] {docker.py:367} INFO - Starting docker container from image apache/hop:latest
[2025-06-27T04:21:11.451+0000] {taskinstance.py:3310} ERROR - Task failed with exception
Traceback (most recent call last):
  File "/home/airflow/.local/lib/python3.12/site-packages/docker/api/client.py", line 275, in _raise_for_status
    response.raise_for_status()
  File "/home/airflow/.local/lib/python3.12/site-packages/requests/models.py", line 1024, in raise_for_status
    raise HTTPError(http_error_msg, response=self)
requests.exceptions.HTTPError: 400 Client Error: Bad Request for url: http+docker://localhost/v1.50/containers/create

The above exception was the direct cause of the following exception:

Traceback (most recent call last):
  File "/home/airflow/.local/lib/python3.12/site-packages/airflow/models/taskinstance.py", line 767, in _execute_task
    result = _execute_callable(context=context, **execute_callable_kwargs)
             ^^^^^^^^^^^^^^^^^^^^^^^^^^^^^^^^^^^^^^^^^^^^^^^^^^^^^^^^^^^^^
  File "/home/airflow/.local/lib/python3.12/site-packages/airflow/models/taskinstance.py", line 733, in _execute_callable
    return ExecutionCallableRunner(
           ^^^^^^^^^^^^^^^^^^^^^^^^
  File "/home/airflow/.local/lib/python3.12/site-packages/airflow/utils/operator_helpers.py", line 252, in run
    return self.func(*args, **kwargs)
           ^^^^^^^^^^^^^^^^^^^^^^^^^^
  File "/home/airflow/.local/lib/python3.12/site-packages/airflow/models/baseoperator.py", line 406, in wrapper
    return func(self, *args, **kwargs)
           ^^^^^^^^^^^^^^^^^^^^^^^^^^^
  File "/home/airflow/.local/lib/python3.12/site-packages/airflow/providers/docker/operators/docker.py", line 513, in execute
    return self._run_image()
           ^^^^^^^^^^^^^^^^^
  File "/home/airflow/.local/lib/python3.12/site-packages/airflow/providers/docker/operators/docker.py", line 372, in _run_image
    return self._run_image_with_mounts([*self.mounts, tmp_mount], add_tmp_variable=True)
           ^^^^^^^^^^^^^^^^^^^^^^^^^^^^^^^^^^^^^^^^^^^^^^^^^^^^^^^^^^^^^^^^^^^^^^^^^^^^^
  File "/home/airflow/.local/lib/python3.12/site-packages/airflow/providers/docker/operators/docker.py", line 399, in _run_image_with_mounts
    self.container = self.cli.create_container(
                     ^^^^^^^^^^^^^^^^^^^^^^^^^^
  File "/home/airflow/.local/lib/python3.12/site-packages/docker/api/container.py", line 440, in create_container
    return self.create_container_from_config(config, name, platform)
           ^^^^^^^^^^^^^^^^^^^^^^^^^^^^^^^^^^^^^^^^^^^^^^^^^^^^^^^^^
  File "/home/airflow/.local/lib/python3.12/site-packages/docker/api/container.py", line 457, in create_container_from_config
    return self._result(res, True)
           ^^^^^^^^^^^^^^^^^^^^^^^
  File "/home/airflow/.local/lib/python3.12/site-packages/docker/api/client.py", line 281, in _result
    self._raise_for_status(response)
  File "/home/airflow/.local/lib/python3.12/site-packages/docker/api/client.py", line 277, in _raise_for_status
    raise create_api_error_from_http_exception(e) from e
          ^^^^^^^^^^^^^^^^^^^^^^^^^^^^^^^^^^^^^^^
  File "/home/airflow/.local/lib/python3.12/site-packages/docker/errors.py", line 39, in create_api_error_from_http_exception
    raise cls(e, response=response, explanation=explanation) from e
docker.errors.APIError: 400 Client Error for http+docker://localhost/v1.50/containers/create: Bad Request ("invalid mount config for type "bind": bind source path does not exist: /mnt/data/ProyectoSmart/ProyectoSmartMed")
[2025-06-27T04:21:11.470+0000] {taskinstance.py:1225} INFO - Marking task as FAILED. dag_id=WF_MAIN_END_MONTH, task_id=run_hop_pipeline, run_id=scheduled__2025-05-01T14:00:00+00:00, execution_date=20250501T140000, start_date=20250627T042110, end_date=20250627T042111
[2025-06-27T04:21:11.492+0000] {taskinstance.py:340} INFO - ::group::Post task execution logs
[2025-06-27T04:21:11.495+0000] {standard_task_runner.py:124} ERROR - Failed to execute job 13 for task run_hop_pipeline (400 Client Error for http+docker://localhost/v1.50/containers/create: Bad Request ("invalid mount config for type "bind": bind source path does not exist: /mnt/data/ProyectoSmart/ProyectoSmartMed"); 194)
Traceback (most recent call last):
  File "/home/airflow/.local/lib/python3.12/site-packages/docker/api/client.py", line 275, in _raise_for_status
    response.raise_for_status()
  File "/home/airflow/.local/lib/python3.12/site-packages/requests/models.py", line 1024, in raise_for_status
    raise HTTPError(http_error_msg, response=self)
requests.exceptions.HTTPError: 400 Client Error: Bad Request for url: http+docker://localhost/v1.50/containers/create

The above exception was the direct cause of the following exception:

Traceback (most recent call last):
  File "/home/airflow/.local/lib/python3.12/site-packages/airflow/task/task_runner/standard_task_runner.py", line 117, in _start_by_fork
    ret = args.func(args, dag=self.dag)
          ^^^^^^^^^^^^^^^^^^^^^^^^^^^^^
  File "/home/airflow/.local/lib/python3.12/site-packages/airflow/cli/cli_config.py", line 49, in command
    return func(*args, **kwargs)
           ^^^^^^^^^^^^^^^^^^^^^
  File "/home/airflow/.local/lib/python3.12/site-packages/airflow/utils/cli.py", line 115, in wrapper
    return f(*args, **kwargs)
           ^^^^^^^^^^^^^^^^^^
  File "/home/airflow/.local/lib/python3.12/site-packages/airflow/cli/commands/task_command.py", line 483, in task_run
    task_return_code = _run_task_by_selected_method(args, _dag, ti)
                       ^^^^^^^^^^^^^^^^^^^^^^^^^^^^^^^^^^^^^^^^^^^^
  File "/home/airflow/.local/lib/python3.12/site-packages/airflow/cli/commands/task_command.py", line 256, in _run_task_by_selected_method
    return _run_raw_task(args, ti)
           ^^^^^^^^^^^^^^^^^^^^^^^
  File "/home/airflow/.local/lib/python3.12/site-packages/airflow/cli/commands/task_command.py", line 341, in _run_raw_task
    return ti._run_raw_task(
           ^^^^^^^^^^^^^^^^^
  File "/home/airflow/.local/lib/python3.12/site-packages/airflow/utils/session.py", line 97, in wrapper
    return func(*args, session=session, **kwargs)
           ^^^^^^^^^^^^^^^^^^^^^^^^^^^^^^^^^^^^^^
  File "/home/airflow/.local/lib/python3.12/site-packages/airflow/models/taskinstance.py", line 3004, in _run_raw_task
    return _run_raw_task(
           ^^^^^^^^^^^^^^
  File "/home/airflow/.local/lib/python3.12/site-packages/airflow/models/taskinstance.py", line 273, in _run_raw_task
    TaskInstance._execute_task_with_callbacks(
  File "/home/airflow/.local/lib/python3.12/site-packages/airflow/models/taskinstance.py", line 3158, in _execute_task_with_callbacks
    result = self._execute_task(context, task_orig)
             ^^^^^^^^^^^^^^^^^^^^^^^^^^^^^^^^^^^^^^
  File "/home/airflow/.local/lib/python3.12/site-packages/airflow/models/taskinstance.py", line 3182, in _execute_task
    return _execute_task(self, context, task_orig)
           ^^^^^^^^^^^^^^^^^^^^^^^^^^^^^^^^^^^^^^^
  File "/home/airflow/.local/lib/python3.12/site-packages/airflow/models/taskinstance.py", line 767, in _execute_task
    result = _execute_callable(context=context, **execute_callable_kwargs)
             ^^^^^^^^^^^^^^^^^^^^^^^^^^^^^^^^^^^^^^^^^^^^^^^^^^^^^^^^^^^^^
  File "/home/airflow/.local/lib/python3.12/site-packages/airflow/models/taskinstance.py", line 733, in _execute_callable
    return ExecutionCallableRunner(
           ^^^^^^^^^^^^^^^^^^^^^^^^
  File "/home/airflow/.local/lib/python3.12/site-packages/airflow/utils/operator_helpers.py", line 252, in run
    return self.func(*args, **kwargs)
           ^^^^^^^^^^^^^^^^^^^^^^^^^^
  File "/home/airflow/.local/lib/python3.12/site-packages/airflow/models/baseoperator.py", line 406, in wrapper
    return func(self, *args, **kwargs)
           ^^^^^^^^^^^^^^^^^^^^^^^^^^^
  File "/home/airflow/.local/lib/python3.12/site-packages/airflow/providers/docker/operators/docker.py", line 513, in execute
    return self._run_image()
           ^^^^^^^^^^^^^^^^^
  File "/home/airflow/.local/lib/python3.12/site-packages/airflow/providers/docker/operators/docker.py", line 372, in _run_image
    return self._run_image_with_mounts([*self.mounts, tmp_mount], add_tmp_variable=True)
           ^^^^^^^^^^^^^^^^^^^^^^^^^^^^^^^^^^^^^^^^^^^^^^^^^^^^^^^^^^^^^^^^^^^^^^^^^^^^^
  File "/home/airflow/.local/lib/python3.12/site-packages/airflow/providers/docker/operators/docker.py", line 399, in _run_image_with_mounts
    self.container = self.cli.create_container(
                     ^^^^^^^^^^^^^^^^^^^^^^^^^^
  File "/home/airflow/.local/lib/python3.12/site-packages/docker/api/container.py", line 440, in create_container
    return self.create_container_from_config(config, name, platform)
           ^^^^^^^^^^^^^^^^^^^^^^^^^^^^^^^^^^^^^^^^^^^^^^^^^^^^^^^^^
  File "/home/airflow/.local/lib/python3.12/site-packages/docker/api/container.py", line 457, in create_container_from_config
    return self._result(res, True)
           ^^^^^^^^^^^^^^^^^^^^^^^
  File "/home/airflow/.local/lib/python3.12/site-packages/docker/api/client.py", line 281, in _result
    self._raise_for_status(response)
  File "/home/airflow/.local/lib/python3.12/site-packages/docker/api/client.py", line 277, in _raise_for_status
    raise create_api_error_from_http_exception(e) from e
          ^^^^^^^^^^^^^^^^^^^^^^^^^^^^^^^^^^^^^^^
  File "/home/airflow/.local/lib/python3.12/site-packages/docker/errors.py", line 39, in create_api_error_from_http_exception
    raise cls(e, response=response, explanation=explanation) from e
docker.errors.APIError: 400 Client Error for http+docker://localhost/v1.50/containers/create: Bad Request ("invalid mount config for type "bind": bind source path does not exist: /mnt/data/ProyectoSmart/ProyectoSmartMed")
[2025-06-27T04:21:11.546+0000] {local_task_job_runner.py:266} INFO - Task exited with return code 1
[2025-06-27T04:21:11.595+0000] {taskinstance.py:3900} INFO - 0 downstream tasks scheduled from follow-on schedule check
[2025-06-27T04:21:11.602+0000] {local_task_job_runner.py:245} INFO - ::endgroup::
[2025-06-27T04:53:31.764+0000] {local_task_job_runner.py:123} INFO - ::group::Pre task execution logs
[2025-06-27T04:53:31.811+0000] {taskinstance.py:2612} INFO - Dependencies all met for dep_context=non-requeueable deps ti=<TaskInstance: WF_MAIN_END_MONTH.run_hop_pipeline scheduled__2025-05-01T14:00:00+00:00 [queued]>
[2025-06-27T04:53:31.838+0000] {taskinstance.py:2612} INFO - Dependencies all met for dep_context=requeueable deps ti=<TaskInstance: WF_MAIN_END_MONTH.run_hop_pipeline scheduled__2025-05-01T14:00:00+00:00 [queued]>
[2025-06-27T04:53:31.839+0000] {taskinstance.py:2865} INFO - Starting attempt 2 of 2
[2025-06-27T04:53:31.878+0000] {taskinstance.py:2888} INFO - Executing <Task(DockerOperator): run_hop_pipeline> on 2025-05-01 14:00:00+00:00
[2025-06-27T04:53:31.895+0000] {warnings.py:112} WARNING - /home/***/.local/lib/python3.12/site-packages/***/task/task_runner/standard_task_runner.py:70: DeprecationWarning: This process (pid=144) is multi-threaded, use of fork() may lead to deadlocks in the child.
  pid = os.fork()

[2025-06-27T04:53:31.899+0000] {standard_task_runner.py:72} INFO - Started process 150 to run task
[2025-06-27T04:53:31.899+0000] {standard_task_runner.py:104} INFO - Running: ['***', 'tasks', 'run', 'WF_MAIN_END_MONTH', 'run_hop_pipeline', 'scheduled__2025-05-01T14:00:00+00:00', '--job-id', '10', '--raw', '--subdir', 'DAGS_FOLDER/apache-hop-dag-wf-main-end-month.py', '--cfg-path', '/tmp/tmpl_kb8b4y']
[2025-06-27T04:53:31.909+0000] {standard_task_runner.py:105} INFO - Job 10: Subtask run_hop_pipeline
[2025-06-27T04:53:32.099+0000] {task_command.py:467} INFO - Running <TaskInstance: WF_MAIN_END_MONTH.run_hop_pipeline scheduled__2025-05-01T14:00:00+00:00 [running]> on host 11460eb2799d
[2025-06-27T04:53:32.379+0000] {taskinstance.py:3131} INFO - Exporting env vars: AIRFLOW_CTX_DAG_OWNER='***' AIRFLOW_CTX_DAG_ID='WF_MAIN_END_MONTH' AIRFLOW_CTX_TASK_ID='run_hop_pipeline' AIRFLOW_CTX_EXECUTION_DATE='2025-05-01T14:00:00+00:00' AIRFLOW_CTX_TRY_NUMBER='2' AIRFLOW_CTX_DAG_RUN_ID='scheduled__2025-05-01T14:00:00+00:00'
[2025-06-27T04:53:32.381+0000] {taskinstance.py:731} INFO - ::endgroup::
[2025-06-27T04:53:32.576+0000] {docker.py:367} INFO - Starting docker container from image apache/hop:latest
[2025-06-27T04:53:32.596+0000] {taskinstance.py:3310} ERROR - Task failed with exception
Traceback (most recent call last):
  File "/home/airflow/.local/lib/python3.12/site-packages/docker/api/client.py", line 275, in _raise_for_status
    response.raise_for_status()
  File "/home/airflow/.local/lib/python3.12/site-packages/requests/models.py", line 1024, in raise_for_status
    raise HTTPError(http_error_msg, response=self)
requests.exceptions.HTTPError: 400 Client Error: Bad Request for url: http+docker://localhost/v1.50/containers/create

The above exception was the direct cause of the following exception:

Traceback (most recent call last):
  File "/home/airflow/.local/lib/python3.12/site-packages/airflow/models/taskinstance.py", line 767, in _execute_task
    result = _execute_callable(context=context, **execute_callable_kwargs)
             ^^^^^^^^^^^^^^^^^^^^^^^^^^^^^^^^^^^^^^^^^^^^^^^^^^^^^^^^^^^^^
  File "/home/airflow/.local/lib/python3.12/site-packages/airflow/models/taskinstance.py", line 733, in _execute_callable
    return ExecutionCallableRunner(
           ^^^^^^^^^^^^^^^^^^^^^^^^
  File "/home/airflow/.local/lib/python3.12/site-packages/airflow/utils/operator_helpers.py", line 252, in run
    return self.func(*args, **kwargs)
           ^^^^^^^^^^^^^^^^^^^^^^^^^^
  File "/home/airflow/.local/lib/python3.12/site-packages/airflow/models/baseoperator.py", line 406, in wrapper
    return func(self, *args, **kwargs)
           ^^^^^^^^^^^^^^^^^^^^^^^^^^^
  File "/home/airflow/.local/lib/python3.12/site-packages/airflow/providers/docker/operators/docker.py", line 513, in execute
    return self._run_image()
           ^^^^^^^^^^^^^^^^^
  File "/home/airflow/.local/lib/python3.12/site-packages/airflow/providers/docker/operators/docker.py", line 372, in _run_image
    return self._run_image_with_mounts([*self.mounts, tmp_mount], add_tmp_variable=True)
           ^^^^^^^^^^^^^^^^^^^^^^^^^^^^^^^^^^^^^^^^^^^^^^^^^^^^^^^^^^^^^^^^^^^^^^^^^^^^^
  File "/home/airflow/.local/lib/python3.12/site-packages/airflow/providers/docker/operators/docker.py", line 399, in _run_image_with_mounts
    self.container = self.cli.create_container(
                     ^^^^^^^^^^^^^^^^^^^^^^^^^^
  File "/home/airflow/.local/lib/python3.12/site-packages/docker/api/container.py", line 440, in create_container
    return self.create_container_from_config(config, name, platform)
           ^^^^^^^^^^^^^^^^^^^^^^^^^^^^^^^^^^^^^^^^^^^^^^^^^^^^^^^^^
  File "/home/airflow/.local/lib/python3.12/site-packages/docker/api/container.py", line 457, in create_container_from_config
    return self._result(res, True)
           ^^^^^^^^^^^^^^^^^^^^^^^
  File "/home/airflow/.local/lib/python3.12/site-packages/docker/api/client.py", line 281, in _result
    self._raise_for_status(response)
  File "/home/airflow/.local/lib/python3.12/site-packages/docker/api/client.py", line 277, in _raise_for_status
    raise create_api_error_from_http_exception(e) from e
          ^^^^^^^^^^^^^^^^^^^^^^^^^^^^^^^^^^^^^^^
  File "/home/airflow/.local/lib/python3.12/site-packages/docker/errors.py", line 39, in create_api_error_from_http_exception
    raise cls(e, response=response, explanation=explanation) from e
docker.errors.APIError: 400 Client Error for http+docker://localhost/v1.50/containers/create: Bad Request ("invalid mount config for type "bind": bind source path does not exist: /mnt/data/ProyectoSmart/ProyectoSmartMed")
[2025-06-27T04:53:32.616+0000] {taskinstance.py:1225} INFO - Marking task as FAILED. dag_id=WF_MAIN_END_MONTH, task_id=run_hop_pipeline, run_id=scheduled__2025-05-01T14:00:00+00:00, execution_date=20250501T140000, start_date=20250627T045331, end_date=20250627T045332
[2025-06-27T04:53:32.645+0000] {taskinstance.py:340} INFO - ::group::Post task execution logs
[2025-06-27T04:53:32.646+0000] {standard_task_runner.py:124} ERROR - Failed to execute job 10 for task run_hop_pipeline (400 Client Error for http+docker://localhost/v1.50/containers/create: Bad Request ("invalid mount config for type "bind": bind source path does not exist: /mnt/data/ProyectoSmart/ProyectoSmartMed"); 150)
Traceback (most recent call last):
  File "/home/airflow/.local/lib/python3.12/site-packages/docker/api/client.py", line 275, in _raise_for_status
    response.raise_for_status()
  File "/home/airflow/.local/lib/python3.12/site-packages/requests/models.py", line 1024, in raise_for_status
    raise HTTPError(http_error_msg, response=self)
requests.exceptions.HTTPError: 400 Client Error: Bad Request for url: http+docker://localhost/v1.50/containers/create

The above exception was the direct cause of the following exception:

Traceback (most recent call last):
  File "/home/airflow/.local/lib/python3.12/site-packages/airflow/task/task_runner/standard_task_runner.py", line 117, in _start_by_fork
    ret = args.func(args, dag=self.dag)
          ^^^^^^^^^^^^^^^^^^^^^^^^^^^^^
  File "/home/airflow/.local/lib/python3.12/site-packages/airflow/cli/cli_config.py", line 49, in command
    return func(*args, **kwargs)
           ^^^^^^^^^^^^^^^^^^^^^
  File "/home/airflow/.local/lib/python3.12/site-packages/airflow/utils/cli.py", line 115, in wrapper
    return f(*args, **kwargs)
           ^^^^^^^^^^^^^^^^^^
  File "/home/airflow/.local/lib/python3.12/site-packages/airflow/cli/commands/task_command.py", line 483, in task_run
    task_return_code = _run_task_by_selected_method(args, _dag, ti)
                       ^^^^^^^^^^^^^^^^^^^^^^^^^^^^^^^^^^^^^^^^^^^^
  File "/home/airflow/.local/lib/python3.12/site-packages/airflow/cli/commands/task_command.py", line 256, in _run_task_by_selected_method
    return _run_raw_task(args, ti)
           ^^^^^^^^^^^^^^^^^^^^^^^
  File "/home/airflow/.local/lib/python3.12/site-packages/airflow/cli/commands/task_command.py", line 341, in _run_raw_task
    return ti._run_raw_task(
           ^^^^^^^^^^^^^^^^^
  File "/home/airflow/.local/lib/python3.12/site-packages/airflow/utils/session.py", line 97, in wrapper
    return func(*args, session=session, **kwargs)
           ^^^^^^^^^^^^^^^^^^^^^^^^^^^^^^^^^^^^^^
  File "/home/airflow/.local/lib/python3.12/site-packages/airflow/models/taskinstance.py", line 3004, in _run_raw_task
    return _run_raw_task(
           ^^^^^^^^^^^^^^
  File "/home/airflow/.local/lib/python3.12/site-packages/airflow/models/taskinstance.py", line 273, in _run_raw_task
    TaskInstance._execute_task_with_callbacks(
  File "/home/airflow/.local/lib/python3.12/site-packages/airflow/models/taskinstance.py", line 3158, in _execute_task_with_callbacks
    result = self._execute_task(context, task_orig)
             ^^^^^^^^^^^^^^^^^^^^^^^^^^^^^^^^^^^^^^
  File "/home/airflow/.local/lib/python3.12/site-packages/airflow/models/taskinstance.py", line 3182, in _execute_task
    return _execute_task(self, context, task_orig)
           ^^^^^^^^^^^^^^^^^^^^^^^^^^^^^^^^^^^^^^^
  File "/home/airflow/.local/lib/python3.12/site-packages/airflow/models/taskinstance.py", line 767, in _execute_task
    result = _execute_callable(context=context, **execute_callable_kwargs)
             ^^^^^^^^^^^^^^^^^^^^^^^^^^^^^^^^^^^^^^^^^^^^^^^^^^^^^^^^^^^^^
  File "/home/airflow/.local/lib/python3.12/site-packages/airflow/models/taskinstance.py", line 733, in _execute_callable
    return ExecutionCallableRunner(
           ^^^^^^^^^^^^^^^^^^^^^^^^
  File "/home/airflow/.local/lib/python3.12/site-packages/airflow/utils/operator_helpers.py", line 252, in run
    return self.func(*args, **kwargs)
           ^^^^^^^^^^^^^^^^^^^^^^^^^^
  File "/home/airflow/.local/lib/python3.12/site-packages/airflow/models/baseoperator.py", line 406, in wrapper
    return func(self, *args, **kwargs)
           ^^^^^^^^^^^^^^^^^^^^^^^^^^^
  File "/home/airflow/.local/lib/python3.12/site-packages/airflow/providers/docker/operators/docker.py", line 513, in execute
    return self._run_image()
           ^^^^^^^^^^^^^^^^^
  File "/home/airflow/.local/lib/python3.12/site-packages/airflow/providers/docker/operators/docker.py", line 372, in _run_image
    return self._run_image_with_mounts([*self.mounts, tmp_mount], add_tmp_variable=True)
           ^^^^^^^^^^^^^^^^^^^^^^^^^^^^^^^^^^^^^^^^^^^^^^^^^^^^^^^^^^^^^^^^^^^^^^^^^^^^^
  File "/home/airflow/.local/lib/python3.12/site-packages/airflow/providers/docker/operators/docker.py", line 399, in _run_image_with_mounts
    self.container = self.cli.create_container(
                     ^^^^^^^^^^^^^^^^^^^^^^^^^^
  File "/home/airflow/.local/lib/python3.12/site-packages/docker/api/container.py", line 440, in create_container
    return self.create_container_from_config(config, name, platform)
           ^^^^^^^^^^^^^^^^^^^^^^^^^^^^^^^^^^^^^^^^^^^^^^^^^^^^^^^^^
  File "/home/airflow/.local/lib/python3.12/site-packages/docker/api/container.py", line 457, in create_container_from_config
    return self._result(res, True)
           ^^^^^^^^^^^^^^^^^^^^^^^
  File "/home/airflow/.local/lib/python3.12/site-packages/docker/api/client.py", line 281, in _result
    self._raise_for_status(response)
  File "/home/airflow/.local/lib/python3.12/site-packages/docker/api/client.py", line 277, in _raise_for_status
    raise create_api_error_from_http_exception(e) from e
          ^^^^^^^^^^^^^^^^^^^^^^^^^^^^^^^^^^^^^^^
  File "/home/airflow/.local/lib/python3.12/site-packages/docker/errors.py", line 39, in create_api_error_from_http_exception
    raise cls(e, response=response, explanation=explanation) from e
docker.errors.APIError: 400 Client Error for http+docker://localhost/v1.50/containers/create: Bad Request ("invalid mount config for type "bind": bind source path does not exist: /mnt/data/ProyectoSmart/ProyectoSmartMed")
[2025-06-27T04:53:32.696+0000] {local_task_job_runner.py:266} INFO - Task exited with return code 1
[2025-06-27T04:53:32.725+0000] {taskinstance.py:3900} INFO - 0 downstream tasks scheduled from follow-on schedule check
[2025-06-27T04:53:32.731+0000] {local_task_job_runner.py:245} INFO - ::endgroup::
[2025-06-27T05:04:20.826+0000] {local_task_job_runner.py:120} INFO - ::group::Pre task execution logs
[2025-06-27T05:04:20.868+0000] {taskinstance.py:2076} INFO - Dependencies all met for dep_context=non-requeueable deps ti=<TaskInstance: WF_MAIN_END_MONTH.run_hop_pipeline scheduled__2025-05-01T14:00:00+00:00 [queued]>
[2025-06-27T05:04:20.883+0000] {taskinstance.py:2076} INFO - Dependencies all met for dep_context=requeueable deps ti=<TaskInstance: WF_MAIN_END_MONTH.run_hop_pipeline scheduled__2025-05-01T14:00:00+00:00 [queued]>
[2025-06-27T05:04:20.884+0000] {taskinstance.py:2306} INFO - Starting attempt 2 of 2
[2025-06-27T05:04:20.911+0000] {taskinstance.py:2330} INFO - Executing <Task(DockerOperator): run_hop_pipeline> on 2025-05-01 14:00:00+00:00
[2025-06-27T05:04:20.945+0000] {warnings.py:110} WARNING - /home/***/.local/lib/python3.12/site-packages/***/task/task_runner/standard_task_runner.py:61: DeprecationWarning: This process (pid=139) is multi-threaded, use of fork() may lead to deadlocks in the child.
  pid = os.fork()

[2025-06-27T05:04:20.947+0000] {standard_task_runner.py:90} INFO - Running: ['***', 'tasks', 'run', 'WF_MAIN_END_MONTH', 'run_hop_pipeline', 'scheduled__2025-05-01T14:00:00+00:00', '--job-id', '11', '--raw', '--subdir', 'DAGS_FOLDER/apache-hop-dag-wf-main-end-month.py', '--cfg-path', '/tmp/tmpuluzoa1o']
[2025-06-27T05:04:20.968+0000] {standard_task_runner.py:91} INFO - Job 11: Subtask run_hop_pipeline
[2025-06-27T05:04:20.961+0000] {standard_task_runner.py:63} INFO - Started process 143 to run task
[2025-06-27T05:04:21.182+0000] {task_command.py:426} INFO - Running <TaskInstance: WF_MAIN_END_MONTH.run_hop_pipeline scheduled__2025-05-01T14:00:00+00:00 [running]> on host 4c575de26931
[2025-06-27T05:04:21.404+0000] {taskinstance.py:2648} INFO - Exporting env vars: AIRFLOW_CTX_DAG_OWNER='***' AIRFLOW_CTX_DAG_ID='WF_MAIN_END_MONTH' AIRFLOW_CTX_TASK_ID='run_hop_pipeline' AIRFLOW_CTX_EXECUTION_DATE='2025-05-01T14:00:00+00:00' AIRFLOW_CTX_TRY_NUMBER='2' AIRFLOW_CTX_DAG_RUN_ID='scheduled__2025-05-01T14:00:00+00:00'
[2025-06-27T05:04:21.407+0000] {taskinstance.py:430} INFO - ::endgroup::
[2025-06-27T05:04:21.587+0000] {docker.py:366} INFO - Starting docker container from image apache/hop:latest
[2025-06-27T05:04:21.608+0000] {taskinstance.py:441} INFO - ::group::Post task execution logs
[2025-06-27T05:04:21.609+0000] {taskinstance.py:2905} ERROR - Task failed with exception
Traceback (most recent call last):
  File "/home/airflow/.local/lib/python3.12/site-packages/docker/api/client.py", line 265, in _raise_for_status
    response.raise_for_status()
  File "/home/airflow/.local/lib/python3.12/site-packages/requests/models.py", line 1021, in raise_for_status
    raise HTTPError(http_error_msg, response=self)
requests.exceptions.HTTPError: 400 Client Error: Bad Request for url: http+docker://localhost/v1.50/containers/create

The above exception was the direct cause of the following exception:

Traceback (most recent call last):
  File "/home/airflow/.local/lib/python3.12/site-packages/airflow/models/taskinstance.py", line 465, in _execute_task
    result = _execute_callable(context=context, **execute_callable_kwargs)
             ^^^^^^^^^^^^^^^^^^^^^^^^^^^^^^^^^^^^^^^^^^^^^^^^^^^^^^^^^^^^^
  File "/home/airflow/.local/lib/python3.12/site-packages/airflow/models/taskinstance.py", line 432, in _execute_callable
    return execute_callable(context=context, **execute_callable_kwargs)
           ^^^^^^^^^^^^^^^^^^^^^^^^^^^^^^^^^^^^^^^^^^^^^^^^^^^^^^^^^^^^
  File "/home/airflow/.local/lib/python3.12/site-packages/airflow/models/baseoperator.py", line 400, in wrapper
    return func(self, *args, **kwargs)
           ^^^^^^^^^^^^^^^^^^^^^^^^^^^
  File "/home/airflow/.local/lib/python3.12/site-packages/airflow/providers/docker/operators/docker.py", line 509, in execute
    return self._run_image()
           ^^^^^^^^^^^^^^^^^
  File "/home/airflow/.local/lib/python3.12/site-packages/airflow/providers/docker/operators/docker.py", line 371, in _run_image
    return self._run_image_with_mounts([*self.mounts, tmp_mount], add_tmp_variable=True)
           ^^^^^^^^^^^^^^^^^^^^^^^^^^^^^^^^^^^^^^^^^^^^^^^^^^^^^^^^^^^^^^^^^^^^^^^^^^^^^
  File "/home/airflow/.local/lib/python3.12/site-packages/airflow/providers/docker/operators/docker.py", line 398, in _run_image_with_mounts
    self.container = self.cli.create_container(
                     ^^^^^^^^^^^^^^^^^^^^^^^^^^
  File "/home/airflow/.local/lib/python3.12/site-packages/docker/api/container.py", line 439, in create_container
    return self.create_container_from_config(config, name, platform)
           ^^^^^^^^^^^^^^^^^^^^^^^^^^^^^^^^^^^^^^^^^^^^^^^^^^^^^^^^^
  File "/home/airflow/.local/lib/python3.12/site-packages/docker/api/container.py", line 456, in create_container_from_config
    return self._result(res, True)
           ^^^^^^^^^^^^^^^^^^^^^^^
  File "/home/airflow/.local/lib/python3.12/site-packages/docker/api/client.py", line 271, in _result
    self._raise_for_status(response)
  File "/home/airflow/.local/lib/python3.12/site-packages/docker/api/client.py", line 267, in _raise_for_status
    raise create_api_error_from_http_exception(e) from e
          ^^^^^^^^^^^^^^^^^^^^^^^^^^^^^^^^^^^^^^^
  File "/home/airflow/.local/lib/python3.12/site-packages/docker/errors.py", line 39, in create_api_error_from_http_exception
    raise cls(e, response=response, explanation=explanation) from e
docker.errors.APIError: 400 Client Error for http+docker://localhost/v1.50/containers/create: Bad Request ("invalid mount config for type "bind": bind source path does not exist: /mnt/data/ProyectoSmart/ProyectoSmartMed")
[2025-06-27T05:04:21.634+0000] {taskinstance.py:1206} INFO - Marking task as FAILED. dag_id=WF_MAIN_END_MONTH, task_id=run_hop_pipeline, run_id=scheduled__2025-05-01T14:00:00+00:00, execution_date=20250501T140000, start_date=20250627T050420, end_date=20250627T050421
[2025-06-27T05:04:21.674+0000] {standard_task_runner.py:110} ERROR - Failed to execute job 11 for task run_hop_pipeline (400 Client Error for http+docker://localhost/v1.50/containers/create: Bad Request ("invalid mount config for type "bind": bind source path does not exist: /mnt/data/ProyectoSmart/ProyectoSmartMed"); 143)
[2025-06-27T05:04:21.720+0000] {local_task_job_runner.py:240} INFO - Task exited with return code 1
[2025-06-27T05:04:21.799+0000] {taskinstance.py:3498} INFO - 0 downstream tasks scheduled from follow-on schedule check
[2025-06-27T05:04:21.808+0000] {local_task_job_runner.py:222} INFO - ::endgroup::
[2025-06-27T05:46:04.825+0000] {local_task_job_runner.py:120} INFO - ::group::Pre task execution logs
[2025-06-27T05:46:04.874+0000] {taskinstance.py:2076} INFO - Dependencies all met for dep_context=non-requeueable deps ti=<TaskInstance: WF_MAIN_END_MONTH.run_hop_pipeline scheduled__2025-05-01T14:00:00+00:00 [queued]>
[2025-06-27T05:46:04.888+0000] {taskinstance.py:2076} INFO - Dependencies all met for dep_context=requeueable deps ti=<TaskInstance: WF_MAIN_END_MONTH.run_hop_pipeline scheduled__2025-05-01T14:00:00+00:00 [queued]>
[2025-06-27T05:46:04.889+0000] {taskinstance.py:2306} INFO - Starting attempt 2 of 2
[2025-06-27T05:46:04.914+0000] {taskinstance.py:2330} INFO - Executing <Task(DockerOperator): run_hop_pipeline> on 2025-05-01 14:00:00+00:00
[2025-06-27T05:46:04.924+0000] {warnings.py:110} WARNING - /home/***/.local/lib/python3.12/site-packages/***/task/task_runner/standard_task_runner.py:61: DeprecationWarning: This process (pid=139) is multi-threaded, use of fork() may lead to deadlocks in the child.
  pid = os.fork()

[2025-06-27T05:46:04.928+0000] {standard_task_runner.py:90} INFO - Running: ['***', 'tasks', 'run', 'WF_MAIN_END_MONTH', 'run_hop_pipeline', 'scheduled__2025-05-01T14:00:00+00:00', '--job-id', '9', '--raw', '--subdir', 'DAGS_FOLDER/apache-hop-dag-wf-main-end-month.py', '--cfg-path', '/tmp/tmppxb__6_z']
[2025-06-27T05:46:04.931+0000] {standard_task_runner.py:63} INFO - Started process 144 to run task
[2025-06-27T05:46:04.931+0000] {standard_task_runner.py:91} INFO - Job 9: Subtask run_hop_pipeline
[2025-06-27T05:46:05.078+0000] {task_command.py:426} INFO - Running <TaskInstance: WF_MAIN_END_MONTH.run_hop_pipeline scheduled__2025-05-01T14:00:00+00:00 [running]> on host 760ca3d6cb03
[2025-06-27T05:46:05.253+0000] {taskinstance.py:2648} INFO - Exporting env vars: AIRFLOW_CTX_DAG_OWNER='***' AIRFLOW_CTX_DAG_ID='WF_MAIN_END_MONTH' AIRFLOW_CTX_TASK_ID='run_hop_pipeline' AIRFLOW_CTX_EXECUTION_DATE='2025-05-01T14:00:00+00:00' AIRFLOW_CTX_TRY_NUMBER='2' AIRFLOW_CTX_DAG_RUN_ID='scheduled__2025-05-01T14:00:00+00:00'
[2025-06-27T05:46:05.256+0000] {taskinstance.py:430} INFO - ::endgroup::
[2025-06-27T05:46:05.392+0000] {docker.py:366} INFO - Starting docker container from image apache/hop:latest
[2025-06-27T05:46:05.418+0000] {taskinstance.py:441} INFO - ::group::Post task execution logs
[2025-06-27T05:46:05.422+0000] {taskinstance.py:2905} ERROR - Task failed with exception
Traceback (most recent call last):
  File "/home/airflow/.local/lib/python3.12/site-packages/docker/api/client.py", line 265, in _raise_for_status
    response.raise_for_status()
  File "/home/airflow/.local/lib/python3.12/site-packages/requests/models.py", line 1021, in raise_for_status
    raise HTTPError(http_error_msg, response=self)
requests.exceptions.HTTPError: 400 Client Error: Bad Request for url: http+docker://localhost/v1.50/containers/create

The above exception was the direct cause of the following exception:

Traceback (most recent call last):
  File "/home/airflow/.local/lib/python3.12/site-packages/airflow/models/taskinstance.py", line 465, in _execute_task
    result = _execute_callable(context=context, **execute_callable_kwargs)
             ^^^^^^^^^^^^^^^^^^^^^^^^^^^^^^^^^^^^^^^^^^^^^^^^^^^^^^^^^^^^^
  File "/home/airflow/.local/lib/python3.12/site-packages/airflow/models/taskinstance.py", line 432, in _execute_callable
    return execute_callable(context=context, **execute_callable_kwargs)
           ^^^^^^^^^^^^^^^^^^^^^^^^^^^^^^^^^^^^^^^^^^^^^^^^^^^^^^^^^^^^
  File "/home/airflow/.local/lib/python3.12/site-packages/airflow/models/baseoperator.py", line 400, in wrapper
    return func(self, *args, **kwargs)
           ^^^^^^^^^^^^^^^^^^^^^^^^^^^
  File "/home/airflow/.local/lib/python3.12/site-packages/airflow/providers/docker/operators/docker.py", line 509, in execute
    return self._run_image()
           ^^^^^^^^^^^^^^^^^
  File "/home/airflow/.local/lib/python3.12/site-packages/airflow/providers/docker/operators/docker.py", line 371, in _run_image
    return self._run_image_with_mounts([*self.mounts, tmp_mount], add_tmp_variable=True)
           ^^^^^^^^^^^^^^^^^^^^^^^^^^^^^^^^^^^^^^^^^^^^^^^^^^^^^^^^^^^^^^^^^^^^^^^^^^^^^
  File "/home/airflow/.local/lib/python3.12/site-packages/airflow/providers/docker/operators/docker.py", line 398, in _run_image_with_mounts
    self.container = self.cli.create_container(
                     ^^^^^^^^^^^^^^^^^^^^^^^^^^
  File "/home/airflow/.local/lib/python3.12/site-packages/docker/api/container.py", line 439, in create_container
    return self.create_container_from_config(config, name, platform)
           ^^^^^^^^^^^^^^^^^^^^^^^^^^^^^^^^^^^^^^^^^^^^^^^^^^^^^^^^^
  File "/home/airflow/.local/lib/python3.12/site-packages/docker/api/container.py", line 456, in create_container_from_config
    return self._result(res, True)
           ^^^^^^^^^^^^^^^^^^^^^^^
  File "/home/airflow/.local/lib/python3.12/site-packages/docker/api/client.py", line 271, in _result
    self._raise_for_status(response)
  File "/home/airflow/.local/lib/python3.12/site-packages/docker/api/client.py", line 267, in _raise_for_status
    raise create_api_error_from_http_exception(e) from e
          ^^^^^^^^^^^^^^^^^^^^^^^^^^^^^^^^^^^^^^^
  File "/home/airflow/.local/lib/python3.12/site-packages/docker/errors.py", line 39, in create_api_error_from_http_exception
    raise cls(e, response=response, explanation=explanation) from e
docker.errors.APIError: 400 Client Error for http+docker://localhost/v1.50/containers/create: Bad Request ("invalid mount config for type "bind": bind source path does not exist: /opt/airflow/ProyectoSmartMed")
[2025-06-27T05:46:05.447+0000] {taskinstance.py:1206} INFO - Marking task as FAILED. dag_id=WF_MAIN_END_MONTH, task_id=run_hop_pipeline, run_id=scheduled__2025-05-01T14:00:00+00:00, execution_date=20250501T140000, start_date=20250627T054604, end_date=20250627T054605
[2025-06-27T05:46:05.473+0000] {standard_task_runner.py:110} ERROR - Failed to execute job 9 for task run_hop_pipeline (400 Client Error for http+docker://localhost/v1.50/containers/create: Bad Request ("invalid mount config for type "bind": bind source path does not exist: /opt/airflow/ProyectoSmartMed"); 144)
[2025-06-27T05:46:05.514+0000] {local_task_job_runner.py:240} INFO - Task exited with return code 1
[2025-06-27T05:46:05.641+0000] {taskinstance.py:3498} INFO - 0 downstream tasks scheduled from follow-on schedule check
[2025-06-27T05:46:05.655+0000] {local_task_job_runner.py:222} INFO - ::endgroup::
[2025-06-27T07:28:12.960+0000] {local_task_job_runner.py:120} INFO - ::group::Pre task execution logs
[2025-06-27T07:28:13.051+0000] {taskinstance.py:2076} INFO - Dependencies all met for dep_context=non-requeueable deps ti=<TaskInstance: WF_MAIN_END_MONTH.run_hop_pipeline scheduled__2025-05-01T14:00:00+00:00 [queued]>
[2025-06-27T07:28:13.073+0000] {taskinstance.py:2076} INFO - Dependencies all met for dep_context=requeueable deps ti=<TaskInstance: WF_MAIN_END_MONTH.run_hop_pipeline scheduled__2025-05-01T14:00:00+00:00 [queued]>
[2025-06-27T07:28:13.074+0000] {taskinstance.py:2306} INFO - Starting attempt 2 of 2
[2025-06-27T07:28:13.095+0000] {taskinstance.py:2330} INFO - Executing <Task(DockerOperator): run_hop_pipeline> on 2025-05-01 14:00:00+00:00
[2025-06-27T07:28:13.106+0000] {warnings.py:110} WARNING - /home/***/.local/lib/python3.12/site-packages/***/task/task_runner/standard_task_runner.py:61: DeprecationWarning: This process (pid=171) is multi-threaded, use of fork() may lead to deadlocks in the child.
  pid = os.fork()

[2025-06-27T07:28:13.107+0000] {standard_task_runner.py:90} INFO - Running: ['***', 'tasks', 'run', 'WF_MAIN_END_MONTH', 'run_hop_pipeline', 'scheduled__2025-05-01T14:00:00+00:00', '--job-id', '12', '--raw', '--subdir', 'DAGS_FOLDER/apache-hop-dag-wf-main-end-month.py', '--cfg-path', '/tmp/tmp7j67bg7r']
[2025-06-27T07:28:13.111+0000] {standard_task_runner.py:91} INFO - Job 12: Subtask run_hop_pipeline
[2025-06-27T07:28:13.111+0000] {standard_task_runner.py:63} INFO - Started process 175 to run task
[2025-06-27T07:28:13.430+0000] {task_command.py:426} INFO - Running <TaskInstance: WF_MAIN_END_MONTH.run_hop_pipeline scheduled__2025-05-01T14:00:00+00:00 [running]> on host 5e15c4a8eeb7
[2025-06-27T07:28:13.623+0000] {taskinstance.py:2648} INFO - Exporting env vars: AIRFLOW_CTX_DAG_OWNER='***' AIRFLOW_CTX_DAG_ID='WF_MAIN_END_MONTH' AIRFLOW_CTX_TASK_ID='run_hop_pipeline' AIRFLOW_CTX_EXECUTION_DATE='2025-05-01T14:00:00+00:00' AIRFLOW_CTX_TRY_NUMBER='2' AIRFLOW_CTX_DAG_RUN_ID='scheduled__2025-05-01T14:00:00+00:00'
[2025-06-27T07:28:13.625+0000] {taskinstance.py:430} INFO - ::endgroup::
[2025-06-27T07:28:13.840+0000] {docker.py:366} INFO - Starting docker container from image apache/hop:latest
[2025-06-27T07:28:13.858+0000] {docker.py:374} WARNING - Using remote engine or docker-in-docker and mounting temporary volume from host is not supported. Falling back to `mount_tmp_dir=False` mode. You can set `mount_tmp_dir` parameter to False to disable mounting and remove the warning
[2025-06-27T07:28:14.385+0000] {docker.py:436} INFO - 2025/06/27 07:28:14 - Running the entrypoint script with PID 7
[2025-06-27T07:28:14.388+0000] {docker.py:436} INFO - 2025/06/27 07:28:14 - The project folder for ProyectoSmartMed is set to: /files
[2025-06-27T07:28:14.389+0000] {docker.py:436} INFO - 2025/06/27 07:28:14 - The specified project folder exists
[2025-06-27T07:28:14.393+0000] {docker.py:436} INFO - 2025/06/27 07:28:14 - Registering project ProyectoSmartMed in the Hop container configuration
[2025-06-27T07:28:14.397+0000] {docker.py:436} INFO - 2025/06/27 07:28:14 - /opt/hop/hop-conf.sh --project=ProyectoSmartMed --project-create --project-home='/files' --project-config-file='project-config.json'
[2025-06-27T07:29:17.568+0000] {docker.py:436} INFO - Creating project 'ProyectoSmartMed'
[2025-06-27T07:29:18.380+0000] {docker.py:436} INFO - Project 'ProyectoSmartMed' was created for home folder : /files
[2025-06-27T07:29:18.592+0000] {docker.py:436} INFO - Configuration file for project 'ProyectoSmartMed' was saved to : file:/files/project-config.json
[2025-06-27T07:29:18.830+0000] {docker.py:436} INFO - 2025/06/27 07:29:18 - Not creating an environment in the container
[2025-06-27T07:29:18.835+0000] {docker.py:436} INFO - 2025/06/27 07:29:18 - Running a single hop workflow / pipeline (${PROJECT_HOME}/workflows/WF_MAIN_END_MONTH.hwf)
[2025-06-27T07:29:52.063+0000] {docker.py:436} INFO - 2025/06/27 07:29:52 - HopRun - Enabling project 'ProyectoSmartMed'
[2025-06-27T07:29:52.733+0000] {docker.py:436} INFO - 2025/06/27 07:29:52 - HopRun - Starting workflow: /files/workflows/WF_MAIN_END_MONTH.hwf
[2025-06-27T07:29:56.751+0000] {docker.py:436} INFO - 2025/06/27 07:29:56 - WF_MAIN_END_MONTH - Start of workflow execution
[2025-06-27T07:29:57.199+0000] {docker.py:436} INFO - 2025/06/27 07:29:57 - WF_MAIN_END_MONTH - Starting action [filename_end_month.hwf]
[2025-06-27T07:29:59.375+0000] {docker.py:436} INFO - 2025/06/27 07:29:59 - filename_end_month - Start of workflow execution
[2025-06-27T07:29:59.547+0000] {docker.py:436} INFO - 2025/06/27 07:29:59 - filename_end_month - Starting action [PRUEBA_END_MONTH.hpl]
[2025-06-27T07:29:59.975+0000] {docker.py:436} INFO - 2025/06/27 07:29:59 - PRUEBA_END_MONTH.hpl - Using run configuration [local]
[2025-06-27T07:30:00.079+0000] {docker.py:436} INFO - 2025/06/27 07:30:00 - PRUEBA_END_MONTH - Executing this pipeline using the Local Pipeline Engine with run configuration 'local'
[2025-06-27T07:30:00.097+0000] {docker.py:436} INFO - 2025/06/27 07:30:00 - PRUEBA_END_MONTH - Execution started for pipeline [PRUEBA_END_MONTH]
[2025-06-27T07:30:10.884+0000] {docker.py:436} INFO - 2025/06/27 07:30:10 - Table input.0 - ERROR: An error occurred, processing will be stopped: 
2025/06/27 07:30:10 - Table input.0 - Error occurred while trying to connect to the database
2025/06/27 07:30:10 - Table input.0 - 
2025/06/27 07:30:10 - Table input.0 - Error connecting to database: (using class org.postgresql.Driver)
2025/06/27 07:30:10 - Table input.0 - The connection attempt failed.
[2025-06-27T07:30:10.886+0000] {docker.py:436} INFO - 2025/06/27 07:30:10 - Table input.0 - ERROR: Error initializing transform [Table input]
[2025-06-27T07:30:10.889+0000] {docker.py:436} INFO - 2025/06/27 07:30:10 - PRUEBA_END_MONTH - ERROR: Transform [Table input.0] failed to initialize!
[2025-06-27T07:30:10.892+0000] {docker.py:436} INFO - 2025/06/27 07:30:10 - Table input.0 - Finished reading query, closing connection.
[2025-06-27T07:30:10.893+0000] {docker.py:436} INFO - 2025/06/27 07:30:10 - PRUEBA_END_MONTH.hpl - ERROR: Unable to prepare for execution of the pipeline
[2025-06-27T07:30:10.894+0000] {docker.py:436} INFO - 2025/06/27 07:30:10 - PRUEBA_END_MONTH.hpl - ERROR: org.apache.hop.core.exception.HopException: 
2025/06/27 07:30:10 - PRUEBA_END_MONTH.hpl - We failed to initialize at least one transform.  Execution can not begin!
2025/06/27 07:30:10 - PRUEBA_END_MONTH.hpl - 
2025/06/27 07:30:10 - PRUEBA_END_MONTH.hpl - 
2025/06/27 07:30:10 - PRUEBA_END_MONTH.hpl - 	at org.apache.hop.pipeline.Pipeline.prepareExecution(Pipeline.java:1088)
2025/06/27 07:30:10 - PRUEBA_END_MONTH.hpl - 	at org.apache.hop.pipeline.engines.local.LocalPipelineEngine.prepareExecution(LocalPipelineEngine.java:232)
2025/06/27 07:30:10 - PRUEBA_END_MONTH.hpl - 	at org.apache.hop.pipeline.Pipeline.execute(Pipeline.java:528)
2025/06/27 07:30:10 - PRUEBA_END_MONTH.hpl - 	at org.apache.hop.workflow.actions.pipeline.ActionPipeline.execute(ActionPipeline.java:543)
2025/06/27 07:30:10 - PRUEBA_END_MONTH.hpl - 	at org.apache.hop.workflow.Workflow.executeFromStart(Workflow.java:751)
2025/06/27 07:30:10 - PRUEBA_END_MONTH.hpl - 	at org.apache.hop.workflow.Workflow.executeFromStart(Workflow.java:902)
2025/06/27 07:30:10 - PRUEBA_END_MONTH.hpl - 	at org.apache.hop.workflow.Workflow.executeFromStart(Workflow.java:453)
2025/06/27 07:30:10 - PRUEBA_END_MONTH.hpl - 	at org.apache.hop.workflow.Workflow.startExecution(Workflow.java:313)
2025/06/27 07:30:10 - PRUEBA_END_MONTH.hpl - 	at org.apache.hop.workflow.engines.local.LocalWorkflowEngine.startExecution(LocalWorkflowEngine.java:249)
2025/06/27 07:30:10 - PRUEBA_END_MONTH.hpl - 	at org.apache.hop.workflow.actions.workflow.ActionWorkflowRunner.run(ActionWorkflowRunner.java:55)
2025/06/27 07:30:10 - PRUEBA_END_MONTH.hpl - 	at java.base/java.lang.Thread.run(Thread.java:840)
[2025-06-27T07:30:10.895+0000] {docker.py:436} INFO - 2025/06/27 07:30:10 - filename_end_month - Finished action [PRUEBA_END_MONTH.hpl] (result=[false])
[2025-06-27T07:30:10.896+0000] {docker.py:436} INFO - 2025/06/27 07:30:10 - filename_end_month - Workflow execution finished
[2025-06-27T07:30:10.908+0000] {docker.py:436} INFO - 2025/06/27 07:30:10 - filename_end_month - Workflow duration : 13.292 seconds [ 13.291" ]
[2025-06-27T07:30:10.914+0000] {docker.py:436} INFO - 2025/06/27 07:30:10 - WF_MAIN_END_MONTH - Finished action [filename_end_month.hwf] (result=[false])
[2025-06-27T07:30:10.915+0000] {docker.py:436} INFO - 2025/06/27 07:30:10 - WF_MAIN_END_MONTH - Workflow execution finished
[2025-06-27T07:30:10.929+0000] {docker.py:436} INFO - 2025/06/27 07:30:10 - WF_MAIN_END_MONTH - Workflow duration : 18.135 seconds [ 18.135" ]
[2025-06-27T07:30:10.930+0000] {docker.py:436} INFO - HopRun exit.
[2025-06-27T07:30:11.323+0000] {taskinstance.py:441} INFO - ::group::Post task execution logs
[2025-06-27T07:30:11.340+0000] {taskinstance.py:2905} ERROR - Task failed with exception
Traceback (most recent call last):
  File "/home/airflow/.local/lib/python3.12/site-packages/docker/api/client.py", line 265, in _raise_for_status
    response.raise_for_status()
  File "/home/airflow/.local/lib/python3.12/site-packages/requests/models.py", line 1021, in raise_for_status
    raise HTTPError(http_error_msg, response=self)
requests.exceptions.HTTPError: 400 Client Error: Bad Request for url: http+docker://localhost/v1.50/containers/create

The above exception was the direct cause of the following exception:

Traceback (most recent call last):
  File "/home/airflow/.local/lib/python3.12/site-packages/airflow/providers/docker/operators/docker.py", line 371, in _run_image
    return self._run_image_with_mounts([*self.mounts, tmp_mount], add_tmp_variable=True)
           ^^^^^^^^^^^^^^^^^^^^^^^^^^^^^^^^^^^^^^^^^^^^^^^^^^^^^^^^^^^^^^^^^^^^^^^^^^^^^
  File "/home/airflow/.local/lib/python3.12/site-packages/airflow/providers/docker/operators/docker.py", line 398, in _run_image_with_mounts
    self.container = self.cli.create_container(
                     ^^^^^^^^^^^^^^^^^^^^^^^^^^
  File "/home/airflow/.local/lib/python3.12/site-packages/docker/api/container.py", line 439, in create_container
    return self.create_container_from_config(config, name, platform)
           ^^^^^^^^^^^^^^^^^^^^^^^^^^^^^^^^^^^^^^^^^^^^^^^^^^^^^^^^^
  File "/home/airflow/.local/lib/python3.12/site-packages/docker/api/container.py", line 456, in create_container_from_config
    return self._result(res, True)
           ^^^^^^^^^^^^^^^^^^^^^^^
  File "/home/airflow/.local/lib/python3.12/site-packages/docker/api/client.py", line 271, in _result
    self._raise_for_status(response)
  File "/home/airflow/.local/lib/python3.12/site-packages/docker/api/client.py", line 267, in _raise_for_status
    raise create_api_error_from_http_exception(e) from e
          ^^^^^^^^^^^^^^^^^^^^^^^^^^^^^^^^^^^^^^^
  File "/home/airflow/.local/lib/python3.12/site-packages/docker/errors.py", line 39, in create_api_error_from_http_exception
    raise cls(e, response=response, explanation=explanation) from e
docker.errors.APIError: 400 Client Error for http+docker://localhost/v1.50/containers/create: Bad Request ("invalid mount config for type "bind": bind source path does not exist: /tmp/airflowtmpkkcnkky0")

During handling of the above exception, another exception occurred:

Traceback (most recent call last):
  File "/home/airflow/.local/lib/python3.12/site-packages/airflow/models/taskinstance.py", line 465, in _execute_task
    result = _execute_callable(context=context, **execute_callable_kwargs)
             ^^^^^^^^^^^^^^^^^^^^^^^^^^^^^^^^^^^^^^^^^^^^^^^^^^^^^^^^^^^^^
  File "/home/airflow/.local/lib/python3.12/site-packages/airflow/models/taskinstance.py", line 432, in _execute_callable
    return execute_callable(context=context, **execute_callable_kwargs)
           ^^^^^^^^^^^^^^^^^^^^^^^^^^^^^^^^^^^^^^^^^^^^^^^^^^^^^^^^^^^^
  File "/home/airflow/.local/lib/python3.12/site-packages/airflow/models/baseoperator.py", line 400, in wrapper
    return func(self, *args, **kwargs)
           ^^^^^^^^^^^^^^^^^^^^^^^^^^^
  File "/home/airflow/.local/lib/python3.12/site-packages/airflow/providers/docker/operators/docker.py", line 509, in execute
    return self._run_image()
           ^^^^^^^^^^^^^^^^^
  File "/home/airflow/.local/lib/python3.12/site-packages/airflow/providers/docker/operators/docker.py", line 380, in _run_image
    return self._run_image_with_mounts(self.mounts, add_tmp_variable=False)
           ^^^^^^^^^^^^^^^^^^^^^^^^^^^^^^^^^^^^^^^^^^^^^^^^^^^^^^^^^^^^^^^^
  File "/home/airflow/.local/lib/python3.12/site-packages/airflow/providers/docker/operators/docker.py", line 444, in _run_image_with_mounts
    raise DockerContainerFailedException(f"Docker container failed: {result!r}", logs=log_lines)
airflow.providers.docker.exceptions.DockerContainerFailedException: Docker container failed: {'StatusCode': 1}
[2025-06-27T07:30:11.351+0000] {taskinstance.py:1206} INFO - Marking task as FAILED. dag_id=WF_MAIN_END_MONTH, task_id=run_hop_pipeline, run_id=scheduled__2025-05-01T14:00:00+00:00, execution_date=20250501T140000, start_date=20250627T072813, end_date=20250627T073011
[2025-06-27T07:30:11.377+0000] {standard_task_runner.py:110} ERROR - Failed to execute job 12 for task run_hop_pipeline (Docker container failed: {'StatusCode': 1}; 175)
[2025-06-27T07:30:11.426+0000] {local_task_job_runner.py:240} INFO - Task exited with return code 1
[2025-06-27T07:30:11.452+0000] {taskinstance.py:3498} INFO - 0 downstream tasks scheduled from follow-on schedule check
[2025-06-27T07:30:11.457+0000] {local_task_job_runner.py:222} INFO - ::endgroup::
