[2025-06-27T04:41:02.791+0000] {local_task_job_runner.py:123} INFO - ::group::Pre task execution logs
[2025-06-27T04:41:02.811+0000] {taskinstance.py:2612} INFO - Dependencies all met for dep_context=non-requeueable deps ti=<TaskInstance: WF_MAIN.run_hop_pipeline scheduled__2025-06-27T03:41:00+00:00 [queued]>
[2025-06-27T04:41:02.821+0000] {taskinstance.py:2612} INFO - Dependencies all met for dep_context=requeueable deps ti=<TaskInstance: WF_MAIN.run_hop_pipeline scheduled__2025-06-27T03:41:00+00:00 [queued]>
[2025-06-27T04:41:02.822+0000] {taskinstance.py:2865} INFO - Starting attempt 1 of 2
[2025-06-27T04:41:02.840+0000] {taskinstance.py:2888} INFO - Executing <Task(DockerOperator): run_hop_pipeline> on 2025-06-27 03:41:00+00:00
[2025-06-27T04:41:02.847+0000] {warnings.py:112} WARNING - /home/***/.local/lib/python3.12/site-packages/***/task/task_runner/standard_task_runner.py:70: DeprecationWarning: This process (pid=469) is multi-threaded, use of fork() may lead to deadlocks in the child.
  pid = os.fork()

[2025-06-27T04:41:02.850+0000] {standard_task_runner.py:72} INFO - Started process 470 to run task
[2025-06-27T04:41:02.851+0000] {standard_task_runner.py:104} INFO - Running: ['***', 'tasks', 'run', 'WF_MAIN', 'run_hop_pipeline', 'scheduled__2025-06-27T03:41:00+00:00', '--job-id', '21', '--raw', '--subdir', 'DAGS_FOLDER/apache-hop-dag-wf-main.py', '--cfg-path', '/tmp/tmplqi5zn1w']
[2025-06-27T04:41:02.853+0000] {standard_task_runner.py:105} INFO - Job 21: Subtask run_hop_pipeline
[2025-06-27T04:41:02.943+0000] {task_command.py:467} INFO - Running <TaskInstance: WF_MAIN.run_hop_pipeline scheduled__2025-06-27T03:41:00+00:00 [running]> on host 9f6303ed7827
[2025-06-27T04:41:03.058+0000] {taskinstance.py:3131} INFO - Exporting env vars: AIRFLOW_CTX_DAG_OWNER='***' AIRFLOW_CTX_DAG_ID='WF_MAIN' AIRFLOW_CTX_TASK_ID='run_hop_pipeline' AIRFLOW_CTX_EXECUTION_DATE='2025-06-27T03:41:00+00:00' AIRFLOW_CTX_TRY_NUMBER='1' AIRFLOW_CTX_DAG_RUN_ID='scheduled__2025-06-27T03:41:00+00:00'
[2025-06-27T04:41:03.061+0000] {taskinstance.py:731} INFO - ::endgroup::
[2025-06-27T04:41:03.148+0000] {docker.py:367} INFO - Starting docker container from image apache/hop:latest
[2025-06-27T04:41:03.160+0000] {taskinstance.py:3310} ERROR - Task failed with exception
Traceback (most recent call last):
  File "/home/airflow/.local/lib/python3.12/site-packages/docker/api/client.py", line 275, in _raise_for_status
    response.raise_for_status()
  File "/home/airflow/.local/lib/python3.12/site-packages/requests/models.py", line 1024, in raise_for_status
    raise HTTPError(http_error_msg, response=self)
requests.exceptions.HTTPError: 400 Client Error: Bad Request for url: http+docker://localhost/v1.50/containers/create

The above exception was the direct cause of the following exception:

Traceback (most recent call last):
  File "/home/airflow/.local/lib/python3.12/site-packages/airflow/models/taskinstance.py", line 767, in _execute_task
    result = _execute_callable(context=context, **execute_callable_kwargs)
             ^^^^^^^^^^^^^^^^^^^^^^^^^^^^^^^^^^^^^^^^^^^^^^^^^^^^^^^^^^^^^
  File "/home/airflow/.local/lib/python3.12/site-packages/airflow/models/taskinstance.py", line 733, in _execute_callable
    return ExecutionCallableRunner(
           ^^^^^^^^^^^^^^^^^^^^^^^^
  File "/home/airflow/.local/lib/python3.12/site-packages/airflow/utils/operator_helpers.py", line 252, in run
    return self.func(*args, **kwargs)
           ^^^^^^^^^^^^^^^^^^^^^^^^^^
  File "/home/airflow/.local/lib/python3.12/site-packages/airflow/models/baseoperator.py", line 406, in wrapper
    return func(self, *args, **kwargs)
           ^^^^^^^^^^^^^^^^^^^^^^^^^^^
  File "/home/airflow/.local/lib/python3.12/site-packages/airflow/providers/docker/operators/docker.py", line 513, in execute
    return self._run_image()
           ^^^^^^^^^^^^^^^^^
  File "/home/airflow/.local/lib/python3.12/site-packages/airflow/providers/docker/operators/docker.py", line 372, in _run_image
    return self._run_image_with_mounts([*self.mounts, tmp_mount], add_tmp_variable=True)
           ^^^^^^^^^^^^^^^^^^^^^^^^^^^^^^^^^^^^^^^^^^^^^^^^^^^^^^^^^^^^^^^^^^^^^^^^^^^^^
  File "/home/airflow/.local/lib/python3.12/site-packages/airflow/providers/docker/operators/docker.py", line 399, in _run_image_with_mounts
    self.container = self.cli.create_container(
                     ^^^^^^^^^^^^^^^^^^^^^^^^^^
  File "/home/airflow/.local/lib/python3.12/site-packages/docker/api/container.py", line 440, in create_container
    return self.create_container_from_config(config, name, platform)
           ^^^^^^^^^^^^^^^^^^^^^^^^^^^^^^^^^^^^^^^^^^^^^^^^^^^^^^^^^
  File "/home/airflow/.local/lib/python3.12/site-packages/docker/api/container.py", line 457, in create_container_from_config
    return self._result(res, True)
           ^^^^^^^^^^^^^^^^^^^^^^^
  File "/home/airflow/.local/lib/python3.12/site-packages/docker/api/client.py", line 281, in _result
    self._raise_for_status(response)
  File "/home/airflow/.local/lib/python3.12/site-packages/docker/api/client.py", line 277, in _raise_for_status
    raise create_api_error_from_http_exception(e) from e
          ^^^^^^^^^^^^^^^^^^^^^^^^^^^^^^^^^^^^^^^
  File "/home/airflow/.local/lib/python3.12/site-packages/docker/errors.py", line 39, in create_api_error_from_http_exception
    raise cls(e, response=response, explanation=explanation) from e
docker.errors.APIError: 400 Client Error for http+docker://localhost/v1.50/containers/create: Bad Request ("invalid mount config for type "bind": bind source path does not exist: /mnt/data/ProyectoSmart/ProyectoSmartMed")
[2025-06-27T04:41:03.175+0000] {taskinstance.py:1225} INFO - Marking task as UP_FOR_RETRY. dag_id=WF_MAIN, task_id=run_hop_pipeline, run_id=scheduled__2025-06-27T03:41:00+00:00, execution_date=20250627T034100, start_date=20250627T044102, end_date=20250627T044103
[2025-06-27T04:41:03.191+0000] {taskinstance.py:340} INFO - ::group::Post task execution logs
[2025-06-27T04:41:03.192+0000] {standard_task_runner.py:124} ERROR - Failed to execute job 21 for task run_hop_pipeline (400 Client Error for http+docker://localhost/v1.50/containers/create: Bad Request ("invalid mount config for type "bind": bind source path does not exist: /mnt/data/ProyectoSmart/ProyectoSmartMed"); 470)
Traceback (most recent call last):
  File "/home/airflow/.local/lib/python3.12/site-packages/docker/api/client.py", line 275, in _raise_for_status
    response.raise_for_status()
  File "/home/airflow/.local/lib/python3.12/site-packages/requests/models.py", line 1024, in raise_for_status
    raise HTTPError(http_error_msg, response=self)
requests.exceptions.HTTPError: 400 Client Error: Bad Request for url: http+docker://localhost/v1.50/containers/create

The above exception was the direct cause of the following exception:

Traceback (most recent call last):
  File "/home/airflow/.local/lib/python3.12/site-packages/airflow/task/task_runner/standard_task_runner.py", line 117, in _start_by_fork
    ret = args.func(args, dag=self.dag)
          ^^^^^^^^^^^^^^^^^^^^^^^^^^^^^
  File "/home/airflow/.local/lib/python3.12/site-packages/airflow/cli/cli_config.py", line 49, in command
    return func(*args, **kwargs)
           ^^^^^^^^^^^^^^^^^^^^^
  File "/home/airflow/.local/lib/python3.12/site-packages/airflow/utils/cli.py", line 115, in wrapper
    return f(*args, **kwargs)
           ^^^^^^^^^^^^^^^^^^
  File "/home/airflow/.local/lib/python3.12/site-packages/airflow/cli/commands/task_command.py", line 483, in task_run
    task_return_code = _run_task_by_selected_method(args, _dag, ti)
                       ^^^^^^^^^^^^^^^^^^^^^^^^^^^^^^^^^^^^^^^^^^^^
  File "/home/airflow/.local/lib/python3.12/site-packages/airflow/cli/commands/task_command.py", line 256, in _run_task_by_selected_method
    return _run_raw_task(args, ti)
           ^^^^^^^^^^^^^^^^^^^^^^^
  File "/home/airflow/.local/lib/python3.12/site-packages/airflow/cli/commands/task_command.py", line 341, in _run_raw_task
    return ti._run_raw_task(
           ^^^^^^^^^^^^^^^^^
  File "/home/airflow/.local/lib/python3.12/site-packages/airflow/utils/session.py", line 97, in wrapper
    return func(*args, session=session, **kwargs)
           ^^^^^^^^^^^^^^^^^^^^^^^^^^^^^^^^^^^^^^
  File "/home/airflow/.local/lib/python3.12/site-packages/airflow/models/taskinstance.py", line 3004, in _run_raw_task
    return _run_raw_task(
           ^^^^^^^^^^^^^^
  File "/home/airflow/.local/lib/python3.12/site-packages/airflow/models/taskinstance.py", line 273, in _run_raw_task
    TaskInstance._execute_task_with_callbacks(
  File "/home/airflow/.local/lib/python3.12/site-packages/airflow/models/taskinstance.py", line 3158, in _execute_task_with_callbacks
    result = self._execute_task(context, task_orig)
             ^^^^^^^^^^^^^^^^^^^^^^^^^^^^^^^^^^^^^^
  File "/home/airflow/.local/lib/python3.12/site-packages/airflow/models/taskinstance.py", line 3182, in _execute_task
    return _execute_task(self, context, task_orig)
           ^^^^^^^^^^^^^^^^^^^^^^^^^^^^^^^^^^^^^^^
  File "/home/airflow/.local/lib/python3.12/site-packages/airflow/models/taskinstance.py", line 767, in _execute_task
    result = _execute_callable(context=context, **execute_callable_kwargs)
             ^^^^^^^^^^^^^^^^^^^^^^^^^^^^^^^^^^^^^^^^^^^^^^^^^^^^^^^^^^^^^
  File "/home/airflow/.local/lib/python3.12/site-packages/airflow/models/taskinstance.py", line 733, in _execute_callable
    return ExecutionCallableRunner(
           ^^^^^^^^^^^^^^^^^^^^^^^^
  File "/home/airflow/.local/lib/python3.12/site-packages/airflow/utils/operator_helpers.py", line 252, in run
    return self.func(*args, **kwargs)
           ^^^^^^^^^^^^^^^^^^^^^^^^^^
  File "/home/airflow/.local/lib/python3.12/site-packages/airflow/models/baseoperator.py", line 406, in wrapper
    return func(self, *args, **kwargs)
           ^^^^^^^^^^^^^^^^^^^^^^^^^^^
  File "/home/airflow/.local/lib/python3.12/site-packages/airflow/providers/docker/operators/docker.py", line 513, in execute
    return self._run_image()
           ^^^^^^^^^^^^^^^^^
  File "/home/airflow/.local/lib/python3.12/site-packages/airflow/providers/docker/operators/docker.py", line 372, in _run_image
    return self._run_image_with_mounts([*self.mounts, tmp_mount], add_tmp_variable=True)
           ^^^^^^^^^^^^^^^^^^^^^^^^^^^^^^^^^^^^^^^^^^^^^^^^^^^^^^^^^^^^^^^^^^^^^^^^^^^^^
  File "/home/airflow/.local/lib/python3.12/site-packages/airflow/providers/docker/operators/docker.py", line 399, in _run_image_with_mounts
    self.container = self.cli.create_container(
                     ^^^^^^^^^^^^^^^^^^^^^^^^^^
  File "/home/airflow/.local/lib/python3.12/site-packages/docker/api/container.py", line 440, in create_container
    return self.create_container_from_config(config, name, platform)
           ^^^^^^^^^^^^^^^^^^^^^^^^^^^^^^^^^^^^^^^^^^^^^^^^^^^^^^^^^
  File "/home/airflow/.local/lib/python3.12/site-packages/docker/api/container.py", line 457, in create_container_from_config
    return self._result(res, True)
           ^^^^^^^^^^^^^^^^^^^^^^^
  File "/home/airflow/.local/lib/python3.12/site-packages/docker/api/client.py", line 281, in _result
    self._raise_for_status(response)
  File "/home/airflow/.local/lib/python3.12/site-packages/docker/api/client.py", line 277, in _raise_for_status
    raise create_api_error_from_http_exception(e) from e
          ^^^^^^^^^^^^^^^^^^^^^^^^^^^^^^^^^^^^^^^
  File "/home/airflow/.local/lib/python3.12/site-packages/docker/errors.py", line 39, in create_api_error_from_http_exception
    raise cls(e, response=response, explanation=explanation) from e
docker.errors.APIError: 400 Client Error for http+docker://localhost/v1.50/containers/create: Bad Request ("invalid mount config for type "bind": bind source path does not exist: /mnt/data/ProyectoSmart/ProyectoSmartMed")
[2025-06-27T04:41:03.228+0000] {local_task_job_runner.py:266} INFO - Task exited with return code 1
[2025-06-27T04:41:03.238+0000] {local_task_job_runner.py:245} INFO - ::endgroup::
[2025-06-27T04:48:28.575+0000] {local_task_job_runner.py:123} INFO - ::group::Pre task execution logs
[2025-06-27T04:48:28.612+0000] {taskinstance.py:2612} INFO - Dependencies all met for dep_context=non-requeueable deps ti=<TaskInstance: WF_MAIN.run_hop_pipeline scheduled__2025-06-27T03:41:00+00:00 [queued]>
[2025-06-27T04:48:28.635+0000] {taskinstance.py:2612} INFO - Dependencies all met for dep_context=requeueable deps ti=<TaskInstance: WF_MAIN.run_hop_pipeline scheduled__2025-06-27T03:41:00+00:00 [queued]>
[2025-06-27T04:48:28.639+0000] {taskinstance.py:2865} INFO - Starting attempt 1 of 2
[2025-06-27T04:48:28.695+0000] {taskinstance.py:2888} INFO - Executing <Task(DockerOperator): run_hop_pipeline> on 2025-06-27 03:41:00+00:00
[2025-06-27T04:48:28.720+0000] {standard_task_runner.py:104} INFO - Running: ['***', 'tasks', 'run', 'WF_MAIN', 'run_hop_pipeline', 'scheduled__2025-06-27T03:41:00+00:00', '--job-id', '7', '--raw', '--subdir', 'DAGS_FOLDER/apache-hop-dag-wf-main.py', '--cfg-path', '/tmp/tmpog9ue1ov']
[2025-06-27T04:48:28.717+0000] {warnings.py:112} WARNING - /home/***/.local/lib/python3.12/site-packages/***/task/task_runner/standard_task_runner.py:70: DeprecationWarning: This process (pid=67) is multi-threaded, use of fork() may lead to deadlocks in the child.
  pid = os.fork()

[2025-06-27T04:48:28.729+0000] {standard_task_runner.py:105} INFO - Job 7: Subtask run_hop_pipeline
[2025-06-27T04:48:28.730+0000] {standard_task_runner.py:72} INFO - Started process 76 to run task
[2025-06-27T04:48:28.918+0000] {task_command.py:467} INFO - Running <TaskInstance: WF_MAIN.run_hop_pipeline scheduled__2025-06-27T03:41:00+00:00 [running]> on host 11460eb2799d
[2025-06-27T04:48:29.263+0000] {taskinstance.py:3131} INFO - Exporting env vars: AIRFLOW_CTX_DAG_OWNER='***' AIRFLOW_CTX_DAG_ID='WF_MAIN' AIRFLOW_CTX_TASK_ID='run_hop_pipeline' AIRFLOW_CTX_EXECUTION_DATE='2025-06-27T03:41:00+00:00' AIRFLOW_CTX_TRY_NUMBER='1' AIRFLOW_CTX_DAG_RUN_ID='scheduled__2025-06-27T03:41:00+00:00'
[2025-06-27T04:48:29.274+0000] {taskinstance.py:731} INFO - ::endgroup::
[2025-06-27T04:48:29.605+0000] {docker.py:367} INFO - Starting docker container from image apache/hop:latest
[2025-06-27T04:48:29.700+0000] {taskinstance.py:3310} ERROR - Task failed with exception
Traceback (most recent call last):
  File "/home/airflow/.local/lib/python3.12/site-packages/docker/api/client.py", line 275, in _raise_for_status
    response.raise_for_status()
  File "/home/airflow/.local/lib/python3.12/site-packages/requests/models.py", line 1024, in raise_for_status
    raise HTTPError(http_error_msg, response=self)
requests.exceptions.HTTPError: 400 Client Error: Bad Request for url: http+docker://localhost/v1.50/containers/create

The above exception was the direct cause of the following exception:

Traceback (most recent call last):
  File "/home/airflow/.local/lib/python3.12/site-packages/airflow/models/taskinstance.py", line 767, in _execute_task
    result = _execute_callable(context=context, **execute_callable_kwargs)
             ^^^^^^^^^^^^^^^^^^^^^^^^^^^^^^^^^^^^^^^^^^^^^^^^^^^^^^^^^^^^^
  File "/home/airflow/.local/lib/python3.12/site-packages/airflow/models/taskinstance.py", line 733, in _execute_callable
    return ExecutionCallableRunner(
           ^^^^^^^^^^^^^^^^^^^^^^^^
  File "/home/airflow/.local/lib/python3.12/site-packages/airflow/utils/operator_helpers.py", line 252, in run
    return self.func(*args, **kwargs)
           ^^^^^^^^^^^^^^^^^^^^^^^^^^
  File "/home/airflow/.local/lib/python3.12/site-packages/airflow/models/baseoperator.py", line 406, in wrapper
    return func(self, *args, **kwargs)
           ^^^^^^^^^^^^^^^^^^^^^^^^^^^
  File "/home/airflow/.local/lib/python3.12/site-packages/airflow/providers/docker/operators/docker.py", line 513, in execute
    return self._run_image()
           ^^^^^^^^^^^^^^^^^
  File "/home/airflow/.local/lib/python3.12/site-packages/airflow/providers/docker/operators/docker.py", line 372, in _run_image
    return self._run_image_with_mounts([*self.mounts, tmp_mount], add_tmp_variable=True)
           ^^^^^^^^^^^^^^^^^^^^^^^^^^^^^^^^^^^^^^^^^^^^^^^^^^^^^^^^^^^^^^^^^^^^^^^^^^^^^
  File "/home/airflow/.local/lib/python3.12/site-packages/airflow/providers/docker/operators/docker.py", line 399, in _run_image_with_mounts
    self.container = self.cli.create_container(
                     ^^^^^^^^^^^^^^^^^^^^^^^^^^
  File "/home/airflow/.local/lib/python3.12/site-packages/docker/api/container.py", line 440, in create_container
    return self.create_container_from_config(config, name, platform)
           ^^^^^^^^^^^^^^^^^^^^^^^^^^^^^^^^^^^^^^^^^^^^^^^^^^^^^^^^^
  File "/home/airflow/.local/lib/python3.12/site-packages/docker/api/container.py", line 457, in create_container_from_config
    return self._result(res, True)
           ^^^^^^^^^^^^^^^^^^^^^^^
  File "/home/airflow/.local/lib/python3.12/site-packages/docker/api/client.py", line 281, in _result
    self._raise_for_status(response)
  File "/home/airflow/.local/lib/python3.12/site-packages/docker/api/client.py", line 277, in _raise_for_status
    raise create_api_error_from_http_exception(e) from e
          ^^^^^^^^^^^^^^^^^^^^^^^^^^^^^^^^^^^^^^^
  File "/home/airflow/.local/lib/python3.12/site-packages/docker/errors.py", line 39, in create_api_error_from_http_exception
    raise cls(e, response=response, explanation=explanation) from e
docker.errors.APIError: 400 Client Error for http+docker://localhost/v1.50/containers/create: Bad Request ("invalid mount config for type "bind": bind source path does not exist: /mnt/data/ProyectoSmart/ProyectoSmartMed")
[2025-06-27T04:48:29.769+0000] {taskinstance.py:1225} INFO - Marking task as UP_FOR_RETRY. dag_id=WF_MAIN, task_id=run_hop_pipeline, run_id=scheduled__2025-06-27T03:41:00+00:00, execution_date=20250627T034100, start_date=20250627T044828, end_date=20250627T044829
[2025-06-27T04:48:29.826+0000] {taskinstance.py:340} INFO - ::group::Post task execution logs
[2025-06-27T04:48:29.828+0000] {standard_task_runner.py:124} ERROR - Failed to execute job 7 for task run_hop_pipeline (400 Client Error for http+docker://localhost/v1.50/containers/create: Bad Request ("invalid mount config for type "bind": bind source path does not exist: /mnt/data/ProyectoSmart/ProyectoSmartMed"); 76)
Traceback (most recent call last):
  File "/home/airflow/.local/lib/python3.12/site-packages/docker/api/client.py", line 275, in _raise_for_status
    response.raise_for_status()
  File "/home/airflow/.local/lib/python3.12/site-packages/requests/models.py", line 1024, in raise_for_status
    raise HTTPError(http_error_msg, response=self)
requests.exceptions.HTTPError: 400 Client Error: Bad Request for url: http+docker://localhost/v1.50/containers/create

The above exception was the direct cause of the following exception:

Traceback (most recent call last):
  File "/home/airflow/.local/lib/python3.12/site-packages/airflow/task/task_runner/standard_task_runner.py", line 117, in _start_by_fork
    ret = args.func(args, dag=self.dag)
          ^^^^^^^^^^^^^^^^^^^^^^^^^^^^^
  File "/home/airflow/.local/lib/python3.12/site-packages/airflow/cli/cli_config.py", line 49, in command
    return func(*args, **kwargs)
           ^^^^^^^^^^^^^^^^^^^^^
  File "/home/airflow/.local/lib/python3.12/site-packages/airflow/utils/cli.py", line 115, in wrapper
    return f(*args, **kwargs)
           ^^^^^^^^^^^^^^^^^^
  File "/home/airflow/.local/lib/python3.12/site-packages/airflow/cli/commands/task_command.py", line 483, in task_run
    task_return_code = _run_task_by_selected_method(args, _dag, ti)
                       ^^^^^^^^^^^^^^^^^^^^^^^^^^^^^^^^^^^^^^^^^^^^
  File "/home/airflow/.local/lib/python3.12/site-packages/airflow/cli/commands/task_command.py", line 256, in _run_task_by_selected_method
    return _run_raw_task(args, ti)
           ^^^^^^^^^^^^^^^^^^^^^^^
  File "/home/airflow/.local/lib/python3.12/site-packages/airflow/cli/commands/task_command.py", line 341, in _run_raw_task
    return ti._run_raw_task(
           ^^^^^^^^^^^^^^^^^
  File "/home/airflow/.local/lib/python3.12/site-packages/airflow/utils/session.py", line 97, in wrapper
    return func(*args, session=session, **kwargs)
           ^^^^^^^^^^^^^^^^^^^^^^^^^^^^^^^^^^^^^^
  File "/home/airflow/.local/lib/python3.12/site-packages/airflow/models/taskinstance.py", line 3004, in _run_raw_task
    return _run_raw_task(
           ^^^^^^^^^^^^^^
  File "/home/airflow/.local/lib/python3.12/site-packages/airflow/models/taskinstance.py", line 273, in _run_raw_task
    TaskInstance._execute_task_with_callbacks(
  File "/home/airflow/.local/lib/python3.12/site-packages/airflow/models/taskinstance.py", line 3158, in _execute_task_with_callbacks
    result = self._execute_task(context, task_orig)
             ^^^^^^^^^^^^^^^^^^^^^^^^^^^^^^^^^^^^^^
  File "/home/airflow/.local/lib/python3.12/site-packages/airflow/models/taskinstance.py", line 3182, in _execute_task
    return _execute_task(self, context, task_orig)
           ^^^^^^^^^^^^^^^^^^^^^^^^^^^^^^^^^^^^^^^
  File "/home/airflow/.local/lib/python3.12/site-packages/airflow/models/taskinstance.py", line 767, in _execute_task
    result = _execute_callable(context=context, **execute_callable_kwargs)
             ^^^^^^^^^^^^^^^^^^^^^^^^^^^^^^^^^^^^^^^^^^^^^^^^^^^^^^^^^^^^^
  File "/home/airflow/.local/lib/python3.12/site-packages/airflow/models/taskinstance.py", line 733, in _execute_callable
    return ExecutionCallableRunner(
           ^^^^^^^^^^^^^^^^^^^^^^^^
  File "/home/airflow/.local/lib/python3.12/site-packages/airflow/utils/operator_helpers.py", line 252, in run
    return self.func(*args, **kwargs)
           ^^^^^^^^^^^^^^^^^^^^^^^^^^
  File "/home/airflow/.local/lib/python3.12/site-packages/airflow/models/baseoperator.py", line 406, in wrapper
    return func(self, *args, **kwargs)
           ^^^^^^^^^^^^^^^^^^^^^^^^^^^
  File "/home/airflow/.local/lib/python3.12/site-packages/airflow/providers/docker/operators/docker.py", line 513, in execute
    return self._run_image()
           ^^^^^^^^^^^^^^^^^
  File "/home/airflow/.local/lib/python3.12/site-packages/airflow/providers/docker/operators/docker.py", line 372, in _run_image
    return self._run_image_with_mounts([*self.mounts, tmp_mount], add_tmp_variable=True)
           ^^^^^^^^^^^^^^^^^^^^^^^^^^^^^^^^^^^^^^^^^^^^^^^^^^^^^^^^^^^^^^^^^^^^^^^^^^^^^
  File "/home/airflow/.local/lib/python3.12/site-packages/airflow/providers/docker/operators/docker.py", line 399, in _run_image_with_mounts
    self.container = self.cli.create_container(
                     ^^^^^^^^^^^^^^^^^^^^^^^^^^
  File "/home/airflow/.local/lib/python3.12/site-packages/docker/api/container.py", line 440, in create_container
    return self.create_container_from_config(config, name, platform)
           ^^^^^^^^^^^^^^^^^^^^^^^^^^^^^^^^^^^^^^^^^^^^^^^^^^^^^^^^^
  File "/home/airflow/.local/lib/python3.12/site-packages/docker/api/container.py", line 457, in create_container_from_config
    return self._result(res, True)
           ^^^^^^^^^^^^^^^^^^^^^^^
  File "/home/airflow/.local/lib/python3.12/site-packages/docker/api/client.py", line 281, in _result
    self._raise_for_status(response)
  File "/home/airflow/.local/lib/python3.12/site-packages/docker/api/client.py", line 277, in _raise_for_status
    raise create_api_error_from_http_exception(e) from e
          ^^^^^^^^^^^^^^^^^^^^^^^^^^^^^^^^^^^^^^^
  File "/home/airflow/.local/lib/python3.12/site-packages/docker/errors.py", line 39, in create_api_error_from_http_exception
    raise cls(e, response=response, explanation=explanation) from e
docker.errors.APIError: 400 Client Error for http+docker://localhost/v1.50/containers/create: Bad Request ("invalid mount config for type "bind": bind source path does not exist: /mnt/data/ProyectoSmart/ProyectoSmartMed")
[2025-06-27T04:48:29.877+0000] {local_task_job_runner.py:266} INFO - Task exited with return code 1
[2025-06-27T04:48:29.930+0000] {taskinstance.py:3900} INFO - 0 downstream tasks scheduled from follow-on schedule check
[2025-06-27T04:48:29.935+0000] {local_task_job_runner.py:245} INFO - ::endgroup::
[2025-06-27T04:59:17.276+0000] {local_task_job_runner.py:120} INFO - ::group::Pre task execution logs
[2025-06-27T04:59:17.337+0000] {taskinstance.py:2076} INFO - Dependencies all met for dep_context=non-requeueable deps ti=<TaskInstance: WF_MAIN.run_hop_pipeline scheduled__2025-06-27T03:41:00+00:00 [queued]>
[2025-06-27T04:59:17.359+0000] {taskinstance.py:2076} INFO - Dependencies all met for dep_context=requeueable deps ti=<TaskInstance: WF_MAIN.run_hop_pipeline scheduled__2025-06-27T03:41:00+00:00 [queued]>
[2025-06-27T04:59:17.360+0000] {taskinstance.py:2306} INFO - Starting attempt 1 of 2
[2025-06-27T04:59:17.391+0000] {taskinstance.py:2330} INFO - Executing <Task(DockerOperator): run_hop_pipeline> on 2025-06-27 03:41:00+00:00
[2025-06-27T04:59:17.408+0000] {warnings.py:110} WARNING - /home/***/.local/lib/python3.12/site-packages/***/task/task_runner/standard_task_runner.py:61: DeprecationWarning: This process (pid=64) is multi-threaded, use of fork() may lead to deadlocks in the child.
  pid = os.fork()

[2025-06-27T04:59:17.414+0000] {standard_task_runner.py:63} INFO - Started process 69 to run task
[2025-06-27T04:59:17.413+0000] {standard_task_runner.py:90} INFO - Running: ['***', 'tasks', 'run', 'WF_MAIN', 'run_hop_pipeline', 'scheduled__2025-06-27T03:41:00+00:00', '--job-id', '3', '--raw', '--subdir', 'DAGS_FOLDER/apache-hop-dag-wf-main.py', '--cfg-path', '/tmp/tmpzi7w5wob']
[2025-06-27T04:59:17.418+0000] {standard_task_runner.py:91} INFO - Job 3: Subtask run_hop_pipeline
[2025-06-27T04:59:17.609+0000] {task_command.py:426} INFO - Running <TaskInstance: WF_MAIN.run_hop_pipeline scheduled__2025-06-27T03:41:00+00:00 [running]> on host 4c575de26931
[2025-06-27T04:59:17.838+0000] {taskinstance.py:2648} INFO - Exporting env vars: AIRFLOW_CTX_DAG_OWNER='***' AIRFLOW_CTX_DAG_ID='WF_MAIN' AIRFLOW_CTX_TASK_ID='run_hop_pipeline' AIRFLOW_CTX_EXECUTION_DATE='2025-06-27T03:41:00+00:00' AIRFLOW_CTX_TRY_NUMBER='1' AIRFLOW_CTX_DAG_RUN_ID='scheduled__2025-06-27T03:41:00+00:00'
[2025-06-27T04:59:17.843+0000] {taskinstance.py:430} INFO - ::endgroup::
[2025-06-27T04:59:18.173+0000] {docker.py:366} INFO - Starting docker container from image apache/hop:latest
[2025-06-27T04:59:18.221+0000] {taskinstance.py:441} INFO - ::group::Post task execution logs
[2025-06-27T04:59:18.225+0000] {taskinstance.py:2905} ERROR - Task failed with exception
Traceback (most recent call last):
  File "/home/airflow/.local/lib/python3.12/site-packages/docker/api/client.py", line 265, in _raise_for_status
    response.raise_for_status()
  File "/home/airflow/.local/lib/python3.12/site-packages/requests/models.py", line 1021, in raise_for_status
    raise HTTPError(http_error_msg, response=self)
requests.exceptions.HTTPError: 400 Client Error: Bad Request for url: http+docker://localhost/v1.50/containers/create

The above exception was the direct cause of the following exception:

Traceback (most recent call last):
  File "/home/airflow/.local/lib/python3.12/site-packages/airflow/models/taskinstance.py", line 465, in _execute_task
    result = _execute_callable(context=context, **execute_callable_kwargs)
             ^^^^^^^^^^^^^^^^^^^^^^^^^^^^^^^^^^^^^^^^^^^^^^^^^^^^^^^^^^^^^
  File "/home/airflow/.local/lib/python3.12/site-packages/airflow/models/taskinstance.py", line 432, in _execute_callable
    return execute_callable(context=context, **execute_callable_kwargs)
           ^^^^^^^^^^^^^^^^^^^^^^^^^^^^^^^^^^^^^^^^^^^^^^^^^^^^^^^^^^^^
  File "/home/airflow/.local/lib/python3.12/site-packages/airflow/models/baseoperator.py", line 400, in wrapper
    return func(self, *args, **kwargs)
           ^^^^^^^^^^^^^^^^^^^^^^^^^^^
  File "/home/airflow/.local/lib/python3.12/site-packages/airflow/providers/docker/operators/docker.py", line 509, in execute
    return self._run_image()
           ^^^^^^^^^^^^^^^^^
  File "/home/airflow/.local/lib/python3.12/site-packages/airflow/providers/docker/operators/docker.py", line 371, in _run_image
    return self._run_image_with_mounts([*self.mounts, tmp_mount], add_tmp_variable=True)
           ^^^^^^^^^^^^^^^^^^^^^^^^^^^^^^^^^^^^^^^^^^^^^^^^^^^^^^^^^^^^^^^^^^^^^^^^^^^^^
  File "/home/airflow/.local/lib/python3.12/site-packages/airflow/providers/docker/operators/docker.py", line 398, in _run_image_with_mounts
    self.container = self.cli.create_container(
                     ^^^^^^^^^^^^^^^^^^^^^^^^^^
  File "/home/airflow/.local/lib/python3.12/site-packages/docker/api/container.py", line 439, in create_container
    return self.create_container_from_config(config, name, platform)
           ^^^^^^^^^^^^^^^^^^^^^^^^^^^^^^^^^^^^^^^^^^^^^^^^^^^^^^^^^
  File "/home/airflow/.local/lib/python3.12/site-packages/docker/api/container.py", line 456, in create_container_from_config
    return self._result(res, True)
           ^^^^^^^^^^^^^^^^^^^^^^^
  File "/home/airflow/.local/lib/python3.12/site-packages/docker/api/client.py", line 271, in _result
    self._raise_for_status(response)
  File "/home/airflow/.local/lib/python3.12/site-packages/docker/api/client.py", line 267, in _raise_for_status
    raise create_api_error_from_http_exception(e) from e
          ^^^^^^^^^^^^^^^^^^^^^^^^^^^^^^^^^^^^^^^
  File "/home/airflow/.local/lib/python3.12/site-packages/docker/errors.py", line 39, in create_api_error_from_http_exception
    raise cls(e, response=response, explanation=explanation) from e
docker.errors.APIError: 400 Client Error for http+docker://localhost/v1.50/containers/create: Bad Request ("invalid mount config for type "bind": bind source path does not exist: /mnt/data/ProyectoSmart/ProyectoSmartMed")
[2025-06-27T04:59:18.263+0000] {taskinstance.py:1206} INFO - Marking task as UP_FOR_RETRY. dag_id=WF_MAIN, task_id=run_hop_pipeline, run_id=scheduled__2025-06-27T03:41:00+00:00, execution_date=20250627T034100, start_date=20250627T045917, end_date=20250627T045918
[2025-06-27T04:59:18.307+0000] {standard_task_runner.py:110} ERROR - Failed to execute job 3 for task run_hop_pipeline (400 Client Error for http+docker://localhost/v1.50/containers/create: Bad Request ("invalid mount config for type "bind": bind source path does not exist: /mnt/data/ProyectoSmart/ProyectoSmartMed"); 69)
[2025-06-27T04:59:18.366+0000] {local_task_job_runner.py:240} INFO - Task exited with return code 1
[2025-06-27T04:59:18.445+0000] {taskinstance.py:3498} INFO - 0 downstream tasks scheduled from follow-on schedule check
[2025-06-27T04:59:18.451+0000] {local_task_job_runner.py:222} INFO - ::endgroup::
[2025-06-27T05:41:02.109+0000] {local_task_job_runner.py:120} INFO - ::group::Pre task execution logs
[2025-06-27T05:41:02.233+0000] {taskinstance.py:2076} INFO - Dependencies all met for dep_context=non-requeueable deps ti=<TaskInstance: WF_MAIN.run_hop_pipeline scheduled__2025-06-27T03:41:00+00:00 [queued]>
[2025-06-27T05:41:02.263+0000] {taskinstance.py:2076} INFO - Dependencies all met for dep_context=requeueable deps ti=<TaskInstance: WF_MAIN.run_hop_pipeline scheduled__2025-06-27T03:41:00+00:00 [queued]>
[2025-06-27T05:41:02.264+0000] {taskinstance.py:2306} INFO - Starting attempt 1 of 2
[2025-06-27T05:41:02.381+0000] {taskinstance.py:2330} INFO - Executing <Task(DockerOperator): run_hop_pipeline> on 2025-06-27 03:41:00+00:00
[2025-06-27T05:41:02.404+0000] {warnings.py:110} WARNING - /home/***/.local/lib/python3.12/site-packages/***/task/task_runner/standard_task_runner.py:61: DeprecationWarning: This process (pid=64) is multi-threaded, use of fork() may lead to deadlocks in the child.
  pid = os.fork()

[2025-06-27T05:41:02.411+0000] {standard_task_runner.py:63} INFO - Started process 69 to run task
[2025-06-27T05:41:02.409+0000] {standard_task_runner.py:90} INFO - Running: ['***', 'tasks', 'run', 'WF_MAIN', 'run_hop_pipeline', 'scheduled__2025-06-27T03:41:00+00:00', '--job-id', '3', '--raw', '--subdir', 'DAGS_FOLDER/apache-hop-dag-wf-main.py', '--cfg-path', '/tmp/tmpg3keijz0']
[2025-06-27T05:41:02.421+0000] {standard_task_runner.py:91} INFO - Job 3: Subtask run_hop_pipeline
[2025-06-27T05:41:02.706+0000] {task_command.py:426} INFO - Running <TaskInstance: WF_MAIN.run_hop_pipeline scheduled__2025-06-27T03:41:00+00:00 [running]> on host 760ca3d6cb03
[2025-06-27T05:41:02.975+0000] {taskinstance.py:2648} INFO - Exporting env vars: AIRFLOW_CTX_DAG_OWNER='***' AIRFLOW_CTX_DAG_ID='WF_MAIN' AIRFLOW_CTX_TASK_ID='run_hop_pipeline' AIRFLOW_CTX_EXECUTION_DATE='2025-06-27T03:41:00+00:00' AIRFLOW_CTX_TRY_NUMBER='1' AIRFLOW_CTX_DAG_RUN_ID='scheduled__2025-06-27T03:41:00+00:00'
[2025-06-27T05:41:02.979+0000] {taskinstance.py:430} INFO - ::endgroup::
[2025-06-27T05:41:03.248+0000] {docker.py:366} INFO - Starting docker container from image apache/hop:latest
[2025-06-27T05:41:03.294+0000] {taskinstance.py:441} INFO - ::group::Post task execution logs
[2025-06-27T05:41:03.297+0000] {taskinstance.py:2905} ERROR - Task failed with exception
Traceback (most recent call last):
  File "/home/airflow/.local/lib/python3.12/site-packages/docker/api/client.py", line 265, in _raise_for_status
    response.raise_for_status()
  File "/home/airflow/.local/lib/python3.12/site-packages/requests/models.py", line 1021, in raise_for_status
    raise HTTPError(http_error_msg, response=self)
requests.exceptions.HTTPError: 400 Client Error: Bad Request for url: http+docker://localhost/v1.50/containers/create

The above exception was the direct cause of the following exception:

Traceback (most recent call last):
  File "/home/airflow/.local/lib/python3.12/site-packages/airflow/models/taskinstance.py", line 465, in _execute_task
    result = _execute_callable(context=context, **execute_callable_kwargs)
             ^^^^^^^^^^^^^^^^^^^^^^^^^^^^^^^^^^^^^^^^^^^^^^^^^^^^^^^^^^^^^
  File "/home/airflow/.local/lib/python3.12/site-packages/airflow/models/taskinstance.py", line 432, in _execute_callable
    return execute_callable(context=context, **execute_callable_kwargs)
           ^^^^^^^^^^^^^^^^^^^^^^^^^^^^^^^^^^^^^^^^^^^^^^^^^^^^^^^^^^^^
  File "/home/airflow/.local/lib/python3.12/site-packages/airflow/models/baseoperator.py", line 400, in wrapper
    return func(self, *args, **kwargs)
           ^^^^^^^^^^^^^^^^^^^^^^^^^^^
  File "/home/airflow/.local/lib/python3.12/site-packages/airflow/providers/docker/operators/docker.py", line 509, in execute
    return self._run_image()
           ^^^^^^^^^^^^^^^^^
  File "/home/airflow/.local/lib/python3.12/site-packages/airflow/providers/docker/operators/docker.py", line 371, in _run_image
    return self._run_image_with_mounts([*self.mounts, tmp_mount], add_tmp_variable=True)
           ^^^^^^^^^^^^^^^^^^^^^^^^^^^^^^^^^^^^^^^^^^^^^^^^^^^^^^^^^^^^^^^^^^^^^^^^^^^^^
  File "/home/airflow/.local/lib/python3.12/site-packages/airflow/providers/docker/operators/docker.py", line 398, in _run_image_with_mounts
    self.container = self.cli.create_container(
                     ^^^^^^^^^^^^^^^^^^^^^^^^^^
  File "/home/airflow/.local/lib/python3.12/site-packages/docker/api/container.py", line 439, in create_container
    return self.create_container_from_config(config, name, platform)
           ^^^^^^^^^^^^^^^^^^^^^^^^^^^^^^^^^^^^^^^^^^^^^^^^^^^^^^^^^
  File "/home/airflow/.local/lib/python3.12/site-packages/docker/api/container.py", line 456, in create_container_from_config
    return self._result(res, True)
           ^^^^^^^^^^^^^^^^^^^^^^^
  File "/home/airflow/.local/lib/python3.12/site-packages/docker/api/client.py", line 271, in _result
    self._raise_for_status(response)
  File "/home/airflow/.local/lib/python3.12/site-packages/docker/api/client.py", line 267, in _raise_for_status
    raise create_api_error_from_http_exception(e) from e
          ^^^^^^^^^^^^^^^^^^^^^^^^^^^^^^^^^^^^^^^
  File "/home/airflow/.local/lib/python3.12/site-packages/docker/errors.py", line 39, in create_api_error_from_http_exception
    raise cls(e, response=response, explanation=explanation) from e
docker.errors.APIError: 400 Client Error for http+docker://localhost/v1.50/containers/create: Bad Request ("invalid mount config for type "bind": bind source path does not exist: /opt/airflow/ProyectoSmartMed")
[2025-06-27T05:41:03.335+0000] {taskinstance.py:1206} INFO - Marking task as UP_FOR_RETRY. dag_id=WF_MAIN, task_id=run_hop_pipeline, run_id=scheduled__2025-06-27T03:41:00+00:00, execution_date=20250627T034100, start_date=20250627T054102, end_date=20250627T054103
[2025-06-27T05:41:03.374+0000] {standard_task_runner.py:110} ERROR - Failed to execute job 3 for task run_hop_pipeline (400 Client Error for http+docker://localhost/v1.50/containers/create: Bad Request ("invalid mount config for type "bind": bind source path does not exist: /opt/airflow/ProyectoSmartMed"); 69)
[2025-06-27T05:41:03.416+0000] {local_task_job_runner.py:240} INFO - Task exited with return code 1
[2025-06-27T05:41:03.493+0000] {taskinstance.py:3498} INFO - 0 downstream tasks scheduled from follow-on schedule check
[2025-06-27T05:41:03.497+0000] {local_task_job_runner.py:222} INFO - ::endgroup::
