[2025-06-27T04:21:03.321+0000] {local_task_job_runner.py:123} INFO - ::group::Pre task execution logs
[2025-06-27T04:21:03.356+0000] {taskinstance.py:2612} INFO - Dependencies all met for dep_context=non-requeueable deps ti=<TaskInstance: STG4_MEDIDORES.run_hop_pipeline scheduled__2025-06-27T03:21:00+00:00 [queued]>
[2025-06-27T04:21:03.369+0000] {taskinstance.py:2612} INFO - Dependencies all met for dep_context=requeueable deps ti=<TaskInstance: STG4_MEDIDORES.run_hop_pipeline scheduled__2025-06-27T03:21:00+00:00 [queued]>
[2025-06-27T04:21:03.369+0000] {taskinstance.py:2865} INFO - Starting attempt 1 of 2
[2025-06-27T04:21:03.432+0000] {taskinstance.py:2888} INFO - Executing <Task(DockerOperator): run_hop_pipeline> on 2025-06-27 03:21:00+00:00
[2025-06-27T04:21:03.444+0000] {warnings.py:112} WARNING - /home/***/.local/lib/python3.12/site-packages/***/task/task_runner/standard_task_runner.py:70: DeprecationWarning: This process (pid=177) is multi-threaded, use of fork() may lead to deadlocks in the child.
  pid = os.fork()

[2025-06-27T04:21:03.447+0000] {standard_task_runner.py:104} INFO - Running: ['***', 'tasks', 'run', 'STG4_MEDIDORES', 'run_hop_pipeline', 'scheduled__2025-06-27T03:21:00+00:00', '--job-id', '8', '--raw', '--subdir', 'DAGS_FOLDER/apache-hop-dag-simple.py', '--cfg-path', '/tmp/tmphlogp8w4']
[2025-06-27T04:21:03.449+0000] {standard_task_runner.py:72} INFO - Started process 179 to run task
[2025-06-27T04:21:03.449+0000] {standard_task_runner.py:105} INFO - Job 8: Subtask run_hop_pipeline
[2025-06-27T04:21:03.743+0000] {task_command.py:467} INFO - Running <TaskInstance: STG4_MEDIDORES.run_hop_pipeline scheduled__2025-06-27T03:21:00+00:00 [running]> on host 9f6303ed7827
[2025-06-27T04:21:03.874+0000] {taskinstance.py:3131} INFO - Exporting env vars: AIRFLOW_CTX_DAG_OWNER='***' AIRFLOW_CTX_DAG_ID='STG4_MEDIDORES' AIRFLOW_CTX_TASK_ID='run_hop_pipeline' AIRFLOW_CTX_EXECUTION_DATE='2025-06-27T03:21:00+00:00' AIRFLOW_CTX_TRY_NUMBER='1' AIRFLOW_CTX_DAG_RUN_ID='scheduled__2025-06-27T03:21:00+00:00'
[2025-06-27T04:21:03.875+0000] {taskinstance.py:731} INFO - ::endgroup::
[2025-06-27T04:21:04.018+0000] {docker.py:367} INFO - Starting docker container from image apache/hop:latest
[2025-06-27T04:21:04.038+0000] {taskinstance.py:3310} ERROR - Task failed with exception
Traceback (most recent call last):
  File "/home/airflow/.local/lib/python3.12/site-packages/docker/api/client.py", line 275, in _raise_for_status
    response.raise_for_status()
  File "/home/airflow/.local/lib/python3.12/site-packages/requests/models.py", line 1024, in raise_for_status
    raise HTTPError(http_error_msg, response=self)
requests.exceptions.HTTPError: 400 Client Error: Bad Request for url: http+docker://localhost/v1.50/containers/create

The above exception was the direct cause of the following exception:

Traceback (most recent call last):
  File "/home/airflow/.local/lib/python3.12/site-packages/airflow/models/taskinstance.py", line 767, in _execute_task
    result = _execute_callable(context=context, **execute_callable_kwargs)
             ^^^^^^^^^^^^^^^^^^^^^^^^^^^^^^^^^^^^^^^^^^^^^^^^^^^^^^^^^^^^^
  File "/home/airflow/.local/lib/python3.12/site-packages/airflow/models/taskinstance.py", line 733, in _execute_callable
    return ExecutionCallableRunner(
           ^^^^^^^^^^^^^^^^^^^^^^^^
  File "/home/airflow/.local/lib/python3.12/site-packages/airflow/utils/operator_helpers.py", line 252, in run
    return self.func(*args, **kwargs)
           ^^^^^^^^^^^^^^^^^^^^^^^^^^
  File "/home/airflow/.local/lib/python3.12/site-packages/airflow/models/baseoperator.py", line 406, in wrapper
    return func(self, *args, **kwargs)
           ^^^^^^^^^^^^^^^^^^^^^^^^^^^
  File "/home/airflow/.local/lib/python3.12/site-packages/airflow/providers/docker/operators/docker.py", line 513, in execute
    return self._run_image()
           ^^^^^^^^^^^^^^^^^
  File "/home/airflow/.local/lib/python3.12/site-packages/airflow/providers/docker/operators/docker.py", line 372, in _run_image
    return self._run_image_with_mounts([*self.mounts, tmp_mount], add_tmp_variable=True)
           ^^^^^^^^^^^^^^^^^^^^^^^^^^^^^^^^^^^^^^^^^^^^^^^^^^^^^^^^^^^^^^^^^^^^^^^^^^^^^
  File "/home/airflow/.local/lib/python3.12/site-packages/airflow/providers/docker/operators/docker.py", line 399, in _run_image_with_mounts
    self.container = self.cli.create_container(
                     ^^^^^^^^^^^^^^^^^^^^^^^^^^
  File "/home/airflow/.local/lib/python3.12/site-packages/docker/api/container.py", line 440, in create_container
    return self.create_container_from_config(config, name, platform)
           ^^^^^^^^^^^^^^^^^^^^^^^^^^^^^^^^^^^^^^^^^^^^^^^^^^^^^^^^^
  File "/home/airflow/.local/lib/python3.12/site-packages/docker/api/container.py", line 457, in create_container_from_config
    return self._result(res, True)
           ^^^^^^^^^^^^^^^^^^^^^^^
  File "/home/airflow/.local/lib/python3.12/site-packages/docker/api/client.py", line 281, in _result
    self._raise_for_status(response)
  File "/home/airflow/.local/lib/python3.12/site-packages/docker/api/client.py", line 277, in _raise_for_status
    raise create_api_error_from_http_exception(e) from e
          ^^^^^^^^^^^^^^^^^^^^^^^^^^^^^^^^^^^^^^^
  File "/home/airflow/.local/lib/python3.12/site-packages/docker/errors.py", line 39, in create_api_error_from_http_exception
    raise cls(e, response=response, explanation=explanation) from e
docker.errors.APIError: 400 Client Error for http+docker://localhost/v1.50/containers/create: Bad Request ("invalid mount config for type "bind": bind source path does not exist: /mnt/data/ProyectoSmart/ProyectoSmartMed")
[2025-06-27T04:21:04.071+0000] {taskinstance.py:1225} INFO - Marking task as UP_FOR_RETRY. dag_id=STG4_MEDIDORES, task_id=run_hop_pipeline, run_id=scheduled__2025-06-27T03:21:00+00:00, execution_date=20250627T032100, start_date=20250627T042103, end_date=20250627T042104
[2025-06-27T04:21:04.105+0000] {taskinstance.py:340} INFO - ::group::Post task execution logs
[2025-06-27T04:21:04.106+0000] {standard_task_runner.py:124} ERROR - Failed to execute job 8 for task run_hop_pipeline (400 Client Error for http+docker://localhost/v1.50/containers/create: Bad Request ("invalid mount config for type "bind": bind source path does not exist: /mnt/data/ProyectoSmart/ProyectoSmartMed"); 179)
Traceback (most recent call last):
  File "/home/airflow/.local/lib/python3.12/site-packages/docker/api/client.py", line 275, in _raise_for_status
    response.raise_for_status()
  File "/home/airflow/.local/lib/python3.12/site-packages/requests/models.py", line 1024, in raise_for_status
    raise HTTPError(http_error_msg, response=self)
requests.exceptions.HTTPError: 400 Client Error: Bad Request for url: http+docker://localhost/v1.50/containers/create

The above exception was the direct cause of the following exception:

Traceback (most recent call last):
  File "/home/airflow/.local/lib/python3.12/site-packages/airflow/task/task_runner/standard_task_runner.py", line 117, in _start_by_fork
    ret = args.func(args, dag=self.dag)
          ^^^^^^^^^^^^^^^^^^^^^^^^^^^^^
  File "/home/airflow/.local/lib/python3.12/site-packages/airflow/cli/cli_config.py", line 49, in command
    return func(*args, **kwargs)
           ^^^^^^^^^^^^^^^^^^^^^
  File "/home/airflow/.local/lib/python3.12/site-packages/airflow/utils/cli.py", line 115, in wrapper
    return f(*args, **kwargs)
           ^^^^^^^^^^^^^^^^^^
  File "/home/airflow/.local/lib/python3.12/site-packages/airflow/cli/commands/task_command.py", line 483, in task_run
    task_return_code = _run_task_by_selected_method(args, _dag, ti)
                       ^^^^^^^^^^^^^^^^^^^^^^^^^^^^^^^^^^^^^^^^^^^^
  File "/home/airflow/.local/lib/python3.12/site-packages/airflow/cli/commands/task_command.py", line 256, in _run_task_by_selected_method
    return _run_raw_task(args, ti)
           ^^^^^^^^^^^^^^^^^^^^^^^
  File "/home/airflow/.local/lib/python3.12/site-packages/airflow/cli/commands/task_command.py", line 341, in _run_raw_task
    return ti._run_raw_task(
           ^^^^^^^^^^^^^^^^^
  File "/home/airflow/.local/lib/python3.12/site-packages/airflow/utils/session.py", line 97, in wrapper
    return func(*args, session=session, **kwargs)
           ^^^^^^^^^^^^^^^^^^^^^^^^^^^^^^^^^^^^^^
  File "/home/airflow/.local/lib/python3.12/site-packages/airflow/models/taskinstance.py", line 3004, in _run_raw_task
    return _run_raw_task(
           ^^^^^^^^^^^^^^
  File "/home/airflow/.local/lib/python3.12/site-packages/airflow/models/taskinstance.py", line 273, in _run_raw_task
    TaskInstance._execute_task_with_callbacks(
  File "/home/airflow/.local/lib/python3.12/site-packages/airflow/models/taskinstance.py", line 3158, in _execute_task_with_callbacks
    result = self._execute_task(context, task_orig)
             ^^^^^^^^^^^^^^^^^^^^^^^^^^^^^^^^^^^^^^
  File "/home/airflow/.local/lib/python3.12/site-packages/airflow/models/taskinstance.py", line 3182, in _execute_task
    return _execute_task(self, context, task_orig)
           ^^^^^^^^^^^^^^^^^^^^^^^^^^^^^^^^^^^^^^^
  File "/home/airflow/.local/lib/python3.12/site-packages/airflow/models/taskinstance.py", line 767, in _execute_task
    result = _execute_callable(context=context, **execute_callable_kwargs)
             ^^^^^^^^^^^^^^^^^^^^^^^^^^^^^^^^^^^^^^^^^^^^^^^^^^^^^^^^^^^^^
  File "/home/airflow/.local/lib/python3.12/site-packages/airflow/models/taskinstance.py", line 733, in _execute_callable
    return ExecutionCallableRunner(
           ^^^^^^^^^^^^^^^^^^^^^^^^
  File "/home/airflow/.local/lib/python3.12/site-packages/airflow/utils/operator_helpers.py", line 252, in run
    return self.func(*args, **kwargs)
           ^^^^^^^^^^^^^^^^^^^^^^^^^^
  File "/home/airflow/.local/lib/python3.12/site-packages/airflow/models/baseoperator.py", line 406, in wrapper
    return func(self, *args, **kwargs)
           ^^^^^^^^^^^^^^^^^^^^^^^^^^^
  File "/home/airflow/.local/lib/python3.12/site-packages/airflow/providers/docker/operators/docker.py", line 513, in execute
    return self._run_image()
           ^^^^^^^^^^^^^^^^^
  File "/home/airflow/.local/lib/python3.12/site-packages/airflow/providers/docker/operators/docker.py", line 372, in _run_image
    return self._run_image_with_mounts([*self.mounts, tmp_mount], add_tmp_variable=True)
           ^^^^^^^^^^^^^^^^^^^^^^^^^^^^^^^^^^^^^^^^^^^^^^^^^^^^^^^^^^^^^^^^^^^^^^^^^^^^^
  File "/home/airflow/.local/lib/python3.12/site-packages/airflow/providers/docker/operators/docker.py", line 399, in _run_image_with_mounts
    self.container = self.cli.create_container(
                     ^^^^^^^^^^^^^^^^^^^^^^^^^^
  File "/home/airflow/.local/lib/python3.12/site-packages/docker/api/container.py", line 440, in create_container
    return self.create_container_from_config(config, name, platform)
           ^^^^^^^^^^^^^^^^^^^^^^^^^^^^^^^^^^^^^^^^^^^^^^^^^^^^^^^^^
  File "/home/airflow/.local/lib/python3.12/site-packages/docker/api/container.py", line 457, in create_container_from_config
    return self._result(res, True)
           ^^^^^^^^^^^^^^^^^^^^^^^
  File "/home/airflow/.local/lib/python3.12/site-packages/docker/api/client.py", line 281, in _result
    self._raise_for_status(response)
  File "/home/airflow/.local/lib/python3.12/site-packages/docker/api/client.py", line 277, in _raise_for_status
    raise create_api_error_from_http_exception(e) from e
          ^^^^^^^^^^^^^^^^^^^^^^^^^^^^^^^^^^^^^^^
  File "/home/airflow/.local/lib/python3.12/site-packages/docker/errors.py", line 39, in create_api_error_from_http_exception
    raise cls(e, response=response, explanation=explanation) from e
docker.errors.APIError: 400 Client Error for http+docker://localhost/v1.50/containers/create: Bad Request ("invalid mount config for type "bind": bind source path does not exist: /mnt/data/ProyectoSmart/ProyectoSmartMed")
[2025-06-27T04:21:04.193+0000] {local_task_job_runner.py:266} INFO - Task exited with return code 1
[2025-06-27T04:21:04.224+0000] {taskinstance.py:3900} INFO - 0 downstream tasks scheduled from follow-on schedule check
[2025-06-27T04:21:04.227+0000] {local_task_job_runner.py:245} INFO - ::endgroup::
[2025-06-27T04:48:28.217+0000] {local_task_job_runner.py:123} INFO - ::group::Pre task execution logs
[2025-06-27T04:48:28.263+0000] {taskinstance.py:2612} INFO - Dependencies all met for dep_context=non-requeueable deps ti=<TaskInstance: STG4_MEDIDORES.run_hop_pipeline scheduled__2025-06-27T03:21:00+00:00 [queued]>
[2025-06-27T04:48:28.296+0000] {taskinstance.py:2612} INFO - Dependencies all met for dep_context=requeueable deps ti=<TaskInstance: STG4_MEDIDORES.run_hop_pipeline scheduled__2025-06-27T03:21:00+00:00 [queued]>
[2025-06-27T04:48:28.298+0000] {taskinstance.py:2865} INFO - Starting attempt 1 of 2
[2025-06-27T04:48:28.371+0000] {taskinstance.py:2888} INFO - Executing <Task(DockerOperator): run_hop_pipeline> on 2025-06-27 03:21:00+00:00
[2025-06-27T04:48:28.401+0000] {warnings.py:112} WARNING - /home/***/.local/lib/python3.12/site-packages/***/task/task_runner/standard_task_runner.py:70: DeprecationWarning: This process (pid=64) is multi-threaded, use of fork() may lead to deadlocks in the child.
  pid = os.fork()

[2025-06-27T04:48:28.407+0000] {standard_task_runner.py:72} INFO - Started process 72 to run task
[2025-06-27T04:48:28.416+0000] {standard_task_runner.py:104} INFO - Running: ['***', 'tasks', 'run', 'STG4_MEDIDORES', 'run_hop_pipeline', 'scheduled__2025-06-27T03:21:00+00:00', '--job-id', '5', '--raw', '--subdir', 'DAGS_FOLDER/apache-hop-dag-simple.py', '--cfg-path', '/tmp/tmp5370qwz6']
[2025-06-27T04:48:28.425+0000] {standard_task_runner.py:105} INFO - Job 5: Subtask run_hop_pipeline
[2025-06-27T04:48:28.637+0000] {task_command.py:467} INFO - Running <TaskInstance: STG4_MEDIDORES.run_hop_pipeline scheduled__2025-06-27T03:21:00+00:00 [running]> on host 11460eb2799d
[2025-06-27T04:48:28.921+0000] {taskinstance.py:3131} INFO - Exporting env vars: AIRFLOW_CTX_DAG_OWNER='***' AIRFLOW_CTX_DAG_ID='STG4_MEDIDORES' AIRFLOW_CTX_TASK_ID='run_hop_pipeline' AIRFLOW_CTX_EXECUTION_DATE='2025-06-27T03:21:00+00:00' AIRFLOW_CTX_TRY_NUMBER='1' AIRFLOW_CTX_DAG_RUN_ID='scheduled__2025-06-27T03:21:00+00:00'
[2025-06-27T04:48:28.924+0000] {taskinstance.py:731} INFO - ::endgroup::
[2025-06-27T04:48:29.347+0000] {docker.py:367} INFO - Starting docker container from image apache/hop:latest
[2025-06-27T04:48:29.380+0000] {taskinstance.py:3310} ERROR - Task failed with exception
Traceback (most recent call last):
  File "/home/airflow/.local/lib/python3.12/site-packages/docker/api/client.py", line 275, in _raise_for_status
    response.raise_for_status()
  File "/home/airflow/.local/lib/python3.12/site-packages/requests/models.py", line 1024, in raise_for_status
    raise HTTPError(http_error_msg, response=self)
requests.exceptions.HTTPError: 400 Client Error: Bad Request for url: http+docker://localhost/v1.50/containers/create

The above exception was the direct cause of the following exception:

Traceback (most recent call last):
  File "/home/airflow/.local/lib/python3.12/site-packages/airflow/models/taskinstance.py", line 767, in _execute_task
    result = _execute_callable(context=context, **execute_callable_kwargs)
             ^^^^^^^^^^^^^^^^^^^^^^^^^^^^^^^^^^^^^^^^^^^^^^^^^^^^^^^^^^^^^
  File "/home/airflow/.local/lib/python3.12/site-packages/airflow/models/taskinstance.py", line 733, in _execute_callable
    return ExecutionCallableRunner(
           ^^^^^^^^^^^^^^^^^^^^^^^^
  File "/home/airflow/.local/lib/python3.12/site-packages/airflow/utils/operator_helpers.py", line 252, in run
    return self.func(*args, **kwargs)
           ^^^^^^^^^^^^^^^^^^^^^^^^^^
  File "/home/airflow/.local/lib/python3.12/site-packages/airflow/models/baseoperator.py", line 406, in wrapper
    return func(self, *args, **kwargs)
           ^^^^^^^^^^^^^^^^^^^^^^^^^^^
  File "/home/airflow/.local/lib/python3.12/site-packages/airflow/providers/docker/operators/docker.py", line 513, in execute
    return self._run_image()
           ^^^^^^^^^^^^^^^^^
  File "/home/airflow/.local/lib/python3.12/site-packages/airflow/providers/docker/operators/docker.py", line 372, in _run_image
    return self._run_image_with_mounts([*self.mounts, tmp_mount], add_tmp_variable=True)
           ^^^^^^^^^^^^^^^^^^^^^^^^^^^^^^^^^^^^^^^^^^^^^^^^^^^^^^^^^^^^^^^^^^^^^^^^^^^^^
  File "/home/airflow/.local/lib/python3.12/site-packages/airflow/providers/docker/operators/docker.py", line 399, in _run_image_with_mounts
    self.container = self.cli.create_container(
                     ^^^^^^^^^^^^^^^^^^^^^^^^^^
  File "/home/airflow/.local/lib/python3.12/site-packages/docker/api/container.py", line 440, in create_container
    return self.create_container_from_config(config, name, platform)
           ^^^^^^^^^^^^^^^^^^^^^^^^^^^^^^^^^^^^^^^^^^^^^^^^^^^^^^^^^
  File "/home/airflow/.local/lib/python3.12/site-packages/docker/api/container.py", line 457, in create_container_from_config
    return self._result(res, True)
           ^^^^^^^^^^^^^^^^^^^^^^^
  File "/home/airflow/.local/lib/python3.12/site-packages/docker/api/client.py", line 281, in _result
    self._raise_for_status(response)
  File "/home/airflow/.local/lib/python3.12/site-packages/docker/api/client.py", line 277, in _raise_for_status
    raise create_api_error_from_http_exception(e) from e
          ^^^^^^^^^^^^^^^^^^^^^^^^^^^^^^^^^^^^^^^
  File "/home/airflow/.local/lib/python3.12/site-packages/docker/errors.py", line 39, in create_api_error_from_http_exception
    raise cls(e, response=response, explanation=explanation) from e
docker.errors.APIError: 400 Client Error for http+docker://localhost/v1.50/containers/create: Bad Request ("invalid mount config for type "bind": bind source path does not exist: /mnt/data/ProyectoSmart/ProyectoSmartMed")
[2025-06-27T04:48:29.447+0000] {taskinstance.py:1225} INFO - Marking task as UP_FOR_RETRY. dag_id=STG4_MEDIDORES, task_id=run_hop_pipeline, run_id=scheduled__2025-06-27T03:21:00+00:00, execution_date=20250627T032100, start_date=20250627T044828, end_date=20250627T044829
[2025-06-27T04:48:29.491+0000] {taskinstance.py:340} INFO - ::group::Post task execution logs
[2025-06-27T04:48:29.492+0000] {standard_task_runner.py:124} ERROR - Failed to execute job 5 for task run_hop_pipeline (400 Client Error for http+docker://localhost/v1.50/containers/create: Bad Request ("invalid mount config for type "bind": bind source path does not exist: /mnt/data/ProyectoSmart/ProyectoSmartMed"); 72)
Traceback (most recent call last):
  File "/home/airflow/.local/lib/python3.12/site-packages/docker/api/client.py", line 275, in _raise_for_status
    response.raise_for_status()
  File "/home/airflow/.local/lib/python3.12/site-packages/requests/models.py", line 1024, in raise_for_status
    raise HTTPError(http_error_msg, response=self)
requests.exceptions.HTTPError: 400 Client Error: Bad Request for url: http+docker://localhost/v1.50/containers/create

The above exception was the direct cause of the following exception:

Traceback (most recent call last):
  File "/home/airflow/.local/lib/python3.12/site-packages/airflow/task/task_runner/standard_task_runner.py", line 117, in _start_by_fork
    ret = args.func(args, dag=self.dag)
          ^^^^^^^^^^^^^^^^^^^^^^^^^^^^^
  File "/home/airflow/.local/lib/python3.12/site-packages/airflow/cli/cli_config.py", line 49, in command
    return func(*args, **kwargs)
           ^^^^^^^^^^^^^^^^^^^^^
  File "/home/airflow/.local/lib/python3.12/site-packages/airflow/utils/cli.py", line 115, in wrapper
    return f(*args, **kwargs)
           ^^^^^^^^^^^^^^^^^^
  File "/home/airflow/.local/lib/python3.12/site-packages/airflow/cli/commands/task_command.py", line 483, in task_run
    task_return_code = _run_task_by_selected_method(args, _dag, ti)
                       ^^^^^^^^^^^^^^^^^^^^^^^^^^^^^^^^^^^^^^^^^^^^
  File "/home/airflow/.local/lib/python3.12/site-packages/airflow/cli/commands/task_command.py", line 256, in _run_task_by_selected_method
    return _run_raw_task(args, ti)
           ^^^^^^^^^^^^^^^^^^^^^^^
  File "/home/airflow/.local/lib/python3.12/site-packages/airflow/cli/commands/task_command.py", line 341, in _run_raw_task
    return ti._run_raw_task(
           ^^^^^^^^^^^^^^^^^
  File "/home/airflow/.local/lib/python3.12/site-packages/airflow/utils/session.py", line 97, in wrapper
    return func(*args, session=session, **kwargs)
           ^^^^^^^^^^^^^^^^^^^^^^^^^^^^^^^^^^^^^^
  File "/home/airflow/.local/lib/python3.12/site-packages/airflow/models/taskinstance.py", line 3004, in _run_raw_task
    return _run_raw_task(
           ^^^^^^^^^^^^^^
  File "/home/airflow/.local/lib/python3.12/site-packages/airflow/models/taskinstance.py", line 273, in _run_raw_task
    TaskInstance._execute_task_with_callbacks(
  File "/home/airflow/.local/lib/python3.12/site-packages/airflow/models/taskinstance.py", line 3158, in _execute_task_with_callbacks
    result = self._execute_task(context, task_orig)
             ^^^^^^^^^^^^^^^^^^^^^^^^^^^^^^^^^^^^^^
  File "/home/airflow/.local/lib/python3.12/site-packages/airflow/models/taskinstance.py", line 3182, in _execute_task
    return _execute_task(self, context, task_orig)
           ^^^^^^^^^^^^^^^^^^^^^^^^^^^^^^^^^^^^^^^
  File "/home/airflow/.local/lib/python3.12/site-packages/airflow/models/taskinstance.py", line 767, in _execute_task
    result = _execute_callable(context=context, **execute_callable_kwargs)
             ^^^^^^^^^^^^^^^^^^^^^^^^^^^^^^^^^^^^^^^^^^^^^^^^^^^^^^^^^^^^^
  File "/home/airflow/.local/lib/python3.12/site-packages/airflow/models/taskinstance.py", line 733, in _execute_callable
    return ExecutionCallableRunner(
           ^^^^^^^^^^^^^^^^^^^^^^^^
  File "/home/airflow/.local/lib/python3.12/site-packages/airflow/utils/operator_helpers.py", line 252, in run
    return self.func(*args, **kwargs)
           ^^^^^^^^^^^^^^^^^^^^^^^^^^
  File "/home/airflow/.local/lib/python3.12/site-packages/airflow/models/baseoperator.py", line 406, in wrapper
    return func(self, *args, **kwargs)
           ^^^^^^^^^^^^^^^^^^^^^^^^^^^
  File "/home/airflow/.local/lib/python3.12/site-packages/airflow/providers/docker/operators/docker.py", line 513, in execute
    return self._run_image()
           ^^^^^^^^^^^^^^^^^
  File "/home/airflow/.local/lib/python3.12/site-packages/airflow/providers/docker/operators/docker.py", line 372, in _run_image
    return self._run_image_with_mounts([*self.mounts, tmp_mount], add_tmp_variable=True)
           ^^^^^^^^^^^^^^^^^^^^^^^^^^^^^^^^^^^^^^^^^^^^^^^^^^^^^^^^^^^^^^^^^^^^^^^^^^^^^
  File "/home/airflow/.local/lib/python3.12/site-packages/airflow/providers/docker/operators/docker.py", line 399, in _run_image_with_mounts
    self.container = self.cli.create_container(
                     ^^^^^^^^^^^^^^^^^^^^^^^^^^
  File "/home/airflow/.local/lib/python3.12/site-packages/docker/api/container.py", line 440, in create_container
    return self.create_container_from_config(config, name, platform)
           ^^^^^^^^^^^^^^^^^^^^^^^^^^^^^^^^^^^^^^^^^^^^^^^^^^^^^^^^^
  File "/home/airflow/.local/lib/python3.12/site-packages/docker/api/container.py", line 457, in create_container_from_config
    return self._result(res, True)
           ^^^^^^^^^^^^^^^^^^^^^^^
  File "/home/airflow/.local/lib/python3.12/site-packages/docker/api/client.py", line 281, in _result
    self._raise_for_status(response)
  File "/home/airflow/.local/lib/python3.12/site-packages/docker/api/client.py", line 277, in _raise_for_status
    raise create_api_error_from_http_exception(e) from e
          ^^^^^^^^^^^^^^^^^^^^^^^^^^^^^^^^^^^^^^^
  File "/home/airflow/.local/lib/python3.12/site-packages/docker/errors.py", line 39, in create_api_error_from_http_exception
    raise cls(e, response=response, explanation=explanation) from e
docker.errors.APIError: 400 Client Error for http+docker://localhost/v1.50/containers/create: Bad Request ("invalid mount config for type "bind": bind source path does not exist: /mnt/data/ProyectoSmart/ProyectoSmartMed")
[2025-06-27T04:48:29.561+0000] {local_task_job_runner.py:266} INFO - Task exited with return code 1
[2025-06-27T04:48:29.655+0000] {taskinstance.py:3900} INFO - 0 downstream tasks scheduled from follow-on schedule check
[2025-06-27T04:48:29.681+0000] {local_task_job_runner.py:245} INFO - ::endgroup::
[2025-06-27T04:59:17.298+0000] {local_task_job_runner.py:120} INFO - ::group::Pre task execution logs
[2025-06-27T04:59:17.358+0000] {taskinstance.py:2076} INFO - Dependencies all met for dep_context=non-requeueable deps ti=<TaskInstance: STG4_MEDIDORES.run_hop_pipeline scheduled__2025-06-27T03:21:00+00:00 [queued]>
[2025-06-27T04:59:17.376+0000] {taskinstance.py:2076} INFO - Dependencies all met for dep_context=requeueable deps ti=<TaskInstance: STG4_MEDIDORES.run_hop_pipeline scheduled__2025-06-27T03:21:00+00:00 [queued]>
[2025-06-27T04:59:17.377+0000] {taskinstance.py:2306} INFO - Starting attempt 1 of 2
[2025-06-27T04:59:17.409+0000] {taskinstance.py:2330} INFO - Executing <Task(DockerOperator): run_hop_pipeline> on 2025-06-27 03:21:00+00:00
[2025-06-27T04:59:17.424+0000] {warnings.py:110} WARNING - /home/***/.local/lib/python3.12/site-packages/***/task/task_runner/standard_task_runner.py:61: DeprecationWarning: This process (pid=67) is multi-threaded, use of fork() may lead to deadlocks in the child.
  pid = os.fork()

[2025-06-27T04:59:17.427+0000] {standard_task_runner.py:63} INFO - Started process 71 to run task
[2025-06-27T04:59:17.431+0000] {standard_task_runner.py:90} INFO - Running: ['***', 'tasks', 'run', 'STG4_MEDIDORES', 'run_hop_pipeline', 'scheduled__2025-06-27T03:21:00+00:00', '--job-id', '5', '--raw', '--subdir', 'DAGS_FOLDER/apache-hop-dag-simple.py', '--cfg-path', '/tmp/tmprj72geyo']
[2025-06-27T04:59:17.435+0000] {standard_task_runner.py:91} INFO - Job 5: Subtask run_hop_pipeline
[2025-06-27T04:59:17.623+0000] {task_command.py:426} INFO - Running <TaskInstance: STG4_MEDIDORES.run_hop_pipeline scheduled__2025-06-27T03:21:00+00:00 [running]> on host 4c575de26931
[2025-06-27T04:59:17.854+0000] {taskinstance.py:2648} INFO - Exporting env vars: AIRFLOW_CTX_DAG_OWNER='***' AIRFLOW_CTX_DAG_ID='STG4_MEDIDORES' AIRFLOW_CTX_TASK_ID='run_hop_pipeline' AIRFLOW_CTX_EXECUTION_DATE='2025-06-27T03:21:00+00:00' AIRFLOW_CTX_TRY_NUMBER='1' AIRFLOW_CTX_DAG_RUN_ID='scheduled__2025-06-27T03:21:00+00:00'
[2025-06-27T04:59:17.855+0000] {taskinstance.py:430} INFO - ::endgroup::
[2025-06-27T04:59:18.137+0000] {docker.py:366} INFO - Starting docker container from image apache/hop:latest
[2025-06-27T04:59:18.174+0000] {taskinstance.py:441} INFO - ::group::Post task execution logs
[2025-06-27T04:59:18.177+0000] {taskinstance.py:2905} ERROR - Task failed with exception
Traceback (most recent call last):
  File "/home/airflow/.local/lib/python3.12/site-packages/docker/api/client.py", line 265, in _raise_for_status
    response.raise_for_status()
  File "/home/airflow/.local/lib/python3.12/site-packages/requests/models.py", line 1021, in raise_for_status
    raise HTTPError(http_error_msg, response=self)
requests.exceptions.HTTPError: 400 Client Error: Bad Request for url: http+docker://localhost/v1.50/containers/create

The above exception was the direct cause of the following exception:

Traceback (most recent call last):
  File "/home/airflow/.local/lib/python3.12/site-packages/airflow/models/taskinstance.py", line 465, in _execute_task
    result = _execute_callable(context=context, **execute_callable_kwargs)
             ^^^^^^^^^^^^^^^^^^^^^^^^^^^^^^^^^^^^^^^^^^^^^^^^^^^^^^^^^^^^^
  File "/home/airflow/.local/lib/python3.12/site-packages/airflow/models/taskinstance.py", line 432, in _execute_callable
    return execute_callable(context=context, **execute_callable_kwargs)
           ^^^^^^^^^^^^^^^^^^^^^^^^^^^^^^^^^^^^^^^^^^^^^^^^^^^^^^^^^^^^
  File "/home/airflow/.local/lib/python3.12/site-packages/airflow/models/baseoperator.py", line 400, in wrapper
    return func(self, *args, **kwargs)
           ^^^^^^^^^^^^^^^^^^^^^^^^^^^
  File "/home/airflow/.local/lib/python3.12/site-packages/airflow/providers/docker/operators/docker.py", line 509, in execute
    return self._run_image()
           ^^^^^^^^^^^^^^^^^
  File "/home/airflow/.local/lib/python3.12/site-packages/airflow/providers/docker/operators/docker.py", line 371, in _run_image
    return self._run_image_with_mounts([*self.mounts, tmp_mount], add_tmp_variable=True)
           ^^^^^^^^^^^^^^^^^^^^^^^^^^^^^^^^^^^^^^^^^^^^^^^^^^^^^^^^^^^^^^^^^^^^^^^^^^^^^
  File "/home/airflow/.local/lib/python3.12/site-packages/airflow/providers/docker/operators/docker.py", line 398, in _run_image_with_mounts
    self.container = self.cli.create_container(
                     ^^^^^^^^^^^^^^^^^^^^^^^^^^
  File "/home/airflow/.local/lib/python3.12/site-packages/docker/api/container.py", line 439, in create_container
    return self.create_container_from_config(config, name, platform)
           ^^^^^^^^^^^^^^^^^^^^^^^^^^^^^^^^^^^^^^^^^^^^^^^^^^^^^^^^^
  File "/home/airflow/.local/lib/python3.12/site-packages/docker/api/container.py", line 456, in create_container_from_config
    return self._result(res, True)
           ^^^^^^^^^^^^^^^^^^^^^^^
  File "/home/airflow/.local/lib/python3.12/site-packages/docker/api/client.py", line 271, in _result
    self._raise_for_status(response)
  File "/home/airflow/.local/lib/python3.12/site-packages/docker/api/client.py", line 267, in _raise_for_status
    raise create_api_error_from_http_exception(e) from e
          ^^^^^^^^^^^^^^^^^^^^^^^^^^^^^^^^^^^^^^^
  File "/home/airflow/.local/lib/python3.12/site-packages/docker/errors.py", line 39, in create_api_error_from_http_exception
    raise cls(e, response=response, explanation=explanation) from e
docker.errors.APIError: 400 Client Error for http+docker://localhost/v1.50/containers/create: Bad Request ("invalid mount config for type "bind": bind source path does not exist: /mnt/data/ProyectoSmart/ProyectoSmartMed")
[2025-06-27T04:59:18.212+0000] {taskinstance.py:1206} INFO - Marking task as UP_FOR_RETRY. dag_id=STG4_MEDIDORES, task_id=run_hop_pipeline, run_id=scheduled__2025-06-27T03:21:00+00:00, execution_date=20250627T032100, start_date=20250627T045917, end_date=20250627T045918
[2025-06-27T04:59:18.253+0000] {standard_task_runner.py:110} ERROR - Failed to execute job 5 for task run_hop_pipeline (400 Client Error for http+docker://localhost/v1.50/containers/create: Bad Request ("invalid mount config for type "bind": bind source path does not exist: /mnt/data/ProyectoSmart/ProyectoSmartMed"); 71)
[2025-06-27T04:59:18.315+0000] {local_task_job_runner.py:240} INFO - Task exited with return code 1
[2025-06-27T04:59:18.343+0000] {local_task_job_runner.py:222} INFO - ::endgroup::
