[2025-06-27T05:11:22.698+0000] {local_task_job_runner.py:120} INFO - ::group::Pre task execution logs
[2025-06-27T05:11:22.725+0000] {taskinstance.py:2076} INFO - Dependencies all met for dep_context=non-requeueable deps ti=<TaskInstance: WF_INCIDENCIAS.run_hop_pipeline manual__2025-06-27T05:06:19.260487+00:00 [queued]>
[2025-06-27T05:11:22.734+0000] {taskinstance.py:2076} INFO - Dependencies all met for dep_context=requeueable deps ti=<TaskInstance: WF_INCIDENCIAS.run_hop_pipeline manual__2025-06-27T05:06:19.260487+00:00 [queued]>
[2025-06-27T05:11:22.735+0000] {taskinstance.py:2306} INFO - Starting attempt 2 of 2
[2025-06-27T05:11:22.751+0000] {taskinstance.py:2330} INFO - Executing <Task(DockerOperator): run_hop_pipeline> on 2025-06-27 05:06:19.260487+00:00
[2025-06-27T05:11:22.758+0000] {warnings.py:110} WARNING - /home/***/.local/lib/python3.12/site-packages/***/task/task_runner/standard_task_runner.py:61: DeprecationWarning: This process (pid=241) is multi-threaded, use of fork() may lead to deadlocks in the child.
  pid = os.fork()

[2025-06-27T05:11:22.760+0000] {standard_task_runner.py:63} INFO - Started process 242 to run task
[2025-06-27T05:11:22.760+0000] {standard_task_runner.py:90} INFO - Running: ['***', 'tasks', 'run', 'WF_INCIDENCIAS', 'run_hop_pipeline', 'manual__2025-06-27T05:06:19.260487+00:00', '--job-id', '15', '--raw', '--subdir', 'DAGS_FOLDER/apache-hop-dag-wf-incidencias.py', '--cfg-path', '/tmp/tmpao68xza7']
[2025-06-27T05:11:22.761+0000] {standard_task_runner.py:91} INFO - Job 15: Subtask run_hop_pipeline
[2025-06-27T05:11:22.836+0000] {task_command.py:426} INFO - Running <TaskInstance: WF_INCIDENCIAS.run_hop_pipeline manual__2025-06-27T05:06:19.260487+00:00 [running]> on host 4c575de26931
[2025-06-27T05:11:22.932+0000] {taskinstance.py:2648} INFO - Exporting env vars: AIRFLOW_CTX_DAG_OWNER='***' AIRFLOW_CTX_DAG_ID='WF_INCIDENCIAS' AIRFLOW_CTX_TASK_ID='run_hop_pipeline' AIRFLOW_CTX_EXECUTION_DATE='2025-06-27T05:06:19.260487+00:00' AIRFLOW_CTX_TRY_NUMBER='2' AIRFLOW_CTX_DAG_RUN_ID='manual__2025-06-27T05:06:19.260487+00:00'
[2025-06-27T05:11:22.934+0000] {taskinstance.py:430} INFO - ::endgroup::
[2025-06-27T05:11:23.017+0000] {docker.py:366} INFO - Starting docker container from image apache/hop:latest
[2025-06-27T05:11:23.028+0000] {taskinstance.py:441} INFO - ::group::Post task execution logs
[2025-06-27T05:11:23.028+0000] {taskinstance.py:2905} ERROR - Task failed with exception
Traceback (most recent call last):
  File "/home/airflow/.local/lib/python3.12/site-packages/docker/api/client.py", line 265, in _raise_for_status
    response.raise_for_status()
  File "/home/airflow/.local/lib/python3.12/site-packages/requests/models.py", line 1021, in raise_for_status
    raise HTTPError(http_error_msg, response=self)
requests.exceptions.HTTPError: 400 Client Error: Bad Request for url: http+docker://localhost/v1.50/containers/create

The above exception was the direct cause of the following exception:

Traceback (most recent call last):
  File "/home/airflow/.local/lib/python3.12/site-packages/airflow/models/taskinstance.py", line 465, in _execute_task
    result = _execute_callable(context=context, **execute_callable_kwargs)
             ^^^^^^^^^^^^^^^^^^^^^^^^^^^^^^^^^^^^^^^^^^^^^^^^^^^^^^^^^^^^^
  File "/home/airflow/.local/lib/python3.12/site-packages/airflow/models/taskinstance.py", line 432, in _execute_callable
    return execute_callable(context=context, **execute_callable_kwargs)
           ^^^^^^^^^^^^^^^^^^^^^^^^^^^^^^^^^^^^^^^^^^^^^^^^^^^^^^^^^^^^
  File "/home/airflow/.local/lib/python3.12/site-packages/airflow/models/baseoperator.py", line 400, in wrapper
    return func(self, *args, **kwargs)
           ^^^^^^^^^^^^^^^^^^^^^^^^^^^
  File "/home/airflow/.local/lib/python3.12/site-packages/airflow/providers/docker/operators/docker.py", line 509, in execute
    return self._run_image()
           ^^^^^^^^^^^^^^^^^
  File "/home/airflow/.local/lib/python3.12/site-packages/airflow/providers/docker/operators/docker.py", line 371, in _run_image
    return self._run_image_with_mounts([*self.mounts, tmp_mount], add_tmp_variable=True)
           ^^^^^^^^^^^^^^^^^^^^^^^^^^^^^^^^^^^^^^^^^^^^^^^^^^^^^^^^^^^^^^^^^^^^^^^^^^^^^
  File "/home/airflow/.local/lib/python3.12/site-packages/airflow/providers/docker/operators/docker.py", line 398, in _run_image_with_mounts
    self.container = self.cli.create_container(
                     ^^^^^^^^^^^^^^^^^^^^^^^^^^
  File "/home/airflow/.local/lib/python3.12/site-packages/docker/api/container.py", line 439, in create_container
    return self.create_container_from_config(config, name, platform)
           ^^^^^^^^^^^^^^^^^^^^^^^^^^^^^^^^^^^^^^^^^^^^^^^^^^^^^^^^^
  File "/home/airflow/.local/lib/python3.12/site-packages/docker/api/container.py", line 456, in create_container_from_config
    return self._result(res, True)
           ^^^^^^^^^^^^^^^^^^^^^^^
  File "/home/airflow/.local/lib/python3.12/site-packages/docker/api/client.py", line 271, in _result
    self._raise_for_status(response)
  File "/home/airflow/.local/lib/python3.12/site-packages/docker/api/client.py", line 267, in _raise_for_status
    raise create_api_error_from_http_exception(e) from e
          ^^^^^^^^^^^^^^^^^^^^^^^^^^^^^^^^^^^^^^^
  File "/home/airflow/.local/lib/python3.12/site-packages/docker/errors.py", line 39, in create_api_error_from_http_exception
    raise cls(e, response=response, explanation=explanation) from e
docker.errors.APIError: 400 Client Error for http+docker://localhost/v1.50/containers/create: Bad Request ("invalid mount config for type "bind": bind source path does not exist: /mnt/data/ProyectoSmart/ProyectoSmartMed")
[2025-06-27T05:11:23.040+0000] {taskinstance.py:1206} INFO - Marking task as FAILED. dag_id=WF_INCIDENCIAS, task_id=run_hop_pipeline, run_id=manual__2025-06-27T05:06:19.260487+00:00, execution_date=20250627T050619, start_date=20250627T051122, end_date=20250627T051123
[2025-06-27T05:11:23.054+0000] {standard_task_runner.py:110} ERROR - Failed to execute job 15 for task run_hop_pipeline (400 Client Error for http+docker://localhost/v1.50/containers/create: Bad Request ("invalid mount config for type "bind": bind source path does not exist: /mnt/data/ProyectoSmart/ProyectoSmartMed"); 242)
[2025-06-27T05:11:23.095+0000] {local_task_job_runner.py:240} INFO - Task exited with return code 1
[2025-06-27T05:11:23.120+0000] {taskinstance.py:3498} INFO - 0 downstream tasks scheduled from follow-on schedule check
[2025-06-27T05:11:23.126+0000] {local_task_job_runner.py:222} INFO - ::endgroup::
