[2025-06-27T01:29:13.377+0000] {local_task_job_runner.py:120} INFO - ::group::Pre task execution logs
[2025-06-27T01:29:13.691+0000] {taskinstance.py:2076} INFO - Dependencies all met for dep_context=non-requeueable deps ti=<TaskInstance: STG4_MEDIDORES.run_hop_pipeline scheduled__2025-06-26T22:21:00+00:00 [queued]>
[2025-06-27T01:29:13.837+0000] {taskinstance.py:2076} INFO - Dependencies all met for dep_context=requeueable deps ti=<TaskInstance: STG4_MEDIDORES.run_hop_pipeline scheduled__2025-06-26T22:21:00+00:00 [queued]>
[2025-06-27T01:29:13.872+0000] {taskinstance.py:2306} INFO - Starting attempt 2 of 2
[2025-06-27T01:29:13.999+0000] {taskinstance.py:2330} INFO - Executing <Task(DockerOperator): run_hop_pipeline> on 2025-06-26 22:21:00+00:00
[2025-06-27T01:29:14.759+0000] {standard_task_runner.py:90} INFO - Running: ['***', 'tasks', 'run', 'STG4_MEDIDORES', 'run_hop_pipeline', 'scheduled__2025-06-26T22:21:00+00:00', '--job-id', '11', '--raw', '--subdir', 'DAGS_FOLDER/apache-hop-dag-simple.py', '--cfg-path', '/tmp/tmpqb8njhd_']
[2025-06-27T01:29:14.791+0000] {standard_task_runner.py:91} INFO - Job 11: Subtask run_hop_pipeline
[2025-06-27T01:29:14.769+0000] {warnings.py:110} WARNING - /home/***/.local/lib/python3.12/site-packages/***/task/task_runner/standard_task_runner.py:61: DeprecationWarning: This process (pid=127) is multi-threaded, use of fork() may lead to deadlocks in the child.
  pid = os.fork()

[2025-06-27T01:29:15.012+0000] {standard_task_runner.py:63} INFO - Started process 132 to run task
[2025-06-27T01:29:22.167+0000] {task_command.py:426} INFO - Running <TaskInstance: STG4_MEDIDORES.run_hop_pipeline scheduled__2025-06-26T22:21:00+00:00 [running]> on host ca79c413dce4
[2025-06-27T01:29:41.427+0000] {taskinstance.py:2648} INFO - Exporting env vars: AIRFLOW_CTX_DAG_OWNER='***' AIRFLOW_CTX_DAG_ID='STG4_MEDIDORES' AIRFLOW_CTX_TASK_ID='run_hop_pipeline' AIRFLOW_CTX_EXECUTION_DATE='2025-06-26T22:21:00+00:00' AIRFLOW_CTX_TRY_NUMBER='2' AIRFLOW_CTX_DAG_RUN_ID='scheduled__2025-06-26T22:21:00+00:00'
[2025-06-27T01:29:41.432+0000] {taskinstance.py:430} INFO - ::endgroup::
[2025-06-27T01:29:46.496+0000] {docker.py:493} INFO - Pulling docker image apache/hop:latest
[2025-06-27T01:30:07.651+0000] {docker.py:507} INFO - latest: Pulling from apache/hop
[2025-06-27T01:30:14.569+0000] {docker.py:507} INFO - 4f4fb700ef54: Pulling fs layer
[2025-06-27T01:30:14.570+0000] {docker.py:507} INFO - d4d2578e96cd: Pulling fs layer
[2025-06-27T01:30:14.570+0000] {docker.py:507} INFO - f18232174bc9: Pulling fs layer
[2025-06-27T01:30:14.571+0000] {docker.py:507} INFO - f488a4dddc73: Pulling fs layer
[2025-06-27T01:30:14.572+0000] {docker.py:507} INFO - 9b6bc2cf1037: Pulling fs layer
[2025-06-27T01:30:14.572+0000] {docker.py:507} INFO - bf26d906d0f5: Pulling fs layer
[2025-06-27T01:30:14.573+0000] {docker.py:507} INFO - eb2b48b7cabe: Pulling fs layer
[2025-06-27T01:30:14.573+0000] {docker.py:507} INFO - 19f1029c3f10: Pulling fs layer
[2025-06-27T01:30:14.633+0000] {docker.py:507} INFO - 4f4fb700ef54: Already exists
[2025-06-27T01:30:14.639+0000] {docker.py:507} INFO - 4f4fb700ef54: Pull complete
[2025-06-27T01:30:16.594+0000] {docker.py:507} INFO - d4d2578e96cd: Downloading
[2025-06-27T01:30:16.651+0000] {docker.py:507} INFO - 9b6bc2cf1037: Downloading
[2025-06-27T01:30:16.985+0000] {docker.py:507} INFO - f488a4dddc73: Downloading
[2025-06-27T01:30:18.289+0000] {docker.py:507} INFO - 19f1029c3f10: Downloading
[2025-06-27T01:30:18.819+0000] {docker.py:507} INFO - eb2b48b7cabe: Downloading
[2025-06-27T01:30:19.001+0000] {docker.py:507} INFO - f18232174bc9: Downloading
[2025-06-27T01:30:19.056+0000] {docker.py:507} INFO - bf26d906d0f5: Downloading
[2025-06-27T01:30:47.730+0000] {docker.py:507} INFO - 9b6bc2cf1037: Download complete
[2025-06-27T01:30:47.844+0000] {docker.py:507} INFO - d4d2578e96cd: Download complete
[2025-06-27T01:30:53.032+0000] {docker.py:507} INFO - eb2b48b7cabe: Download complete
[2025-06-27T01:30:53.033+0000] {docker.py:507} INFO - bf26d906d0f5: Download complete
[2025-06-27T01:30:53.225+0000] {docker.py:507} INFO - f18232174bc9: Download complete
[2025-06-27T01:30:53.247+0000] {docker.py:507} INFO - f18232174bc9: Extracting
[2025-06-27T01:30:58.987+0000] {docker.py:507} INFO - 19f1029c3f10: Download complete
[2025-06-27T01:31:42.762+0000] {docker.py:507} INFO - f18232174bc9: Pull complete
[2025-06-27T01:31:56.869+0000] {docker.py:507} INFO - d4d2578e96cd: Extracting
[2025-06-27T01:32:04.026+0000] {docker.py:507} INFO - d4d2578e96cd: Pull complete
[2025-06-27T01:32:07.945+0000] {docker.py:507} INFO - 19f1029c3f10: Extracting
[2025-06-27T01:34:39.483+0000] {docker.py:507} INFO - f488a4dddc73: Download complete
[2025-06-27T01:34:45.229+0000] {docker.py:507} INFO - 19f1029c3f10: Pull complete
[2025-06-27T01:34:45.690+0000] {docker.py:507} INFO - bf26d906d0f5: Extracting
[2025-06-27T01:34:46.660+0000] {docker.py:507} INFO - bf26d906d0f5: Pull complete
[2025-06-27T01:34:46.874+0000] {docker.py:507} INFO - f488a4dddc73: Extracting
[2025-06-27T01:36:50.896+0000] {docker.py:507} INFO - f488a4dddc73: Pull complete
[2025-06-27T01:36:51.181+0000] {docker.py:507} INFO - 9b6bc2cf1037: Extracting
[2025-06-27T01:36:51.280+0000] {docker.py:507} INFO - 9b6bc2cf1037: Pull complete
[2025-06-27T01:36:51.383+0000] {docker.py:507} INFO - eb2b48b7cabe: Extracting
[2025-06-27T01:36:51.480+0000] {docker.py:507} INFO - eb2b48b7cabe: Pull complete
[2025-06-27T01:36:51.942+0000] {docker.py:502} INFO - Digest: sha256:950a95da3332a2782706665b58adeed820689d87e0ca5b54df59bc995b2d955e
[2025-06-27T01:36:51.950+0000] {docker.py:502} INFO - Status: Downloaded newer image for apache/hop:latest
[2025-06-27T01:36:52.099+0000] {docker.py:366} INFO - Starting docker container from image apache/hop:latest
[2025-06-27T01:36:52.243+0000] {taskinstance.py:441} INFO - ::group::Post task execution logs
[2025-06-27T01:36:52.253+0000] {taskinstance.py:2905} ERROR - Task failed with exception
Traceback (most recent call last):
  File "/home/airflow/.local/lib/python3.12/site-packages/docker/api/client.py", line 265, in _raise_for_status
    response.raise_for_status()
  File "/home/airflow/.local/lib/python3.12/site-packages/requests/models.py", line 1021, in raise_for_status
    raise HTTPError(http_error_msg, response=self)
requests.exceptions.HTTPError: 500 Server Error: Internal Server Error for url: http+docker://localhost/v1.50/containers/create

The above exception was the direct cause of the following exception:

Traceback (most recent call last):
  File "/home/airflow/.local/lib/python3.12/site-packages/airflow/models/taskinstance.py", line 465, in _execute_task
    result = _execute_callable(context=context, **execute_callable_kwargs)
             ^^^^^^^^^^^^^^^^^^^^^^^^^^^^^^^^^^^^^^^^^^^^^^^^^^^^^^^^^^^^^
  File "/home/airflow/.local/lib/python3.12/site-packages/airflow/models/taskinstance.py", line 432, in _execute_callable
    return execute_callable(context=context, **execute_callable_kwargs)
           ^^^^^^^^^^^^^^^^^^^^^^^^^^^^^^^^^^^^^^^^^^^^^^^^^^^^^^^^^^^^
  File "/home/airflow/.local/lib/python3.12/site-packages/airflow/models/baseoperator.py", line 400, in wrapper
    return func(self, *args, **kwargs)
           ^^^^^^^^^^^^^^^^^^^^^^^^^^^
  File "/home/airflow/.local/lib/python3.12/site-packages/airflow/providers/docker/operators/docker.py", line 509, in execute
    return self._run_image()
           ^^^^^^^^^^^^^^^^^
  File "/home/airflow/.local/lib/python3.12/site-packages/airflow/providers/docker/operators/docker.py", line 371, in _run_image
    return self._run_image_with_mounts([*self.mounts, tmp_mount], add_tmp_variable=True)
           ^^^^^^^^^^^^^^^^^^^^^^^^^^^^^^^^^^^^^^^^^^^^^^^^^^^^^^^^^^^^^^^^^^^^^^^^^^^^^
  File "/home/airflow/.local/lib/python3.12/site-packages/airflow/providers/docker/operators/docker.py", line 398, in _run_image_with_mounts
    self.container = self.cli.create_container(
                     ^^^^^^^^^^^^^^^^^^^^^^^^^^
  File "/home/airflow/.local/lib/python3.12/site-packages/docker/api/container.py", line 439, in create_container
    return self.create_container_from_config(config, name, platform)
           ^^^^^^^^^^^^^^^^^^^^^^^^^^^^^^^^^^^^^^^^^^^^^^^^^^^^^^^^^
  File "/home/airflow/.local/lib/python3.12/site-packages/docker/api/container.py", line 456, in create_container_from_config
    return self._result(res, True)
           ^^^^^^^^^^^^^^^^^^^^^^^
  File "/home/airflow/.local/lib/python3.12/site-packages/docker/api/client.py", line 271, in _result
    self._raise_for_status(response)
  File "/home/airflow/.local/lib/python3.12/site-packages/docker/api/client.py", line 267, in _raise_for_status
    raise create_api_error_from_http_exception(e) from e
          ^^^^^^^^^^^^^^^^^^^^^^^^^^^^^^^^^^^^^^^
  File "/home/airflow/.local/lib/python3.12/site-packages/docker/errors.py", line 39, in create_api_error_from_http_exception
    raise cls(e, response=response, explanation=explanation) from e
docker.errors.APIError: 500 Server Error for http+docker://localhost/v1.50/containers/create: Internal Server Error ("mkdir C:\Users\danie: Access is denied.")
[2025-06-27T01:36:52.430+0000] {taskinstance.py:1206} INFO - Marking task as FAILED. dag_id=STG4_MEDIDORES, task_id=run_hop_pipeline, run_id=scheduled__2025-06-26T22:21:00+00:00, execution_date=20250626T222100, start_date=20250627T012913, end_date=20250627T013652
[2025-06-27T01:36:52.493+0000] {standard_task_runner.py:110} ERROR - Failed to execute job 11 for task run_hop_pipeline (500 Server Error for http+docker://localhost/v1.50/containers/create: Internal Server Error ("mkdir C:\Users\danie: Access is denied."); 132)
[2025-06-27T01:36:52.586+0000] {local_task_job_runner.py:240} INFO - Task exited with return code 1
[2025-06-27T01:36:52.725+0000] {taskinstance.py:3498} INFO - 0 downstream tasks scheduled from follow-on schedule check
[2025-06-27T01:36:52.744+0000] {local_task_job_runner.py:222} INFO - ::endgroup::
