[2025-06-27T06:46:18.198+0000] {local_task_job_runner.py:120} INFO - ::group::Pre task execution logs
[2025-06-27T06:46:18.251+0000] {taskinstance.py:2076} INFO - Dependencies all met for dep_context=non-requeueable deps ti=<TaskInstance: WF_MAIN.run_hop_pipeline scheduled__2025-06-27T05:41:00+00:00 [queued]>
[2025-06-27T06:46:18.281+0000] {taskinstance.py:2076} INFO - Dependencies all met for dep_context=requeueable deps ti=<TaskInstance: WF_MAIN.run_hop_pipeline scheduled__2025-06-27T05:41:00+00:00 [queued]>
[2025-06-27T06:46:18.283+0000] {taskinstance.py:2306} INFO - Starting attempt 1 of 2
[2025-06-27T06:46:18.320+0000] {taskinstance.py:2330} INFO - Executing <Task(DockerOperator): run_hop_pipeline> on 2025-06-27 05:41:00+00:00
[2025-06-27T06:46:18.349+0000] {warnings.py:110} WARNING - /home/***/.local/lib/python3.12/site-packages/***/task/task_runner/standard_task_runner.py:61: DeprecationWarning: This process (pid=64) is multi-threaded, use of fork() may lead to deadlocks in the child.
  pid = os.fork()

[2025-06-27T06:46:18.359+0000] {standard_task_runner.py:63} INFO - Started process 71 to run task
[2025-06-27T06:46:18.371+0000] {standard_task_runner.py:90} INFO - Running: ['***', 'tasks', 'run', 'WF_MAIN', 'run_hop_pipeline', 'scheduled__2025-06-27T05:41:00+00:00', '--job-id', '5', '--raw', '--subdir', 'DAGS_FOLDER/apache-hop-dag-wf-main.py', '--cfg-path', '/tmp/tmp1_z7ulmf']
[2025-06-27T06:46:18.375+0000] {standard_task_runner.py:91} INFO - Job 5: Subtask run_hop_pipeline
[2025-06-27T06:46:18.547+0000] {task_command.py:426} INFO - Running <TaskInstance: WF_MAIN.run_hop_pipeline scheduled__2025-06-27T05:41:00+00:00 [running]> on host eefc0d82eb46
[2025-06-27T06:46:18.813+0000] {taskinstance.py:2648} INFO - Exporting env vars: AIRFLOW_CTX_DAG_OWNER='***' AIRFLOW_CTX_DAG_ID='WF_MAIN' AIRFLOW_CTX_TASK_ID='run_hop_pipeline' AIRFLOW_CTX_EXECUTION_DATE='2025-06-27T05:41:00+00:00' AIRFLOW_CTX_TRY_NUMBER='1' AIRFLOW_CTX_DAG_RUN_ID='scheduled__2025-06-27T05:41:00+00:00'
[2025-06-27T06:46:18.815+0000] {taskinstance.py:430} INFO - ::endgroup::
[2025-06-27T06:46:19.019+0000] {docker.py:366} INFO - Starting docker container from image apache/hop:latest
[2025-06-27T06:46:19.050+0000] {docker.py:374} WARNING - Using remote engine or docker-in-docker and mounting temporary volume from host is not supported. Falling back to `mount_tmp_dir=False` mode. You can set `mount_tmp_dir` parameter to False to disable mounting and remove the warning
[2025-06-27T06:46:20.404+0000] {docker.py:436} INFO - 2025/06/27 06:46:20 - Running the entrypoint script with PID 8
[2025-06-27T06:46:20.405+0000] {docker.py:436} INFO - 2025/06/27 06:46:20 - The project folder for ProyectoSmartMed is set to: /files
[2025-06-27T06:46:20.407+0000] {docker.py:436} INFO - 2025/06/27 06:46:20 - The specified project folder exists
[2025-06-27T06:46:20.411+0000] {docker.py:436} INFO - 2025/06/27 06:46:20 - Registering project ProyectoSmartMed in the Hop container configuration
[2025-06-27T06:46:20.414+0000] {docker.py:436} INFO - 2025/06/27 06:46:20 - /opt/hop/hop-conf.sh --project=ProyectoSmartMed --project-create --project-home='/files' --project-config-file='project-config.json'
[2025-06-27T06:47:24.463+0000] {docker.py:436} INFO - Creating project 'ProyectoSmartMed'
[2025-06-27T06:47:25.096+0000] {docker.py:436} INFO - Project 'ProyectoSmartMed' was created for home folder : /files
[2025-06-27T06:47:25.442+0000] {docker.py:436} INFO - Configuration file for project 'ProyectoSmartMed' was saved to : file:/files/project-config.json
[2025-06-27T06:47:25.706+0000] {docker.py:436} INFO - 2025/06/27 06:47:25 - Not creating an environment in the container
[2025-06-27T06:47:25.708+0000] {docker.py:436} INFO - 2025/06/27 06:47:25 - Running a single hop workflow / pipeline (${PROJECT_HOME}/workflows/WF_MAIN.hwf)
[2025-06-27T06:47:50.005+0000] {docker.py:436} INFO - 2025/06/27 06:47:49 - HopRun - Enabling project 'ProyectoSmartMed'
[2025-06-27T06:47:50.576+0000] {docker.py:436} INFO - 2025/06/27 06:47:50 - HopRun - Starting workflow: /files/workflows/WF_MAIN.hwf
[2025-06-27T06:47:53.993+0000] {docker.py:436} INFO - 2025/06/27 06:47:53 - WF_MAIN - Start of workflow execution
[2025-06-27T06:47:54.171+0000] {docker.py:436} INFO - 2025/06/27 06:47:54 - WF_MAIN - Starting action [filename.hwf]
[2025-06-27T06:47:55.164+0000] {docker.py:436} INFO - 2025/06/27 06:47:55 - filename - Start of workflow execution
[2025-06-27T06:47:55.230+0000] {docker.py:436} INFO - 2025/06/27 06:47:55 - filename - Starting action [prueba.hpl]
[2025-06-27T06:47:55.542+0000] {docker.py:436} INFO - 2025/06/27 06:47:55 - prueba.hpl - Using run configuration [local]
[2025-06-27T06:47:55.632+0000] {docker.py:436} INFO - 2025/06/27 06:47:55 - prueba - Executing this pipeline using the Local Pipeline Engine with run configuration 'local'
[2025-06-27T06:47:55.651+0000] {docker.py:436} INFO - 2025/06/27 06:47:55 - prueba - Execution started for pipeline [prueba]
[2025-06-27T06:48:00.924+0000] {docker.py:436} INFO - 2025/06/27 06:48:00 - Set variables.0 - Setting project variables...
[2025-06-27T06:48:00.931+0000] {docker.py:436} INFO - 2025/06/27 06:48:00 - Set variables.0 - Set variable lastDate to value [2025-06-27 01:20:57]
[2025-06-27T06:48:00.934+0000] {docker.py:436} INFO - 2025/06/27 06:48:00 - Table input.0 - Finished reading query, closing connection.
[2025-06-27T06:48:00.994+0000] {docker.py:436} INFO - 2025/06/27 06:48:00 - Set variables.0 - Finished after 1 rows.
2025/06/27 06:48:00 - Set variables.0 - Finished processing (I=0, O=0, R=1, W=1, U=0, E=0)
[2025-06-27T06:48:01.117+0000] {docker.py:436} INFO - 2025/06/27 06:48:01 - Table input.0 - Finished processing (I=1, O=0, R=0, W=1, U=0, E=0)
[2025-06-27T06:48:14.048+0000] {docker.py:436} INFO - 2025/06/27 06:48:14 - REST client.0 - ERROR: Because of an error, this transform can't continue:
2025/06/27 06:48:14 - REST client.0 - Can not read result from [http://20.0.1.136:8000/api/v1/dags/dagruns]
2025/06/27 06:48:14 - REST client.0 - 
2025/06/27 06:48:14 - REST client.0 - Request could not be processed
2025/06/27 06:48:14 - REST client.0 - org.apache.http.conn.ConnectTimeoutException: Connect to 20.0.1.136:8000 [/20.0.1.136] failed: Connect timed out
[2025-06-27T06:48:14.052+0000] {docker.py:436} INFO - 2025/06/27 06:48:14 - REST client.0 - ERROR: org.apache.hop.core.exception.HopException: 
2025/06/27 06:48:14 - REST client.0 - Can not read result from [http://20.0.1.136:8000/api/v1/dags/dagruns]
2025/06/27 06:48:14 - REST client.0 - 
2025/06/27 06:48:14 - REST client.0 - Request could not be processed
2025/06/27 06:48:14 - REST client.0 - org.apache.http.conn.ConnectTimeoutException: Connect to 20.0.1.136:8000 [/20.0.1.136] failed: Connect timed out
2025/06/27 06:48:14 - REST client.0 - 
2025/06/27 06:48:14 - REST client.0 - 
2025/06/27 06:48:14 - REST client.0 - 	at org.apache.hop.pipeline.transforms.rest.Rest.callRest(Rest.java:321)
2025/06/27 06:48:14 - REST client.0 - 	at org.apache.hop.pipeline.transforms.rest.Rest.processRow(Rest.java:538)
2025/06/27 06:48:14 - REST client.0 - 	at org.apache.hop.pipeline.transform.RunThread.run(RunThread.java:54)
2025/06/27 06:48:14 - REST client.0 - 	at java.base/java.lang.Thread.run(Thread.java:840)
2025/06/27 06:48:14 - REST client.0 - Caused by: org.apache.hop.core.exception.HopException: 
2025/06/27 06:48:14 - REST client.0 - Request could not be processed
2025/06/27 06:48:14 - REST client.0 - org.apache.http.conn.ConnectTimeoutException: Connect to 20.0.1.136:8000 [/20.0.1.136] failed: Connect timed out
2025/06/27 06:48:14 - REST client.0 - 
2025/06/27 06:48:14 - REST client.0 - 	at org.apache.hop.pipeline.transforms.rest.Rest.callRest(Rest.java:258)
2025/06/27 06:48:14 - REST client.0 - 	... 3 more
2025/06/27 06:48:14 - REST client.0 - Caused by: javax.ws.rs.ProcessingException: org.apache.http.conn.ConnectTimeoutException: Connect to 20.0.1.136:8000 [/20.0.1.136] failed: Connect timed out
2025/06/27 06:48:14 - REST client.0 - 	at org.glassfish.jersey.apache.connector.ApacheConnector.apply(ApacheConnector.java:533)
2025/06/27 06:48:14 - REST client.0 - 	at org.glassfish.jersey.client.ClientRuntime.invoke(ClientRuntime.java:300)
2025/06/27 06:48:14 - REST client.0 - 	at org.glassfish.jersey.client.JerseyInvocation.lambda$invoke$1(JerseyInvocation.java:687)
2025/06/27 06:48:14 - REST client.0 - 	at org.glassfish.jersey.client.JerseyInvocation.call(JerseyInvocation.java:709)
2025/06/27 06:48:14 - REST client.0 - 	at org.glassfish.jersey.client.JerseyInvocation.lambda$runInScope$3(JerseyInvocation.java:703)
2025/06/27 06:48:14 - REST client.0 - 	at org.glassfish.jersey.internal.Errors.process(Errors.java:292)
2025/06/27 06:48:14 - REST client.0 - 	at org.glassfish.jersey.internal.Errors.process(Errors.java:274)
2025/06/27 06:48:14 - REST client.0 - 	at org.glassfish.jersey.internal.Errors.process(Errors.java:205)
2025/06/27 06:48:14 - REST client.0 - 	at org.glassfish.jersey.process.internal.RequestScope.runInScope(RequestScope.java:390)
2025/06/27 06:48:14 - REST client.0 - 	at org.glassfish.jersey.client.JerseyInvocation.runInScope(JerseyInvocation.java:703)
2025/06/27 06:48:14 - REST client.0 - 	at org.glassfish.jersey.client.JerseyInvocation.invoke(JerseyInvocation.java:686)
2025/06/27 06:48:14 - REST client.0 - 	at org.glassfish.jersey.client.JerseyInvocation$Builder.method(JerseyInvocation.java:422)
2025/06/27 06:48:14 - REST client.0 - 	at org.glassfish.jersey.client.JerseyInvocation$Builder.get(JerseyInvocation.java:318)
2025/06/27 06:48:14 - REST client.0 - 	at org.apache.hop.pipeline.transforms.rest.Rest.callRest(Rest.java:224)
2025/06/27 06:48:14 - REST client.0 - 	... 3 more
2025/06/27 06:48:14 - REST client.0 - Caused by: org.apache.http.conn.ConnectTimeoutException: Connect to 20.0.1.136:8000 [/20.0.1.136] failed: Connect timed out
2025/06/27 06:48:14 - REST client.0 - 	at org.apache.http.impl.conn.DefaultHttpClientConnectionOperator.connect(DefaultHttpClientConnectionOperator.java:151)
2025/06/27 06:48:14 - REST client.0 - 	at org.apache.http.impl.conn.PoolingHttpClientConnectionManager.connect(PoolingHttpClientConnectionManager.java:376)
2025/06/27 06:48:14 - REST client.0 - 	at org.apache.http.impl.execchain.MainClientExec.establishRoute(MainClientExec.java:393)
2025/06/27 06:48:14 - REST client.0 - 	at org.apache.http.impl.execchain.MainClientExec.execute(MainClientExec.java:236)
2025/06/27 06:48:14 - REST client.0 - 	at org.apache.http.impl.execchain.ProtocolExec.execute(ProtocolExec.java:186)
2025/06/27 06:48:14 - REST client.0 - 	at org.apache.http.impl.execchain.RetryExec.execute(RetryExec.java:89)
2025/06/27 06:48:14 - REST client.0 - 	at org.apache.http.impl.execchain.RedirectExec.execute(RedirectExec.java:110)
2025/06/27 06:48:14 - REST client.0 - 	at org.apache.http.impl.client.InternalHttpClient.doExecute(InternalHttpClient.java:185)
2025/06/27 06:48:14 - REST client.0 - 	at org.apache.http.impl.client.CloseableHttpClient.execute(CloseableHttpClient.java:72)
2025/06/27 06:48:14 - REST client.0 - 	at org.glassfish.jersey.apache.connector.ApacheConnector.apply(ApacheConnector.java:485)
2025/06/27 06:48:14 - REST client.0 - 	... 16 more
2025/06/27 06:48:14 - REST client.0 - Caused by: java.net.SocketTimeoutException: Connect timed out
2025/06/27 06:48:14 - REST client.0 - 	at java.base/sun.nio.ch.NioSocketImpl.timedFinishConnect(NioSocketImpl.java:551)
2025/06/27 06:48:14 - REST client.0 - 	at java.base/sun.nio.ch.NioSocketImpl.connect(NioSocketImpl.java:602)
2025/06/27 06:48:14 - REST client.0 - 	at java.base/java.net.SocksSocketImpl.connect(SocksSocketImpl.java:327)
2025/06/27 06:48:14 - REST client.0 - 	at java.base/java.net.Socket.connect(Socket.java:633)
2025/06/27 06:48:14 - REST client.0 - 	at org.apache.http.conn.socket.PlainConnectionSocketFactory.connectSocket(PlainConnectionSocketFactory.java:75)
2025/06/27 06:48:14 - REST client.0 - 	at org.apache.http.impl.conn.DefaultHttpClientConnectionOperator.connect(DefaultHttpClientConnectionOperator.java:142)
2025/06/27 06:48:14 - REST client.0 - 	... 25 more
[2025-06-27T06:48:14.054+0000] {docker.py:436} INFO - 2025/06/27 06:48:14 - REST client.0 - Finished processing (I=0, O=0, R=1, W=0, U=0, E=1)
[2025-06-27T06:48:14.055+0000] {docker.py:436} INFO - 2025/06/27 06:48:14 - prueba - Pipeline detected one or more transforms with errors.
[2025-06-27T06:48:14.056+0000] {docker.py:436} INFO - 2025/06/27 06:48:14 - prueba - Pipeline is killing the other transforms!
[2025-06-27T06:48:14.068+0000] {docker.py:436} INFO - 2025/06/27 06:48:14 - Set variables 2.0 - We didn't receive a row while setting the default values.
[2025-06-27T06:48:14.069+0000] {docker.py:436} INFO - 2025/06/27 06:48:14 - Set variables 2.0 - Finished after 0 rows.
[2025-06-27T06:48:14.080+0000] {docker.py:436} INFO - 2025/06/27 06:48:14 - prueba - Pipeline duration : 18.444 seconds [ 18.443" ]
[2025-06-27T06:48:14.116+0000] {docker.py:436} INFO - 2025/06/27 06:48:14 - prueba - Execution finished on a local pipeline engine with run configuration 'local'
[2025-06-27T06:48:14.122+0000] {docker.py:436} INFO - 2025/06/27 06:48:14 - filename - Finished action [prueba.hpl] (result=[false])
[2025-06-27T06:48:14.125+0000] {docker.py:436} INFO - 2025/06/27 06:48:14 - filename - Workflow execution finished
[2025-06-27T06:48:14.135+0000] {docker.py:436} INFO - 2025/06/27 06:48:14 - filename - Workflow duration : 19.708 seconds [ 19.707" ]
[2025-06-27T06:48:14.142+0000] {docker.py:436} INFO - 2025/06/27 06:48:14 - WF_MAIN - Finished action [filename.hwf] (result=[false])
[2025-06-27T06:48:14.145+0000] {docker.py:436} INFO - 2025/06/27 06:48:14 - WF_MAIN - Workflow execution finished
[2025-06-27T06:48:14.156+0000] {docker.py:436} INFO - 2025/06/27 06:48:14 - WF_MAIN - Workflow duration : 23.532 seconds [ 23.532" ]
[2025-06-27T06:48:14.157+0000] {docker.py:436} INFO - HopRun exit.
[2025-06-27T06:48:14.638+0000] {taskinstance.py:441} INFO - ::group::Post task execution logs
[2025-06-27T06:48:14.666+0000] {taskinstance.py:2905} ERROR - Task failed with exception
Traceback (most recent call last):
  File "/home/airflow/.local/lib/python3.12/site-packages/docker/api/client.py", line 265, in _raise_for_status
    response.raise_for_status()
  File "/home/airflow/.local/lib/python3.12/site-packages/requests/models.py", line 1021, in raise_for_status
    raise HTTPError(http_error_msg, response=self)
requests.exceptions.HTTPError: 400 Client Error: Bad Request for url: http+docker://localhost/v1.50/containers/create

The above exception was the direct cause of the following exception:

Traceback (most recent call last):
  File "/home/airflow/.local/lib/python3.12/site-packages/airflow/providers/docker/operators/docker.py", line 371, in _run_image
    return self._run_image_with_mounts([*self.mounts, tmp_mount], add_tmp_variable=True)
           ^^^^^^^^^^^^^^^^^^^^^^^^^^^^^^^^^^^^^^^^^^^^^^^^^^^^^^^^^^^^^^^^^^^^^^^^^^^^^
  File "/home/airflow/.local/lib/python3.12/site-packages/airflow/providers/docker/operators/docker.py", line 398, in _run_image_with_mounts
    self.container = self.cli.create_container(
                     ^^^^^^^^^^^^^^^^^^^^^^^^^^
  File "/home/airflow/.local/lib/python3.12/site-packages/docker/api/container.py", line 439, in create_container
    return self.create_container_from_config(config, name, platform)
           ^^^^^^^^^^^^^^^^^^^^^^^^^^^^^^^^^^^^^^^^^^^^^^^^^^^^^^^^^
  File "/home/airflow/.local/lib/python3.12/site-packages/docker/api/container.py", line 456, in create_container_from_config
    return self._result(res, True)
           ^^^^^^^^^^^^^^^^^^^^^^^
  File "/home/airflow/.local/lib/python3.12/site-packages/docker/api/client.py", line 271, in _result
    self._raise_for_status(response)
  File "/home/airflow/.local/lib/python3.12/site-packages/docker/api/client.py", line 267, in _raise_for_status
    raise create_api_error_from_http_exception(e) from e
          ^^^^^^^^^^^^^^^^^^^^^^^^^^^^^^^^^^^^^^^
  File "/home/airflow/.local/lib/python3.12/site-packages/docker/errors.py", line 39, in create_api_error_from_http_exception
    raise cls(e, response=response, explanation=explanation) from e
docker.errors.APIError: 400 Client Error for http+docker://localhost/v1.50/containers/create: Bad Request ("invalid mount config for type "bind": bind source path does not exist: /tmp/airflowtmp1jcjt_9e")

During handling of the above exception, another exception occurred:

Traceback (most recent call last):
  File "/home/airflow/.local/lib/python3.12/site-packages/airflow/models/taskinstance.py", line 465, in _execute_task
    result = _execute_callable(context=context, **execute_callable_kwargs)
             ^^^^^^^^^^^^^^^^^^^^^^^^^^^^^^^^^^^^^^^^^^^^^^^^^^^^^^^^^^^^^
  File "/home/airflow/.local/lib/python3.12/site-packages/airflow/models/taskinstance.py", line 432, in _execute_callable
    return execute_callable(context=context, **execute_callable_kwargs)
           ^^^^^^^^^^^^^^^^^^^^^^^^^^^^^^^^^^^^^^^^^^^^^^^^^^^^^^^^^^^^
  File "/home/airflow/.local/lib/python3.12/site-packages/airflow/models/baseoperator.py", line 400, in wrapper
    return func(self, *args, **kwargs)
           ^^^^^^^^^^^^^^^^^^^^^^^^^^^
  File "/home/airflow/.local/lib/python3.12/site-packages/airflow/providers/docker/operators/docker.py", line 509, in execute
    return self._run_image()
           ^^^^^^^^^^^^^^^^^
  File "/home/airflow/.local/lib/python3.12/site-packages/airflow/providers/docker/operators/docker.py", line 380, in _run_image
    return self._run_image_with_mounts(self.mounts, add_tmp_variable=False)
           ^^^^^^^^^^^^^^^^^^^^^^^^^^^^^^^^^^^^^^^^^^^^^^^^^^^^^^^^^^^^^^^^
  File "/home/airflow/.local/lib/python3.12/site-packages/airflow/providers/docker/operators/docker.py", line 444, in _run_image_with_mounts
    raise DockerContainerFailedException(f"Docker container failed: {result!r}", logs=log_lines)
airflow.providers.docker.exceptions.DockerContainerFailedException: Docker container failed: {'StatusCode': 1}
[2025-06-27T06:48:14.697+0000] {taskinstance.py:1206} INFO - Marking task as UP_FOR_RETRY. dag_id=WF_MAIN, task_id=run_hop_pipeline, run_id=scheduled__2025-06-27T05:41:00+00:00, execution_date=20250627T054100, start_date=20250627T064618, end_date=20250627T064814
[2025-06-27T06:48:14.763+0000] {standard_task_runner.py:110} ERROR - Failed to execute job 5 for task run_hop_pipeline (Docker container failed: {'StatusCode': 1}; 71)
[2025-06-27T06:48:14.802+0000] {local_task_job_runner.py:240} INFO - Task exited with return code 1
[2025-06-27T06:48:14.836+0000] {local_task_job_runner.py:222} INFO - ::endgroup::
[2025-06-27T07:20:45.945+0000] {local_task_job_runner.py:120} INFO - ::group::Pre task execution logs
[2025-06-27T07:20:46.035+0000] {taskinstance.py:2076} INFO - Dependencies all met for dep_context=non-requeueable deps ti=<TaskInstance: WF_MAIN.run_hop_pipeline scheduled__2025-06-27T05:41:00+00:00 [queued]>
[2025-06-27T07:20:46.091+0000] {taskinstance.py:2076} INFO - Dependencies all met for dep_context=requeueable deps ti=<TaskInstance: WF_MAIN.run_hop_pipeline scheduled__2025-06-27T05:41:00+00:00 [queued]>
[2025-06-27T07:20:46.097+0000] {taskinstance.py:2306} INFO - Starting attempt 1 of 2
[2025-06-27T07:20:46.168+0000] {taskinstance.py:2330} INFO - Executing <Task(DockerOperator): run_hop_pipeline> on 2025-06-27 05:41:00+00:00
[2025-06-27T07:20:46.202+0000] {warnings.py:110} WARNING - /home/***/.local/lib/python3.12/site-packages/***/task/task_runner/standard_task_runner.py:61: DeprecationWarning: This process (pid=66) is multi-threaded, use of fork() may lead to deadlocks in the child.
  pid = os.fork()

[2025-06-27T07:20:46.214+0000] {standard_task_runner.py:63} INFO - Started process 73 to run task
[2025-06-27T07:20:46.214+0000] {standard_task_runner.py:90} INFO - Running: ['***', 'tasks', 'run', 'WF_MAIN', 'run_hop_pipeline', 'scheduled__2025-06-27T05:41:00+00:00', '--job-id', '4', '--raw', '--subdir', 'DAGS_FOLDER/apache-hop-dag-wf-main.py', '--cfg-path', '/tmp/tmp8m8iaybv']
[2025-06-27T07:20:46.224+0000] {standard_task_runner.py:91} INFO - Job 4: Subtask run_hop_pipeline
[2025-06-27T07:20:46.519+0000] {task_command.py:426} INFO - Running <TaskInstance: WF_MAIN.run_hop_pipeline scheduled__2025-06-27T05:41:00+00:00 [running]> on host 5e15c4a8eeb7
[2025-06-27T07:20:46.776+0000] {taskinstance.py:2648} INFO - Exporting env vars: AIRFLOW_CTX_DAG_OWNER='***' AIRFLOW_CTX_DAG_ID='WF_MAIN' AIRFLOW_CTX_TASK_ID='run_hop_pipeline' AIRFLOW_CTX_EXECUTION_DATE='2025-06-27T05:41:00+00:00' AIRFLOW_CTX_TRY_NUMBER='1' AIRFLOW_CTX_DAG_RUN_ID='scheduled__2025-06-27T05:41:00+00:00'
[2025-06-27T07:20:46.780+0000] {taskinstance.py:430} INFO - ::endgroup::
[2025-06-27T07:20:46.996+0000] {docker.py:366} INFO - Starting docker container from image apache/hop:latest
[2025-06-27T07:20:47.034+0000] {docker.py:374} WARNING - Using remote engine or docker-in-docker and mounting temporary volume from host is not supported. Falling back to `mount_tmp_dir=False` mode. You can set `mount_tmp_dir` parameter to False to disable mounting and remove the warning
[2025-06-27T07:20:48.449+0000] {docker.py:436} INFO - 2025/06/27 07:20:48 - Running the entrypoint script with PID 6
[2025-06-27T07:20:48.451+0000] {docker.py:436} INFO - 2025/06/27 07:20:48 - The project folder for ProyectoSmartMed is set to: /files
[2025-06-27T07:20:48.452+0000] {docker.py:436} INFO - 2025/06/27 07:20:48 - The specified project folder exists
[2025-06-27T07:20:48.453+0000] {docker.py:436} INFO - 2025/06/27 07:20:48 - Registering project ProyectoSmartMed in the Hop container configuration
[2025-06-27T07:20:48.456+0000] {docker.py:436} INFO - 2025/06/27 07:20:48 - /opt/hop/hop-conf.sh --project=ProyectoSmartMed --project-create --project-home='/files' --project-config-file='project-config.json'
[2025-06-27T07:22:14.112+0000] {docker.py:436} INFO - Creating project 'ProyectoSmartMed'
[2025-06-27T07:22:14.969+0000] {docker.py:436} INFO - Project 'ProyectoSmartMed' was created for home folder : /files
[2025-06-27T07:22:15.264+0000] {docker.py:436} INFO - Configuration file for project 'ProyectoSmartMed' was saved to : file:/files/project-config.json
[2025-06-27T07:22:15.663+0000] {docker.py:436} INFO - 2025/06/27 07:22:15 - Not creating an environment in the container
[2025-06-27T07:22:15.671+0000] {docker.py:436} INFO - 2025/06/27 07:22:15 - Running a single hop workflow / pipeline (${PROJECT_HOME}/workflows/WF_MAIN.hwf)
[2025-06-27T07:22:50.693+0000] {docker.py:436} INFO - 2025/06/27 07:22:50 - HopRun - Enabling project 'ProyectoSmartMed'
[2025-06-27T07:22:51.692+0000] {docker.py:436} INFO - 2025/06/27 07:22:51 - HopRun - Starting workflow: /files/workflows/WF_MAIN.hwf
[2025-06-27T07:22:56.687+0000] {docker.py:436} INFO - 2025/06/27 07:22:56 - WF_MAIN - Start of workflow execution
[2025-06-27T07:22:57.132+0000] {docker.py:436} INFO - 2025/06/27 07:22:57 - WF_MAIN - Starting action [filename.hwf]
[2025-06-27T07:22:58.283+0000] {docker.py:436} INFO - 2025/06/27 07:22:58 - filename - Start of workflow execution
[2025-06-27T07:22:58.387+0000] {docker.py:436} INFO - 2025/06/27 07:22:58 - filename - Starting action [prueba.hpl]
[2025-06-27T07:22:58.874+0000] {docker.py:436} INFO - 2025/06/27 07:22:58 - prueba.hpl - Using run configuration [local]
[2025-06-27T07:22:59.030+0000] {docker.py:436} INFO - 2025/06/27 07:22:59 - prueba - Executing this pipeline using the Local Pipeline Engine with run configuration 'local'
[2025-06-27T07:22:59.065+0000] {docker.py:436} INFO - 2025/06/27 07:22:59 - prueba - Execution started for pipeline [prueba]
[2025-06-27T07:23:10.274+0000] {docker.py:436} INFO - 2025/06/27 07:23:10 - Table input.0 - ERROR: An error occurred, processing will be stopped: 
2025/06/27 07:23:10 - Table input.0 - Error occurred while trying to connect to the database
2025/06/27 07:23:10 - Table input.0 - 
2025/06/27 07:23:10 - Table input.0 - Error connecting to database: (using class org.postgresql.Driver)
2025/06/27 07:23:10 - Table input.0 - The connection attempt failed.
[2025-06-27T07:23:10.280+0000] {docker.py:436} INFO - 2025/06/27 07:23:10 - Table input.0 - ERROR: Error initializing transform [Table input]
2025/06/27 07:23:10 - prueba - ERROR: Transform [Table input.0] failed to initialize!
2025/06/27 07:23:10 - Table input.0 - Finished reading query, closing connection.
[2025-06-27T07:23:10.281+0000] {docker.py:436} INFO - 2025/06/27 07:23:10 - prueba.hpl - ERROR: Unable to prepare for execution of the pipeline
[2025-06-27T07:23:10.354+0000] {docker.py:436} INFO - 2025/06/27 07:23:10 - prueba.hpl - ERROR: org.apache.hop.core.exception.HopException: 
2025/06/27 07:23:10 - prueba.hpl - We failed to initialize at least one transform.  Execution can not begin!
2025/06/27 07:23:10 - prueba.hpl - 
2025/06/27 07:23:10 - prueba.hpl - 
2025/06/27 07:23:10 - prueba.hpl - 	at org.apache.hop.pipeline.Pipeline.prepareExecution(Pipeline.java:1088)
2025/06/27 07:23:10 - prueba.hpl - 	at org.apache.hop.pipeline.engines.local.LocalPipelineEngine.prepareExecution(LocalPipelineEngine.java:232)
2025/06/27 07:23:10 - prueba.hpl - 	at org.apache.hop.pipeline.Pipeline.execute(Pipeline.java:528)
2025/06/27 07:23:10 - prueba.hpl - 	at org.apache.hop.workflow.actions.pipeline.ActionPipeline.execute(ActionPipeline.java:543)
2025/06/27 07:23:10 - prueba.hpl - 	at org.apache.hop.workflow.Workflow.executeFromStart(Workflow.java:751)
2025/06/27 07:23:10 - prueba.hpl - 	at org.apache.hop.workflow.Workflow.executeFromStart(Workflow.java:902)
2025/06/27 07:23:10 - prueba.hpl - 	at org.apache.hop.workfl
[2025-06-27T07:23:10.364+0000] {docker.py:436} INFO - ow.Workflow.executeFromStart(Workflow.java:453)
2025/06/27 07:23:10 - prueba.hpl - 	at org.apache.hop.workflow.Workflow.startExecution(Workflow.java:313)
2025/06/27 07:23:10 - prueba.hpl - 	at org.apache.hop.workflow.engines.local.LocalWorkflowEngine.startExecution(LocalWorkflowEngine.java:249)
2025/06/27 07:23:10 - prueba.hpl - 	at org.apache.hop.workflow.actions.workflow.ActionWorkflowRunner.run(ActionWorkflowRunner.java:55)
2025/06/27 07:23:10 - prueba.hpl - 	at java.base/java.lang.Thread.run(Thread.java:840)
[2025-06-27T07:23:10.832+0000] {docker.py:436} INFO - 2025/06/27 07:23:10 - filename - Finished action [prueba.hpl] (result=[false])
[2025-06-27T07:23:10.878+0000] {docker.py:436} INFO - 2025/06/27 07:23:10 - filename - Workflow execution finished
[2025-06-27T07:23:11.099+0000] {docker.py:436} INFO - 2025/06/27 07:23:11 - filename - Workflow duration : 13.435 seconds [ 13.435" ]
[2025-06-27T07:23:11.122+0000] {docker.py:436} INFO - 2025/06/27 07:23:11 - WF_MAIN - Finished action [filename.hwf] (result=[false])
[2025-06-27T07:23:11.144+0000] {docker.py:436} INFO - 2025/06/27 07:23:11 - WF_MAIN - Workflow execution finished
[2025-06-27T07:23:11.185+0000] {docker.py:436} INFO - 2025/06/27 07:23:11 - WF_MAIN - Workflow duration : 19.372 seconds [ 19.371" ]
[2025-06-27T07:23:11.224+0000] {docker.py:436} INFO - HopRun exit.
[2025-06-27T07:23:12.055+0000] {taskinstance.py:441} INFO - ::group::Post task execution logs
[2025-06-27T07:23:12.092+0000] {taskinstance.py:2905} ERROR - Task failed with exception
Traceback (most recent call last):
  File "/home/airflow/.local/lib/python3.12/site-packages/docker/api/client.py", line 265, in _raise_for_status
    response.raise_for_status()
  File "/home/airflow/.local/lib/python3.12/site-packages/requests/models.py", line 1021, in raise_for_status
    raise HTTPError(http_error_msg, response=self)
requests.exceptions.HTTPError: 400 Client Error: Bad Request for url: http+docker://localhost/v1.50/containers/create

The above exception was the direct cause of the following exception:

Traceback (most recent call last):
  File "/home/airflow/.local/lib/python3.12/site-packages/airflow/providers/docker/operators/docker.py", line 371, in _run_image
    return self._run_image_with_mounts([*self.mounts, tmp_mount], add_tmp_variable=True)
           ^^^^^^^^^^^^^^^^^^^^^^^^^^^^^^^^^^^^^^^^^^^^^^^^^^^^^^^^^^^^^^^^^^^^^^^^^^^^^
  File "/home/airflow/.local/lib/python3.12/site-packages/airflow/providers/docker/operators/docker.py", line 398, in _run_image_with_mounts
    self.container = self.cli.create_container(
                     ^^^^^^^^^^^^^^^^^^^^^^^^^^
  File "/home/airflow/.local/lib/python3.12/site-packages/docker/api/container.py", line 439, in create_container
    return self.create_container_from_config(config, name, platform)
           ^^^^^^^^^^^^^^^^^^^^^^^^^^^^^^^^^^^^^^^^^^^^^^^^^^^^^^^^^
  File "/home/airflow/.local/lib/python3.12/site-packages/docker/api/container.py", line 456, in create_container_from_config
    return self._result(res, True)
           ^^^^^^^^^^^^^^^^^^^^^^^
  File "/home/airflow/.local/lib/python3.12/site-packages/docker/api/client.py", line 271, in _result
    self._raise_for_status(response)
  File "/home/airflow/.local/lib/python3.12/site-packages/docker/api/client.py", line 267, in _raise_for_status
    raise create_api_error_from_http_exception(e) from e
          ^^^^^^^^^^^^^^^^^^^^^^^^^^^^^^^^^^^^^^^
  File "/home/airflow/.local/lib/python3.12/site-packages/docker/errors.py", line 39, in create_api_error_from_http_exception
    raise cls(e, response=response, explanation=explanation) from e
docker.errors.APIError: 400 Client Error for http+docker://localhost/v1.50/containers/create: Bad Request ("invalid mount config for type "bind": bind source path does not exist: /tmp/airflowtmpkj7dkd4f")

During handling of the above exception, another exception occurred:

Traceback (most recent call last):
  File "/home/airflow/.local/lib/python3.12/site-packages/airflow/models/taskinstance.py", line 465, in _execute_task
    result = _execute_callable(context=context, **execute_callable_kwargs)
             ^^^^^^^^^^^^^^^^^^^^^^^^^^^^^^^^^^^^^^^^^^^^^^^^^^^^^^^^^^^^^
  File "/home/airflow/.local/lib/python3.12/site-packages/airflow/models/taskinstance.py", line 432, in _execute_callable
    return execute_callable(context=context, **execute_callable_kwargs)
           ^^^^^^^^^^^^^^^^^^^^^^^^^^^^^^^^^^^^^^^^^^^^^^^^^^^^^^^^^^^^
  File "/home/airflow/.local/lib/python3.12/site-packages/airflow/models/baseoperator.py", line 400, in wrapper
    return func(self, *args, **kwargs)
           ^^^^^^^^^^^^^^^^^^^^^^^^^^^
  File "/home/airflow/.local/lib/python3.12/site-packages/airflow/providers/docker/operators/docker.py", line 509, in execute
    return self._run_image()
           ^^^^^^^^^^^^^^^^^
  File "/home/airflow/.local/lib/python3.12/site-packages/airflow/providers/docker/operators/docker.py", line 380, in _run_image
    return self._run_image_with_mounts(self.mounts, add_tmp_variable=False)
           ^^^^^^^^^^^^^^^^^^^^^^^^^^^^^^^^^^^^^^^^^^^^^^^^^^^^^^^^^^^^^^^^
  File "/home/airflow/.local/lib/python3.12/site-packages/airflow/providers/docker/operators/docker.py", line 444, in _run_image_with_mounts
    raise DockerContainerFailedException(f"Docker container failed: {result!r}", logs=log_lines)
airflow.providers.docker.exceptions.DockerContainerFailedException: Docker container failed: {'StatusCode': 1}
[2025-06-27T07:23:12.134+0000] {taskinstance.py:1206} INFO - Marking task as UP_FOR_RETRY. dag_id=WF_MAIN, task_id=run_hop_pipeline, run_id=scheduled__2025-06-27T05:41:00+00:00, execution_date=20250627T054100, start_date=20250627T072046, end_date=20250627T072312
[2025-06-27T07:23:12.175+0000] {standard_task_runner.py:110} ERROR - Failed to execute job 4 for task run_hop_pipeline (Docker container failed: {'StatusCode': 1}; 73)
[2025-06-27T07:23:12.243+0000] {local_task_job_runner.py:240} INFO - Task exited with return code 1
[2025-06-27T07:23:12.307+0000] {taskinstance.py:3498} INFO - 0 downstream tasks scheduled from follow-on schedule check
[2025-06-27T07:23:12.314+0000] {local_task_job_runner.py:222} INFO - ::endgroup::
[2025-06-27T07:37:09.178+0000] {local_task_job_runner.py:120} INFO - ::group::Pre task execution logs
[2025-06-27T07:37:09.230+0000] {taskinstance.py:2076} INFO - Dependencies all met for dep_context=non-requeueable deps ti=<TaskInstance: WF_MAIN.run_hop_pipeline scheduled__2025-06-27T05:41:00+00:00 [queued]>
[2025-06-27T07:37:09.246+0000] {taskinstance.py:2076} INFO - Dependencies all met for dep_context=requeueable deps ti=<TaskInstance: WF_MAIN.run_hop_pipeline scheduled__2025-06-27T05:41:00+00:00 [queued]>
[2025-06-27T07:37:09.246+0000] {taskinstance.py:2306} INFO - Starting attempt 1 of 2
[2025-06-27T07:37:09.272+0000] {taskinstance.py:2330} INFO - Executing <Task(DockerOperator): run_hop_pipeline> on 2025-06-27 05:41:00+00:00
[2025-06-27T07:37:09.280+0000] {warnings.py:110} WARNING - /home/***/.local/lib/python3.12/site-packages/***/task/task_runner/standard_task_runner.py:61: DeprecationWarning: This process (pid=68) is multi-threaded, use of fork() may lead to deadlocks in the child.
  pid = os.fork()

[2025-06-27T07:37:09.289+0000] {standard_task_runner.py:63} INFO - Started process 73 to run task
[2025-06-27T07:37:09.289+0000] {standard_task_runner.py:90} INFO - Running: ['***', 'tasks', 'run', 'WF_MAIN', 'run_hop_pipeline', 'scheduled__2025-06-27T05:41:00+00:00', '--job-id', '3', '--raw', '--subdir', 'DAGS_FOLDER/apache-hop-dag-wf-main.py', '--cfg-path', '/tmp/tmp2zziu_t5']
[2025-06-27T07:37:09.296+0000] {standard_task_runner.py:91} INFO - Job 3: Subtask run_hop_pipeline
[2025-06-27T07:37:09.450+0000] {task_command.py:426} INFO - Running <TaskInstance: WF_MAIN.run_hop_pipeline scheduled__2025-06-27T05:41:00+00:00 [running]> on host ec14a5b8088e
[2025-06-27T07:37:09.630+0000] {taskinstance.py:2648} INFO - Exporting env vars: AIRFLOW_CTX_DAG_OWNER='***' AIRFLOW_CTX_DAG_ID='WF_MAIN' AIRFLOW_CTX_TASK_ID='run_hop_pipeline' AIRFLOW_CTX_EXECUTION_DATE='2025-06-27T05:41:00+00:00' AIRFLOW_CTX_TRY_NUMBER='1' AIRFLOW_CTX_DAG_RUN_ID='scheduled__2025-06-27T05:41:00+00:00'
[2025-06-27T07:37:09.631+0000] {taskinstance.py:430} INFO - ::endgroup::
[2025-06-27T07:37:09.832+0000] {docker.py:366} INFO - Starting docker container from image apache/hop:latest
[2025-06-27T07:37:09.863+0000] {docker.py:374} WARNING - Using remote engine or docker-in-docker and mounting temporary volume from host is not supported. Falling back to `mount_tmp_dir=False` mode. You can set `mount_tmp_dir` parameter to False to disable mounting and remove the warning
[2025-06-27T07:37:10.831+0000] {docker.py:436} INFO - 2025/06/27 07:37:10 - Running the entrypoint script with PID 7
[2025-06-27T07:37:10.833+0000] {docker.py:436} INFO - 2025/06/27 07:37:10 - The project folder for ProyectoSmartMed is set to: /files
[2025-06-27T07:37:10.841+0000] {docker.py:436} INFO - 2025/06/27 07:37:10 - The specified project folder exists
[2025-06-27T07:37:10.850+0000] {docker.py:436} INFO - 2025/06/27 07:37:10 - Registering project ProyectoSmartMed in the Hop container configuration
[2025-06-27T07:37:10.854+0000] {docker.py:436} INFO - 2025/06/27 07:37:10 - /opt/hop/hop-conf.sh --project=ProyectoSmartMed --project-create --project-home='/files' --project-config-file='project-config.json'
[2025-06-27T07:38:02.923+0000] {docker.py:436} INFO - Creating project 'ProyectoSmartMed'
[2025-06-27T07:38:03.310+0000] {docker.py:436} INFO - Project 'ProyectoSmartMed' was created for home folder : /files
[2025-06-27T07:38:03.470+0000] {docker.py:436} INFO - Configuration file for project 'ProyectoSmartMed' was saved to : file:/files/project-config.json
[2025-06-27T07:38:03.647+0000] {docker.py:436} INFO - 2025/06/27 07:38:03 - Not creating an environment in the container
[2025-06-27T07:38:03.651+0000] {docker.py:436} INFO - 2025/06/27 07:38:03 - Running a single hop workflow / pipeline (${PROJECT_HOME}/workflows/WF_MAIN.hwf)
[2025-06-27T07:38:30.421+0000] {docker.py:436} INFO - 2025/06/27 07:38:30 - HopRun - Enabling project 'ProyectoSmartMed'
[2025-06-27T07:38:30.865+0000] {docker.py:436} INFO - 2025/06/27 07:38:30 - HopRun - Starting workflow: /files/workflows/WF_MAIN.hwf
[2025-06-27T07:38:34.107+0000] {docker.py:436} INFO - 2025/06/27 07:38:34 - WF_MAIN - Start of workflow execution
[2025-06-27T07:38:34.320+0000] {docker.py:436} INFO - 2025/06/27 07:38:34 - WF_MAIN - Starting action [filename.hwf]
[2025-06-27T07:38:35.020+0000] {docker.py:436} INFO - 2025/06/27 07:38:35 - filename - Start of workflow execution
[2025-06-27T07:38:35.042+0000] {docker.py:436} INFO - 2025/06/27 07:38:35 - filename - Starting action [prueba.hpl]
[2025-06-27T07:38:35.284+0000] {docker.py:436} INFO - 2025/06/27 07:38:35 - prueba.hpl - Using run configuration [local]
[2025-06-27T07:38:35.387+0000] {docker.py:436} INFO - 2025/06/27 07:38:35 - prueba - Executing this pipeline using the Local Pipeline Engine with run configuration 'local'
[2025-06-27T07:38:35.401+0000] {docker.py:436} INFO - 2025/06/27 07:38:35 - prueba - Execution started for pipeline [prueba]
[2025-06-27T07:38:39.905+0000] {docker.py:436} INFO - 2025/06/27 07:38:39 - Table input.0 - Finished reading query, closing connection.
[2025-06-27T07:38:39.909+0000] {docker.py:436} INFO - 2025/06/27 07:38:39 - Set variables.0 - Setting project variables...
2025/06/27 07:38:39 - Set variables.0 - Set variable lastDate to value [2025-06-27 01:20:57]
[2025-06-27T07:38:39.937+0000] {docker.py:436} INFO - 2025/06/27 07:38:39 - Set variables.0 - Finished after 1 rows.
[2025-06-27T07:38:39.938+0000] {docker.py:436} INFO - 2025/06/27 07:38:39 - Set variables.0 - Finished processing (I=0, O=0, R=1, W=1, U=0, E=0)
[2025-06-27T07:38:40.012+0000] {docker.py:436} INFO - 2025/06/27 07:38:40 - Table input.0 - Finished processing (I=1, O=0, R=0, W=1, U=0, E=0)
[2025-06-27T07:38:52.067+0000] {docker.py:436} INFO - 2025/06/27 07:38:52 - REST client.0 - ERROR: Because of an error, this transform can't continue:
2025/06/27 07:38:52 - REST client.0 - Can not read result from [http://20.0.1.136:8000/api/v1/dags/dagruns]
2025/06/27 07:38:52 - REST client.0 - 
2025/06/27 07:38:52 - REST client.0 - Request could not be processed
2025/06/27 07:38:52 - REST client.0 - org.apache.http.conn.ConnectTimeoutException: Connect to 20.0.1.136:8000 [/20.0.1.136] failed: Connect timed out
[2025-06-27T07:38:52.072+0000] {docker.py:436} INFO - 2025/06/27 07:38:52 - REST client.0 - ERROR: org.apache.hop.core.exception.HopException: 
2025/06/27 07:38:52 - REST client.0 - Can not read result from [http://20.0.1.136:8000/api/v1/dags/dagruns]
2025/06/27 07:38:52 - REST client.0 - 
2025/06/27 07:38:52 - REST client.0 - Request could not be processed
2025/06/27 07:38:52 - REST client.0 - org.apache.http.conn.ConnectTimeoutException: Connect to 20.0.1.136:8000 [/20.0.1.136] failed: Connect timed out
2025/06/27 07:38:52 - REST client.0 - 
2025/06/27 07:38:52 - REST client.0 - 
2025/06/27 07:38:52 - REST client.0 - 	at org.apache.hop.pipeline.transforms.rest.Rest.callRest(Rest.java:321)
2025/06/27 07:38:52 - REST client.0 - 	at org.apache.hop.pipeline.transforms.rest.Rest.processRow(Rest.java:538)
2025/06/27 07:38:52 - REST client.0 - 	at org.apache.hop.pipeline.transform.RunThread.run(RunThread.java:54)
2025/06/27 07:38:52 - REST client.0 - 	at java.base/java.lang.Thread.run(Thread.java:840)
2025/06/27 07:38:52 - REST client.0 - Caused by: org.apache.hop.co
[2025-06-27T07:38:52.073+0000] {docker.py:436} INFO - re.exception.HopException: 
2025/06/27 07:38:52 - REST client.0 - Request could not be processed
2025/06/27 07:38:52 - REST client.0 - org.apache.http.conn.ConnectTimeoutException: Connect to 20.0.1.136:8000 [/20.0.1.136] failed: Connect timed out
2025/06/27 07:38:52 - REST client.0 - 
2025/06/27 07:38:52 - REST client.0 - 	at org.apache.hop.pipeline.transforms.rest.Rest.callRest(Rest.java:258)
2025/06/27 07:38:52 - REST client.0 - 	... 3 more
2025/06/27 07:38:52 - REST client.0 - Caused by: javax.ws.rs.ProcessingException: org.apache.http.conn.ConnectTimeoutException: Connect to 20.0.1.136:8000 [/20.0.1.136] failed: Connect timed out
2025/06/27 07:38:52 - REST client.0 - 	at org.glassfish.jersey.apache.connector.ApacheConnector.apply(ApacheConnector.java:533)
2025/06/27 07:38:52 - REST client.0 - 	at org.glassfish.jersey.client.ClientRuntime.invoke(ClientRuntime.java:300)
2025/06/27 07:38:52 - REST client.0 - 	at org.glassfish.jersey.client.JerseyInvocation.lambda$invoke$1(JerseyInvocation.java:687)
2025/06/27 07:38:52 - REST client.0 - 	at org.glassfish.jersey.client.JerseyInvocation.call(JerseyInvocation.java:709)
2025/06/27 07:38:52 - REST client.0 - 	at org.glassfish.jersey.client.JerseyInvocation.lambda$runInScope$3(JerseyInvocation.java:703)
2025/06/27 07:38:52 - REST client.0 - 	at org.glassfish.jersey.internal.Errors.process(Errors.java:292)
2025/06/27 07:38:52 - REST client.0 - 	at org.glassfish.jersey.internal.Errors.process(Errors.java:274)
2025/06/27 07:38:52 - REST client.0 - 	at org.glassfish.jersey.internal.Errors.process(Errors.java:205)
2025/06/27 07:38:52 - REST client.0 - 	at org.glassfish.jersey.process.internal.RequestScope.runInScope(RequestScope.java:390)
2025/06/27 07:38:52 - REST client.0 - 	at org.glassfish.jersey.client.JerseyInvocation.runInScope(JerseyInvocation.java:703)
2025/06/27 07:38:52 - REST client.0 - 	at org.glassfish.jersey.client.JerseyInvocation.invoke(JerseyInvocation.java:686)
2025/06/27 07:38:52 - REST client.0 - 	at org.glassfish.jersey.client.JerseyInvocation$Builder
[2025-06-27T07:38:52.074+0000] {docker.py:436} INFO - .method(JerseyInvocation.java:422)
2025/06/27 07:38:52 - REST client.0 - 	at org.glassfish.jersey.client.JerseyInvocation$Builder.get(JerseyInvocation.java:318)
2025/06/27 07:38:52 - REST client.0 - 	at org.apache.hop.pipeline.transforms.rest.Rest.callRest(Rest.java:224)
2025/06/27 07:38:52 - REST client.0 - 	... 3 more
2025/06/27 07:38:52 - REST client.0 - Caused by: org.apache.http.conn.ConnectTimeoutException: Connect to 20.0.1.136:8000 [/20.0.1.136] failed: Connect timed out
2025/06/27 07:38:52 - REST client.0 - 	at org.apache.http.impl.conn.DefaultHttpClientConnectionOperator.connect(DefaultHttpClientConnectionOperator.java:151)
2025/06/27 07:38:52 - REST client.0 - 	at org.apache.http.impl.conn.PoolingHttpClientConnectionManager.connect(PoolingHttpClientConnectionManager.java:376)
2025/06/27 07:38:52 - REST client.0 - 	at org.apache.http.impl.execchain.MainClientExec.establishRoute(MainClientExec.java:393)
2025/06/27 07:38:52 - REST client.0 - 	at org.apache.http.impl.execchain.MainClientExec.execute(Ma
[2025-06-27T07:38:52.076+0000] {docker.py:436} INFO - inClientExec.java:236)
2025/06/27 07:38:52 - REST client.0 - 	at org.apache.http.impl.execchain.ProtocolExec.execute(ProtocolExec.java:186)
2025/06/27 07:38:52 - REST client.0 - 	at org.apache.http.impl.execchain.RetryExec.execute(RetryExec.java:89)
2025/06/27 07:38:52 - REST client.0 - 	at org.apache.http.impl.execchain.RedirectExec.execute(RedirectExec.java:110)
2025/06/27 07:38:52 - REST client.0 - 	at org.apache.http.impl.client.InternalHttpClient.doExecute(InternalHttpClient.java:185)
2025/06/27 07:38:52 - REST client.0 - 	at org.apache.http.impl.client.CloseableHttpClient.execute(CloseableHttpClient.java:72)
2025/06/27 07:38:52 - REST client.0 - 	at org.glassfish.jersey.apache.connector.ApacheConnector.apply(ApacheConnector.java:485)
2025/06/27 07:38:52 - REST client.0 - 	... 16 more
2025/06/27 07:38:52 - REST client.0 - Caused by: java.net.SocketTimeoutException: Connect timed out
2025/06/27 07:38:52 - REST client.0 - 	at java.base/sun.nio.ch.NioSocketImpl.timedFinishConnect(NioSocketImpl.java:551)
2025/06/27 07:38:52 - REST client.0 - 	at java.base/sun.nio.ch.NioSocketImpl.connect(NioSocketImpl.java:602)
2025/06/27 07:38:52 - REST client.0 - 	at java.base/java.net.SocksSocketImpl.connect(SocksSocketImpl.java:327)
2025/06/27 07:38:52 - REST client.0 - 	at java.base/java.net.Socket.connect(Socket.java:633)
2025/06/27 07:38:52 - REST client.0 - 	at org.apache.http.conn.socket.PlainConnectionSocketFactory.connectSocket(PlainConnectionSocketFactory.java:75)
2025/06/27 07:38:52 - REST client.0 - 	at org.apache.http.impl.conn.DefaultHttpClientConnectionOperator.connect(DefaultHttpClientConnectionOperator.java:142)
2025/06/27 07:38:52 - REST client.0 - 	... 25 more
[2025-06-27T07:38:52.077+0000] {docker.py:436} INFO - 2025/06/27 07:38:52 - REST client.0 - Finished processing (I=0, O=0, R=1, W=0, U=0, E=1)
[2025-06-27T07:38:52.079+0000] {docker.py:436} INFO - 2025/06/27 07:38:52 - prueba - Pipeline detected one or more transforms with errors.
[2025-06-27T07:38:52.080+0000] {docker.py:436} INFO - 2025/06/27 07:38:52 - prueba - Pipeline is killing the other transforms!
[2025-06-27T07:38:52.082+0000] {docker.py:436} INFO - 2025/06/27 07:38:52 - Set variables 2.0 - We didn't receive a row while setting the default values.
[2025-06-27T07:38:52.084+0000] {docker.py:436} INFO - 2025/06/27 07:38:52 - Set variables 2.0 - Finished after 0 rows.
[2025-06-27T07:38:52.095+0000] {docker.py:436} INFO - 2025/06/27 07:38:52 - prueba - Pipeline duration : 16.701 seconds [ 16.701" ]
[2025-06-27T07:38:52.136+0000] {docker.py:436} INFO - 2025/06/27 07:38:52 - prueba - Execution finished on a local pipeline engine with run configuration 'local'
[2025-06-27T07:38:52.147+0000] {docker.py:436} INFO - 2025/06/27 07:38:52 - filename - Finished action [prueba.hpl] (result=[false])
[2025-06-27T07:38:52.149+0000] {docker.py:436} INFO - 2025/06/27 07:38:52 - filename - Workflow execution finished
[2025-06-27T07:38:52.162+0000] {docker.py:436} INFO - 2025/06/27 07:38:52 - filename - Workflow duration : 17.676 seconds [ 17.675" ]
[2025-06-27T07:38:52.175+0000] {docker.py:436} INFO - 2025/06/27 07:38:52 - WF_MAIN - Finished action [filename.hwf] (result=[false])
2025/06/27 07:38:52 - WF_MAIN - Workflow execution finished
[2025-06-27T07:38:52.186+0000] {docker.py:436} INFO - 2025/06/27 07:38:52 - WF_MAIN - Workflow duration : 21.284 seconds [ 21.283" ]
[2025-06-27T07:38:52.188+0000] {docker.py:436} INFO - HopRun exit.
[2025-06-27T07:38:52.633+0000] {taskinstance.py:441} INFO - ::group::Post task execution logs
[2025-06-27T07:38:52.660+0000] {taskinstance.py:2905} ERROR - Task failed with exception
Traceback (most recent call last):
  File "/home/airflow/.local/lib/python3.12/site-packages/docker/api/client.py", line 265, in _raise_for_status
    response.raise_for_status()
  File "/home/airflow/.local/lib/python3.12/site-packages/requests/models.py", line 1021, in raise_for_status
    raise HTTPError(http_error_msg, response=self)
requests.exceptions.HTTPError: 400 Client Error: Bad Request for url: http+docker://localhost/v1.50/containers/create

The above exception was the direct cause of the following exception:

Traceback (most recent call last):
  File "/home/airflow/.local/lib/python3.12/site-packages/airflow/providers/docker/operators/docker.py", line 371, in _run_image
    return self._run_image_with_mounts([*self.mounts, tmp_mount], add_tmp_variable=True)
           ^^^^^^^^^^^^^^^^^^^^^^^^^^^^^^^^^^^^^^^^^^^^^^^^^^^^^^^^^^^^^^^^^^^^^^^^^^^^^
  File "/home/airflow/.local/lib/python3.12/site-packages/airflow/providers/docker/operators/docker.py", line 398, in _run_image_with_mounts
    self.container = self.cli.create_container(
                     ^^^^^^^^^^^^^^^^^^^^^^^^^^
  File "/home/airflow/.local/lib/python3.12/site-packages/docker/api/container.py", line 439, in create_container
    return self.create_container_from_config(config, name, platform)
           ^^^^^^^^^^^^^^^^^^^^^^^^^^^^^^^^^^^^^^^^^^^^^^^^^^^^^^^^^
  File "/home/airflow/.local/lib/python3.12/site-packages/docker/api/container.py", line 456, in create_container_from_config
    return self._result(res, True)
           ^^^^^^^^^^^^^^^^^^^^^^^
  File "/home/airflow/.local/lib/python3.12/site-packages/docker/api/client.py", line 271, in _result
    self._raise_for_status(response)
  File "/home/airflow/.local/lib/python3.12/site-packages/docker/api/client.py", line 267, in _raise_for_status
    raise create_api_error_from_http_exception(e) from e
          ^^^^^^^^^^^^^^^^^^^^^^^^^^^^^^^^^^^^^^^
  File "/home/airflow/.local/lib/python3.12/site-packages/docker/errors.py", line 39, in create_api_error_from_http_exception
    raise cls(e, response=response, explanation=explanation) from e
docker.errors.APIError: 400 Client Error for http+docker://localhost/v1.50/containers/create: Bad Request ("invalid mount config for type "bind": bind source path does not exist: /tmp/airflowtmphh0pf8nn")

During handling of the above exception, another exception occurred:

Traceback (most recent call last):
  File "/home/airflow/.local/lib/python3.12/site-packages/airflow/models/taskinstance.py", line 465, in _execute_task
    result = _execute_callable(context=context, **execute_callable_kwargs)
             ^^^^^^^^^^^^^^^^^^^^^^^^^^^^^^^^^^^^^^^^^^^^^^^^^^^^^^^^^^^^^
  File "/home/airflow/.local/lib/python3.12/site-packages/airflow/models/taskinstance.py", line 432, in _execute_callable
    return execute_callable(context=context, **execute_callable_kwargs)
           ^^^^^^^^^^^^^^^^^^^^^^^^^^^^^^^^^^^^^^^^^^^^^^^^^^^^^^^^^^^^
  File "/home/airflow/.local/lib/python3.12/site-packages/airflow/models/baseoperator.py", line 400, in wrapper
    return func(self, *args, **kwargs)
           ^^^^^^^^^^^^^^^^^^^^^^^^^^^
  File "/home/airflow/.local/lib/python3.12/site-packages/airflow/providers/docker/operators/docker.py", line 509, in execute
    return self._run_image()
           ^^^^^^^^^^^^^^^^^
  File "/home/airflow/.local/lib/python3.12/site-packages/airflow/providers/docker/operators/docker.py", line 380, in _run_image
    return self._run_image_with_mounts(self.mounts, add_tmp_variable=False)
           ^^^^^^^^^^^^^^^^^^^^^^^^^^^^^^^^^^^^^^^^^^^^^^^^^^^^^^^^^^^^^^^^
  File "/home/airflow/.local/lib/python3.12/site-packages/airflow/providers/docker/operators/docker.py", line 444, in _run_image_with_mounts
    raise DockerContainerFailedException(f"Docker container failed: {result!r}", logs=log_lines)
airflow.providers.docker.exceptions.DockerContainerFailedException: Docker container failed: {'StatusCode': 1}
[2025-06-27T07:38:52.692+0000] {taskinstance.py:1206} INFO - Marking task as UP_FOR_RETRY. dag_id=WF_MAIN, task_id=run_hop_pipeline, run_id=scheduled__2025-06-27T05:41:00+00:00, execution_date=20250627T054100, start_date=20250627T073709, end_date=20250627T073852
[2025-06-27T07:38:52.739+0000] {standard_task_runner.py:110} ERROR - Failed to execute job 3 for task run_hop_pipeline (Docker container failed: {'StatusCode': 1}; 73)
[2025-06-27T07:38:52.803+0000] {local_task_job_runner.py:240} INFO - Task exited with return code 1
[2025-06-27T07:38:52.850+0000] {taskinstance.py:3498} INFO - 0 downstream tasks scheduled from follow-on schedule check
[2025-06-27T07:38:52.854+0000] {local_task_job_runner.py:222} INFO - ::endgroup::
