[2025-06-27T07:28:14.932+0000] {local_task_job_runner.py:120} INFO - ::group::Pre task execution logs
[2025-06-27T07:28:15.080+0000] {taskinstance.py:2076} INFO - Dependencies all met for dep_context=non-requeueable deps ti=<TaskInstance: WF_MAIN.run_hop_pipeline scheduled__2025-06-27T05:41:00+00:00 [queued]>
[2025-06-27T07:28:15.111+0000] {taskinstance.py:2076} INFO - Dependencies all met for dep_context=requeueable deps ti=<TaskInstance: WF_MAIN.run_hop_pipeline scheduled__2025-06-27T05:41:00+00:00 [queued]>
[2025-06-27T07:28:15.112+0000] {taskinstance.py:2306} INFO - Starting attempt 2 of 2
[2025-06-27T07:28:15.149+0000] {taskinstance.py:2330} INFO - Executing <Task(DockerOperator): run_hop_pipeline> on 2025-06-27 05:41:00+00:00
[2025-06-27T07:28:15.163+0000] {warnings.py:110} WARNING - /home/***/.local/lib/python3.12/site-packages/***/task/task_runner/standard_task_runner.py:61: DeprecationWarning: This process (pid=174) is multi-threaded, use of fork() may lead to deadlocks in the child.
  pid = os.fork()

[2025-06-27T07:28:15.168+0000] {standard_task_runner.py:63} INFO - Started process 176 to run task
[2025-06-27T07:28:15.168+0000] {standard_task_runner.py:90} INFO - Running: ['***', 'tasks', 'run', 'WF_MAIN', 'run_hop_pipeline', 'scheduled__2025-06-27T05:41:00+00:00', '--job-id', '13', '--raw', '--subdir', 'DAGS_FOLDER/apache-hop-dag-wf-main.py', '--cfg-path', '/tmp/tmpubrzv5rw']
[2025-06-27T07:28:15.175+0000] {standard_task_runner.py:91} INFO - Job 13: Subtask run_hop_pipeline
[2025-06-27T07:28:15.356+0000] {task_command.py:426} INFO - Running <TaskInstance: WF_MAIN.run_hop_pipeline scheduled__2025-06-27T05:41:00+00:00 [running]> on host 5e15c4a8eeb7
[2025-06-27T07:28:15.756+0000] {taskinstance.py:2648} INFO - Exporting env vars: AIRFLOW_CTX_DAG_OWNER='***' AIRFLOW_CTX_DAG_ID='WF_MAIN' AIRFLOW_CTX_TASK_ID='run_hop_pipeline' AIRFLOW_CTX_EXECUTION_DATE='2025-06-27T05:41:00+00:00' AIRFLOW_CTX_TRY_NUMBER='2' AIRFLOW_CTX_DAG_RUN_ID='scheduled__2025-06-27T05:41:00+00:00'
[2025-06-27T07:28:15.770+0000] {taskinstance.py:430} INFO - ::endgroup::
[2025-06-27T07:28:16.179+0000] {docker.py:366} INFO - Starting docker container from image apache/hop:latest
[2025-06-27T07:28:16.204+0000] {docker.py:374} WARNING - Using remote engine or docker-in-docker and mounting temporary volume from host is not supported. Falling back to `mount_tmp_dir=False` mode. You can set `mount_tmp_dir` parameter to False to disable mounting and remove the warning
[2025-06-27T07:28:17.022+0000] {docker.py:436} INFO - 2025/06/27 07:28:16 - Running the entrypoint script with PID 6
[2025-06-27T07:28:17.024+0000] {docker.py:436} INFO - 2025/06/27 07:28:16 - The project folder for ProyectoSmartMed is set to: /files
[2025-06-27T07:28:17.027+0000] {docker.py:436} INFO - 2025/06/27 07:28:17 - The specified project folder exists
[2025-06-27T07:28:17.029+0000] {docker.py:436} INFO - 2025/06/27 07:28:17 - Registering project ProyectoSmartMed in the Hop container configuration
[2025-06-27T07:28:17.031+0000] {docker.py:436} INFO - 2025/06/27 07:28:17 - /opt/hop/hop-conf.sh --project=ProyectoSmartMed --project-create --project-home='/files' --project-config-file='project-config.json'
[2025-06-27T07:29:18.545+0000] {docker.py:436} INFO - Creating project 'ProyectoSmartMed'
[2025-06-27T07:29:19.228+0000] {docker.py:436} INFO - Project 'ProyectoSmartMed' was created for home folder : /files
[2025-06-27T07:29:19.372+0000] {docker.py:436} INFO - Configuration file for project 'ProyectoSmartMed' was saved to : file:/files/project-config.json
[2025-06-27T07:29:19.590+0000] {docker.py:436} INFO - 2025/06/27 07:29:19 - Not creating an environment in the container
[2025-06-27T07:29:19.597+0000] {docker.py:436} INFO - 2025/06/27 07:29:19 - Running a single hop workflow / pipeline (${PROJECT_HOME}/workflows/WF_MAIN.hwf)
[2025-06-27T07:29:51.302+0000] {docker.py:436} INFO - 2025/06/27 07:29:51 - HopRun - Enabling project 'ProyectoSmartMed'
[2025-06-27T07:29:52.278+0000] {docker.py:436} INFO - 2025/06/27 07:29:52 - HopRun - Starting workflow: /files/workflows/WF_MAIN.hwf
[2025-06-27T07:29:56.059+0000] {docker.py:436} INFO - 2025/06/27 07:29:56 - WF_MAIN - Start of workflow execution
[2025-06-27T07:29:56.372+0000] {docker.py:436} INFO - 2025/06/27 07:29:56 - WF_MAIN - Starting action [filename.hwf]
[2025-06-27T07:29:57.773+0000] {docker.py:436} INFO - 2025/06/27 07:29:57 - filename - Start of workflow execution
[2025-06-27T07:29:57.874+0000] {docker.py:436} INFO - 2025/06/27 07:29:57 - filename - Starting action [prueba.hpl]
[2025-06-27T07:29:58.222+0000] {docker.py:436} INFO - 2025/06/27 07:29:58 - prueba.hpl - Using run configuration [local]
[2025-06-27T07:29:58.414+0000] {docker.py:436} INFO - 2025/06/27 07:29:58 - prueba - Executing this pipeline using the Local Pipeline Engine with run configuration 'local'
[2025-06-27T07:29:58.493+0000] {docker.py:436} INFO - 2025/06/27 07:29:58 - prueba - Execution started for pipeline [prueba]
[2025-06-27T07:30:09.576+0000] {docker.py:436} INFO - 2025/06/27 07:30:09 - Table input.0 - ERROR: An error occurred, processing will be stopped: 
2025/06/27 07:30:09 - Table input.0 - Error occurred while trying to connect to the database
2025/06/27 07:30:09 - Table input.0 - 
2025/06/27 07:30:09 - Table input.0 - Error connecting to database: (using class org.postgresql.Driver)
2025/06/27 07:30:09 - Table input.0 - The connection attempt failed.
[2025-06-27T07:30:09.578+0000] {docker.py:436} INFO - 2025/06/27 07:30:09 - Table input.0 - ERROR: Error initializing transform [Table input]
[2025-06-27T07:30:09.580+0000] {docker.py:436} INFO - 2025/06/27 07:30:09 - prueba - ERROR: Transform [Table input.0] failed to initialize!
[2025-06-27T07:30:09.580+0000] {docker.py:436} INFO - 2025/06/27 07:30:09 - Table input.0 - Finished reading query, closing connection.
[2025-06-27T07:30:09.585+0000] {docker.py:436} INFO - 2025/06/27 07:30:09 - prueba.hpl - ERROR: Unable to prepare for execution of the pipeline
[2025-06-27T07:30:09.589+0000] {docker.py:436} INFO - 2025/06/27 07:30:09 - prueba.hpl - ERROR: org.apache.hop.core.exception.HopException: 
2025/06/27 07:30:09 - prueba.hpl - We failed to initialize at least one transform.  Execution can not begin!
2025/06/27 07:30:09 - prueba.hpl - 
2025/06/27 07:30:09 - prueba.hpl - 
2025/06/27 07:30:09 - prueba.hpl - 	at org.apache.hop.pipeline.Pipeline.prepareExecution(Pipeline.java:1088)
2025/06/27 07:30:09 - prueba.hpl - 	at org.apache.hop.pipeline.engines.local.LocalPipelineEngine.prepareExecution(LocalPipelineEngine.java:232)
2025/06/27 07:30:09 - prueba.hpl - 	at org.apache.hop.pipeline.Pipeline.execute(Pipeline.java:528)
2025/06/27 07:30:09 - prueba.hpl - 	at org.apache.hop.workflow.actions.pipeline.ActionPipeline.execute(ActionPipeline.java:543)
2025/06/27 07:30:09 - prueba.hpl - 	at org.apache.hop.workflow.Workflow.executeFromStart(Workflow.java:751)
2025/06/27 07:30:09 - prueba.hpl - 	at org.apache.hop.workflow.Workflow.executeFromStart(Workflow.java:902)
2025/06/27 07:30:09 - prueba.hpl - 	at org.apache.hop.workflow.Workflow.executeFromStart(Workflow.java:453)
2025/06/27 07:30:09 - prueba.hpl - 	at org.apache.hop.workflow.Workflow.startExecution(Workflow.java:313)
2025/06/27 07:30:09 - prueba.hpl - 	at org.apache.hop.workflow.engines.local.LocalWorkflowEngine.startExecution(LocalWorkflowEngine.java:249)
2025/06/27 07:30:09 - prueba.hpl - 	at org.apache.hop.workflow.actions.workflow.ActionWorkflowRunner.run(ActionWorkflowRunner.java:55)
2025/06/27 07:30:09 - prueba.hpl - 	at java.base/java.lang.Thread.run(Thread.java:840)
[2025-06-27T07:30:09.590+0000] {docker.py:436} INFO - 2025/06/27 07:30:09 - filename - Finished action [prueba.hpl] (result=[false])
[2025-06-27T07:30:09.591+0000] {docker.py:436} INFO - 2025/06/27 07:30:09 - filename - Workflow execution finished
[2025-06-27T07:30:09.603+0000] {docker.py:436} INFO - 2025/06/27 07:30:09 - filename - Workflow duration : 12.906 seconds [ 12.906" ]
[2025-06-27T07:30:09.610+0000] {docker.py:436} INFO - 2025/06/27 07:30:09 - WF_MAIN - Finished action [filename.hwf] (result=[false])
[2025-06-27T07:30:09.611+0000] {docker.py:436} INFO - 2025/06/27 07:30:09 - WF_MAIN - Workflow execution finished
[2025-06-27T07:30:09.621+0000] {docker.py:436} INFO - 2025/06/27 07:30:09 - WF_MAIN - Workflow duration : 17.281 seconds [ 17.280" ]
[2025-06-27T07:30:09.622+0000] {docker.py:436} INFO - HopRun exit.
[2025-06-27T07:30:09.980+0000] {taskinstance.py:441} INFO - ::group::Post task execution logs
[2025-06-27T07:30:09.998+0000] {taskinstance.py:2905} ERROR - Task failed with exception
Traceback (most recent call last):
  File "/home/airflow/.local/lib/python3.12/site-packages/docker/api/client.py", line 265, in _raise_for_status
    response.raise_for_status()
  File "/home/airflow/.local/lib/python3.12/site-packages/requests/models.py", line 1021, in raise_for_status
    raise HTTPError(http_error_msg, response=self)
requests.exceptions.HTTPError: 400 Client Error: Bad Request for url: http+docker://localhost/v1.50/containers/create

The above exception was the direct cause of the following exception:

Traceback (most recent call last):
  File "/home/airflow/.local/lib/python3.12/site-packages/airflow/providers/docker/operators/docker.py", line 371, in _run_image
    return self._run_image_with_mounts([*self.mounts, tmp_mount], add_tmp_variable=True)
           ^^^^^^^^^^^^^^^^^^^^^^^^^^^^^^^^^^^^^^^^^^^^^^^^^^^^^^^^^^^^^^^^^^^^^^^^^^^^^
  File "/home/airflow/.local/lib/python3.12/site-packages/airflow/providers/docker/operators/docker.py", line 398, in _run_image_with_mounts
    self.container = self.cli.create_container(
                     ^^^^^^^^^^^^^^^^^^^^^^^^^^
  File "/home/airflow/.local/lib/python3.12/site-packages/docker/api/container.py", line 439, in create_container
    return self.create_container_from_config(config, name, platform)
           ^^^^^^^^^^^^^^^^^^^^^^^^^^^^^^^^^^^^^^^^^^^^^^^^^^^^^^^^^
  File "/home/airflow/.local/lib/python3.12/site-packages/docker/api/container.py", line 456, in create_container_from_config
    return self._result(res, True)
           ^^^^^^^^^^^^^^^^^^^^^^^
  File "/home/airflow/.local/lib/python3.12/site-packages/docker/api/client.py", line 271, in _result
    self._raise_for_status(response)
  File "/home/airflow/.local/lib/python3.12/site-packages/docker/api/client.py", line 267, in _raise_for_status
    raise create_api_error_from_http_exception(e) from e
          ^^^^^^^^^^^^^^^^^^^^^^^^^^^^^^^^^^^^^^^
  File "/home/airflow/.local/lib/python3.12/site-packages/docker/errors.py", line 39, in create_api_error_from_http_exception
    raise cls(e, response=response, explanation=explanation) from e
docker.errors.APIError: 400 Client Error for http+docker://localhost/v1.50/containers/create: Bad Request ("invalid mount config for type "bind": bind source path does not exist: /tmp/airflowtmpghhmdwu9")

During handling of the above exception, another exception occurred:

Traceback (most recent call last):
  File "/home/airflow/.local/lib/python3.12/site-packages/airflow/models/taskinstance.py", line 465, in _execute_task
    result = _execute_callable(context=context, **execute_callable_kwargs)
             ^^^^^^^^^^^^^^^^^^^^^^^^^^^^^^^^^^^^^^^^^^^^^^^^^^^^^^^^^^^^^
  File "/home/airflow/.local/lib/python3.12/site-packages/airflow/models/taskinstance.py", line 432, in _execute_callable
    return execute_callable(context=context, **execute_callable_kwargs)
           ^^^^^^^^^^^^^^^^^^^^^^^^^^^^^^^^^^^^^^^^^^^^^^^^^^^^^^^^^^^^
  File "/home/airflow/.local/lib/python3.12/site-packages/airflow/models/baseoperator.py", line 400, in wrapper
    return func(self, *args, **kwargs)
           ^^^^^^^^^^^^^^^^^^^^^^^^^^^
  File "/home/airflow/.local/lib/python3.12/site-packages/airflow/providers/docker/operators/docker.py", line 509, in execute
    return self._run_image()
           ^^^^^^^^^^^^^^^^^
  File "/home/airflow/.local/lib/python3.12/site-packages/airflow/providers/docker/operators/docker.py", line 380, in _run_image
    return self._run_image_with_mounts(self.mounts, add_tmp_variable=False)
           ^^^^^^^^^^^^^^^^^^^^^^^^^^^^^^^^^^^^^^^^^^^^^^^^^^^^^^^^^^^^^^^^
  File "/home/airflow/.local/lib/python3.12/site-packages/airflow/providers/docker/operators/docker.py", line 444, in _run_image_with_mounts
    raise DockerContainerFailedException(f"Docker container failed: {result!r}", logs=log_lines)
airflow.providers.docker.exceptions.DockerContainerFailedException: Docker container failed: {'StatusCode': 1}
[2025-06-27T07:30:10.013+0000] {taskinstance.py:1206} INFO - Marking task as FAILED. dag_id=WF_MAIN, task_id=run_hop_pipeline, run_id=scheduled__2025-06-27T05:41:00+00:00, execution_date=20250627T054100, start_date=20250627T072815, end_date=20250627T073010
[2025-06-27T07:30:10.039+0000] {standard_task_runner.py:110} ERROR - Failed to execute job 13 for task run_hop_pipeline (Docker container failed: {'StatusCode': 1}; 176)
[2025-06-27T07:30:10.088+0000] {local_task_job_runner.py:240} INFO - Task exited with return code 1
[2025-06-27T07:30:10.113+0000] {taskinstance.py:3498} INFO - 0 downstream tasks scheduled from follow-on schedule check
[2025-06-27T07:30:10.117+0000] {local_task_job_runner.py:222} INFO - ::endgroup::
[2025-06-27T07:43:54.196+0000] {local_task_job_runner.py:120} INFO - ::group::Pre task execution logs
[2025-06-27T07:43:54.223+0000] {taskinstance.py:2076} INFO - Dependencies all met for dep_context=non-requeueable deps ti=<TaskInstance: WF_MAIN.run_hop_pipeline scheduled__2025-06-27T05:41:00+00:00 [queued]>
[2025-06-27T07:43:54.232+0000] {taskinstance.py:2076} INFO - Dependencies all met for dep_context=requeueable deps ti=<TaskInstance: WF_MAIN.run_hop_pipeline scheduled__2025-06-27T05:41:00+00:00 [queued]>
[2025-06-27T07:43:54.233+0000] {taskinstance.py:2306} INFO - Starting attempt 2 of 2
[2025-06-27T07:43:54.247+0000] {taskinstance.py:2330} INFO - Executing <Task(DockerOperator): run_hop_pipeline> on 2025-06-27 05:41:00+00:00
[2025-06-27T07:43:54.254+0000] {warnings.py:110} WARNING - /home/***/.local/lib/python3.12/site-packages/***/task/task_runner/standard_task_runner.py:61: DeprecationWarning: This process (pid=156) is multi-threaded, use of fork() may lead to deadlocks in the child.
  pid = os.fork()

[2025-06-27T07:43:54.257+0000] {standard_task_runner.py:63} INFO - Started process 157 to run task
[2025-06-27T07:43:54.257+0000] {standard_task_runner.py:90} INFO - Running: ['***', 'tasks', 'run', 'WF_MAIN', 'run_hop_pipeline', 'scheduled__2025-06-27T05:41:00+00:00', '--job-id', '9', '--raw', '--subdir', 'DAGS_FOLDER/apache-hop-dag-wf-main.py', '--cfg-path', '/tmp/tmpnwuwfe0a']
[2025-06-27T07:43:54.259+0000] {standard_task_runner.py:91} INFO - Job 9: Subtask run_hop_pipeline
[2025-06-27T07:43:54.334+0000] {task_command.py:426} INFO - Running <TaskInstance: WF_MAIN.run_hop_pipeline scheduled__2025-06-27T05:41:00+00:00 [running]> on host ec14a5b8088e
[2025-06-27T07:43:54.451+0000] {taskinstance.py:2648} INFO - Exporting env vars: AIRFLOW_CTX_DAG_OWNER='***' AIRFLOW_CTX_DAG_ID='WF_MAIN' AIRFLOW_CTX_TASK_ID='run_hop_pipeline' AIRFLOW_CTX_EXECUTION_DATE='2025-06-27T05:41:00+00:00' AIRFLOW_CTX_TRY_NUMBER='2' AIRFLOW_CTX_DAG_RUN_ID='scheduled__2025-06-27T05:41:00+00:00'
[2025-06-27T07:43:54.455+0000] {taskinstance.py:430} INFO - ::endgroup::
[2025-06-27T07:43:54.561+0000] {docker.py:366} INFO - Starting docker container from image apache/hop:latest
[2025-06-27T07:43:54.574+0000] {docker.py:374} WARNING - Using remote engine or docker-in-docker and mounting temporary volume from host is not supported. Falling back to `mount_tmp_dir=False` mode. You can set `mount_tmp_dir` parameter to False to disable mounting and remove the warning
[2025-06-27T07:43:55.006+0000] {docker.py:436} INFO - 2025/06/27 07:43:54 - Running the entrypoint script with PID 6
[2025-06-27T07:43:55.007+0000] {docker.py:436} INFO - 2025/06/27 07:43:54 - The project folder for ProyectoSmartMed is set to: /files
[2025-06-27T07:43:55.008+0000] {docker.py:436} INFO - 2025/06/27 07:43:55 - The specified project folder exists
[2025-06-27T07:43:55.009+0000] {docker.py:436} INFO - 2025/06/27 07:43:55 - Registering project ProyectoSmartMed in the Hop container configuration
[2025-06-27T07:43:55.010+0000] {docker.py:436} INFO - 2025/06/27 07:43:55 - /opt/hop/hop-conf.sh --project=ProyectoSmartMed --project-create --project-home='/files' --project-config-file='project-config.json'
[2025-06-27T07:44:09.220+0000] {docker.py:436} INFO - Creating project 'ProyectoSmartMed'
[2025-06-27T07:44:09.406+0000] {docker.py:436} INFO - Project 'ProyectoSmartMed' was created for home folder : /files
[2025-06-27T07:44:09.457+0000] {docker.py:436} INFO - Configuration file for project 'ProyectoSmartMed' was saved to : file:/files/project-config.json
[2025-06-27T07:44:09.547+0000] {docker.py:436} INFO - 2025/06/27 07:44:09 - Not creating an environment in the container
[2025-06-27T07:44:09.548+0000] {docker.py:436} INFO - 2025/06/27 07:44:09 - Running a single hop workflow / pipeline (${PROJECT_HOME}/workflows/WF_MAIN.hwf)
[2025-06-27T07:44:17.093+0000] {docker.py:436} INFO - 2025/06/27 07:44:17 - HopRun - Enabling project 'ProyectoSmartMed'
[2025-06-27T07:44:17.277+0000] {docker.py:436} INFO - 2025/06/27 07:44:17 - HopRun - Starting workflow: /files/workflows/WF_MAIN.hwf
[2025-06-27T07:44:18.552+0000] {docker.py:436} INFO - 2025/06/27 07:44:18 - WF_MAIN - Start of workflow execution
[2025-06-27T07:44:18.623+0000] {docker.py:436} INFO - 2025/06/27 07:44:18 - WF_MAIN - Starting action [filename.hwf]
[2025-06-27T07:44:19.112+0000] {docker.py:436} INFO - 2025/06/27 07:44:19 - filename - Start of workflow execution
[2025-06-27T07:44:19.133+0000] {docker.py:436} INFO - 2025/06/27 07:44:19 - filename - Starting action [prueba.hpl]
[2025-06-27T07:44:19.203+0000] {docker.py:436} INFO - 2025/06/27 07:44:19 - prueba.hpl - Using run configuration [local]
[2025-06-27T07:44:19.233+0000] {docker.py:436} INFO - 2025/06/27 07:44:19 - prueba - Executing this pipeline using the Local Pipeline Engine with run configuration 'local'
[2025-06-27T07:44:19.241+0000] {docker.py:436} INFO - 2025/06/27 07:44:19 - prueba - Execution started for pipeline [prueba]
[2025-06-27T07:44:21.852+0000] {docker.py:436} INFO - 2025/06/27 07:44:21 - Table input.0 - Finished reading query, closing connection.
[2025-06-27T07:44:21.853+0000] {docker.py:436} INFO - 2025/06/27 07:44:21 - Set variables.0 - Setting project variables...
[2025-06-27T07:44:21.854+0000] {docker.py:436} INFO - 2025/06/27 07:44:21 - Set variables.0 - Set variable lastDate to value [2025-06-27 02:20:59]
[2025-06-27T07:44:21.858+0000] {docker.py:436} INFO - 2025/06/27 07:44:21 - Set variables.0 - Finished after 1 rows.
[2025-06-27T07:44:21.859+0000] {docker.py:436} INFO - 2025/06/27 07:44:21 - Set variables.0 - Finished processing (I=0, O=0, R=1, W=1, U=0, E=0)
[2025-06-27T07:44:21.956+0000] {docker.py:436} INFO - 2025/06/27 07:44:21 - Table input.0 - Finished processing (I=1, O=0, R=0, W=1, U=0, E=0)
[2025-06-27T07:44:32.258+0000] {docker.py:436} INFO - 2025/06/27 07:44:32 - REST client.0 - ERROR: Because of an error, this transform can't continue:
2025/06/27 07:44:32 - REST client.0 - Can not read result from [http://20.0.1.136:8000/api/v1/dags/dagruns]
2025/06/27 07:44:32 - REST client.0 - 
2025/06/27 07:44:32 - REST client.0 - Request could not be processed
2025/06/27 07:44:32 - REST client.0 - org.apache.http.conn.ConnectTimeoutException: Connect to 20.0.1.136:8000 [/20.0.1.136] failed: Connect timed out
[2025-06-27T07:44:32.261+0000] {docker.py:436} INFO - 2025/06/27 07:44:32 - REST client.0 - ERROR: org.apache.hop.core.exception.HopException: 
2025/06/27 07:44:32 - REST client.0 - Can not read result from [http://20.0.1.136:8000/api/v1/dags/dagruns]
2025/06/27 07:44:32 - REST client.0 - 
2025/06/27 07:44:32 - REST client.0 - Request could not be processed
2025/06/27 07:44:32 - REST client.0 - org.apache.http.conn.ConnectTimeoutException: Connect to 20.0.1.136:8000 [/20.0.1.136] failed: Connect timed out
2025/06/27 07:44:32 - REST client.0 - 
2025/06/27 07:44:32 - REST client.0 - 
2025/06/27 07:44:32 - REST client.0 - 	at org.apache.hop.pipeline.transforms.rest.Rest.callRest(Rest.java:321)
2025/06/27 07:44:32 - REST client.0 - 	at org.apache.hop.pipeline.transforms.rest.Rest.processRow(Rest.java:538)
2025/06/27 07:44:32 - REST client.0 - 	at org.apache.hop.pipeline.transform.RunThread.run(RunThread.java:54)
2025/06/27 07:44:32 - REST client.0 - 	at java.base/java.lang.Thread.run(Thread.java:840)
2025/06/27 07:44:32 - REST client.0 - Caused by: org.apache.hop.core.exception.HopException: 
2025/06/27 07:44:32 - REST client.0 - Request could not be processed
2025/06/27 07:44:32 - REST client.0 - org.apache.http.conn.ConnectTimeoutException: Connect to 20.0.1.136:8000 [/20.0.1.136] failed: Connect timed out
2025/06/27 07:44:32 - REST client.0 - 
2025/06/27 07:44:32 - REST client.0 - 	at org.apache.hop.pipeline.transforms.rest.Rest.callRest(Rest.java:258)
2025/06/27 07:44:32 - REST client.0 - 	... 3 more
2025/06/27 07:44:32 - REST client.0 - Caused by: javax.ws.rs.ProcessingException: org.apache.http.conn.ConnectTimeoutException: Connect to 20.0.1.136:8000 [/20.0.1.136] failed: Connect timed out
2025/06/27 07:44:32 - REST client.0 - 	at org.glassfish.jersey.apache.connector.ApacheConnector.apply(ApacheConnector.java:533)
2025/06/27 07:44:32 - REST client.0 - 	at org.glassfish.jersey.client.ClientRuntime.invoke(ClientRuntime.java:300)
2025/06/27 07:44:32 - REST client.0 - 	at org.glassfish.jersey.client.JerseyInvocation.lambda$invoke$1(JerseyInvocation.java:687)
2025/06/27 07:44:32 - REST client.0 - 	at org.glassfish.jersey.client.JerseyInvocation.call(JerseyInvocation.java:709)
2025/06/27 07:44:32 - REST client.0 - 	at org.glassfish.jersey.client.JerseyInvocation.lambda$runInScope$3(JerseyInvocation.java:703)
2025/06/27 07:44:32 - REST client.0 - 	at org.glassfish.jersey.internal.Errors.process(Errors.java:292)
2025/06/27 07:44:32 - REST client.0 - 	at org.glassfish.jersey.internal.Errors.process(Errors.java:274)
2025/06/27 07:44:32 - REST client.0 - 	at org.glassfish.jersey.internal.Errors.process(Errors.java:205)
2025/06/27 07:44:32 - REST client.0 - 	at org.glassfish.jersey.process.internal.RequestScope.runInScope(RequestScope.java:390)
2025/06/27 07:44:32 - REST client.0 - 	at org.glassfish.jersey.client.JerseyInvocation.runInScope(JerseyInvocation.java:703)
2025/06/27 07:44:32 - REST client.0 - 	at org.glassfish.jersey.client.JerseyInvocation.invoke(JerseyInvocation.java:686)
2025/06/27 07:44:32 - REST client.0 - 	at org.glassfish.jersey.client.JerseyInvocation$Builder.method(JerseyInvocation.java:422)
2025/06/27 07:44:32 - REST client.0 - 	at org.glassfish.jersey.client.JerseyInvocation$Builder.get(JerseyInvocation.java:318)
2025/06/27 07:44:32 - REST client.0 - 	at org.apache.hop.pipeline.transforms.rest.Rest.callRest(Rest.java:224)
2025/06/27 07:44:32 - REST client.0 - 	... 3 more
2025/06/27 07:44:32 - REST client.0 - Caused by: org.apache.http.conn.ConnectTimeoutException: Connect to 20.0.1.136:8000 [/20.0.1.136] failed: Connect timed out
2025/06/27 07:44:32 - REST client.0 - 	at org.apache.http.impl.conn.DefaultHttpClientConnectionOperator.connect(DefaultHttpClientConnectionOperator.java:151)
2025/06/27 07:44:32 - REST client.0 - 	at org.apache.http.impl.conn.PoolingHttpClientConnectionManager.connect(PoolingHttpClientConnectionManager.java:376)
2025/06/27 07:44:32 - REST client.0 - 	at org.apache.http.impl.execchain.MainClientExec.establishRoute(MainClientExec.java:393)
2025/06/27 07:44:32 - REST client.0 - 	at org.apache.http.impl.execchain.MainClientExec.execute(MainClientExec.java:236)
2025/06/27 07:44:32 - REST client.0 - 	at org.apache.http.impl.execchain.ProtocolExec.execute(ProtocolExec.java:186)
2025/06/27 07:44:32 - REST client.0 - 	at org.apache.http.impl.execchain.RetryExec.execute(RetryExec.java:89)
2025/06/27 07:44:32 - REST client.0 - 	at org.apache.http.impl.execchain.RedirectExec.execute(RedirectExec.java:110)
2025/06/27 07:44:32 - REST client.0 - 	at org.apache.http.impl.client.InternalHttpClient.doExecute(InternalHttpClient.java:185)
2025/06/27 07:44:32 - REST client.0 - 	at org.apache.http.impl.client.CloseableHttpClient.execute(CloseableHttpClient.java:72)
2025/06/27 07:44:32 - REST client.0 - 	at org.glassfish.jersey.apache.connector.ApacheConnector.apply(ApacheConnector.java:485)
2025/06/27 07:44:32 - REST client.0 - 	... 16 more
2025/06/27 07:44:32 - REST client.0 - Caused by: java.net.SocketTimeoutException: Connect timed out
2025/06/27 07:44:32 - REST client.0 - 	at java.base/sun.nio.ch.NioSocketImpl.timedFinishConnect(NioSocketImpl.java:551)
2025/06/27 07:44:32 - REST client.0 - 	at java.base/sun.nio.ch.NioSocketImpl.connect(NioSocketImpl.java:602)
2025/06/27 07:44:32 - REST client.0 - 	at java.base/java.net.SocksSocketImpl.connect(SocksSocketImpl.java:327)
2025/06/27 07:44:32 - REST client.0 - 	at java.base/java.net.Socket.connect(Socket.java:633)
2025/06/27 07:44:32 - REST client.0 - 	at org.apache.http.conn.socket.PlainConnectionSocketFactory.connectSocket(PlainConnectionSocketFactory.java:75)
2025/06/27 07:44:32 - REST client.0 - 	at org.apache.http.impl.conn.DefaultHttpClientConnectionOperator.connect(DefaultHttpClientConnectionOperator.java:142)
2025/06/27 07:44:32 - REST client.0 - 	... 25 more
[2025-06-27T07:44:32.262+0000] {docker.py:436} INFO - 2025/06/27 07:44:32 - REST client.0 - Finished processing (I=0, O=0, R=1, W=0, U=0, E=1)
2025/06/27 07:44:32 - prueba - Pipeline detected one or more transforms with errors.
2025/06/27 07:44:32 - prueba - Pipeline is killing the other transforms!
[2025-06-27T07:44:32.270+0000] {docker.py:436} INFO - 2025/06/27 07:44:32 - Set variables 2.0 - We didn't receive a row while setting the default values.
2025/06/27 07:44:32 - Set variables 2.0 - Finished after 0 rows.
[2025-06-27T07:44:32.278+0000] {docker.py:436} INFO - 2025/06/27 07:44:32 - prueba - Pipeline duration : 13.04 seconds [ 13.039" ]
[2025-06-27T07:44:32.310+0000] {docker.py:436} INFO - 2025/06/27 07:44:32 - prueba - Execution finished on a local pipeline engine with run configuration 'local'
[2025-06-27T07:44:32.317+0000] {docker.py:436} INFO - 2025/06/27 07:44:32 - filename - Finished action [prueba.hpl] (result=[false])
[2025-06-27T07:44:32.318+0000] {docker.py:436} INFO - 2025/06/27 07:44:32 - filename - Workflow execution finished
[2025-06-27T07:44:32.325+0000] {docker.py:436} INFO - 2025/06/27 07:44:32 - filename - Workflow duration : 13.645 seconds [ 13.644" ]
[2025-06-27T07:44:32.339+0000] {docker.py:436} INFO - 2025/06/27 07:44:32 - WF_MAIN - Finished action [filename.hwf] (result=[false])
2025/06/27 07:44:32 - WF_MAIN - Workflow execution finished
[2025-06-27T07:44:32.362+0000] {docker.py:436} INFO - 2025/06/27 07:44:32 - WF_MAIN - Workflow duration : 15.047 seconds [ 15.047" ]
HopRun exit.
[2025-06-27T07:44:32.895+0000] {taskinstance.py:441} INFO - ::group::Post task execution logs
[2025-06-27T07:44:32.919+0000] {taskinstance.py:2905} ERROR - Task failed with exception
Traceback (most recent call last):
  File "/home/airflow/.local/lib/python3.12/site-packages/docker/api/client.py", line 265, in _raise_for_status
    response.raise_for_status()
  File "/home/airflow/.local/lib/python3.12/site-packages/requests/models.py", line 1021, in raise_for_status
    raise HTTPError(http_error_msg, response=self)
requests.exceptions.HTTPError: 400 Client Error: Bad Request for url: http+docker://localhost/v1.50/containers/create

The above exception was the direct cause of the following exception:

Traceback (most recent call last):
  File "/home/airflow/.local/lib/python3.12/site-packages/airflow/providers/docker/operators/docker.py", line 371, in _run_image
    return self._run_image_with_mounts([*self.mounts, tmp_mount], add_tmp_variable=True)
           ^^^^^^^^^^^^^^^^^^^^^^^^^^^^^^^^^^^^^^^^^^^^^^^^^^^^^^^^^^^^^^^^^^^^^^^^^^^^^
  File "/home/airflow/.local/lib/python3.12/site-packages/airflow/providers/docker/operators/docker.py", line 398, in _run_image_with_mounts
    self.container = self.cli.create_container(
                     ^^^^^^^^^^^^^^^^^^^^^^^^^^
  File "/home/airflow/.local/lib/python3.12/site-packages/docker/api/container.py", line 439, in create_container
    return self.create_container_from_config(config, name, platform)
           ^^^^^^^^^^^^^^^^^^^^^^^^^^^^^^^^^^^^^^^^^^^^^^^^^^^^^^^^^
  File "/home/airflow/.local/lib/python3.12/site-packages/docker/api/container.py", line 456, in create_container_from_config
    return self._result(res, True)
           ^^^^^^^^^^^^^^^^^^^^^^^
  File "/home/airflow/.local/lib/python3.12/site-packages/docker/api/client.py", line 271, in _result
    self._raise_for_status(response)
  File "/home/airflow/.local/lib/python3.12/site-packages/docker/api/client.py", line 267, in _raise_for_status
    raise create_api_error_from_http_exception(e) from e
          ^^^^^^^^^^^^^^^^^^^^^^^^^^^^^^^^^^^^^^^
  File "/home/airflow/.local/lib/python3.12/site-packages/docker/errors.py", line 39, in create_api_error_from_http_exception
    raise cls(e, response=response, explanation=explanation) from e
docker.errors.APIError: 400 Client Error for http+docker://localhost/v1.50/containers/create: Bad Request ("invalid mount config for type "bind": bind source path does not exist: /tmp/airflowtmpo53wo_f2")

During handling of the above exception, another exception occurred:

Traceback (most recent call last):
  File "/home/airflow/.local/lib/python3.12/site-packages/airflow/models/taskinstance.py", line 465, in _execute_task
    result = _execute_callable(context=context, **execute_callable_kwargs)
             ^^^^^^^^^^^^^^^^^^^^^^^^^^^^^^^^^^^^^^^^^^^^^^^^^^^^^^^^^^^^^
  File "/home/airflow/.local/lib/python3.12/site-packages/airflow/models/taskinstance.py", line 432, in _execute_callable
    return execute_callable(context=context, **execute_callable_kwargs)
           ^^^^^^^^^^^^^^^^^^^^^^^^^^^^^^^^^^^^^^^^^^^^^^^^^^^^^^^^^^^^
  File "/home/airflow/.local/lib/python3.12/site-packages/airflow/models/baseoperator.py", line 400, in wrapper
    return func(self, *args, **kwargs)
           ^^^^^^^^^^^^^^^^^^^^^^^^^^^
  File "/home/airflow/.local/lib/python3.12/site-packages/airflow/providers/docker/operators/docker.py", line 509, in execute
    return self._run_image()
           ^^^^^^^^^^^^^^^^^
  File "/home/airflow/.local/lib/python3.12/site-packages/airflow/providers/docker/operators/docker.py", line 380, in _run_image
    return self._run_image_with_mounts(self.mounts, add_tmp_variable=False)
           ^^^^^^^^^^^^^^^^^^^^^^^^^^^^^^^^^^^^^^^^^^^^^^^^^^^^^^^^^^^^^^^^
  File "/home/airflow/.local/lib/python3.12/site-packages/airflow/providers/docker/operators/docker.py", line 444, in _run_image_with_mounts
    raise DockerContainerFailedException(f"Docker container failed: {result!r}", logs=log_lines)
airflow.providers.docker.exceptions.DockerContainerFailedException: Docker container failed: {'StatusCode': 1}
[2025-06-27T07:44:32.930+0000] {taskinstance.py:1206} INFO - Marking task as FAILED. dag_id=WF_MAIN, task_id=run_hop_pipeline, run_id=scheduled__2025-06-27T05:41:00+00:00, execution_date=20250627T054100, start_date=20250627T074354, end_date=20250627T074432
[2025-06-27T07:44:32.950+0000] {standard_task_runner.py:110} ERROR - Failed to execute job 9 for task run_hop_pipeline (Docker container failed: {'StatusCode': 1}; 157)
[2025-06-27T07:44:32.972+0000] {local_task_job_runner.py:240} INFO - Task exited with return code 1
[2025-06-27T07:44:33.011+0000] {taskinstance.py:3498} INFO - 0 downstream tasks scheduled from follow-on schedule check
[2025-06-27T07:44:33.016+0000] {local_task_job_runner.py:222} INFO - ::endgroup::
