[2025-06-27T02:22:29.688+0000] {local_task_job_runner.py:120} INFO - ::group::Pre task execution logs
[2025-06-27T02:22:29.774+0000] {taskinstance.py:2076} INFO - Dependencies all met for dep_context=non-requeueable deps ti=<TaskInstance: CARGA_MEDIDORES.run_hop_pipeline scheduled__2025-06-27T01:21:00+00:00 [queued]>
[2025-06-27T02:22:29.805+0000] {taskinstance.py:2076} INFO - Dependencies all met for dep_context=requeueable deps ti=<TaskInstance: CARGA_MEDIDORES.run_hop_pipeline scheduled__2025-06-27T01:21:00+00:00 [queued]>
[2025-06-27T02:22:29.809+0000] {taskinstance.py:2306} INFO - Starting attempt 1 of 2
[2025-06-27T02:22:29.881+0000] {taskinstance.py:2330} INFO - Executing <Task(DockerOperator): run_hop_pipeline> on 2025-06-27 01:21:00+00:00
[2025-06-27T02:22:29.915+0000] {warnings.py:110} WARNING - /home/***/.local/lib/python3.12/site-packages/***/task/task_runner/standard_task_runner.py:61: DeprecationWarning: This process (pid=66) is multi-threaded, use of fork() may lead to deadlocks in the child.
  pid = os.fork()

[2025-06-27T02:22:29.925+0000] {standard_task_runner.py:63} INFO - Started process 72 to run task
[2025-06-27T02:22:29.926+0000] {standard_task_runner.py:90} INFO - Running: ['***', 'tasks', 'run', 'CARGA_MEDIDORES', 'run_hop_pipeline', 'scheduled__2025-06-27T01:21:00+00:00', '--job-id', '7', '--raw', '--subdir', 'DAGS_FOLDER/apache-hop-dag-pipeline-carga-medidores.py', '--cfg-path', '/tmp/tmpdj8u7b9u']
[2025-06-27T02:22:29.938+0000] {standard_task_runner.py:91} INFO - Job 7: Subtask run_hop_pipeline
[2025-06-27T02:22:30.452+0000] {task_command.py:426} INFO - Running <TaskInstance: CARGA_MEDIDORES.run_hop_pipeline scheduled__2025-06-27T01:21:00+00:00 [running]> on host 0b41c6d28592
[2025-06-27T02:22:30.819+0000] {taskinstance.py:2648} INFO - Exporting env vars: AIRFLOW_CTX_DAG_OWNER='***' AIRFLOW_CTX_DAG_ID='CARGA_MEDIDORES' AIRFLOW_CTX_TASK_ID='run_hop_pipeline' AIRFLOW_CTX_EXECUTION_DATE='2025-06-27T01:21:00+00:00' AIRFLOW_CTX_TRY_NUMBER='1' AIRFLOW_CTX_DAG_RUN_ID='scheduled__2025-06-27T01:21:00+00:00'
[2025-06-27T02:22:30.821+0000] {taskinstance.py:430} INFO - ::endgroup::
[2025-06-27T02:22:30.952+0000] {docker.py:493} INFO - Pulling docker image apache/hop:latest
[2025-06-27T02:22:33.723+0000] {docker.py:507} INFO - latest: Pulling from apache/hop
[2025-06-27T02:22:37.968+0000] {docker.py:507} INFO - 4f4fb700ef54: Pulling fs layer
[2025-06-27T02:22:37.969+0000] {docker.py:507} INFO - 19f1029c3f10: Pulling fs layer
[2025-06-27T02:22:37.969+0000] {docker.py:507} INFO - eb2b48b7cabe: Pulling fs layer
[2025-06-27T02:22:37.971+0000] {docker.py:507} INFO - f488a4dddc73: Pulling fs layer
[2025-06-27T02:22:37.971+0000] {docker.py:507} INFO - d4d2578e96cd: Pulling fs layer
[2025-06-27T02:22:37.972+0000] {docker.py:507} INFO - bf26d906d0f5: Pulling fs layer
[2025-06-27T02:22:37.974+0000] {docker.py:507} INFO - f18232174bc9: Pulling fs layer
[2025-06-27T02:22:37.975+0000] {docker.py:507} INFO - 9b6bc2cf1037: Pulling fs layer
[2025-06-27T02:22:37.999+0000] {docker.py:507} INFO - 4f4fb700ef54: Already exists
[2025-06-27T02:22:38.004+0000] {docker.py:507} INFO - 4f4fb700ef54: Pull complete
[2025-06-27T02:22:38.297+0000] {docker.py:507} INFO - 9b6bc2cf1037: Downloading
[2025-06-27T02:22:38.710+0000] {docker.py:507} INFO - f488a4dddc73: Downloading
[2025-06-27T02:22:38.711+0000] {docker.py:507} INFO - eb2b48b7cabe: Downloading
[2025-06-27T02:22:38.715+0000] {docker.py:507} INFO - d4d2578e96cd: Downloading
[2025-06-27T02:22:39.115+0000] {docker.py:507} INFO - bf26d906d0f5: Downloading
[2025-06-27T02:22:39.332+0000] {docker.py:507} INFO - 19f1029c3f10: Downloading
[2025-06-27T02:22:39.337+0000] {docker.py:507} INFO - f18232174bc9: Downloading
[2025-06-27T02:22:47.951+0000] {docker.py:507} INFO - 9b6bc2cf1037: Download complete
[2025-06-27T02:22:48.163+0000] {docker.py:507} INFO - eb2b48b7cabe: Download complete
[2025-06-27T02:22:48.231+0000] {docker.py:507} INFO - d4d2578e96cd: Download complete
[2025-06-27T02:22:49.021+0000] {docker.py:507} INFO - bf26d906d0f5: Download complete
[2025-06-27T02:22:49.043+0000] {docker.py:507} INFO - f18232174bc9: Download complete
[2025-06-27T02:22:49.101+0000] {docker.py:507} INFO - f18232174bc9: Extracting
[2025-06-27T02:22:52.538+0000] {docker.py:507} INFO - 19f1029c3f10: Download complete
[2025-06-27T02:22:54.035+0000] {docker.py:507} INFO - f18232174bc9: Pull complete
[2025-06-27T02:23:00.899+0000] {docker.py:507} INFO - d4d2578e96cd: Extracting
[2025-06-27T02:23:06.507+0000] {docker.py:507} INFO - d4d2578e96cd: Pull complete
[2025-06-27T02:23:09.801+0000] {docker.py:507} INFO - 19f1029c3f10: Extracting
[2025-06-27T02:23:24.865+0000] {docker.py:507} INFO - 19f1029c3f10: Pull complete
[2025-06-27T02:23:30.294+0000] {docker.py:507} INFO - bf26d906d0f5: Extracting
[2025-06-27T02:23:31.096+0000] {docker.py:507} INFO - bf26d906d0f5: Pull complete
[2025-06-27T02:23:40.685+0000] {docker.py:507} INFO - f488a4dddc73: Download complete
[2025-06-27T02:23:40.698+0000] {docker.py:507} INFO - f488a4dddc73: Extracting
[2025-06-27T02:24:20.386+0000] {docker.py:507} INFO - f488a4dddc73: Pull complete
[2025-06-27T02:24:20.484+0000] {docker.py:507} INFO - 9b6bc2cf1037: Pull complete
[2025-06-27T02:24:20.684+0000] {docker.py:507} INFO - eb2b48b7cabe: Pull complete
[2025-06-27T02:24:21.157+0000] {docker.py:502} INFO - Digest: sha256:950a95da3332a2782706665b58adeed820689d87e0ca5b54df59bc995b2d955e
[2025-06-27T02:24:21.158+0000] {docker.py:502} INFO - Status: Downloaded newer image for apache/hop:latest
[2025-06-27T02:24:21.173+0000] {docker.py:366} INFO - Starting docker container from image apache/hop:latest
[2025-06-27T02:24:21.319+0000] {taskinstance.py:441} INFO - ::group::Post task execution logs
[2025-06-27T02:24:21.341+0000] {taskinstance.py:2905} ERROR - Task failed with exception
Traceback (most recent call last):
  File "/home/airflow/.local/lib/python3.12/site-packages/docker/api/client.py", line 265, in _raise_for_status
    response.raise_for_status()
  File "/home/airflow/.local/lib/python3.12/site-packages/requests/models.py", line 1021, in raise_for_status
    raise HTTPError(http_error_msg, response=self)
requests.exceptions.HTTPError: 400 Client Error: Bad Request for url: http+docker://localhost/v1.50/containers/create

The above exception was the direct cause of the following exception:

Traceback (most recent call last):
  File "/home/airflow/.local/lib/python3.12/site-packages/airflow/models/taskinstance.py", line 465, in _execute_task
    result = _execute_callable(context=context, **execute_callable_kwargs)
             ^^^^^^^^^^^^^^^^^^^^^^^^^^^^^^^^^^^^^^^^^^^^^^^^^^^^^^^^^^^^^
  File "/home/airflow/.local/lib/python3.12/site-packages/airflow/models/taskinstance.py", line 432, in _execute_callable
    return execute_callable(context=context, **execute_callable_kwargs)
           ^^^^^^^^^^^^^^^^^^^^^^^^^^^^^^^^^^^^^^^^^^^^^^^^^^^^^^^^^^^^
  File "/home/airflow/.local/lib/python3.12/site-packages/airflow/models/baseoperator.py", line 400, in wrapper
    return func(self, *args, **kwargs)
           ^^^^^^^^^^^^^^^^^^^^^^^^^^^
  File "/home/airflow/.local/lib/python3.12/site-packages/airflow/providers/docker/operators/docker.py", line 509, in execute
    return self._run_image()
           ^^^^^^^^^^^^^^^^^
  File "/home/airflow/.local/lib/python3.12/site-packages/airflow/providers/docker/operators/docker.py", line 371, in _run_image
    return self._run_image_with_mounts([*self.mounts, tmp_mount], add_tmp_variable=True)
           ^^^^^^^^^^^^^^^^^^^^^^^^^^^^^^^^^^^^^^^^^^^^^^^^^^^^^^^^^^^^^^^^^^^^^^^^^^^^^
  File "/home/airflow/.local/lib/python3.12/site-packages/airflow/providers/docker/operators/docker.py", line 398, in _run_image_with_mounts
    self.container = self.cli.create_container(
                     ^^^^^^^^^^^^^^^^^^^^^^^^^^
  File "/home/airflow/.local/lib/python3.12/site-packages/docker/api/container.py", line 439, in create_container
    return self.create_container_from_config(config, name, platform)
           ^^^^^^^^^^^^^^^^^^^^^^^^^^^^^^^^^^^^^^^^^^^^^^^^^^^^^^^^^
  File "/home/airflow/.local/lib/python3.12/site-packages/docker/api/container.py", line 456, in create_container_from_config
    return self._result(res, True)
           ^^^^^^^^^^^^^^^^^^^^^^^
  File "/home/airflow/.local/lib/python3.12/site-packages/docker/api/client.py", line 271, in _result
    self._raise_for_status(response)
  File "/home/airflow/.local/lib/python3.12/site-packages/docker/api/client.py", line 267, in _raise_for_status
    raise create_api_error_from_http_exception(e) from e
          ^^^^^^^^^^^^^^^^^^^^^^^^^^^^^^^^^^^^^^^
  File "/home/airflow/.local/lib/python3.12/site-packages/docker/errors.py", line 39, in create_api_error_from_http_exception
    raise cls(e, response=response, explanation=explanation) from e
docker.errors.APIError: 400 Client Error for http+docker://localhost/v1.50/containers/create: Bad Request ("invalid mount config for type "bind": bind source path does not exist: /mnt/data/ProyectoSmart/ProyectoSmartMed")
[2025-06-27T02:24:21.438+0000] {taskinstance.py:1206} INFO - Marking task as UP_FOR_RETRY. dag_id=CARGA_MEDIDORES, task_id=run_hop_pipeline, run_id=scheduled__2025-06-27T01:21:00+00:00, execution_date=20250627T012100, start_date=20250627T022229, end_date=20250627T022421
[2025-06-27T02:24:21.492+0000] {standard_task_runner.py:110} ERROR - Failed to execute job 7 for task run_hop_pipeline (400 Client Error for http+docker://localhost/v1.50/containers/create: Bad Request ("invalid mount config for type "bind": bind source path does not exist: /mnt/data/ProyectoSmart/ProyectoSmartMed"); 72)
[2025-06-27T02:24:21.589+0000] {local_task_job_runner.py:240} INFO - Task exited with return code 1
[2025-06-27T02:24:21.701+0000] {taskinstance.py:3498} INFO - 0 downstream tasks scheduled from follow-on schedule check
[2025-06-27T02:24:21.715+0000] {local_task_job_runner.py:222} INFO - ::endgroup::
