[2025-06-27T01:29:15.194+0000] {local_task_job_runner.py:120} INFO - ::group::Pre task execution logs
[2025-06-27T01:29:15.516+0000] {taskinstance.py:2076} INFO - Dependencies all met for dep_context=non-requeueable deps ti=<TaskInstance: CARGA_MEDIDORES.run_hop_pipeline scheduled__2025-06-27T00:21:00+00:00 [queued]>
[2025-06-27T01:29:16.419+0000] {taskinstance.py:2076} INFO - Dependencies all met for dep_context=requeueable deps ti=<TaskInstance: CARGA_MEDIDORES.run_hop_pipeline scheduled__2025-06-27T00:21:00+00:00 [queued]>
[2025-06-27T01:29:16.427+0000] {taskinstance.py:2306} INFO - Starting attempt 1 of 2
[2025-06-27T01:29:17.257+0000] {taskinstance.py:2330} INFO - Executing <Task(DockerOperator): run_hop_pipeline> on 2025-06-27 00:21:00+00:00
[2025-06-27T01:29:17.397+0000] {warnings.py:110} WARNING - /home/***/.local/lib/python3.12/site-packages/***/task/task_runner/standard_task_runner.py:61: DeprecationWarning: This process (pid=129) is multi-threaded, use of fork() may lead to deadlocks in the child.
  pid = os.fork()

[2025-06-27T01:29:17.565+0000] {standard_task_runner.py:63} INFO - Started process 135 to run task
[2025-06-27T01:29:17.375+0000] {standard_task_runner.py:90} INFO - Running: ['***', 'tasks', 'run', 'CARGA_MEDIDORES', 'run_hop_pipeline', 'scheduled__2025-06-27T00:21:00+00:00', '--job-id', '12', '--raw', '--subdir', 'DAGS_FOLDER/apache-hop-dag-pipeline-carga-medidores.py', '--cfg-path', '/tmp/tmpass8klpv']
[2025-06-27T01:29:17.724+0000] {standard_task_runner.py:91} INFO - Job 12: Subtask run_hop_pipeline
[2025-06-27T01:29:31.711+0000] {task_command.py:426} INFO - Running <TaskInstance: CARGA_MEDIDORES.run_hop_pipeline scheduled__2025-06-27T00:21:00+00:00 [running]> on host ca79c413dce4
[2025-06-27T01:29:42.478+0000] {taskinstance.py:2648} INFO - Exporting env vars: AIRFLOW_CTX_DAG_OWNER='***' AIRFLOW_CTX_DAG_ID='CARGA_MEDIDORES' AIRFLOW_CTX_TASK_ID='run_hop_pipeline' AIRFLOW_CTX_EXECUTION_DATE='2025-06-27T00:21:00+00:00' AIRFLOW_CTX_TRY_NUMBER='1' AIRFLOW_CTX_DAG_RUN_ID='scheduled__2025-06-27T00:21:00+00:00'
[2025-06-27T01:29:42.480+0000] {taskinstance.py:430} INFO - ::endgroup::
[2025-06-27T01:29:51.004+0000] {docker.py:493} INFO - Pulling docker image apache/hop:latest
[2025-06-27T01:30:07.651+0000] {docker.py:507} INFO - latest: Pulling from apache/hop
[2025-06-27T01:30:14.283+0000] {docker.py:507} INFO - 4f4fb700ef54: Pulling fs layer
[2025-06-27T01:30:14.284+0000] {docker.py:507} INFO - 9b6bc2cf1037: Pulling fs layer
[2025-06-27T01:30:14.285+0000] {docker.py:507} INFO - d4d2578e96cd: Pulling fs layer
[2025-06-27T01:30:14.285+0000] {docker.py:507} INFO - eb2b48b7cabe: Pulling fs layer
[2025-06-27T01:30:14.286+0000] {docker.py:507} INFO - 19f1029c3f10: Pulling fs layer
[2025-06-27T01:30:14.286+0000] {docker.py:507} INFO - f488a4dddc73: Pulling fs layer
[2025-06-27T01:30:14.287+0000] {docker.py:507} INFO - f18232174bc9: Pulling fs layer
[2025-06-27T01:30:14.288+0000] {docker.py:507} INFO - bf26d906d0f5: Pulling fs layer
[2025-06-27T01:30:14.313+0000] {docker.py:507} INFO - 4f4fb700ef54: Already exists
[2025-06-27T01:30:14.318+0000] {docker.py:507} INFO - 4f4fb700ef54: Pull complete
[2025-06-27T01:30:16.655+0000] {docker.py:507} INFO - 9b6bc2cf1037: Downloading
[2025-06-27T01:30:16.660+0000] {docker.py:507} INFO - d4d2578e96cd: Downloading
[2025-06-27T01:30:16.805+0000] {docker.py:507} INFO - f488a4dddc73: Downloading
[2025-06-27T01:30:17.273+0000] {docker.py:507} INFO - 19f1029c3f10: Downloading
[2025-06-27T01:30:18.554+0000] {docker.py:507} INFO - eb2b48b7cabe: Downloading
[2025-06-27T01:30:18.842+0000] {docker.py:507} INFO - f18232174bc9: Downloading
[2025-06-27T01:30:19.056+0000] {docker.py:507} INFO - bf26d906d0f5: Downloading
[2025-06-27T01:30:47.706+0000] {docker.py:507} INFO - 9b6bc2cf1037: Download complete
[2025-06-27T01:30:47.804+0000] {docker.py:507} INFO - d4d2578e96cd: Download complete
[2025-06-27T01:30:53.031+0000] {docker.py:507} INFO - eb2b48b7cabe: Download complete
[2025-06-27T01:30:53.033+0000] {docker.py:507} INFO - bf26d906d0f5: Download complete
[2025-06-27T01:30:53.202+0000] {docker.py:507} INFO - f18232174bc9: Download complete
[2025-06-27T01:30:53.231+0000] {docker.py:507} INFO - f18232174bc9: Extracting
[2025-06-27T01:30:58.992+0000] {docker.py:507} INFO - 19f1029c3f10: Download complete
[2025-06-27T01:31:41.005+0000] {docker.py:507} INFO - f18232174bc9: Pull complete
[2025-06-27T01:31:56.857+0000] {docker.py:507} INFO - d4d2578e96cd: Extracting
[2025-06-27T01:32:03.999+0000] {docker.py:507} INFO - d4d2578e96cd: Pull complete
[2025-06-27T01:32:07.927+0000] {docker.py:507} INFO - 19f1029c3f10: Extracting
[2025-06-27T01:34:40.708+0000] {docker.py:507} INFO - f488a4dddc73: Download complete
[2025-06-27T01:34:45.419+0000] {docker.py:507} INFO - 19f1029c3f10: Pull complete
[2025-06-27T01:34:45.730+0000] {docker.py:507} INFO - bf26d906d0f5: Extracting
[2025-06-27T01:34:46.657+0000] {docker.py:507} INFO - bf26d906d0f5: Pull complete
[2025-06-27T01:34:46.842+0000] {docker.py:507} INFO - f488a4dddc73: Extracting
[2025-06-27T01:36:50.967+0000] {docker.py:507} INFO - f488a4dddc73: Pull complete
[2025-06-27T01:36:51.161+0000] {docker.py:507} INFO - 9b6bc2cf1037: Extracting
[2025-06-27T01:36:51.260+0000] {docker.py:507} INFO - 9b6bc2cf1037: Pull complete
[2025-06-27T01:36:51.465+0000] {docker.py:507} INFO - eb2b48b7cabe: Pull complete
[2025-06-27T01:36:51.942+0000] {docker.py:502} INFO - Digest: sha256:950a95da3332a2782706665b58adeed820689d87e0ca5b54df59bc995b2d955e
[2025-06-27T01:36:51.950+0000] {docker.py:502} INFO - Status: Downloaded newer image for apache/hop:latest
[2025-06-27T01:36:52.165+0000] {docker.py:366} INFO - Starting docker container from image apache/hop:latest
[2025-06-27T01:36:52.315+0000] {taskinstance.py:441} INFO - ::group::Post task execution logs
[2025-06-27T01:36:52.324+0000] {taskinstance.py:2905} ERROR - Task failed with exception
Traceback (most recent call last):
  File "/home/airflow/.local/lib/python3.12/site-packages/docker/api/client.py", line 265, in _raise_for_status
    response.raise_for_status()
  File "/home/airflow/.local/lib/python3.12/site-packages/requests/models.py", line 1021, in raise_for_status
    raise HTTPError(http_error_msg, response=self)
requests.exceptions.HTTPError: 500 Server Error: Internal Server Error for url: http+docker://localhost/v1.50/containers/create

The above exception was the direct cause of the following exception:

Traceback (most recent call last):
  File "/home/airflow/.local/lib/python3.12/site-packages/airflow/models/taskinstance.py", line 465, in _execute_task
    result = _execute_callable(context=context, **execute_callable_kwargs)
             ^^^^^^^^^^^^^^^^^^^^^^^^^^^^^^^^^^^^^^^^^^^^^^^^^^^^^^^^^^^^^
  File "/home/airflow/.local/lib/python3.12/site-packages/airflow/models/taskinstance.py", line 432, in _execute_callable
    return execute_callable(context=context, **execute_callable_kwargs)
           ^^^^^^^^^^^^^^^^^^^^^^^^^^^^^^^^^^^^^^^^^^^^^^^^^^^^^^^^^^^^
  File "/home/airflow/.local/lib/python3.12/site-packages/airflow/models/baseoperator.py", line 400, in wrapper
    return func(self, *args, **kwargs)
           ^^^^^^^^^^^^^^^^^^^^^^^^^^^
  File "/home/airflow/.local/lib/python3.12/site-packages/airflow/providers/docker/operators/docker.py", line 509, in execute
    return self._run_image()
           ^^^^^^^^^^^^^^^^^
  File "/home/airflow/.local/lib/python3.12/site-packages/airflow/providers/docker/operators/docker.py", line 371, in _run_image
    return self._run_image_with_mounts([*self.mounts, tmp_mount], add_tmp_variable=True)
           ^^^^^^^^^^^^^^^^^^^^^^^^^^^^^^^^^^^^^^^^^^^^^^^^^^^^^^^^^^^^^^^^^^^^^^^^^^^^^
  File "/home/airflow/.local/lib/python3.12/site-packages/airflow/providers/docker/operators/docker.py", line 398, in _run_image_with_mounts
    self.container = self.cli.create_container(
                     ^^^^^^^^^^^^^^^^^^^^^^^^^^
  File "/home/airflow/.local/lib/python3.12/site-packages/docker/api/container.py", line 439, in create_container
    return self.create_container_from_config(config, name, platform)
           ^^^^^^^^^^^^^^^^^^^^^^^^^^^^^^^^^^^^^^^^^^^^^^^^^^^^^^^^^
  File "/home/airflow/.local/lib/python3.12/site-packages/docker/api/container.py", line 456, in create_container_from_config
    return self._result(res, True)
           ^^^^^^^^^^^^^^^^^^^^^^^
  File "/home/airflow/.local/lib/python3.12/site-packages/docker/api/client.py", line 271, in _result
    self._raise_for_status(response)
  File "/home/airflow/.local/lib/python3.12/site-packages/docker/api/client.py", line 267, in _raise_for_status
    raise create_api_error_from_http_exception(e) from e
          ^^^^^^^^^^^^^^^^^^^^^^^^^^^^^^^^^^^^^^^
  File "/home/airflow/.local/lib/python3.12/site-packages/docker/errors.py", line 39, in create_api_error_from_http_exception
    raise cls(e, response=response, explanation=explanation) from e
docker.errors.APIError: 500 Server Error for http+docker://localhost/v1.50/containers/create: Internal Server Error ("mkdir C:\Users\danie: Access is denied.")
[2025-06-27T01:36:52.490+0000] {taskinstance.py:1206} INFO - Marking task as UP_FOR_RETRY. dag_id=CARGA_MEDIDORES, task_id=run_hop_pipeline, run_id=scheduled__2025-06-27T00:21:00+00:00, execution_date=20250627T002100, start_date=20250627T012915, end_date=20250627T013652
[2025-06-27T01:36:52.599+0000] {standard_task_runner.py:110} ERROR - Failed to execute job 12 for task run_hop_pipeline (500 Server Error for http+docker://localhost/v1.50/containers/create: Internal Server Error ("mkdir C:\Users\danie: Access is denied."); 135)
[2025-06-27T01:36:52.723+0000] {local_task_job_runner.py:240} INFO - Task exited with return code 1
[2025-06-27T01:36:52.903+0000] {taskinstance.py:3498} INFO - 0 downstream tasks scheduled from follow-on schedule check
[2025-06-27T01:36:52.933+0000] {local_task_job_runner.py:222} INFO - ::endgroup::
