[2025-06-27T06:46:18.196+0000] {local_task_job_runner.py:120} INFO - ::group::Pre task execution logs
[2025-06-27T06:46:18.251+0000] {taskinstance.py:2076} INFO - Dependencies all met for dep_context=non-requeueable deps ti=<TaskInstance: STG4_MEDIDORES.run_hop_pipeline scheduled__2025-06-27T05:21:00+00:00 [queued]>
[2025-06-27T06:46:18.277+0000] {taskinstance.py:2076} INFO - Dependencies all met for dep_context=requeueable deps ti=<TaskInstance: STG4_MEDIDORES.run_hop_pipeline scheduled__2025-06-27T05:21:00+00:00 [queued]>
[2025-06-27T06:46:18.278+0000] {taskinstance.py:2306} INFO - Starting attempt 1 of 2
[2025-06-27T06:46:18.314+0000] {taskinstance.py:2330} INFO - Executing <Task(DockerOperator): run_hop_pipeline> on 2025-06-27 05:21:00+00:00
[2025-06-27T06:46:18.331+0000] {warnings.py:110} WARNING - /home/***/.local/lib/python3.12/site-packages/***/task/task_runner/standard_task_runner.py:61: DeprecationWarning: This process (pid=66) is multi-threaded, use of fork() may lead to deadlocks in the child.
  pid = os.fork()

[2025-06-27T06:46:18.334+0000] {standard_task_runner.py:63} INFO - Started process 70 to run task
[2025-06-27T06:46:18.335+0000] {standard_task_runner.py:90} INFO - Running: ['***', 'tasks', 'run', 'STG4_MEDIDORES', 'run_hop_pipeline', 'scheduled__2025-06-27T05:21:00+00:00', '--job-id', '4', '--raw', '--subdir', 'DAGS_FOLDER/apache-hop-dag-simple.py', '--cfg-path', '/tmp/tmp9lhbk_9q']
[2025-06-27T06:46:18.338+0000] {standard_task_runner.py:91} INFO - Job 4: Subtask run_hop_pipeline
[2025-06-27T06:46:18.506+0000] {task_command.py:426} INFO - Running <TaskInstance: STG4_MEDIDORES.run_hop_pipeline scheduled__2025-06-27T05:21:00+00:00 [running]> on host eefc0d82eb46
[2025-06-27T06:46:18.755+0000] {taskinstance.py:2648} INFO - Exporting env vars: AIRFLOW_CTX_DAG_OWNER='***' AIRFLOW_CTX_DAG_ID='STG4_MEDIDORES' AIRFLOW_CTX_TASK_ID='run_hop_pipeline' AIRFLOW_CTX_EXECUTION_DATE='2025-06-27T05:21:00+00:00' AIRFLOW_CTX_TRY_NUMBER='1' AIRFLOW_CTX_DAG_RUN_ID='scheduled__2025-06-27T05:21:00+00:00'
[2025-06-27T06:46:18.758+0000] {taskinstance.py:430} INFO - ::endgroup::
[2025-06-27T06:46:19.026+0000] {docker.py:366} INFO - Starting docker container from image apache/hop:latest
[2025-06-27T06:46:19.060+0000] {docker.py:374} WARNING - Using remote engine or docker-in-docker and mounting temporary volume from host is not supported. Falling back to `mount_tmp_dir=False` mode. You can set `mount_tmp_dir` parameter to False to disable mounting and remove the warning
[2025-06-27T06:46:20.481+0000] {docker.py:436} INFO - 2025/06/27 06:46:20 - Running the entrypoint script with PID 7
[2025-06-27T06:46:20.485+0000] {docker.py:436} INFO - 2025/06/27 06:46:20 - The project folder for ProyectoSmartMed is set to: /files
[2025-06-27T06:46:20.491+0000] {docker.py:436} INFO - 2025/06/27 06:46:20 - The specified project folder exists
[2025-06-27T06:46:20.498+0000] {docker.py:436} INFO - 2025/06/27 06:46:20 - Registering project ProyectoSmartMed in the Hop container configuration
[2025-06-27T06:46:20.499+0000] {docker.py:436} INFO - 2025/06/27 06:46:20 - /opt/hop/hop-conf.sh --project=ProyectoSmartMed --project-create --project-home='/files' --project-config-file='project-config.json'
[2025-06-27T06:47:22.733+0000] {docker.py:436} INFO - Creating project 'ProyectoSmartMed'
[2025-06-27T06:47:23.337+0000] {docker.py:436} INFO - Project 'ProyectoSmartMed' was created for home folder : /files
[2025-06-27T06:47:23.526+0000] {docker.py:436} INFO - Configuration file for project 'ProyectoSmartMed' was saved to : file:/files/project-config.json
[2025-06-27T06:47:23.702+0000] {docker.py:436} INFO - 2025/06/27 06:47:23 - Not creating an environment in the container
[2025-06-27T06:47:23.709+0000] {docker.py:436} INFO - 2025/06/27 06:47:23 - Running a single hop workflow / pipeline (${PROJECT_HOME}/Pipelines/STG4_MEDIDORES.hpl)
[2025-06-27T06:47:48.638+0000] {docker.py:436} INFO - 2025/06/27 06:47:48 - HopRun - Enabling project 'ProyectoSmartMed'
[2025-06-27T06:47:49.485+0000] {docker.py:436} INFO - 2025/06/27 06:47:49 - HopRun - Starting pipeline: /files/Pipelines/STG4_MEDIDORES.hpl
[2025-06-27T06:47:49.501+0000] {docker.py:436} INFO - 2025/06/27 06:47:49 - STG4_MEDIDORES - Executing this pipeline using the Local Pipeline Engine with run configuration 'local'
[2025-06-27T06:47:49.539+0000] {docker.py:436} INFO - 2025/06/27 06:47:49 - STG4_MEDIDORES - Execution started for pipeline [STG4_MEDIDORES]
[2025-06-27T06:47:52.890+0000] {docker.py:436} INFO - 2025/06/27 06:47:52 - STG4_MEDIDORES.0 - Connected to database [POSTGRES_SMART] (commit=1000)
[2025-06-27T06:48:01.537+0000] {docker.py:436} INFO - 2025/06/27 06:48:01 - STG3_MEDIDORES.0 - Finished reading query, closing connection.
[2025-06-27T06:48:01.658+0000] {docker.py:436} INFO - 2025/06/27 06:48:01 - STG3_MEDIDORES.0 - Finished processing (I=16398, O=0, R=0, W=16398, U=0, E=0)
[2025-06-27T06:48:07.745+0000] {docker.py:436} INFO - 2025/06/27 06:48:07 - STG4_MEDIDORES.0 - Finished processing (I=0, O=16398, R=16398, W=16398, U=0, E=0)
[2025-06-27T06:48:07.766+0000] {docker.py:436} INFO - 2025/06/27 06:48:07 - STG4_MEDIDORES - Pipeline duration : 18.263 seconds [ 18.263" ]
[2025-06-27T06:48:07.833+0000] {docker.py:436} INFO - HopRun exit.
2025/06/27 06:48:07 - STG4_MEDIDORES - Execution finished on a local pipeline engine with run configuration 'local'
[2025-06-27T06:48:08.258+0000] {taskinstance.py:441} INFO - ::group::Post task execution logs
[2025-06-27T06:48:08.321+0000] {taskinstance.py:1206} INFO - Marking task as SUCCESS. dag_id=STG4_MEDIDORES, task_id=run_hop_pipeline, run_id=scheduled__2025-06-27T05:21:00+00:00, execution_date=20250627T052100, start_date=20250627T064618, end_date=20250627T064808
[2025-06-27T06:48:08.392+0000] {local_task_job_runner.py:240} INFO - Task exited with return code 0
[2025-06-27T06:48:08.427+0000] {taskinstance.py:3498} INFO - 0 downstream tasks scheduled from follow-on schedule check
[2025-06-27T06:48:08.430+0000] {local_task_job_runner.py:222} INFO - ::endgroup::
[2025-06-27T07:20:45.942+0000] {local_task_job_runner.py:120} INFO - ::group::Pre task execution logs
[2025-06-27T07:20:46.023+0000] {taskinstance.py:2076} INFO - Dependencies all met for dep_context=non-requeueable deps ti=<TaskInstance: STG4_MEDIDORES.run_hop_pipeline scheduled__2025-06-27T05:21:00+00:00 [queued]>
[2025-06-27T07:20:46.050+0000] {taskinstance.py:2076} INFO - Dependencies all met for dep_context=requeueable deps ti=<TaskInstance: STG4_MEDIDORES.run_hop_pipeline scheduled__2025-06-27T05:21:00+00:00 [queued]>
[2025-06-27T07:20:46.057+0000] {taskinstance.py:2306} INFO - Starting attempt 1 of 2
[2025-06-27T07:20:46.136+0000] {taskinstance.py:2330} INFO - Executing <Task(DockerOperator): run_hop_pipeline> on 2025-06-27 05:21:00+00:00
[2025-06-27T07:20:46.171+0000] {warnings.py:110} WARNING - /home/***/.local/lib/python3.12/site-packages/***/task/task_runner/standard_task_runner.py:61: DeprecationWarning: This process (pid=65) is multi-threaded, use of fork() may lead to deadlocks in the child.
  pid = os.fork()

[2025-06-27T07:20:46.175+0000] {standard_task_runner.py:63} INFO - Started process 72 to run task
[2025-06-27T07:20:46.188+0000] {standard_task_runner.py:90} INFO - Running: ['***', 'tasks', 'run', 'STG4_MEDIDORES', 'run_hop_pipeline', 'scheduled__2025-06-27T05:21:00+00:00', '--job-id', '6', '--raw', '--subdir', 'DAGS_FOLDER/apache-hop-dag-simple.py', '--cfg-path', '/tmp/tmpty5y2t8a']
[2025-06-27T07:20:46.199+0000] {standard_task_runner.py:91} INFO - Job 6: Subtask run_hop_pipeline
[2025-06-27T07:20:46.467+0000] {task_command.py:426} INFO - Running <TaskInstance: STG4_MEDIDORES.run_hop_pipeline scheduled__2025-06-27T05:21:00+00:00 [running]> on host 5e15c4a8eeb7
[2025-06-27T07:20:46.713+0000] {taskinstance.py:2648} INFO - Exporting env vars: AIRFLOW_CTX_DAG_OWNER='***' AIRFLOW_CTX_DAG_ID='STG4_MEDIDORES' AIRFLOW_CTX_TASK_ID='run_hop_pipeline' AIRFLOW_CTX_EXECUTION_DATE='2025-06-27T05:21:00+00:00' AIRFLOW_CTX_TRY_NUMBER='1' AIRFLOW_CTX_DAG_RUN_ID='scheduled__2025-06-27T05:21:00+00:00'
[2025-06-27T07:20:46.716+0000] {taskinstance.py:430} INFO - ::endgroup::
[2025-06-27T07:20:46.987+0000] {docker.py:366} INFO - Starting docker container from image apache/hop:latest
[2025-06-27T07:20:47.021+0000] {docker.py:374} WARNING - Using remote engine or docker-in-docker and mounting temporary volume from host is not supported. Falling back to `mount_tmp_dir=False` mode. You can set `mount_tmp_dir` parameter to False to disable mounting and remove the warning
[2025-06-27T07:20:48.503+0000] {docker.py:436} INFO - 2025/06/27 07:20:48 - The project folder for ProyectoSmartMed is set to: /files
2025/06/27 07:20:48 - Running the entrypoint script with PID 7
[2025-06-27T07:20:48.508+0000] {docker.py:436} INFO - 2025/06/27 07:20:48 - The specified project folder exists
[2025-06-27T07:20:48.510+0000] {docker.py:436} INFO - 2025/06/27 07:20:48 - Registering project ProyectoSmartMed in the Hop container configuration
[2025-06-27T07:20:48.514+0000] {docker.py:436} INFO - 2025/06/27 07:20:48 - /opt/hop/hop-conf.sh --project=ProyectoSmartMed --project-create --project-home='/files' --project-config-file='project-config.json'
[2025-06-27T07:22:15.388+0000] {docker.py:436} INFO - Creating project 'ProyectoSmartMed'
[2025-06-27T07:22:16.806+0000] {docker.py:436} INFO - Project 'ProyectoSmartMed' was created for home folder : /files
[2025-06-27T07:22:16.848+0000] {docker.py:436} INFO - Error found during execution!
[2025-06-27T07:22:16.864+0000] {docker.py:436} INFO - picocli.CommandLine$ExecutionException: There was an error handling options
	at org.apache.hop.config.HopConfig.run(HopConfig.java:101)
	at org.apache.hop.config.HopConfig.main(HopConfig.java:181)
Caused by: org.apache.hop.core.exception.HopException: 
Error handling environment configuration options

Error checking config filename 'file:/files/project-config.json' existence while loading project

Error saving project configuration to file 'file:/files/project-config.json'
No content to map due to end-of-input
 at [Source: (org.apache.commons.vfs2.provider.DefaultFileContent$FileContentInputStream); line: 1, column: 0]



	at org.apache.hop.projects.project.ManageProjectsOptionPlugin.handleOption(ManageProjectsOptionPlugin.java:200)
	at org.apache.hop.config.HopConfig.run(HopConfig.java:92)
	... 1 more
Caused by: org.apache.hop.core.exception.HopException: 
Error checking config filename 'file:/files/project-config.json' existence while loading project

Error saving project configuration to file 'file:/files/project-config.json'
No content to map due to end-of-input
 at [Source: (org.apache.commons.vfs2.provider.DefaultFileContent$FileContentInputStream); line: 1, column: 0]


	at org.apache.hop.projects.project.ProjectConfig.loadProject(ProjectConfig.java:109)
	at org.apache.hop.projects.project.ManageProjectsOptionPlugin.createProject(ManageProjectsOptionPlugin.java:383)
	at org.apache.hop.projects.project.ManageProjectsOptionPlugin.handleOption(ManageProjectsOptionPlugin.java:174)
	... 2 more
Caused by: org.apache.hop.core.exception.HopException: 
Error saving project configuration to file 'file:/files/project-config.json'
No content to map due to end-of-input
 at [Source: (org.apache.commons.vfs2.provider.DefaultFileContent$FileContentInputStream); line: 1, column: 0]

	at org.apache.hop.projects.project.Project.readFromFile(Project.java:154)
	at org.apache.hop.projects.project.ProjectConfig.loadProject(ProjectConfig.java:106)
	... 4 more
Caused by: com.fasterxml.jackson.databind.exc.MismatchedInputException: No content to map due to end-of-input
 at [Source: (org.apache.commons.vfs2.provider.DefaultFileContent$FileContentInputStream); line: 1, column: 0]
	at com.fasterxml.jackson.databind.exc.MismatchedInputException.from(MismatchedInputException.java:59)
	at com.fasterxml.jackson.databind.ObjectMapper._initForReading(ObjectMapper.java:4916)
	at com.fasterxml.jackson.databind.ObjectMapper._readMapAndClose(ObjectMapper.java:4818)
	at com.fasterxml.jackson.databind.ObjectMapper.readValue(ObjectMapper.java:3809)
	at org.apache.hop.projects.project.Project.readFromFile(Project.java:142)
	... 5 more
[2025-06-27T07:22:17.127+0000] {docker.py:436} INFO - 2025/06/27 07:22:17 - Not creating an environment in the container
[2025-06-27T07:22:17.137+0000] {docker.py:436} INFO - 2025/06/27 07:22:17 - Running a single hop workflow / pipeline (${PROJECT_HOME}/Pipelines/STG4_MEDIDORES.hpl)
[2025-06-27T07:22:53.788+0000] {docker.py:436} INFO - 2025/06/27 07:22:53 - HopRun - Enabling project 'ProyectoSmartMed'
[2025-06-27T07:22:54.732+0000] {docker.py:436} INFO - 2025/06/27 07:22:54 - HopRun - Starting pipeline: /files/Pipelines/STG4_MEDIDORES.hpl
[2025-06-27T07:22:54.769+0000] {docker.py:436} INFO - 2025/06/27 07:22:54 - STG4_MEDIDORES - Executing this pipeline using the Local Pipeline Engine with run configuration 'local'
[2025-06-27T07:22:54.791+0000] {docker.py:436} INFO - 2025/06/27 07:22:54 - STG4_MEDIDORES - Execution started for pipeline [STG4_MEDIDORES]
[2025-06-27T07:23:08.808+0000] {docker.py:436} INFO - 2025/06/27 07:23:08 - STG3_MEDIDORES.0 - ERROR: An error occurred, processing will be stopped: 
2025/06/27 07:23:08 - STG3_MEDIDORES.0 - Error occurred while trying to connect to the database
2025/06/27 07:23:08 - STG3_MEDIDORES.0 - 
2025/06/27 07:23:08 - STG3_MEDIDORES.0 - Error connecting to database: (using class org.postgresql.Driver)
2025/06/27 07:23:08 - STG3_MEDIDORES.0 - The connection attempt failed.
[2025-06-27T07:23:08.814+0000] {docker.py:436} INFO - 2025/06/27 07:23:08 - STG4_MEDIDORES.0 - ERROR: An error occurred initializing this transform: 
2025/06/27 07:23:08 - STG4_MEDIDORES.0 - Error occurred while trying to connect to the database
2025/06/27 07:23:08 - STG4_MEDIDORES.0 - 
2025/06/27 07:23:08 - STG4_MEDIDORES.0 - Error connecting to database: (using class org.postgresql.Driver)
2025/06/27 07:23:08 - STG4_MEDIDORES.0 - The connection attempt failed.
[2025-06-27T07:23:08.825+0000] {docker.py:436} INFO - 2025/06/27 07:23:08 - STG3_MEDIDORES.0 - ERROR: Error initializing transform [STG3_MEDIDORES]
[2025-06-27T07:23:08.830+0000] {docker.py:436} INFO - 2025/06/27 07:23:08 - STG4_MEDIDORES.0 - ERROR: Error initializing transform [STG4_MEDIDORES]
[2025-06-27T07:23:08.839+0000] {docker.py:436} INFO - 2025/06/27 07:23:08 - STG4_MEDIDORES - ERROR: Transform [STG3_MEDIDORES.0] failed to initialize!
2025/06/27 07:23:08 - STG4_MEDIDORES - ERROR: Transform [STG4_MEDIDORES.0] failed to initialize!
2025/06/27 07:23:08 - STG3_MEDIDORES.0 - Finished reading query, closing connection.
[2025-06-27T07:23:08.850+0000] {docker.py:436} INFO - 2025/06/27 07:23:08 - STG4_MEDIDORES.0 - ERROR: Unexpected error rolling back the database connection.
[2025-06-27T07:23:08.853+0000] {docker.py:436} INFO - 2025/06/27 07:23:08 - STG4_MEDIDORES.0 - ERROR: org.apache.hop.core.exception.HopDatabaseException: 
2025/06/27 07:23:08 - STG4_MEDIDORES.0 - Unable to get database metadata from this database connection
2025/06/27 07:23:08 - STG4_MEDIDORES.0 - 
2025/06/27 07:23:08 - STG4_MEDIDORES.0 - Error connecting to database [***]
2025/06/27 07:23:08 - STG4_MEDIDORES.0 - 
2025/06/27 07:23:08 - STG4_MEDIDORES.0 - 
2025/06/27 07:23:08 - STG4_MEDIDORES.0 - 	at org.apache.hop.core.database.Database.getDatabaseMetaData(Database.java:2897)
2025/06/27 07:23:08 - STG4_MEDIDORES.0 - 	at org.apache.hop.core.database.Database.rollback(Database.java:737)
2025/06/27 07:23:08 - STG4_MEDIDORES.0 - 	at org.apache.hop.core.database.Database.rollback(Database.java:729)
2025/06/27 07:23:08 - STG4_MEDIDORES.0 - 	at org.apache.hop.pipeline.transforms.tableoutput.TableOutput.emptyAndCommitBatchBuffers(TableOutput.java:648)
2025/06/27 07:23:08 - STG4_MEDIDORES.0 - 	at org.apache.hop.pipeline.transforms.tableoutput.TableOutput.dispose(Tabl
[2025-06-27T07:23:08.863+0000] {docker.py:436} INFO - eOutput.java:568)
2025/06/27 07:23:08 - STG4_MEDIDORES.0 - 	at org.apache.hop.pipeline.Pipeline.prepareExecution(Pipeline.java:1056)
2025/06/27 07:23:08 - STG4_MEDIDORES.0 - 	at org.apache.hop.pipeline.engines.local.LocalPipelineEngine.prepareExecution(LocalPipelineEngine.java:232)
2025/06/27 07:23:08 - STG4_MEDIDORES.0 - 	at org.apache.hop.run.HopRun.runPipeline(HopRun.java:335)
2025/06/27 07:23:08 - STG4_MEDIDORES.0 - 	at org.apache.hop.run.HopRun.runPipeline(HopRun.java:292)
2025/06/27 07:23:08 - STG4_MEDIDORES.0 - 	at org.apache.hop.run.HopRun.run(HopRun.java:203)
2025/06/27 07:23:08 - STG4_MEDIDORES.0 - 	at org.apache.hop.run.HopRun.main(HopRun.java:931)
2025/06/27 07:23:08 - STG4_MEDIDORES.0 - Caused by: org.apache.hop.core.exception.HopDatabaseException: 
2025/06/27 07:23:08 - STG4_MEDIDORES.0 - Error connecting to database [***]
2025/06/27 07:23:08 - STG4_MEDIDORES.0 - 
2025/06/27 07:23:08 - STG4_MEDIDORES.0 - 	at org.apache.hop.core.database.Database.getDatabaseMetaData(Database.java:2890)
2025/06/27 07:23:08 - STG4_MEDIDORES.0 - 	... 10 more
[2025-06-27T07:23:08.868+0000] {docker.py:436} INFO - Error found during execution!
[2025-06-27T07:23:08.871+0000] {docker.py:436} INFO - picocli.CommandLine$ExecutionException: There was an error during execution of file '${PROJECT_HOME}/Pipelines/STG4_MEDIDORES.hpl'
	at org.apache.hop.run.HopRun.run(HopRun.java:212)
	at org.apache.hop.run.HopRun.main(HopRun.java:931)
Caused by: picocli.CommandLine$ExecutionException: There was an error during execution of pipeline '${PROJECT_HOME}/Pipelines/STG4_MEDIDORES.hpl'
	at org.apache.hop.run.HopRun.runPipeline(HopRun.java:294)
	at org.apache.hop.run.HopRun.run(HopRun.java:203)
	... 1 more
Caused by: picocli.CommandLine$ExecutionException: Error running pipeline locally
	at org.apache.hop.run.HopRun.runPipeline(HopRun.java:340)
	at org.apache.hop.run.HopRun.runPipeline(HopRun.java:292)
	... 2 more
Caused by: org.apache.hop.core.exception.HopException: 
We failed to initialize at least one transform.  Execution can not begin!


	at org.apache.hop.pipeline.Pipeline.prepareExecution(Pipeline.java:1088)
	at org.apache.hop.pipeline.engines.local.LocalPipelineEngine.prepareExecution(LocalPipelineEngine.java:232)
	at org.apache.hop.run.HopRun.runPipeline(HopRun.java:335)
	... 3 more
[2025-06-27T07:23:10.431+0000] {taskinstance.py:441} INFO - ::group::Post task execution logs
[2025-06-27T07:23:10.534+0000] {taskinstance.py:2905} ERROR - Task failed with exception
Traceback (most recent call last):
  File "/home/airflow/.local/lib/python3.12/site-packages/docker/api/client.py", line 265, in _raise_for_status
    response.raise_for_status()
  File "/home/airflow/.local/lib/python3.12/site-packages/requests/models.py", line 1021, in raise_for_status
    raise HTTPError(http_error_msg, response=self)
requests.exceptions.HTTPError: 400 Client Error: Bad Request for url: http+docker://localhost/v1.50/containers/create

The above exception was the direct cause of the following exception:

Traceback (most recent call last):
  File "/home/airflow/.local/lib/python3.12/site-packages/airflow/providers/docker/operators/docker.py", line 371, in _run_image
    return self._run_image_with_mounts([*self.mounts, tmp_mount], add_tmp_variable=True)
           ^^^^^^^^^^^^^^^^^^^^^^^^^^^^^^^^^^^^^^^^^^^^^^^^^^^^^^^^^^^^^^^^^^^^^^^^^^^^^
  File "/home/airflow/.local/lib/python3.12/site-packages/airflow/providers/docker/operators/docker.py", line 398, in _run_image_with_mounts
    self.container = self.cli.create_container(
                     ^^^^^^^^^^^^^^^^^^^^^^^^^^
  File "/home/airflow/.local/lib/python3.12/site-packages/docker/api/container.py", line 439, in create_container
    return self.create_container_from_config(config, name, platform)
           ^^^^^^^^^^^^^^^^^^^^^^^^^^^^^^^^^^^^^^^^^^^^^^^^^^^^^^^^^
  File "/home/airflow/.local/lib/python3.12/site-packages/docker/api/container.py", line 456, in create_container_from_config
    return self._result(res, True)
           ^^^^^^^^^^^^^^^^^^^^^^^
  File "/home/airflow/.local/lib/python3.12/site-packages/docker/api/client.py", line 271, in _result
    self._raise_for_status(response)
  File "/home/airflow/.local/lib/python3.12/site-packages/docker/api/client.py", line 267, in _raise_for_status
    raise create_api_error_from_http_exception(e) from e
          ^^^^^^^^^^^^^^^^^^^^^^^^^^^^^^^^^^^^^^^
  File "/home/airflow/.local/lib/python3.12/site-packages/docker/errors.py", line 39, in create_api_error_from_http_exception
    raise cls(e, response=response, explanation=explanation) from e
docker.errors.APIError: 400 Client Error for http+docker://localhost/v1.50/containers/create: Bad Request ("invalid mount config for type "bind": bind source path does not exist: /tmp/airflowtmp1idk2imj")

During handling of the above exception, another exception occurred:

Traceback (most recent call last):
  File "/home/airflow/.local/lib/python3.12/site-packages/airflow/models/taskinstance.py", line 465, in _execute_task
    result = _execute_callable(context=context, **execute_callable_kwargs)
             ^^^^^^^^^^^^^^^^^^^^^^^^^^^^^^^^^^^^^^^^^^^^^^^^^^^^^^^^^^^^^
  File "/home/airflow/.local/lib/python3.12/site-packages/airflow/models/taskinstance.py", line 432, in _execute_callable
    return execute_callable(context=context, **execute_callable_kwargs)
           ^^^^^^^^^^^^^^^^^^^^^^^^^^^^^^^^^^^^^^^^^^^^^^^^^^^^^^^^^^^^
  File "/home/airflow/.local/lib/python3.12/site-packages/airflow/models/baseoperator.py", line 400, in wrapper
    return func(self, *args, **kwargs)
           ^^^^^^^^^^^^^^^^^^^^^^^^^^^
  File "/home/airflow/.local/lib/python3.12/site-packages/airflow/providers/docker/operators/docker.py", line 509, in execute
    return self._run_image()
           ^^^^^^^^^^^^^^^^^
  File "/home/airflow/.local/lib/python3.12/site-packages/airflow/providers/docker/operators/docker.py", line 380, in _run_image
    return self._run_image_with_mounts(self.mounts, add_tmp_variable=False)
           ^^^^^^^^^^^^^^^^^^^^^^^^^^^^^^^^^^^^^^^^^^^^^^^^^^^^^^^^^^^^^^^^
  File "/home/airflow/.local/lib/python3.12/site-packages/airflow/providers/docker/operators/docker.py", line 444, in _run_image_with_mounts
    raise DockerContainerFailedException(f"Docker container failed: {result!r}", logs=log_lines)
airflow.providers.docker.exceptions.DockerContainerFailedException: Docker container failed: {'StatusCode': 1}
[2025-06-27T07:23:10.670+0000] {taskinstance.py:1206} INFO - Marking task as UP_FOR_RETRY. dag_id=STG4_MEDIDORES, task_id=run_hop_pipeline, run_id=scheduled__2025-06-27T05:21:00+00:00, execution_date=20250627T052100, start_date=20250627T072046, end_date=20250627T072310
[2025-06-27T07:23:10.804+0000] {standard_task_runner.py:110} ERROR - Failed to execute job 6 for task run_hop_pipeline (Docker container failed: {'StatusCode': 1}; 72)
[2025-06-27T07:23:10.939+0000] {local_task_job_runner.py:240} INFO - Task exited with return code 1
[2025-06-27T07:23:11.053+0000] {taskinstance.py:3498} INFO - 0 downstream tasks scheduled from follow-on schedule check
[2025-06-27T07:23:11.062+0000] {local_task_job_runner.py:222} INFO - ::endgroup::
