[2025-06-27T07:28:11.955+0000] {local_task_job_runner.py:120} INFO - ::group::Pre task execution logs
[2025-06-27T07:28:12.014+0000] {taskinstance.py:2076} INFO - Dependencies all met for dep_context=non-requeueable deps ti=<TaskInstance: STG4_MEDIDORES.run_hop_pipeline scheduled__2025-06-27T05:21:00+00:00 [queued]>
[2025-06-27T07:28:12.026+0000] {taskinstance.py:2076} INFO - Dependencies all met for dep_context=requeueable deps ti=<TaskInstance: STG4_MEDIDORES.run_hop_pipeline scheduled__2025-06-27T05:21:00+00:00 [queued]>
[2025-06-27T07:28:12.026+0000] {taskinstance.py:2306} INFO - Starting attempt 2 of 2
[2025-06-27T07:28:12.050+0000] {taskinstance.py:2330} INFO - Executing <Task(DockerOperator): run_hop_pipeline> on 2025-06-27 05:21:00+00:00
[2025-06-27T07:28:12.060+0000] {warnings.py:110} WARNING - /home/***/.local/lib/python3.12/site-packages/***/task/task_runner/standard_task_runner.py:61: DeprecationWarning: This process (pid=170) is multi-threaded, use of fork() may lead to deadlocks in the child.
  pid = os.fork()

[2025-06-27T07:28:12.064+0000] {standard_task_runner.py:63} INFO - Started process 172 to run task
[2025-06-27T07:28:12.063+0000] {standard_task_runner.py:90} INFO - Running: ['***', 'tasks', 'run', 'STG4_MEDIDORES', 'run_hop_pipeline', 'scheduled__2025-06-27T05:21:00+00:00', '--job-id', '10', '--raw', '--subdir', 'DAGS_FOLDER/apache-hop-dag-simple.py', '--cfg-path', '/tmp/tmpn7tciqcr']
[2025-06-27T07:28:12.070+0000] {standard_task_runner.py:91} INFO - Job 10: Subtask run_hop_pipeline
[2025-06-27T07:28:12.157+0000] {task_command.py:426} INFO - Running <TaskInstance: STG4_MEDIDORES.run_hop_pipeline scheduled__2025-06-27T05:21:00+00:00 [running]> on host 5e15c4a8eeb7
[2025-06-27T07:28:12.274+0000] {taskinstance.py:2648} INFO - Exporting env vars: AIRFLOW_CTX_DAG_OWNER='***' AIRFLOW_CTX_DAG_ID='STG4_MEDIDORES' AIRFLOW_CTX_TASK_ID='run_hop_pipeline' AIRFLOW_CTX_EXECUTION_DATE='2025-06-27T05:21:00+00:00' AIRFLOW_CTX_TRY_NUMBER='2' AIRFLOW_CTX_DAG_RUN_ID='scheduled__2025-06-27T05:21:00+00:00'
[2025-06-27T07:28:12.276+0000] {taskinstance.py:430} INFO - ::endgroup::
[2025-06-27T07:28:12.398+0000] {docker.py:366} INFO - Starting docker container from image apache/hop:latest
[2025-06-27T07:28:12.421+0000] {docker.py:374} WARNING - Using remote engine or docker-in-docker and mounting temporary volume from host is not supported. Falling back to `mount_tmp_dir=False` mode. You can set `mount_tmp_dir` parameter to False to disable mounting and remove the warning
[2025-06-27T07:28:12.964+0000] {docker.py:436} INFO - 2025/06/27 07:28:12 - Running the entrypoint script with PID 7
[2025-06-27T07:28:12.967+0000] {docker.py:436} INFO - 2025/06/27 07:28:12 - The project folder for ProyectoSmartMed is set to: /files
[2025-06-27T07:28:12.971+0000] {docker.py:436} INFO - 2025/06/27 07:28:12 - The specified project folder exists
[2025-06-27T07:28:12.972+0000] {docker.py:436} INFO - 2025/06/27 07:28:12 - Registering project ProyectoSmartMed in the Hop container configuration
[2025-06-27T07:28:12.974+0000] {docker.py:436} INFO - 2025/06/27 07:28:12 - /opt/hop/hop-conf.sh --project=ProyectoSmartMed --project-create --project-home='/files' --project-config-file='project-config.json'
[2025-06-27T07:29:14.689+0000] {docker.py:436} INFO - Creating project 'ProyectoSmartMed'
[2025-06-27T07:29:15.951+0000] {docker.py:436} INFO - Project 'ProyectoSmartMed' was created for home folder : /files
[2025-06-27T07:29:16.427+0000] {docker.py:436} INFO - Configuration file for project 'ProyectoSmartMed' was saved to : file:/files/project-config.json
[2025-06-27T07:29:16.665+0000] {docker.py:436} INFO - 2025/06/27 07:29:16 - Not creating an environment in the container
[2025-06-27T07:29:16.823+0000] {docker.py:436} INFO - 2025/06/27 07:29:16 - Running a single hop workflow / pipeline (${PROJECT_HOME}/Pipelines/STG4_MEDIDORES.hpl)
[2025-06-27T07:29:46.791+0000] {docker.py:436} INFO - 2025/06/27 07:29:46 - HopRun - Enabling project 'ProyectoSmartMed'
[2025-06-27T07:29:47.628+0000] {docker.py:436} INFO - 2025/06/27 07:29:47 - HopRun - Starting pipeline: /files/Pipelines/STG4_MEDIDORES.hpl
[2025-06-27T07:29:47.652+0000] {docker.py:436} INFO - 2025/06/27 07:29:47 - STG4_MEDIDORES - Executing this pipeline using the Local Pipeline Engine with run configuration 'local'
[2025-06-27T07:29:47.718+0000] {docker.py:436} INFO - 2025/06/27 07:29:47 - STG4_MEDIDORES - Execution started for pipeline [STG4_MEDIDORES]
[2025-06-27T07:30:01.044+0000] {docker.py:436} INFO - 2025/06/27 07:30:01 - STG3_MEDIDORES.0 - ERROR: An error occurred, processing will be stopped: 
2025/06/27 07:30:01 - STG3_MEDIDORES.0 - Error occurred while trying to connect to the database
2025/06/27 07:30:01 - STG3_MEDIDORES.0 - 
2025/06/27 07:30:01 - STG3_MEDIDORES.0 - Error connecting to database: (using class org.postgresql.Driver)
2025/06/27 07:30:01 - STG3_MEDIDORES.0 - The connection attempt failed.
[2025-06-27T07:30:01.057+0000] {docker.py:436} INFO - 2025/06/27 07:30:01 - STG4_MEDIDORES.0 - ERROR: An error occurred initializing this transform: 
2025/06/27 07:30:01 - STG4_MEDIDORES.0 - Error occurred while trying to connect to the database
2025/06/27 07:30:01 - STG4_MEDIDORES.0 - 
2025/06/27 07:30:01 - STG4_MEDIDORES.0 - Error connecting to database: (using class org.postgresql.Driver)
2025/06/27 07:30:01 - STG4_MEDIDORES.0 - The connection attempt failed.
[2025-06-27T07:30:01.059+0000] {docker.py:436} INFO - 2025/06/27 07:30:01 - STG3_MEDIDORES.0 - ERROR: Error initializing transform [STG3_MEDIDORES]
[2025-06-27T07:30:01.060+0000] {docker.py:436} INFO - 2025/06/27 07:30:01 - STG4_MEDIDORES.0 - ERROR: Error initializing transform [STG4_MEDIDORES]
[2025-06-27T07:30:01.075+0000] {docker.py:436} INFO - 2025/06/27 07:30:01 - STG4_MEDIDORES - ERROR: Transform [STG3_MEDIDORES.0] failed to initialize!
2025/06/27 07:30:01 - STG4_MEDIDORES - ERROR: Transform [STG4_MEDIDORES.0] failed to initialize!
[2025-06-27T07:30:01.077+0000] {docker.py:436} INFO - 2025/06/27 07:30:01 - STG3_MEDIDORES.0 - Finished reading query, closing connection.
2025/06/27 07:30:01 - STG4_MEDIDORES.0 - ERROR: Unexpected error rolling back the database connection.
[2025-06-27T07:30:01.079+0000] {docker.py:436} INFO - 2025/06/27 07:30:01 - STG4_MEDIDORES.0 - ERROR: org.apache.hop.core.exception.HopDatabaseException: 
2025/06/27 07:30:01 - STG4_MEDIDORES.0 - Unable to get database metadata from this database connection
2025/06/27 07:30:01 - STG4_MEDIDORES.0 - 
2025/06/27 07:30:01 - STG4_MEDIDORES.0 - Error connecting to database [***]
2025/06/27 07:30:01 - STG4_MEDIDORES.0 - 
2025/06/27 07:30:01 - STG4_MEDIDORES.0 - 
2025/06/27 07:30:01 - STG4_MEDIDORES.0 - 	at org.apache.hop.core.database.Database.getDatabaseMetaData(Database.java:2897)
2025/06/27 07:30:01 - STG4_MEDIDORES.0 - 	at org.apache.hop.core.database.Database.rollback(Database.java:737)
2025/06/27 07:30:01 - STG4_MEDIDORES.0 - 	at org.apache.hop.core.database.Database.rollback(Database.java:729)
2025/06/27 07:30:01 - STG4_MEDIDORES.0 - 	at org.apache.hop.pipeline.transforms.tableoutput.TableOutput.emptyAndCommitBatchBuffers(TableOutput.java:648)
2025/06/27 07:30:01 - STG4_MEDIDORES.0 - 	at org.apache.hop.pipeline.transforms.tableoutput.TableOutput.dispose(Tabl
[2025-06-27T07:30:01.080+0000] {docker.py:436} INFO - eOutput.java:568)
2025/06/27 07:30:01 - STG4_MEDIDORES.0 - 	at org.apache.hop.pipeline.Pipeline.prepareExecution(Pipeline.java:1056)
2025/06/27 07:30:01 - STG4_MEDIDORES.0 - 	at org.apache.hop.pipeline.engines.local.LocalPipelineEngine.prepareExecution(LocalPipelineEngine.java:232)
2025/06/27 07:30:01 - STG4_MEDIDORES.0 - 	at org.apache.hop.run.HopRun.runPipeline(HopRun.java:335)
2025/06/27 07:30:01 - STG4_MEDIDORES.0 - 	at org.apache.hop.run.HopRun.runPipeline(HopRun.java:292)
2025/06/27 07:30:01 - STG4_MEDIDORES.0 - 	at org.apache.hop.run.HopRun.run(HopRun.java:203)
2025/06/27 07:30:01 - STG4_MEDIDORES.0 - 	at org.apache.hop.run.HopRun.main(HopRun.java:931)
2025/06/27 07:30:01 - STG4_MEDIDORES.0 - Caused by: org.apache.hop.core.exception.HopDatabaseException: 
2025/06/27 07:30:01 - STG4_MEDIDORES.0 - Error connecting to database [***]
2025/06/27 07:30:01 - STG4_MEDIDORES.0 - 
2025/06/27 07:30:01 - STG4_MEDIDORES.0 - 	at org.apache.hop.core.database.Database.getDatabaseMetaData(Database.java:2890)
2025/0
[2025-06-27T07:30:01.082+0000] {docker.py:436} INFO - 6/27 07:30:01 - STG4_MEDIDORES.0 - 	... 10 more
[2025-06-27T07:30:01.083+0000] {docker.py:436} INFO - Error found during execution!
[2025-06-27T07:30:01.085+0000] {docker.py:436} INFO - picocli.CommandLine$ExecutionException: There was an error during execution of file '${PROJECT_HOME}/Pipelines/STG4_MEDIDORES.hpl'
	at org.apache.hop.run.HopRun.run(HopRun.java:212)
	at org.apache.hop.run.HopRun.main(HopRun.java:931)
Caused by: picocli.CommandLine$ExecutionException: There was an error during execution of pipeline '${PROJECT_HOME}/Pipelines/STG4_MEDIDORES.hpl'
	at org.apache.hop.run.HopRun.runPipeline(HopRun.java:294)
	at org.apache.hop.run.HopRun.run(HopRun.java:203)
	... 1 more
Caused by: picocli.CommandLine$ExecutionException: Error running pipeline locally
	at org.apache.hop.run.HopRun.runPipeline(HopRun.java:340)
	at org.apache.hop.run.HopRun.runPipeline(HopRun.java:292)
	... 2 more
Caused by: org.apache.hop.core.exception.HopException: 
We failed to initialize at least one transform.  Execution can not begin!


	at org.apache.hop.pipeline.Pipeline.prepareExecution(Pipeline.java:1088)
	at org.apache.hop.pipeline.engines.local.LocalPipelineEngine.prepareExecution(LocalPipelineEngine.java:
[2025-06-27T07:30:01.086+0000] {docker.py:436} INFO - 232)
	at org.apache.hop.run.HopRun.runPipeline(HopRun.java:335)
	... 3 more
[2025-06-27T07:30:02.011+0000] {taskinstance.py:441} INFO - ::group::Post task execution logs
[2025-06-27T07:30:02.102+0000] {taskinstance.py:2905} ERROR - Task failed with exception
Traceback (most recent call last):
  File "/home/airflow/.local/lib/python3.12/site-packages/docker/api/client.py", line 265, in _raise_for_status
    response.raise_for_status()
  File "/home/airflow/.local/lib/python3.12/site-packages/requests/models.py", line 1021, in raise_for_status
    raise HTTPError(http_error_msg, response=self)
requests.exceptions.HTTPError: 400 Client Error: Bad Request for url: http+docker://localhost/v1.50/containers/create

The above exception was the direct cause of the following exception:

Traceback (most recent call last):
  File "/home/airflow/.local/lib/python3.12/site-packages/airflow/providers/docker/operators/docker.py", line 371, in _run_image
    return self._run_image_with_mounts([*self.mounts, tmp_mount], add_tmp_variable=True)
           ^^^^^^^^^^^^^^^^^^^^^^^^^^^^^^^^^^^^^^^^^^^^^^^^^^^^^^^^^^^^^^^^^^^^^^^^^^^^^
  File "/home/airflow/.local/lib/python3.12/site-packages/airflow/providers/docker/operators/docker.py", line 398, in _run_image_with_mounts
    self.container = self.cli.create_container(
                     ^^^^^^^^^^^^^^^^^^^^^^^^^^
  File "/home/airflow/.local/lib/python3.12/site-packages/docker/api/container.py", line 439, in create_container
    return self.create_container_from_config(config, name, platform)
           ^^^^^^^^^^^^^^^^^^^^^^^^^^^^^^^^^^^^^^^^^^^^^^^^^^^^^^^^^
  File "/home/airflow/.local/lib/python3.12/site-packages/docker/api/container.py", line 456, in create_container_from_config
    return self._result(res, True)
           ^^^^^^^^^^^^^^^^^^^^^^^
  File "/home/airflow/.local/lib/python3.12/site-packages/docker/api/client.py", line 271, in _result
    self._raise_for_status(response)
  File "/home/airflow/.local/lib/python3.12/site-packages/docker/api/client.py", line 267, in _raise_for_status
    raise create_api_error_from_http_exception(e) from e
          ^^^^^^^^^^^^^^^^^^^^^^^^^^^^^^^^^^^^^^^
  File "/home/airflow/.local/lib/python3.12/site-packages/docker/errors.py", line 39, in create_api_error_from_http_exception
    raise cls(e, response=response, explanation=explanation) from e
docker.errors.APIError: 400 Client Error for http+docker://localhost/v1.50/containers/create: Bad Request ("invalid mount config for type "bind": bind source path does not exist: /tmp/airflowtmpwo3909q7")

During handling of the above exception, another exception occurred:

Traceback (most recent call last):
  File "/home/airflow/.local/lib/python3.12/site-packages/airflow/models/taskinstance.py", line 465, in _execute_task
    result = _execute_callable(context=context, **execute_callable_kwargs)
             ^^^^^^^^^^^^^^^^^^^^^^^^^^^^^^^^^^^^^^^^^^^^^^^^^^^^^^^^^^^^^
  File "/home/airflow/.local/lib/python3.12/site-packages/airflow/models/taskinstance.py", line 432, in _execute_callable
    return execute_callable(context=context, **execute_callable_kwargs)
           ^^^^^^^^^^^^^^^^^^^^^^^^^^^^^^^^^^^^^^^^^^^^^^^^^^^^^^^^^^^^
  File "/home/airflow/.local/lib/python3.12/site-packages/airflow/models/baseoperator.py", line 400, in wrapper
    return func(self, *args, **kwargs)
           ^^^^^^^^^^^^^^^^^^^^^^^^^^^
  File "/home/airflow/.local/lib/python3.12/site-packages/airflow/providers/docker/operators/docker.py", line 509, in execute
    return self._run_image()
           ^^^^^^^^^^^^^^^^^
  File "/home/airflow/.local/lib/python3.12/site-packages/airflow/providers/docker/operators/docker.py", line 380, in _run_image
    return self._run_image_with_mounts(self.mounts, add_tmp_variable=False)
           ^^^^^^^^^^^^^^^^^^^^^^^^^^^^^^^^^^^^^^^^^^^^^^^^^^^^^^^^^^^^^^^^
  File "/home/airflow/.local/lib/python3.12/site-packages/airflow/providers/docker/operators/docker.py", line 444, in _run_image_with_mounts
    raise DockerContainerFailedException(f"Docker container failed: {result!r}", logs=log_lines)
airflow.providers.docker.exceptions.DockerContainerFailedException: Docker container failed: {'StatusCode': 1}
[2025-06-27T07:30:02.124+0000] {taskinstance.py:1206} INFO - Marking task as FAILED. dag_id=STG4_MEDIDORES, task_id=run_hop_pipeline, run_id=scheduled__2025-06-27T05:21:00+00:00, execution_date=20250627T052100, start_date=20250627T072812, end_date=20250627T073002
[2025-06-27T07:30:02.188+0000] {standard_task_runner.py:110} ERROR - Failed to execute job 10 for task run_hop_pipeline (Docker container failed: {'StatusCode': 1}; 172)
[2025-06-27T07:30:02.272+0000] {local_task_job_runner.py:240} INFO - Task exited with return code 1
[2025-06-27T07:30:02.386+0000] {taskinstance.py:3498} INFO - 0 downstream tasks scheduled from follow-on schedule check
[2025-06-27T07:30:02.403+0000] {local_task_job_runner.py:222} INFO - ::endgroup::
