[2025-06-27T02:22:29.673+0000] {local_task_job_runner.py:120} INFO - ::group::Pre task execution logs
[2025-06-27T02:22:29.782+0000] {taskinstance.py:2076} INFO - Dependencies all met for dep_context=non-requeueable deps ti=<TaskInstance: WF_MAIN.run_hop_pipeline scheduled__2025-06-27T00:41:00+00:00 [queued]>
[2025-06-27T02:22:29.817+0000] {taskinstance.py:2076} INFO - Dependencies all met for dep_context=requeueable deps ti=<TaskInstance: WF_MAIN.run_hop_pipeline scheduled__2025-06-27T00:41:00+00:00 [queued]>
[2025-06-27T02:22:29.819+0000] {taskinstance.py:2306} INFO - Starting attempt 1 of 2
[2025-06-27T02:22:29.875+0000] {taskinstance.py:2330} INFO - Executing <Task(DockerOperator): run_hop_pipeline> on 2025-06-27 00:41:00+00:00
[2025-06-27T02:22:29.903+0000] {warnings.py:110} WARNING - /home/***/.local/lib/python3.12/site-packages/***/task/task_runner/standard_task_runner.py:61: DeprecationWarning: This process (pid=68) is multi-threaded, use of fork() may lead to deadlocks in the child.
  pid = os.fork()

[2025-06-27T02:22:29.916+0000] {standard_task_runner.py:63} INFO - Started process 69 to run task
[2025-06-27T02:22:29.922+0000] {standard_task_runner.py:90} INFO - Running: ['***', 'tasks', 'run', 'WF_MAIN', 'run_hop_pipeline', 'scheduled__2025-06-27T00:41:00+00:00', '--job-id', '4', '--raw', '--subdir', 'DAGS_FOLDER/apache-hop-dag-wf-main.py', '--cfg-path', '/tmp/tmp71_eo92d']
[2025-06-27T02:22:29.926+0000] {standard_task_runner.py:91} INFO - Job 4: Subtask run_hop_pipeline
[2025-06-27T02:22:30.419+0000] {task_command.py:426} INFO - Running <TaskInstance: WF_MAIN.run_hop_pipeline scheduled__2025-06-27T00:41:00+00:00 [running]> on host 0b41c6d28592
[2025-06-27T02:22:30.817+0000] {taskinstance.py:2648} INFO - Exporting env vars: AIRFLOW_CTX_DAG_OWNER='***' AIRFLOW_CTX_DAG_ID='WF_MAIN' AIRFLOW_CTX_TASK_ID='run_hop_pipeline' AIRFLOW_CTX_EXECUTION_DATE='2025-06-27T00:41:00+00:00' AIRFLOW_CTX_TRY_NUMBER='1' AIRFLOW_CTX_DAG_RUN_ID='scheduled__2025-06-27T00:41:00+00:00'
[2025-06-27T02:22:30.819+0000] {taskinstance.py:430} INFO - ::endgroup::
[2025-06-27T02:22:30.987+0000] {docker.py:493} INFO - Pulling docker image apache/hop:latest
[2025-06-27T02:22:33.716+0000] {docker.py:507} INFO - latest: Pulling from apache/hop
[2025-06-27T02:22:37.957+0000] {docker.py:507} INFO - 4f4fb700ef54: Pulling fs layer
[2025-06-27T02:22:37.961+0000] {docker.py:507} INFO - d4d2578e96cd: Pulling fs layer
[2025-06-27T02:22:37.962+0000] {docker.py:507} INFO - 9b6bc2cf1037: Pulling fs layer
[2025-06-27T02:22:37.963+0000] {docker.py:507} INFO - f488a4dddc73: Pulling fs layer
[2025-06-27T02:22:37.964+0000] {docker.py:507} INFO - bf26d906d0f5: Pulling fs layer
[2025-06-27T02:22:37.964+0000] {docker.py:507} INFO - 19f1029c3f10: Pulling fs layer
[2025-06-27T02:22:37.965+0000] {docker.py:507} INFO - eb2b48b7cabe: Pulling fs layer
[2025-06-27T02:22:37.966+0000] {docker.py:507} INFO - f18232174bc9: Pulling fs layer
[2025-06-27T02:22:38.018+0000] {docker.py:507} INFO - 4f4fb700ef54: Already exists
[2025-06-27T02:22:38.021+0000] {docker.py:507} INFO - 4f4fb700ef54: Pull complete
[2025-06-27T02:22:38.321+0000] {docker.py:507} INFO - 9b6bc2cf1037: Downloading
[2025-06-27T02:22:38.622+0000] {docker.py:507} INFO - f488a4dddc73: Downloading
[2025-06-27T02:22:38.728+0000] {docker.py:507} INFO - eb2b48b7cabe: Downloading
[2025-06-27T02:22:38.730+0000] {docker.py:507} INFO - d4d2578e96cd: Downloading
[2025-06-27T02:22:39.150+0000] {docker.py:507} INFO - bf26d906d0f5: Downloading
[2025-06-27T02:22:39.226+0000] {docker.py:507} INFO - f18232174bc9: Downloading
[2025-06-27T02:22:39.331+0000] {docker.py:507} INFO - 19f1029c3f10: Downloading
[2025-06-27T02:22:47.951+0000] {docker.py:507} INFO - 9b6bc2cf1037: Download complete
[2025-06-27T02:22:48.177+0000] {docker.py:507} INFO - eb2b48b7cabe: Download complete
[2025-06-27T02:22:48.266+0000] {docker.py:507} INFO - d4d2578e96cd: Download complete
[2025-06-27T02:22:49.046+0000] {docker.py:507} INFO - f18232174bc9: Download complete
[2025-06-27T02:22:49.065+0000] {docker.py:507} INFO - bf26d906d0f5: Download complete
[2025-06-27T02:22:49.127+0000] {docker.py:507} INFO - f18232174bc9: Extracting
[2025-06-27T02:22:52.550+0000] {docker.py:507} INFO - 19f1029c3f10: Download complete
[2025-06-27T02:22:54.179+0000] {docker.py:507} INFO - f18232174bc9: Pull complete
[2025-06-27T02:23:00.917+0000] {docker.py:507} INFO - d4d2578e96cd: Extracting
[2025-06-27T02:23:06.530+0000] {docker.py:507} INFO - d4d2578e96cd: Pull complete
[2025-06-27T02:23:09.851+0000] {docker.py:507} INFO - 19f1029c3f10: Extracting
[2025-06-27T02:23:24.902+0000] {docker.py:507} INFO - 19f1029c3f10: Pull complete
[2025-06-27T02:23:30.318+0000] {docker.py:507} INFO - bf26d906d0f5: Extracting
[2025-06-27T02:23:31.119+0000] {docker.py:507} INFO - bf26d906d0f5: Pull complete
[2025-06-27T02:23:40.706+0000] {docker.py:507} INFO - f488a4dddc73: Download complete
[2025-06-27T02:23:40.722+0000] {docker.py:507} INFO - f488a4dddc73: Extracting
[2025-06-27T02:24:20.315+0000] {docker.py:507} INFO - f488a4dddc73: Pull complete
[2025-06-27T02:24:20.535+0000] {docker.py:507} INFO - 9b6bc2cf1037: Pull complete
[2025-06-27T02:24:20.703+0000] {docker.py:507} INFO - eb2b48b7cabe: Pull complete
[2025-06-27T02:24:21.154+0000] {docker.py:502} INFO - Digest: sha256:950a95da3332a2782706665b58adeed820689d87e0ca5b54df59bc995b2d955e
[2025-06-27T02:24:21.160+0000] {docker.py:502} INFO - Status: Downloaded newer image for apache/hop:latest
[2025-06-27T02:24:21.161+0000] {docker.py:366} INFO - Starting docker container from image apache/hop:latest
[2025-06-27T02:24:21.310+0000] {taskinstance.py:441} INFO - ::group::Post task execution logs
[2025-06-27T02:24:21.316+0000] {taskinstance.py:2905} ERROR - Task failed with exception
Traceback (most recent call last):
  File "/home/airflow/.local/lib/python3.12/site-packages/docker/api/client.py", line 265, in _raise_for_status
    response.raise_for_status()
  File "/home/airflow/.local/lib/python3.12/site-packages/requests/models.py", line 1021, in raise_for_status
    raise HTTPError(http_error_msg, response=self)
requests.exceptions.HTTPError: 400 Client Error: Bad Request for url: http+docker://localhost/v1.50/containers/create

The above exception was the direct cause of the following exception:

Traceback (most recent call last):
  File "/home/airflow/.local/lib/python3.12/site-packages/airflow/models/taskinstance.py", line 465, in _execute_task
    result = _execute_callable(context=context, **execute_callable_kwargs)
             ^^^^^^^^^^^^^^^^^^^^^^^^^^^^^^^^^^^^^^^^^^^^^^^^^^^^^^^^^^^^^
  File "/home/airflow/.local/lib/python3.12/site-packages/airflow/models/taskinstance.py", line 432, in _execute_callable
    return execute_callable(context=context, **execute_callable_kwargs)
           ^^^^^^^^^^^^^^^^^^^^^^^^^^^^^^^^^^^^^^^^^^^^^^^^^^^^^^^^^^^^
  File "/home/airflow/.local/lib/python3.12/site-packages/airflow/models/baseoperator.py", line 400, in wrapper
    return func(self, *args, **kwargs)
           ^^^^^^^^^^^^^^^^^^^^^^^^^^^
  File "/home/airflow/.local/lib/python3.12/site-packages/airflow/providers/docker/operators/docker.py", line 509, in execute
    return self._run_image()
           ^^^^^^^^^^^^^^^^^
  File "/home/airflow/.local/lib/python3.12/site-packages/airflow/providers/docker/operators/docker.py", line 371, in _run_image
    return self._run_image_with_mounts([*self.mounts, tmp_mount], add_tmp_variable=True)
           ^^^^^^^^^^^^^^^^^^^^^^^^^^^^^^^^^^^^^^^^^^^^^^^^^^^^^^^^^^^^^^^^^^^^^^^^^^^^^
  File "/home/airflow/.local/lib/python3.12/site-packages/airflow/providers/docker/operators/docker.py", line 398, in _run_image_with_mounts
    self.container = self.cli.create_container(
                     ^^^^^^^^^^^^^^^^^^^^^^^^^^
  File "/home/airflow/.local/lib/python3.12/site-packages/docker/api/container.py", line 439, in create_container
    return self.create_container_from_config(config, name, platform)
           ^^^^^^^^^^^^^^^^^^^^^^^^^^^^^^^^^^^^^^^^^^^^^^^^^^^^^^^^^
  File "/home/airflow/.local/lib/python3.12/site-packages/docker/api/container.py", line 456, in create_container_from_config
    return self._result(res, True)
           ^^^^^^^^^^^^^^^^^^^^^^^
  File "/home/airflow/.local/lib/python3.12/site-packages/docker/api/client.py", line 271, in _result
    self._raise_for_status(response)
  File "/home/airflow/.local/lib/python3.12/site-packages/docker/api/client.py", line 267, in _raise_for_status
    raise create_api_error_from_http_exception(e) from e
          ^^^^^^^^^^^^^^^^^^^^^^^^^^^^^^^^^^^^^^^
  File "/home/airflow/.local/lib/python3.12/site-packages/docker/errors.py", line 39, in create_api_error_from_http_exception
    raise cls(e, response=response, explanation=explanation) from e
docker.errors.APIError: 400 Client Error for http+docker://localhost/v1.50/containers/create: Bad Request ("invalid mount config for type "bind": bind source path does not exist: /mnt/data/ProyectoSmart/ProyectoSmartMed")
[2025-06-27T02:24:21.378+0000] {taskinstance.py:1206} INFO - Marking task as UP_FOR_RETRY. dag_id=WF_MAIN, task_id=run_hop_pipeline, run_id=scheduled__2025-06-27T00:41:00+00:00, execution_date=20250627T004100, start_date=20250627T022229, end_date=20250627T022421
[2025-06-27T02:24:21.474+0000] {standard_task_runner.py:110} ERROR - Failed to execute job 4 for task run_hop_pipeline (400 Client Error for http+docker://localhost/v1.50/containers/create: Bad Request ("invalid mount config for type "bind": bind source path does not exist: /mnt/data/ProyectoSmart/ProyectoSmartMed"); 69)
[2025-06-27T02:24:21.557+0000] {local_task_job_runner.py:240} INFO - Task exited with return code 1
[2025-06-27T02:24:21.704+0000] {taskinstance.py:3498} INFO - 0 downstream tasks scheduled from follow-on schedule check
[2025-06-27T02:24:21.731+0000] {local_task_job_runner.py:222} INFO - ::endgroup::
